Workbook

Sheet Sheet1
A1: Vanilla | B1: 2024 M06 | C1: 2024 M07 | D1: 2024 M08 | E1: 2024 M09 | F1: 2024 M10 | G1: 2024 M11 | H1: 2024 M12 | I1: 2025 M01 | J1: 2025 M02 | K1: 2025 M03 | L1: 2025 M04 | M1: 2025 M05 | N1: 2025 M06 | O1: 2025 M07 | P1: 2025 M08 | Q1: 2025 M09 | R1: 2025 M10 | S1: 2025 M11 | T1: 2025 M12 | U1: 2026 M01 | V1: 2026 M02 | W1: 2026 M03 | X1: 2026 M04 | Z1: 2026 M05 | AA1: 2026 M06 | AB1: 2026 M07
A2: Model Score | B2: 129.86535 | C2: 129.38772 | D2: 129.53706 | E2: 129.51321 | F2: 129.6633 | G2: 129.25177 | H2: 129.68365 | I2: 129.53729 | J2: 129.39334 | K2: 129.77782 | L2: 129.71309 | M2: 129.61554 | N2: 129.44537 | O2: 129.27805 | P2: 129.24252 | Q2: 128.50927 | R2: 131.02134 | S2: 131.34683 | T2: 131.60241 | U2: 132.19218 | V2: 133.00749 | W2: 134.00485 | X2: 134.56534 | Z2: 135.68984 | AA2: 136.49663 | AB2: 137.33714
A3: Gross Loss Impact | B3: 1.2350139 | C3: 0.84904716 | D3: 0.70090476 | E3: 0.56275009 | F3: 0.86450977 | G3: 0.8529963 | H3: 0.80391234 | I3: -0.37146658 | J3: -1.331343 | K3: -1.3310358 | L3: -1.0313611 | M3: -0.96270848 | N3: -1.1899692 | O3: -0.53597967 | P3: 0.77591077 | Q3: 0.63856798 | R3: -0.39328784 | S3: -0.4232758 | T3: -0.44362951 | U3: -0.37766231 | V3: -0.39991915 | W3: -0.3620098 | X3: -0.27814421 | Z3: -0.40171856 | AA3: -0.56807543 | AB3: -0.50856782
A4: Recovery Impact | B4: 0 | C4: 0 | D4: 4.1385927 | E4: 2.1728524 | F4: 1.2089421 | G4: 2.3985009 | H4: 2.8807926 | I4: 2.2101138 | J4: 0.21822452 | K4: 0.8428232 | L4: 1.1157777 | M4: 0.63955836 | N4: 0.70121227 | O4: 0.9091134 | P4: 1.9626067 | Q4: 0.69362863 | R4: 2.8566221 | S4: 2.2408945 | T4: 1.9016229 | U4: 2.1476641 | V4: 1.1568778 | W4: 1.1652602 | X4: 2.2892371 | Z4: 3.39928 | AA4: 3.9973862 | AB4: 4.3730697
A5: LTV Impact | B5: 0 | C5: 0 | D5: 5.274014 | E5: 6.0441161 | F5: 5.7001074 | G5: 4.9095671 | H5: 5.2506239 | I5: 5.7305605 | J5: 5.4983855 | K5: 5.5410338 | L5: 6.3775837 | M5: 5.3167725 | N5: 4.7133478 | O5: 4.456834 | P5: 4.2805857 | Q5: 3.8856134 | R5: 4.6568337 | S5: 4.3504902 | T5: 3.9599386 | U5: 4.4325851 | V5: 4.9778418 | W5: 5.5671093 | X5: 5.8010146 | Z5: 6.4230083 | AA5: 6.1696385 | AB5: 6.3674505
A6: APR Impact | B6: 3.0477022 | C6: 3.3126513 | D6: 2.9733754 | E6: 2.2654378 | F6: 2.030886 | G6: 2.2986462 | H6: 2.3219703 | I6: 2.0589846 | J6: 1.82854 | K6: 1.8605635 | L6: 2.008678 | M6: 2.0073477 | N6: 2.1051038 | O6: 2.1982917 | P6: 2.0737623 | Q6: 2.0963242 | R6: 0.94504752 | S6: 1.1155418 | T6: 1.0915321 | U6: 1.0879239 | V6: 1.1750857 | W6: 1.5046504 | X6: 1.672337 | Z6: 1.7830943 | AA6: 1.8827435 | AB6: 2.0486788
A7: RAGU Score | B7: 134.14807 | C7: 133.54941 | D7: 142.62394 | E7: 140.55836 | F7: 139.46774 | G7: 139.71148 | H7: 140.94094 | I7: 139.16548 | J7: 135.60715 | K7: 136.69121 | L7: 138.18377 | M7: 136.61651 | N7: 135.77507 | O7: 136.30631 | P7: 138.33539 | Q7: 135.82341 | R7: 139.08655 | S7: 138.63048 | T7: 138.11187 | U7: 139.48269 | V7: 139.91738 | W7: 141.88307 | X7: 144.05041 | Z7: 146.89307 | AA7: 147.97832 | AB7: 149.61915
A8: Amount Financed | B8: 1462434.4 | C8: 10919536 | D8: 18319871 | E8: 17387364 | F8: 23124191 | G8: 23510721 | H8: 31543003 | I8: 35545767 | J8: 50802744 | K8: 55019552 | L8: 42442574 | M8: 40719961 | N8: 38242116 | O8: 43485810 | P8: 43419979 | Q8: 44626995 | R8: 31718897 | S8: 46957669 | T8: 48436705 | U8: 41847912 | V8: 51674677 | W8: 1.0772409e+08 | X8: 90227375 | Z8: 72604978 | AA8: 82073268 | AB8: 58437607
A9: Weighted LTV | B9: 1.94 | C9: 1.94 | D9: 1.4806492 | E9: 1.4311679 | F9: 1.4528566 | G9: 1.5052785 | H9: 1.4822056 | I9: 1.4509101 | J9: 1.465883 | K9: 1.4631095 | L9: 1.4107532 | M9: 1.4778123 | N9: 1.5188814 | O9: 1.5370394 | P9: 1.5497694 | Q9: 1.5790774 | R9: 1.522845 | S9: 1.5446952 | T9: 1.5734779 | U9: 1.5387784 | V9: 1.5006023 | W9: 1.4614189 | X9: 1.4464269 | Z9: 1.4080173 | AA9: 1.4234145 | AB9: 1.4113649
A10: Weighted APR | B10: 0.2064614 | C10: 0.20267641 | D10: 0.20752321 | E10: 0.2176366 | F10: 0.22098734 | G10: 0.2171622 | H10: 0.216829 | I10: 0.22058593 | J10: 0.223878 | K10: 0.22342052 | L10: 0.2213046 | M10: 0.2213236 | N10: 0.21992709 | O10: 0.21859583 | P10: 0.22037482 | Q10: 0.22005251 | R10: 0.23649932 | S10: 0.23406369 | T10: 0.23440668 | U10: 0.23445823 | V10: 0.23321306 | W10: 0.22850499 | X10: 0.22610947 | Z10: 0.22452722 | AA10: 0.22310366 | AB10: 0.22073316
C15: STE | D15: 2023 Q3 | E15: 2024 Q3 | F15: 2025 Q3 | G15: 2026 Q1 | H15: 2026 Q2 | I15: 2026 Q3
E16: =AVERAGE(C2:E2) -> 129.47933 | F16: =AVERAGE(D2:F2) -> 129.57119 | G16: =AVERAGE(U2:W2) -> 133.06818 | H16: =AVERAGE(X2:AA2) -> 135.58394 | I16: 137.33714
E17: =AVERAGE(C3:E3) -> 0.70423401 | F17: =AVERAGE(D3:F3) -> 0.70938821 | G17: =AVERAGE(U3:W3) -> -0.37986375 | H17: =AVERAGE(X3:AA3) -> -0.4159794 | I17: -0.50856782
E18: =AVERAGE(C4:E4) -> 2.103815 | F18: =AVERAGE(D4:F4) -> 2.5067957 | G18: =AVERAGE(U4:W4) -> 1.4899341 | H18: =AVERAGE(X4:AA4) -> 3.2286344 | I18: 4.3730697
E19: =AVERAGE(C5:E5) -> 3.77271 | F19: =AVERAGE(D5:F5) -> 5.6727458 | G19: =AVERAGE(U5:W5) -> 4.9925121 | H19: =AVERAGE(X5:AA5) -> 6.1312205 | I19: 6.3674505
E20: =AVERAGE(C6:E6) -> 2.8504882 | F20: =AVERAGE(D6:F6) -> 2.4232331 | G20: =AVERAGE(U6:W6) -> 1.2558867 | H20: =AVERAGE(X6:AA6) -> 1.7793916 | I20: 2.0486788
E21: =AVERAGE(C7:E7) -> 138.91057 | F21: =AVERAGE(D7:F7) -> 140.88335 | G21: =AVERAGE(U7:W7) -> 140.42771 | H21: =AVERAGE(X7:AA7) -> 146.30727 | I21: 149.61915
E22: =SUM(C8:E8) -> 46626771 | F22: =SUM(D8:F8) -> 58831426 | G22: =SUM(U8:W8) -> 2.0124667e+08 | H22: =SUM(X8:AA8) -> 2.4490562e+08 | I22: 58437607
E23: =AVERAGE(C9:E9) -> 1.6172724 | F23: =AVERAGE(D9:F9) -> 1.4548912 | G23: =AVERAGE(U9:W9) -> 1.5002665 | H23: =AVERAGE(X9:AA9) -> 1.4259529 | I23: 1.4113649
E24: =AVERAGE(C10:E10) -> 0.20927874 | F24: =AVERAGE(D10:F10) -> 0.21538238 | G24: =AVERAGE(U10:W10) -> 0.23205876 | H24: =AVERAGE(X10:AA10) -> 0.22458012 | I24: 0.22073316
C29: KMX | D29: 2023 Q3 | E29: 2024 Q3 | F29: 2025 Q3 | G29: 2026 Q1 | H29: 2026 Q2 | I29: 2026 Q3
C30: Model Score | D30: 140.49095 | E30: 139.87965 | F30: 139.90857 | G30: 142.16741 | H30: 142.9469 | I30: 143.54182
C31: Expected Gross Loss Impact | D31: 1.4577705 | E31: 1.8581227 | F31: 1.2723137 | G31: 0.33754176 | H31: 0.31009057 | I31: 0.31896127
C32: Recovery Impact | D32: -0.30240079 | E32: -0.35849527 | F32: 0.64025968 | G32: 0.82064237 | H32: 0.94023214 | I32: 0.74643149
C33: LTV Impact | D33: -3.6904468 | E33: -1.5537898 | F33: -0.53154 | G33: 0.47648522 | H33: 1.0779523 | I33: 1.3140887
C34: APR Impact | D34: 0.0021270859 | E34: 0.2118942 | F34: 0.032567675 | G34: 0.47670557 | H34: 0.69858392 | I34: 0.94607864
C35: RAGU Score | D35: 137.958 | E35: 140.03738 | F35: 141.32218 | G35: 144.27878 | H35: 145.97376 | I35: 146.86738
C36: Amount Financed | D36: 1.4613722e+08 | E36: 3.0035913e+08 | F36: 3.7858788e+08 | G36: 5.5964627e+08 | H36: 4.8419507e+08 | I36: 2.2680581e+08
C37: Weighted LTV | D37: 1.8512165 | E37: 1.6904276 | F37: 1.6229849 | G37: 1.5615508 | H37: 1.5270609 | I37: 1.5139331
C38: Weighted APR | D38: 0.24998025 | E38: 0.24803241 | F38: 0.24969759 | G38: 0.24557345 | H38: 0.24351315 | I38: 0.24121498
C40: nonKMX | D40: 2023 Q3 | E40: 2024 Q3 | F40: 2025 Q3 | G40: 2026 Q1 | H40: 2026 Q2 | I40: 2026 Q3
C41: Model Score | D41: 136.74076 | E41: 139.14619 | F41: 138.89574 | G41: 141.26488 | H41: 142.0023 | I41: 142.54835
C42: Expected Gross Loss Impact | D42: 0.47163377 | E42: 0.86182839 | F42: 1.6634829 | G42: 2.3756397 | H42: 2.682723 | I42: 2.7622328
C43: Recovery Impact | D43: -1.3762849 | E43: 0.18813216 | F43: 2.682649 | G43: 2.6363874 | H43: 2.7463502 | I43: 2.5434179
C44: LTV Impact | D44: 3.6379294 | E44: 3.9287697 | F44: 4.2395848 | G44: 3.5961696 | H44: 3.975328 | I44: 3.8352483
C45: APR Impact | D45: -0.1335049 | E45: -0.079046575 | F45: -0.12682929 | G45: 0.0010451616 | H45: 0.24942325 | I45: 0.32930649
C46: RAGU Score | D46: 139.34053 | E46: 144.04588 | F46: 147.35463 | G46: 149.87412 | H46: 151.65612 | I46: 152.01855
C47: Amount Financed | D47: 1.8204627e+08 | E47: 3.0855481e+08 | F47: 4.4290733e+08 | G47: 4.6912234e+08 | H47: 4.7012169e+08 | I47: 1.9723988e+08
C48: Weighted LTV | D48: 1.3971255 | E48: 1.43804 | F48: 1.4154001 | G48: 1.4625887 | H48: 1.4741773 | I48: 1.4979381
C49: Weighted APR | D49: 0.24460044 | E49: 0.24614126 | F49: 0.24668787 | G49: 0.2449887 | H49: 0.24282078 | I49: 0.2421821
...

Sheet cb_zip impact
A1: ='Data Tables (M) no_cb_zip'!A1 -> AN | B1: ='Data Tables (M) no_cb_zip'!B1 -> 2025 M01 | C1: ='Data Tables (M) no_cb_zip'!C1 -> 2025 M02 | D1: ='Data Tables (M) no_cb_zip'!D1 -> 2025 M03 | E1: ='Data Tables (M) no_cb_zip'!E1 -> 2025 M04 | F1: ='Data Tables (M) no_cb_zip'!F1 -> 2025 M05 | G1: ='Data Tables (M) no_cb_zip'!G1 -> 2025 M06 | H1: ='Data Tables (M) no_cb_zip'!H1 -> 2025 M07 | ... V1: ='Data Tables (M) no_cb_zip'!V1 -> 2026 M09
A2: ='Data Tables (M) no_cb_zip'!A2 -> Model Score | B2: ='Data Tables (M) cb_zip'!B2-'Data Tables (M) no_cb_zip'!B2 -> 0 | C2: ='Data Tables (M) cb_zip'!C2-'Data Tables (M) no_cb_zip'!C2 -> 0 | D2: ='Data Tables (M) cb_zip'!D2-'Data Tables (M) no_cb_zip'!D2 -> 0 | E2: ='Data Tables (M) cb_zip'!E2-'Data Tables (M) no_cb_zip'!E2 -> 0 | F2: ='Data Tables (M) cb_zip'!F2-'Data Tables (M) no_cb_zip'!F2 -> 0 | G2: ='Data Tables (M) cb_zip'!G2-'Data Tables (M) no_cb_zip'!G2 -> 0 | H2: ='Data Tables (M) cb_zip'!H2-'Data Tables (M) no_cb_zip'!H2 -> 0 | I2: ='Data Tables (M) cb_zip'!I2-'Data Tables (M) no_cb_zip'!I2 -> 0 | ... V2: ='Data Tables (M) cb_zip'!V2-'Data Tables (M) no_cb_zip'!V2 -> 0
A3: ='Data Tables (M) no_cb_zip'!A3 -> Expected Gross Loss Impact | B3: ='Data Tables (M) cb_zip'!B3-'Data Tables (M) no_cb_zip'!B3 -> 0.10079865 | C3: ='Data Tables (M) cb_zip'!C3-'Data Tables (M) no_cb_zip'!C3 -> 0.039211646 | D3: ='Data Tables (M) cb_zip'!D3-'Data Tables (M) no_cb_zip'!D3 -> 0.11350166 | E3: ='Data Tables (M) cb_zip'!E3-'Data Tables (M) no_cb_zip'!E3 -> 0.11718101 | F3: ='Data Tables (M) cb_zip'!F3-'Data Tables (M) no_cb_zip'!F3 -> 0.086868808 | G3: ='Data Tables (M) cb_zip'!G3-'Data Tables (M) no_cb_zip'!G3 -> 0.078938962 | H3: ='Data Tables (M) cb_zip'!H3-'Data Tables (M) no_cb_zip'!H3 -> -0.033036119 | I3: ='Data Tables (M) cb_zip'!I3-'Data Tables (M) no_cb_zip'!I3 -> 0.17359512 | ... V3: ='Data Tables (M) cb_zip'!V3-'Data Tables (M) no_cb_zip'!V3 -> 0.04865892
A4: ='Data Tables (M) no_cb_zip'!A4 -> Recovery Impact | B4: ='Data Tables (M) cb_zip'!B4-'Data Tables (M) no_cb_zip'!B4 -> 0.0014336068 | C4: ='Data Tables (M) cb_zip'!C4-'Data Tables (M) no_cb_zip'!C4 -> 0.00011914683 | D4: ='Data Tables (M) cb_zip'!D4-'Data Tables (M) no_cb_zip'!D4 -> 0.00039160348 | E4: ='Data Tables (M) cb_zip'!E4-'Data Tables (M) no_cb_zip'!E4 -> 0.001003838 | F4: ='Data Tables (M) cb_zip'!F4-'Data Tables (M) no_cb_zip'!F4 -> 0.00080057079 | G4: ='Data Tables (M) cb_zip'!G4-'Data Tables (M) no_cb_zip'!G4 -> 0.0010840215 | H4: ='Data Tables (M) cb_zip'!H4-'Data Tables (M) no_cb_zip'!H4 -> -0.00075688131 | I4: ='Data Tables (M) cb_zip'!I4-'Data Tables (M) no_cb_zip'!I4 -> 0.0029661973 | ... V4: ='Data Tables (M) cb_zip'!V4-'Data Tables (M) no_cb_zip'!V4 -> 0.00097655541
A5: ='Data Tables (M) no_cb_zip'!A5 -> LTV Impact | B5: ='Data Tables (M) cb_zip'!B5-'Data Tables (M) no_cb_zip'!B5 -> 0 | C5: ='Data Tables (M) cb_zip'!C5-'Data Tables (M) no_cb_zip'!C5 -> 0 | D5: ='Data Tables (M) cb_zip'!D5-'Data Tables (M) no_cb_zip'!D5 -> 0 | E5: ='Data Tables (M) cb_zip'!E5-'Data Tables (M) no_cb_zip'!E5 -> 0 | F5: ='Data Tables (M) cb_zip'!F5-'Data Tables (M) no_cb_zip'!F5 -> 0 | G5: ='Data Tables (M) cb_zip'!G5-'Data Tables (M) no_cb_zip'!G5 -> 0 | H5: ='Data Tables (M) cb_zip'!H5-'Data Tables (M) no_cb_zip'!H5 -> 0 | I5: ='Data Tables (M) cb_zip'!I5-'Data Tables (M) no_cb_zip'!I5 -> 0 | ... V5: ='Data Tables (M) cb_zip'!V5-'Data Tables (M) no_cb_zip'!V5 -> 0
A6: ='Data Tables (M) no_cb_zip'!A6 -> APR Impact | B6: ='Data Tables (M) cb_zip'!B6-'Data Tables (M) no_cb_zip'!B6 -> 0 | C6: ='Data Tables (M) cb_zip'!C6-'Data Tables (M) no_cb_zip'!C6 -> 0 | D6: ='Data Tables (M) cb_zip'!D6-'Data Tables (M) no_cb_zip'!D6 -> 0 | E6: ='Data Tables (M) cb_zip'!E6-'Data Tables (M) no_cb_zip'!E6 -> 0 | F6: ='Data Tables (M) cb_zip'!F6-'Data Tables (M) no_cb_zip'!F6 -> 0 | G6: ='Data Tables (M) cb_zip'!G6-'Data Tables (M) no_cb_zip'!G6 -> 0 | H6: ='Data Tables (M) cb_zip'!H6-'Data Tables (M) no_cb_zip'!H6 -> 0 | I6: ='Data Tables (M) cb_zip'!I6-'Data Tables (M) no_cb_zip'!I6 -> 0 | ... V6: ='Data Tables (M) cb_zip'!V6-'Data Tables (M) no_cb_zip'!V6 -> 0
A7: ='Data Tables (M) no_cb_zip'!A7 -> RAGU Score | B7: ='Data Tables (M) cb_zip'!B7-'Data Tables (M) no_cb_zip'!B7 -> 0.10223225 | C7: ='Data Tables (M) cb_zip'!C7-'Data Tables (M) no_cb_zip'!C7 -> 0.039330792 | D7: ='Data Tables (M) cb_zip'!D7-'Data Tables (M) no_cb_zip'!D7 -> 0.11389326 | E7: ='Data Tables (M) cb_zip'!E7-'Data Tables (M) no_cb_zip'!E7 -> 0.11818484 | F7: ='Data Tables (M) cb_zip'!F7-'Data Tables (M) no_cb_zip'!F7 -> 0.087669379 | G7: ='Data Tables (M) cb_zip'!G7-'Data Tables (M) no_cb_zip'!G7 -> 0.080022983 | H7: ='Data Tables (M) cb_zip'!H7-'Data Tables (M) no_cb_zip'!H7 -> -0.033793001 | I7: ='Data Tables (M) cb_zip'!I7-'Data Tables (M) no_cb_zip'!I7 -> 0.17656132 | ... V7: ='Data Tables (M) cb_zip'!V7-'Data Tables (M) no_cb_zip'!V7 -> 0.049635475
A8: ='Data Tables (M) no_cb_zip'!A8 -> Amount Financed | B8: ='Data Tables (M) cb_zip'!B8-'Data Tables (M) no_cb_zip'!B8 -> 0 | C8: ='Data Tables (M) cb_zip'!C8-'Data Tables (M) no_cb_zip'!C8 -> 0 | D8: ='Data Tables (M) cb_zip'!D8-'Data Tables (M) no_cb_zip'!D8 -> 0 | E8: ='Data Tables (M) cb_zip'!E8-'Data Tables (M) no_cb_zip'!E8 -> 0 | F8: ='Data Tables (M) cb_zip'!F8-'Data Tables (M) no_cb_zip'!F8 -> 0 | G8: ='Data Tables (M) cb_zip'!G8-'Data Tables (M) no_cb_zip'!G8 -> 0 | H8: ='Data Tables (M) cb_zip'!H8-'Data Tables (M) no_cb_zip'!H8 -> 0 | I8: ='Data Tables (M) cb_zip'!I8-'Data Tables (M) no_cb_zip'!I8 -> 0 | ... V8: ='Data Tables (M) cb_zip'!V8-'Data Tables (M) no_cb_zip'!V8 -> 0
A9: ='Data Tables (M) no_cb_zip'!A9 -> Weighted LTV | B9: ='Data Tables (M) cb_zip'!B9-'Data Tables (M) no_cb_zip'!B9 -> 0 | C9: ='Data Tables (M) cb_zip'!C9-'Data Tables (M) no_cb_zip'!C9 -> 0 | D9: ='Data Tables (M) cb_zip'!D9-'Data Tables (M) no_cb_zip'!D9 -> 0 | E9: ='Data Tables (M) cb_zip'!E9-'Data Tables (M) no_cb_zip'!E9 -> 0 | F9: ='Data Tables (M) cb_zip'!F9-'Data Tables (M) no_cb_zip'!F9 -> 0 | G9: ='Data Tables (M) cb_zip'!G9-'Data Tables (M) no_cb_zip'!G9 -> 0 | H9: ='Data Tables (M) cb_zip'!H9-'Data Tables (M) no_cb_zip'!H9 -> 0 | I9: ='Data Tables (M) cb_zip'!I9-'Data Tables (M) no_cb_zip'!I9 -> 0 | ... V9: ='Data Tables (M) cb_zip'!V9-'Data Tables (M) no_cb_zip'!V9 -> 0
A10: ='Data Tables (M) no_cb_zip'!A10 -> Weighted APR | B10: ='Data Tables (M) cb_zip'!B10-'Data Tables (M) no_cb_zip'!B10 -> 0 | C10: ='Data Tables (M) cb_zip'!C10-'Data Tables (M) no_cb_zip'!C10 -> 0 | D10: ='Data Tables (M) cb_zip'!D10-'Data Tables (M) no_cb_zip'!D10 -> 0 | E10: ='Data Tables (M) cb_zip'!E10-'Data Tables (M) no_cb_zip'!E10 -> 0 | F10: ='Data Tables (M) cb_zip'!F10-'Data Tables (M) no_cb_zip'!F10 -> 0 | G10: ='Data Tables (M) cb_zip'!G10-'Data Tables (M) no_cb_zip'!G10 -> 0 | H10: ='Data Tables (M) cb_zip'!H10-'Data Tables (M) no_cb_zip'!H10 -> 0 | I10: ='Data Tables (M) cb_zip'!I10-'Data Tables (M) no_cb_zip'!I10 -> 0 | ... V10: ='Data Tables (M) cb_zip'!V10-'Data Tables (M) no_cb_zip'!V10 -> 0
A11: ='Data Tables (M) no_cb_zip'!A11 -> 0 | B11: ='Data Tables (M) cb_zip'!B11-'Data Tables (M) no_cb_zip'!B11 -> 0 | C11: ='Data Tables (M) cb_zip'!C11-'Data Tables (M) no_cb_zip'!C11 -> 0 | D11: ='Data Tables (M) cb_zip'!D11-'Data Tables (M) no_cb_zip'!D11 -> 0 | E11: ='Data Tables (M) cb_zip'!E11-'Data Tables (M) no_cb_zip'!E11 -> 0 | F11: ='Data Tables (M) cb_zip'!F11-'Data Tables (M) no_cb_zip'!F11 -> 0 | G11: ='Data Tables (M) cb_zip'!G11-'Data Tables (M) no_cb_zip'!G11 -> 0 | H11: ='Data Tables (M) cb_zip'!H11-'Data Tables (M) no_cb_zip'!H11 -> 0 | I11: ='Data Tables (M) cb_zip'!I11-'Data Tables (M) no_cb_zip'!I11 -> 0 | ... V11: ='Data Tables (M) cb_zip'!V11-'Data Tables (M) no_cb_zip'!V11 -> 0
A12: ='Data Tables (M) no_cb_zip'!A12 -> FRN | B12: ='Data Tables (M) cb_zip'!B12-'Data Tables (M) no_cb_zip'!B12 -> #VALUE! | C12: ='Data Tables (M) cb_zip'!C12-'Data Tables (M) no_cb_zip'!C12 -> #VALUE! | D12: ='Data Tables (M) cb_zip'!D12-'Data Tables (M) no_cb_zip'!D12 -> #VALUE! | E12: ='Data Tables (M) cb_zip'!E12-'Data Tables (M) no_cb_zip'!E12 -> #VALUE! | F12: ='Data Tables (M) cb_zip'!F12-'Data Tables (M) no_cb_zip'!F12 -> #VALUE! | G12: ='Data Tables (M) cb_zip'!G12-'Data Tables (M) no_cb_zip'!G12 -> #VALUE! | H12: ='Data Tables (M) cb_zip'!H12-'Data Tables (M) no_cb_zip'!H12 -> #VALUE! | I12: ='Data Tables (M) cb_zip'!I12-'Data Tables (M) no_cb_zip'!I12 -> #VALUE! | ... V12: ='Data Tables (M) cb_zip'!V12-'Data Tables (M) no_cb_zip'!V12 -> #VALUE!
A13: ='Data Tables (M) no_cb_zip'!A13 -> Model Score | B13: ='Data Tables (M) cb_zip'!B13-'Data Tables (M) no_cb_zip'!B13 -> 0 | C13: ='Data Tables (M) cb_zip'!C13-'Data Tables (M) no_cb_zip'!C13 -> 0 | D13: ='Data Tables (M) cb_zip'!D13-'Data Tables (M) no_cb_zip'!D13 -> 0 | E13: ='Data Tables (M) cb_zip'!E13-'Data Tables (M) no_cb_zip'!E13 -> 0 | F13: ='Data Tables (M) cb_zip'!F13-'Data Tables (M) no_cb_zip'!F13 -> 0 | G13: ='Data Tables (M) cb_zip'!G13-'Data Tables (M) no_cb_zip'!G13 -> 0 | H13: ='Data Tables (M) cb_zip'!H13-'Data Tables (M) no_cb_zip'!H13 -> 0 | I13: ='Data Tables (M) cb_zip'!I13-'Data Tables (M) no_cb_zip'!I13 -> 0 | ... V13: ='Data Tables (M) cb_zip'!V13-'Data Tables (M) no_cb_zip'!V13 -> 0
... A98: ='Data Tables (M) no_cb_zip'!A98 -> Weighted APR | B98: ='Data Tables (M) cb_zip'!B98-'Data Tables (M) no_cb_zip'!B98 -> 0 | C98: ='Data Tables (M) cb_zip'!C98-'Data Tables (M) no_cb_zip'!C98 -> 0 | D98: ='Data Tables (M) cb_zip'!D98-'Data Tables (M) no_cb_zip'!D98 -> 0 | E98: ='Data Tables (M) cb_zip'!E98-'Data Tables (M) no_cb_zip'!E98 -> 0 | F98: ='Data Tables (M) cb_zip'!F98-'Data Tables (M) no_cb_zip'!F98 -> 0 | G98: ='Data Tables (M) cb_zip'!G98-'Data Tables (M) no_cb_zip'!G98 -> 0 | H98: ='Data Tables (M) cb_zip'!H98-'Data Tables (M) no_cb_zip'!H98 -> 0 | I98: ='Data Tables (M) cb_zip'!I98-'Data Tables (M) no_cb_zip'!I98 -> 0 | ... V98: ='Data Tables (M) cb_zip'!V98-'Data Tables (M) no_cb_zip'!V98 -> 0

Sheet Data Tables (M) no_cb_zip
A1: AN | B1: 2025 M01 | C1: 2025 M02 | D1: 2025 M03 | E1: 2025 M04 | F1: 2025 M05 | G1: 2025 M06 | H1: 2025 M07 | I1: 2025 M08 | J1: 2025 M09 | K1: 2025 M10 | L1: 2025 M11 | M1: 2025 M12 | N1: 2026 M01 | O1: 2026 M02 | P1: 2026 M03 | Q1: 2026 M04 | R1: 2026 M05 | S1: 2026 M06 | T1: 2026 M07 | U1: 2026 M08 | V1: 2026 M09
A2: Model Score | B2: 136.8238 | C2: 137.05184 | D2: 136.62074 | E2: 137.56525 | F2: 138.3001 | G2: 138.20068 | H2: 138.46662 | I2: 138.33462 | J2: 138.84728 | K2: 138.8122 | L2: 138.99432 | M2: 140.30637 | N2: 140.39662 | O2: 140.16702 | P2: 140.29641 | Q2: 140.73976 | R2: 140.87262 | S2: 141.15513 | T2: 140.93325 | U2: 141.9218 | V2: 141.95806
A3: Expected Gross Loss Impact | B3: 0.55785235 | C3: 0.87069119 | D3: 0.38081665 | E3: 1.3033188 | F3: 1.6767168 | G3: 1.9788574 | H3: 1.9157073 | I3: 1.9506969 | J3: 1.7561283 | K3: 1.6741331 | L3: 1.4198064 | M3: 2.2280307 | N3: 2.3417241 | O3: 1.9532121 | P3: 1.7518468 | Q3: 2.293456 | R3: 2.3204666 | S3: 2.5124959 | T3: 2.6264213 | U3: 2.5779015 | V3: 2.888605
A4: Recovery Impact | B4: 1.953908 | C4: 0.41908549 | D4: 0.47268286 | E4: 1.1896257 | F4: 1.2900067 | G4: 1.9250016 | H4: 3.2162602 | I4: 2.397037 | J4: 2.3424597 | K4: 3.433878 | L4: 2.4518049 | M4: 2.4182781 | N4: 3.6744976 | O4: 2.0039217 | P4: 1.3437441 | Q4: 2.4963365 | R4: 3.846117 | S4: 3.177387 | T4: 3.473124 | U4: 3.7041319 | V4: 2.9069859
A5: LTV Impact | B5: 3.5477644 | C5: 3.4476912 | D5: 3.4831935 | E5: 3.9622565 | F5: 4.3794468 | G5: 3.8948186 | H5: 3.6808772 | I5: 3.9114945 | J5: 4.276292 | K5: 4.7198108 | L5: 4.0870223 | M5: 3.8974914 | N5: 3.8620431 | O5: 4.2823007 | P5: 4.3673661 | Q5: 3.7309076 | R5: 4.5859825 | S5: 4.1143036 | T5: 4.3268183 | U5: 3.9855194 | V5: 4.0751839
A6: APR Impact | B6: 0.013529432 | C6: -0.27298122 | D6: -0.028373703 | E6: 0.27661665 | F6: 0.44710486 | G6: 0.43484576 | H6: 0.67828337 | I6: 0.56777665 | J6: 0.85284911 | K6: 0.62903513 | L6: 0.43625937 | M6: 0.55781854 | N6: 0.68336776 | O6: 0.42747144 | P6: 0.5893034 | Q6: 0.90291096 | R6: 1.4356481 | S6: 1.5235799 | T6: 1.6076206 | U6: 1.3028677 | V6: 1.2154045
A7: RAGU Score | B7: 142.89686 | C7: 141.51633 | D7: 140.92906 | E7: 144.29707 | F7: 146.09337 | G7: 146.4342 | H7: 147.95775 | I7: 147.16162 | J7: 148.07501 | K7: 149.26906 | L7: 147.38922 | M7: 149.40799 | N7: 150.95825 | O7: 148.83393 | P7: 148.34867 | Q7: 150.16337 | R7: 153.06083 | S7: 152.4829 | T7: 152.96724 | U7: 153.49222 | V7: 153.04424
A8: Amount Financed | B8: 13880285 | C8: 14774078 | D8: 26986686 | E8: 20849411 | F8: 20015885 | G8: 16944617 | H8: 17583715 | I8: 17009856 | J8: 16644481 | K8: 14256427 | L8: 11610681 | M8: 13454665 | N8: 13296244 | O8: 15280721 | P8: 24336516 | Q8: 20661230 | R8: 22261812 | S8: 23382324 | T8: 25967503 | U8: 19891359 | V8: 15694851
A9: Weighted LTV | B9: 1.6050408 | C9: 1.612896 | D9: 1.6101005 | E9: 1.5733039 | F9: 1.5426031 | G9: 1.5783817 | H9: 1.5947099 | I9: 1.577123 | J9: 1.5500821 | K9: 1.5184294 | L9: 1.5639951 | M9: 1.5781799 | N9: 1.5808615 | O9: 1.5496445 | P9: 1.5434752 | Q9: 1.5908614 | R9: 1.5278434 | S9: 1.5619743 | T9: 1.5464098 | U9: 1.5715599 | V9: 1.5648736
A10: Weighted APR | B10: 0.24980672 | C10: 0.25389973 | D10: 0.25040534 | E10: 0.24604833 | F10: 0.24361279 | G10: 0.24378792 | H10: 0.24031024 | I10: 0.24188891 | J10: 0.23781644 | K10: 0.24101378 | L10: 0.24376772 | M10: 0.24203116 | N10: 0.2402376 | O10: 0.24389327 | P10: 0.24158138 | Q10: 0.23710127 | R10: 0.22949074 | S10: 0.22823457 | T10: 0.22703399 | U10: 0.2313876 | V10: 0.23263708
A12: FRN | B12: 2025 M01 | C12: 2025 M02 | D12: 2025 M03 | E12: 2025 M04 | F12: 2025 M05 | G12: 2025 M06 | H12: 2025 M07 | I12: 2025 M08 | J12: 2025 M09 | K12: 2025 M10 | L12: 2025 M11 | M12: 2025 M12 | N12: 2026 M01 | O12: 2026 M02 | P12: 2026 M03 | Q12: 2026 M04 | R12: 2026 M05 | S12: 2026 M06 | T12: 2026 M07 | U12: 2026 M08 | V12: 2026 M09
A13: Model Score | B13: 139.70466 | C13: 140.03934 | D13: 139.75818 | E13: 140.29098 | F13: 140.83949 | G13: 140.68426 | H13: 140.85961 | I13: 140.67207 | J13: 141.28166 | K13: 141.57876 | L13: 141.49384 | M13: 142.15471 | N13: 142.79799 | O13: 142.81556 | P13: 142.76467 | Q13: 143.1151 | R13: 142.88262 | S13: 143.30723 | T13: 143.79752 | U13: 143.58337 | V13: 143.59839
A14: Expected Gross Loss Impact | B14: -0.26298515 | C14: -0.43001273 | D14: -0.49354165 | E14: -0.15548746 | F14: 0.45646367 | G14: 0.77557929 | H14: 0.19239147 | I14: 0.8738834 | J14: 1.4040518 | K14: 1.5913292 | L14: 1.4687983 | M14: 1.7678712 | N14: 1.7703835 | O14: 1.5553544 | P14: 1.7556265 | Q14: 1.9521472 | R14: 2.1719948 | S14: 2.0400762 | T14: 2.3360256 | U14: 2.1411319 | V14: 2.3780367
A15: Recovery Impact | B15: 1.6326554 | C15: 1.157952 | D15: 1.3410687 | E15: 1.4564172 | F15: 1.5649062 | G15: 2.1596328 | H15: 2.1576305 | I15: 2.3897556 | J15: 2.6797897 | K15: 3.7587438 | L15: 3.5289428 | M15: 4.1047376 | N15: 3.6239781 | O15: 2.6600011 | P15: 2.2875907 | Q15: 2.5217452 | R15: 3.0902368 | S15: 2.699311 | T15: 2.5960611 | U15: 2.7856168 | V15: 3.2103322
A16: LTV Impact | B16: 5.1363095 | C16: 4.8367189 | D16: 5.2638062 | E16: 5.7249215 | F16: 6.0771583 | G16: 6.3727286 | H16: 6.0218014 | I16: 6.0084558 | J16: 6.3884775 | K16: 6.3013327 | L16: 6.1758518 | M16: 5.6586498 | N16: 5.5458849 | O16: 4.7355345 | P16: 5.0156904 | Q16: 5.0782548 | R16: 5.0288466 | S16: 4.9238666 | T16: 4.7524702 | U16: 4.8406008 | V16: 5.00121
A17: APR Impact | B17: -0.46693652 | C17: -0.5772574 | D17: -0.45220041 | E17: -0.4388664 | F17: -0.38831229 | G17: -0.35601355 | H17: -0.35364494 | I17: -0.45726211 | J17: -0.65907718 | K17: -0.58621544 | L17: -0.50735242 | M17: -0.54536463 | N17: -0.44666112 | O17: -0.44745465 | P17: -0.31545524 | Q17: -0.29322249 | R17: -0.24132865 | S17: -0.49691876 | T17: -0.36244858 | U17: -0.51156446 | V17: -0.40678783
A18: RAGU Score | B18: 145.74371 | C18: 145.02674 | D18: 145.41732 | E18: 146.87797 | F18: 148.5497 | G18: 149.63619 | H18: 148.87779 | I18: 149.4869 | J18: 151.0949 | K18: 152.64395 | L18: 152.16008 | M18: 153.14061 | N18: 153.29157 | O18: 151.31899 | P18: 151.50812 | Q18: 152.37402 | R18: 152.93237 | S18: 152.47356 | T18: 153.11963 | U18: 152.83915 | V18: 153.78118
A19: Amount Financed | B19: 46583212 | C19: 44395004 | D19: 82514330 | E19: 64333408 | F19: 58631919 | G19: 54065072 | H19: 57213498 | I19: 48510745 | J19: 44347400 | K19: 42795868 | L19: 33173999 | M19: 39734134 | N19: 35860313 | O19: 45446165 | P19: 80134279 | Q19: 62030567 | R19: 57906818 | S19: 51136838 | T19: 43767001 | U19: 39670224 | V19: 35393746
A20: Weighted LTV | B20: 1.4898599 | C20: 1.5103002 | D20: 1.481328 | E20: 1.4512701 | F20: 1.4291188 | G20: 1.4110462 | H20: 1.4325551 | I20: 1.4333861 | J20: 1.4100961 | K20: 1.4153697 | L20: 1.4230329 | M20: 1.4555148 | N20: 1.4627947 | O20: 1.517331 | P20: 1.4980225 | Q20: 1.4937775 | R20: 1.4971279 | S20: 1.5042967 | T20: 1.5161496 | U20: 1.5100317 | V20: 1.4990085
A21: Weighted APR | B21: 0.25667052 | C21: 0.25824653 | D21: 0.25646001 | E21: 0.25626952 | F21: 0.25554732 | G21: 0.25508591 | H21: 0.25505207 | I21: 0.25653232 | J21: 0.25941539 | K21: 0.25837451 | L21: 0.25724789 | M21: 0.25779092 | N21: 0.25638087 | O21: 0.25639221 | P21: 0.2545065 | Q21: 0.25418889 | R21: 0.25344755 | S21: 0.25709884 | T21: 0.25517784 | U21: 0.25730806 | V21: 0.25581125
A23: STG | B23: 2025 M01 | C23: 2025 M02 | D23: 2025 M03 | E23: 2025 M04 | F23: 2025 M05 | G23: 2025 M06 | H23: 2025 M07 | I23: 2025 M08 | J23: 2025 M09 | K23: 2025 M10 | L23: 2025 M11 | M23: 2025 M12 | N23: 2026 M01 | O23: 2026 M02 | P23: 2026 M03 | Q23: 2026 M04 | R23: 2026 M05 | S23: 2026 M06 | T23: 2026 M07 | U23: 2026 M08 | V23: 2026 M09
A24: Model Score | B24: 136.76546 | C24: 136.49588 | D24: 136.63459 | E24: 137.44887 | F24: 137.91026 | G24: 138.37186 | H24: 138.44857 | I24: 138.18615 | J24: 138.96646 | K24: 139.13507 | L24: 139.52681 | M24: 141.36722 | N24: 141.59339 | O24: 140.87523 | P24: 140.75014 | Q24: 141.03059 | R24: 141.28067 | S24: 141.15557 | T24: 141.23072 | U24: 141.42943 | V24: 141.49211
A25: Expected Gross Loss Impact | B25: 1.3365267 | C25: 1.0233334 | D25: 0.64271388 | E25: 0.90645627 | F25: 1.0795187 | G25: 1.459519 | H25: 1.1341155 | I25: 1.1236529 | J25: 1.4803614 | K25: 1.3663454 | L25: 1.6095516 | M25: 1.872068 | N25: 2.0019252 | O25: 2.0085233 | P25: 1.6930453 | Q25: 2.0663337 | R25: 2.1800264 | S25: 2.0047103 | T25: 1.9234581 | U25: 2.0630449 | V25: 2.0724193
A26: Recovery Impact | B26: 2.145526 | C26: 2.0275598 | D26: 1.7495365 | E26: 2.3582795 | F26: 2.7929868 | G26: 2.9743203 | H26: 3.0667458 | I26: 2.3506085 | J26: 3.0930983 | K26: 3.8725987 | L26: 3.9989993 | M26: 4.0973073 | N26: 4.176602 | O26: 2.9473374 | P26: 3.087384 | Q26: 3.5227415 | R26: 4.6197845 | S26: 4.2760984 | T26: 3.9834902 | U26: 3.9722574 | V26: 4.4960915
A27: LTV Impact | B27: 5.3015084 | C27: 4.8202722 | D27: 5.3288944 | E27: 5.5588189 | F27: 6.2148109 | G27: 6.5402373 | H27: 5.7277696 | I27: 6.001373 | J27: 6.2080411 | K27: 6.789336 | L27: 5.9907228 | M27: 5.7387811 | N27: 5.1065572 | O27: 5.348444 | P27: 5.2172521 | Q27: 5.3905287 | R27: 5.7781771 | S27: 5.1683993 | T27: 5.1585567 | U27: 5.0759836 | V27: 5.1743057
A28: APR Impact | B28: 0.069451917 | C28: -0.12280433 | D28: 0.032127973 | E28: 0.24756094 | F28: 0.29488002 | G28: 0.40626854 | H28: 0.30480541 | I28: 0.11650396 | J28: 0.33420422 | K28: 0.42436823 | L28: 0.33334888 | M28: 0.60775068 | N28: 0.84333886 | O28: 0.53073501 | P28: 0.77593181 | Q28: 0.77318014 | R28: 1.0975092 | S28: 0.94639933 | T28: 1.0247001 | U28: 0.84369476 | V28: 1.0249065
A29: RAGU Score | B29: 145.61847 | C29: 144.24424 | D29: 144.38786 | E29: 146.51999 | F29: 148.29246 | G29: 149.7522 | H29: 148.68201 | I29: 147.77829 | J29: 150.08217 | K29: 151.58772 | L29: 151.45943 | M29: 153.68313 | N29: 153.72181 | O29: 151.71027 | P29: 151.52375 | Q29: 152.78338 | R29: 154.95617 | S29: 153.55118 | T29: 153.32092 | U29: 153.38441 | V29: 154.25984
A30: Amount Financed | B30: 29218296 | C30: 28704211 | D30: 50946629 | E30: 43605841 | F30: 37502657 | G30: 34131041 | H30: 33269283 | I30: 29007288 | J30: 27004751 | K30: 28852206 | L30: 19064751 | M30: 22918901 | N30: 23856936 | O30: 30556521 | P30: 52672959 | Q30: 41738203 | R30: 38774211 | S30: 38016709 | T30: 39889591 | U30: 34101717 | V30: 29811199
A31: Weighted LTV | B31: 1.4788237 | C31: 1.5114385 | D31: 1.47701 | E31: 1.461956 | F31: 1.4206448 | G31: 1.4010054 | H31: 1.4510883 | I31: 1.4338274 | J31: 1.4210592 | K31: 1.3863355 | L31: 1.4344917 | M31: 1.4503856 | N31: 1.491865 | O31: 1.475718 | P31: 1.484432 | Q31: 1.4729442 | R31: 1.4478771 | S31: 1.4877033 | T31: 1.4883641 | U31: 1.4939312 | V31: 1.487307
A32: Weighted APR | B32: 0.24900783 | C32: 0.25175435 | D32: 0.24954103 | E32: 0.24646342 | F32: 0.24578743 | G32: 0.24419616 | H32: 0.24564564 | I32: 0.24833566 | J32: 0.24522565 | K32: 0.2439376 | L32: 0.24523787 | M32: 0.24131785 | N32: 0.2379523 | O32: 0.24241807 | P32: 0.23891526 | Q32: 0.23895457 | R32: 0.2343213 | S32: 0.23648001 | T32: 0.23536143 | U32: 0.23794722 | V32: 0.23535848
A34: FLD | B34: 2025 M01 | C34: 2025 M02 | D34: 2025 M03 | E34: 2025 M04 | F34: 2025 M05 | G34: 2025 M06 | H34: 2025 M07 | I34: 2025 M08 | J34: 2025 M09 | K34: 2025 M10 | L34: 2025 M11 | M34: 2025 M12 | N34: 2026 M01 | O34: 2026 M02 | P34: 2026 M03 | Q34: 2026 M04 | R34: 2026 M05 | S34: 2026 M06 | T34: 2026 M07 | U34: 2026 M08 | V34: 2026 M09
A35: Model Score | B35: 136.2976 | C35: 136.46221 | D35: 136.9609 | E35: 138.18726 | F35: 138.63591 | G35: 138.10457 | H35: 138.48578 | I35: 137.63944 | J35: 137.98696 | K35: 137.87612 | L35: 138.54181 | M35: 140.28364 | N35: 140.94091 | O35: 140.84271 | P35: 141.11749 | Q35: 141.54083 | R35: 141.70634 | S35: 142.3425 | T35: 142.27061 | U35: 142.64297 | V35: 143.71255
A36: Expected Gross Loss Impact | B36: 2.1076187 | C36: 2.0876088 | D36: 1.2759575 | E36: 1.0643445 | F36: 1.71905 | G36: 2.0219706 | H36: 1.8917677 | I36: 2.1150528 | J36: 2.3568789 | K36: 0.93627023 | L36: 0.73795448 | M36: 1.2803975 | N36: 1.8664443 | O36: 1.7027256 | P36: 1.5026081 | Q36: 1.7161812 | R36: 1.8113524 | S36: 2.1747603 | T36: 1.8040423 | U36: 2.4820115 | V36: 2.8712771
A37: Recovery Impact | B37: 3.2554887 | C37: 3.3114692 | D37: 1.4026645 | E37: 1.3577027 | F37: 1.3773427 | G37: 2.3604875 | H37: 2.8152711 | I37: 1.773004 | J37: 2.5443849 | K37: 2.6374983 | L37: 2.6488656 | M37: 3.0448745 | N37: 1.5866242 | O37: 1.2551898 | P37: 0.82831143 | Q37: 0.54943106 | R37: 0.53093478 | S37: 0.10533617 | T37: -0.2682555 | U37: 0.3271813 | V37: 0.126663
A38: LTV Impact | B38: 1.0735581 | C38: 0.7139736 | D38: 0.78916719 | E38: 0.28920705 | F38: 0.36002738 | G38: 0.54372532 | H38: 0.3541802 | I38: 0.36738063 | J38: 0.46839752 | K38: 0.59282752 | L38: 0.60689818 | M38: 0.11156115 | N38: -0.46516191 | O38: -0.0084071442 | P38: -0.23226849 | Q38: -0.49702664 | R38: -0.28875864 | S38: -0.27323098 | T38: -0.7888476 | U38: -0.49384743 | V38: -0.88216324
A39: APR Impact | B39: -0.46572002 | C39: -0.29866479 | D39: -0.51036508 | E39: -0.47089861 | F39: -0.51269778 | G39: -0.5698639 | H39: -0.65552913 | I39: -0.45399754 | J39: -0.46232864 | K39: -0.50882925 | L39: -0.39948753 | M39: -0.54869921 | N39: -0.57764165 | O39: -0.48232709 | P39: -0.2946618 | Q39: -0.17645223 | R39: -0.44047774 | S39: -0.29349784 | T39: -0.50199294 | U39: -0.64271541 | V39: -0.63535937
A40: RAGU Score | B40: 142.26855 | C40: 142.2766 | D40: 139.91833 | E40: 140.42761 | F40: 141.57963 | G40: 142.46089 | H40: 142.89147 | I40: 141.44088 | J40: 142.89429 | K40: 141.53389 | L40: 142.13604 | M40: 144.17178 | N40: 143.35117 | O40: 143.30989 | P40: 142.92148 | Q40: 143.13297 | R40: 143.31939 | S40: 144.05586 | T40: 142.51556 | U40: 144.3156 | V40: 145.19297
A41: Amount Financed | B41: 10338839 | C41: 11583637 | D41: 21544150 | E41: 14690858 | F41: 13097760 | G41: 12138090 | H41: 12341721 | I41: 14023961 | J41: 16268242 | K41: 16171909 | L41: 13413464 | M41: 13425760 | N41: 12367358 | O41: 19125484 | P41: 30391574 | Q41: 20947460 | R41: 17281542 | S41: 14943408 | T41: 14633500 | U41: 9744764.8 | V41: 9028399.8
A42: Weighted LTV | B42: 1.3638709 | C42: 1.3915568 | D42: 1.3856748 | E42: 1.425745 | F42: 1.4199286 | G42: 1.4050608 | H42: 1.4204071 | I42: 1.4193274 | J42: 1.4111197 | K42: 1.4011392 | L42: 1.4000195 | M42: 1.4405465 | N42: 1.4907917 | O42: 1.4507174 | P42: 1.4700856 | Q42: 1.4936702 | R42: 1.475055 | S42: 1.4736857 | T42: 1.5205582 | U42: 1.4933825 | V42: 1.5293616
A43: Weighted APR | B43: 0.24165314 | C43: 0.23926664 | D43: 0.24229093 | E43: 0.24172712 | F43: 0.24232425 | G43: 0.24314091 | H43: 0.2443647 | I43: 0.24148568 | J43: 0.24160469 | K43: 0.24226899 | L43: 0.24070696 | M43: 0.24283856 | N43: 0.24325202 | O43: 0.24189039 | P43: 0.23920945 | Q43: 0.23752075 | R43: 0.24129254 | S43: 0.23919283 | T43: 0.24217133 | U43: 0.24418165 | V43: 0.24407656
...

Sheet Sheet2

Sheet Data Tables (M) cb_zip
A1: AN | B1: 2025 M01 | C1: 2025 M02 | D1: 2025 M03 | E1: 2025 M04 | F1: 2025 M05 | G1: 2025 M06 | H1: 2025 M07 | I1: 2025 M08 | J1: 2025 M09 | K1: 2025 M10 | L1: 2025 M11 | M1: 2025 M12 | N1: 2026 M01 | O1: 2026 M02 | P1: 2026 M03 | Q1: 2026 M04 | R1: 2026 M05 | S1: 2026 M06 | T1: 2026 M07 | U1: 2026 M08 | V1: 2026 M09
A2: Model Score | B2: 136.8238 | C2: 137.05184 | D2: 136.62074 | E2: 137.56525 | F2: 138.3001 | G2: 138.20068 | H2: 138.46662 | I2: 138.33462 | J2: 138.84728 | K2: 138.8122 | L2: 138.99432 | M2: 140.30637 | N2: 140.39662 | O2: 140.16702 | P2: 140.29641 | Q2: 140.73976 | R2: 140.87262 | S2: 141.15513 | T2: 140.93325 | U2: 141.9218 | V2: 141.95806
A3: Expected Gross Loss Impact | B3: 0.658651 | C3: 0.90990284 | D3: 0.4943183 | E3: 1.4204998 | F3: 1.7635856 | G3: 2.0577964 | H3: 1.8826712 | I3: 2.1242921 | J3: 2.0685196 | K3: 1.749286 | L3: 1.4429464 | M3: 2.297466 | N3: 2.456733 | O3: 1.9711656 | P3: 1.8026736 | Q3: 2.2639354 | R3: 2.3533041 | S3: 2.647665 | T3: 2.6668549 | U3: 2.561879 | V3: 2.9372639
A4: Recovery Impact | B4: 1.9553416 | C4: 0.41920464 | D4: 0.47307446 | E4: 1.1906296 | F4: 1.2908073 | G4: 1.9260857 | H4: 3.2155034 | I4: 2.4000032 | J4: 2.3476642 | K4: 3.4357149 | L4: 2.452209 | M4: 2.4194561 | N4: 3.6774583 | O4: 2.0041749 | P4: 1.3442249 | Q4: 2.4958212 | R4: 3.846999 | S4: 3.1803764 | T4: 3.4741022 | U4: 3.7037212 | V4: 2.9079624
A5: LTV Impact | B5: 3.5477644 | C5: 3.4476912 | D5: 3.4831935 | E5: 3.9622565 | F5: 4.3794468 | G5: 3.8948186 | H5: 3.6808772 | I5: 3.9114945 | J5: 4.276292 | K5: 4.7198108 | L5: 4.0870223 | M5: 3.8974914 | N5: 3.8620431 | O5: 4.2823007 | P5: 4.3673661 | Q5: 3.7309076 | R5: 4.5859825 | S5: 4.1143036 | T5: 4.3268183 | U5: 3.9855194 | V5: 4.0751839
A6: APR Impact | B6: 0.013529432 | C6: -0.27298122 | D6: -0.028373703 | E6: 0.27661665 | F6: 0.44710486 | G6: 0.43484576 | H6: 0.67828337 | I6: 0.56777665 | J6: 0.85284911 | K6: 0.62903513 | L6: 0.43625937 | M6: 0.55781854 | N6: 0.68336776 | O6: 0.42747144 | P6: 0.5893034 | Q6: 0.90291096 | R6: 1.4356481 | S6: 1.5235799 | T6: 1.6076206 | U6: 1.3028677 | V6: 1.2154045
A7: RAGU Score | B7: 142.99909 | C7: 141.55566 | D7: 141.04295 | E7: 144.41525 | F7: 146.18104 | G7: 146.51423 | H7: 147.92395 | I7: 147.33819 | J7: 148.3926 | K7: 149.34605 | L7: 147.41276 | M7: 149.4786 | N7: 151.07622 | O7: 148.85213 | P7: 148.39997 | Q7: 150.13334 | R7: 153.09455 | S7: 152.62105 | T7: 153.00865 | U7: 153.47579 | V7: 153.09387
A8: Amount Financed | B8: 13880285 | C8: 14774078 | D8: 26986686 | E8: 20849411 | F8: 20015885 | G8: 16944617 | H8: 17583715 | I8: 17009856 | J8: 16644481 | K8: 14256427 | L8: 11610681 | M8: 13454665 | N8: 13296244 | O8: 15280721 | P8: 24336516 | Q8: 20661230 | R8: 22261812 | S8: 23382324 | T8: 25967503 | U8: 19891359 | V8: 15694851
A9: Weighted LTV | B9: 1.6050408 | C9: 1.612896 | D9: 1.6101005 | E9: 1.5733039 | F9: 1.5426031 | G9: 1.5783817 | H9: 1.5947099 | I9: 1.577123 | J9: 1.5500821 | K9: 1.5184294 | L9: 1.5639951 | M9: 1.5781799 | N9: 1.5808615 | O9: 1.5496445 | P9: 1.5434752 | Q9: 1.5908614 | R9: 1.5278434 | S9: 1.5619743 | T9: 1.5464098 | U9: 1.5715599 | V9: 1.5648736
A10: Weighted APR | B10: 0.24980672 | C10: 0.25389973 | D10: 0.25040534 | E10: 0.24604833 | F10: 0.24361279 | G10: 0.24378792 | H10: 0.24031024 | I10: 0.24188891 | J10: 0.23781644 | K10: 0.24101378 | L10: 0.24376772 | M10: 0.24203116 | N10: 0.2402376 | O10: 0.24389327 | P10: 0.24158138 | Q10: 0.23710127 | R10: 0.22949074 | S10: 0.22823457 | T10: 0.22703399 | U10: 0.2313876 | V10: 0.23263708
A12: FRN | B12: 2025 M01 | C12: 2025 M02 | D12: 2025 M03 | E12: 2025 M04 | F12: 2025 M05 | G12: 2025 M06 | H12: 2025 M07 | I12: 2025 M08 | J12: 2025 M09 | K12: 2025 M10 | L12: 2025 M11 | M12: 2025 M12 | N12: 2026 M01 | O12: 2026 M02 | P12: 2026 M03 | Q12: 2026 M04 | R12: 2026 M05 | S12: 2026 M06 | T12: 2026 M07 | U12: 2026 M08 | V12: 2026 M09
A13: Model Score | B13: 139.70466 | C13: 140.03934 | D13: 139.75818 | E13: 140.29098 | F13: 140.83949 | G13: 140.68426 | H13: 140.85961 | I13: 140.67207 | J13: 141.28166 | K13: 141.57876 | L13: 141.49384 | M13: 142.15471 | N13: 142.79799 | O13: 142.81556 | P13: 142.76467 | Q13: 143.1151 | R13: 142.88262 | S13: 143.30723 | T13: 143.79752 | U13: 143.58337 | V13: 143.59839
A14: Expected Gross Loss Impact | B14: -0.14331716 | C14: -0.30252811 | D14: -0.32158879 | E14: -0.091754796 | F14: 0.5031251 | G14: 0.83071593 | H14: 0.23511702 | I14: 0.90991819 | J14: 1.5134824 | K14: 1.5939884 | L14: 1.4422035 | M14: 1.7310805 | N14: 1.7312207 | O14: 1.5239499 | P14: 1.7769345 | Q14: 1.9125454 | R14: 2.1818041 | S14: 2.0430917 | T14: 2.363278 | U14: 2.0804909 | V14: 2.3948986
A15: Recovery Impact | B15: 1.6340565 | C15: 1.1590094 | D15: 1.3427245 | E15: 1.4570796 | F15: 1.565423 | G15: 2.1604745 | H15: 2.158284 | I15: 2.390364 | J15: 2.681845 | K15: 3.7588136 | L15: 3.5282863 | M15: 4.1036883 | N15: 3.6229964 | O15: 2.6594225 | P15: 2.287928 | Q15: 2.5210568 | R15: 3.0904458 | S15: 2.699367 | T15: 2.5965452 | U15: 2.7844576 | V15: 3.210703
A16: LTV Impact | B16: 5.1363095 | C16: 4.8367189 | D16: 5.2638062 | E16: 5.7249215 | F16: 6.0771583 | G16: 6.3727286 | H16: 6.0218014 | I16: 6.0084558 | J16: 6.3884775 | K16: 6.3013327 | L16: 6.1758518 | M16: 5.6586498 | N16: 5.5458849 | O16: 4.7355345 | P16: 5.0156904 | Q16: 5.0782548 | R16: 5.0288466 | S16: 4.9238666 | T16: 4.7524702 | U16: 4.8406008 | V16: 5.00121
A17: APR Impact | B17: -0.46693652 | C17: -0.5772574 | D17: -0.45220041 | E17: -0.4388664 | F17: -0.38831229 | G17: -0.35601355 | H17: -0.35364494 | I17: -0.45726211 | J17: -0.65907718 | K17: -0.58621544 | L17: -0.50735242 | M17: -0.54536463 | N17: -0.44666112 | O17: -0.44745465 | P17: -0.31545524 | Q17: -0.29322249 | R17: -0.24132865 | S17: -0.49691876 | T17: -0.36244858 | U17: -0.51156446 | V17: -0.40678783
A18: RAGU Score | B18: 145.86478 | C18: 145.15528 | D18: 145.59092 | E18: 146.94236 | F18: 148.59688 | G18: 149.69217 | H18: 148.92117 | I18: 149.52354 | J18: 151.20639 | K18: 152.64668 | L18: 152.13283 | M18: 153.10277 | N18: 153.25143 | O18: 151.28701 | P18: 151.52977 | Q18: 152.33373 | R18: 152.94238 | S18: 152.47663 | T18: 153.14737 | U18: 152.77735 | V18: 153.79841
A19: Amount Financed | B19: 46583212 | C19: 44395004 | D19: 82514330 | E19: 64333408 | F19: 58631919 | G19: 54065072 | H19: 57213498 | I19: 48510745 | J19: 44347400 | K19: 42795868 | L19: 33173999 | M19: 39734134 | N19: 35860313 | O19: 45446165 | P19: 80134279 | Q19: 62030567 | R19: 57906818 | S19: 51136838 | T19: 43767001 | U19: 39670224 | V19: 35393746
A20: Weighted LTV | B20: 1.4898599 | C20: 1.5103002 | D20: 1.481328 | E20: 1.4512701 | F20: 1.4291188 | G20: 1.4110462 | H20: 1.4325551 | I20: 1.4333861 | J20: 1.4100961 | K20: 1.4153697 | L20: 1.4230329 | M20: 1.4555148 | N20: 1.4627947 | O20: 1.517331 | P20: 1.4980225 | Q20: 1.4937775 | R20: 1.4971279 | S20: 1.5042967 | T20: 1.5161496 | U20: 1.5100317 | V20: 1.4990085
A21: Weighted APR | B21: 0.25667052 | C21: 0.25824653 | D21: 0.25646001 | E21: 0.25626952 | F21: 0.25554732 | G21: 0.25508591 | H21: 0.25505207 | I21: 0.25653232 | J21: 0.25941539 | K21: 0.25837451 | L21: 0.25724789 | M21: 0.25779092 | N21: 0.25638087 | O21: 0.25639221 | P21: 0.2545065 | Q21: 0.25418889 | R21: 0.25344755 | S21: 0.25709884 | T21: 0.25517784 | U21: 0.25730806 | V21: 0.25581125
A23: STG | B23: 2025 M01 | C23: 2025 M02 | D23: 2025 M03 | E23: 2025 M04 | F23: 2025 M05 | G23: 2025 M06 | H23: 2025 M07 | I23: 2025 M08 | J23: 2025 M09 | K23: 2025 M10 | L23: 2025 M11 | M23: 2025 M12 | N23: 2026 M01 | O23: 2026 M02 | P23: 2026 M03 | Q23: 2026 M04 | R23: 2026 M05 | S23: 2026 M06 | T23: 2026 M07 | U23: 2026 M08 | V23: 2026 M09
A24: Model Score | B24: 136.76546 | C24: 136.49588 | D24: 136.63459 | E24: 137.44887 | F24: 137.91026 | G24: 138.37186 | H24: 138.44857 | I24: 138.18615 | J24: 138.96646 | K24: 139.13507 | L24: 139.52681 | M24: 141.36722 | N24: 141.59339 | O24: 140.87523 | P24: 140.75014 | Q24: 141.03059 | R24: 141.28067 | S24: 141.15557 | T24: 141.23072 | U24: 141.42943 | V24: 141.49211
A25: Expected Gross Loss Impact | B25: 1.5105245 | C25: 1.2335533 | D25: 0.82577112 | E25: 1.0419538 | F25: 1.2212377 | G25: 1.6225366 | H25: 1.2893164 | I25: 1.3265735 | J25: 1.6605623 | K25: 1.3501027 | L25: 1.6187045 | M25: 1.8588685 | N25: 2.0363339 | O25: 1.9841186 | P25: 1.7916331 | Q25: 2.0695903 | R25: 2.2308377 | S25: 2.0903225 | T25: 1.964131 | U25: 2.066768 | V25: 2.0668607
A26: Recovery Impact | B26: 2.1482292 | C26: 2.0306592 | D26: 1.7518695 | E26: 2.360589 | F26: 2.7958347 | G26: 2.9777878 | H26: 3.0701557 | I26: 2.3540325 | J26: 3.0970669 | K26: 3.872151 | L26: 3.9992586 | M26: 4.0969297 | N26: 4.1776028 | O26: 2.946834 | P26: 3.0895209 | Q26: 3.5228216 | R26: 4.6214207 | S26: 4.2786555 | T26: 3.984622 | U26: 3.9723604 | V26: 4.4959174
A27: LTV Impact | B27: 5.3015084 | C27: 4.8202722 | D27: 5.3288944 | E27: 5.5588189 | F27: 6.2148109 | G27: 6.5402373 | H27: 5.7277696 | I27: 6.001373 | J27: 6.2080411 | K27: 6.789336 | L27: 5.9907228 | M27: 5.7387811 | N27: 5.1065572 | O27: 5.348444 | P27: 5.2172521 | Q27: 5.3905287 | R27: 5.7781771 | S27: 5.1683993 | T27: 5.1585567 | U27: 5.0759836 | V27: 5.1743057
A28: APR Impact | B28: 0.069451917 | C28: -0.12280433 | D28: 0.032127973 | E28: 0.24756094 | F28: 0.29488002 | G28: 0.40626854 | H28: 0.30480541 | I28: 0.11650396 | J28: 0.33420422 | K28: 0.42436823 | L28: 0.33334888 | M28: 0.60775068 | N28: 0.84333886 | O28: 0.53073501 | P28: 0.77593181 | Q28: 0.77318014 | R28: 1.0975092 | S28: 0.94639933 | T28: 1.0247001 | U28: 0.84369476 | V28: 1.0249065
A29: RAGU Score | B29: 145.79517 | C29: 144.45756 | D29: 144.57325 | E29: 146.65779 | F29: 148.43702 | G29: 149.91869 | H29: 148.84062 | I29: 147.98463 | J29: 150.26633 | K29: 151.57103 | L29: 151.46885 | M29: 153.66955 | N29: 153.75722 | O29: 151.68537 | P29: 151.62448 | Q29: 152.78671 | R29: 155.00862 | S29: 153.63935 | T29: 153.36273 | U29: 153.38823 | V29: 154.2541
A30: Amount Financed | B30: 29218296 | C30: 28704211 | D30: 50946629 | E30: 43605841 | F30: 37502657 | G30: 34131041 | H30: 33269283 | I30: 29007288 | J30: 27004751 | K30: 28852206 | L30: 19064751 | M30: 22918901 | N30: 23856936 | O30: 30556521 | P30: 52672959 | Q30: 41738203 | R30: 38774211 | S30: 38016709 | T30: 39889591 | U30: 34101717 | V30: 29811199
A31: Weighted LTV | B31: 1.4788237 | C31: 1.5114385 | D31: 1.47701 | E31: 1.461956 | F31: 1.4206448 | G31: 1.4010054 | H31: 1.4510883 | I31: 1.4338274 | J31: 1.4210592 | K31: 1.3863355 | L31: 1.4344917 | M31: 1.4503856 | N31: 1.491865 | O31: 1.475718 | P31: 1.484432 | Q31: 1.4729442 | R31: 1.4478771 | S31: 1.4877033 | T31: 1.4883641 | U31: 1.4939312 | V31: 1.487307
A32: Weighted APR | B32: 0.24900783 | C32: 0.25175435 | D32: 0.24954103 | E32: 0.24646342 | F32: 0.24578743 | G32: 0.24419616 | H32: 0.24564564 | I32: 0.24833566 | J32: 0.24522565 | K32: 0.2439376 | L32: 0.24523787 | M32: 0.24131785 | N32: 0.2379523 | O32: 0.24241807 | P32: 0.23891526 | Q32: 0.23895457 | R32: 0.2343213 | S32: 0.23648001 | T32: 0.23536143 | U32: 0.23794722 | V32: 0.23535848
A34: FLD | B34: 2025 M01 | C34: 2025 M02 | D34: 2025 M03 | E34: 2025 M04 | F34: 2025 M05 | G34: 2025 M06 | H34: 2025 M07 | I34: 2025 M08 | J34: 2025 M09 | K34: 2025 M10 | L34: 2025 M11 | M34: 2025 M12 | N34: 2026 M01 | O34: 2026 M02 | P34: 2026 M03 | Q34: 2026 M04 | R34: 2026 M05 | S34: 2026 M06 | T34: 2026 M07 | U34: 2026 M08 | V34: 2026 M09
A35: Model Score | B35: 136.2976 | C35: 136.46221 | D35: 136.9609 | E35: 138.18726 | F35: 138.63591 | G35: 138.10457 | H35: 138.48578 | I35: 137.63944 | J35: 137.98696 | K35: 137.87612 | L35: 138.54181 | M35: 140.28364 | N35: 140.94091 | O35: 140.84271 | P35: 141.11749 | Q35: 141.54083 | R35: 141.70634 | S35: 142.3425 | T35: 142.27061 | U35: 142.64297 | V35: 143.71255
A36: Expected Gross Loss Impact | B36: 2.0847443 | C36: 2.1116203 | D36: 1.4157777 | E36: 1.0297012 | F36: 1.6709416 | G36: 1.9513403 | H36: 1.9125456 | I36: 2.1053961 | J36: 2.3644807 | K36: 0.95418483 | L36: 0.71267748 | M36: 1.2436687 | N36: 1.7385209 | O36: 1.5830092 | P36: 1.4378187 | Q36: 1.627549 | R36: 1.7586289 | S36: 2.0937938 | T36: 1.7144338 | U36: 2.4500581 | V36: 2.7812268
A37: Recovery Impact | B37: 3.2549507 | C37: 3.3120431 | D37: 1.4040832 | E37: 1.357365 | F37: 1.3768706 | G37: 2.3592978 | H37: 2.8156878 | I37: 1.7728815 | J37: 2.5445227 | K37: 2.6378386 | L37: 2.6483849 | M37: 3.0440845 | N37: 1.585203 | O37: 1.2541357 | P37: 0.82793514 | Q37: 0.54909113 | R37: 0.53073973 | S37: 0.10527716 | T37: -0.26808866 | U37: 0.32710926 | V37: 0.12658519
A38: LTV Impact | B38: 1.0735581 | C38: 0.7139736 | D38: 0.78916719 | E38: 0.28920705 | F38: 0.36002738 | G38: 0.54372532 | H38: 0.3541802 | I38: 0.36738063 | J38: 0.46839752 | K38: 0.59282752 | L38: 0.60689818 | M38: 0.11156115 | N38: -0.46516191 | O38: -0.0084071442 | P38: -0.23226849 | Q38: -0.49702664 | R38: -0.28875864 | S38: -0.27323098 | T38: -0.7888476 | U38: -0.49384743 | V38: -0.88216324
A39: APR Impact | B39: -0.46572002 | C39: -0.29866479 | D39: -0.51036508 | E39: -0.47089861 | F39: -0.51269778 | G39: -0.5698639 | H39: -0.65552913 | I39: -0.45399754 | J39: -0.46232864 | K39: -0.50882925 | L39: -0.39948753 | M39: -0.54869921 | N39: -0.57764165 | O39: -0.48232709 | P39: -0.2946618 | Q39: -0.17645223 | R39: -0.44047774 | S39: -0.29349784 | T39: -0.50199294 | U39: -0.64271541 | V39: -0.63535937
A40: RAGU Score | B40: 142.24514 | C40: 142.30118 | D40: 140.05957 | E40: 140.39263 | F40: 141.53105 | G40: 142.38907 | H40: 142.91267 | I40: 141.4311 | J40: 142.90203 | K40: 141.55215 | L40: 142.11028 | M40: 144.13426 | N40: 143.22183 | O40: 143.18912 | P40: 142.85631 | Q40: 143.044 | R40: 143.26647 | S40: 143.97484 | T40: 142.42612 | U40: 144.28357 | V40: 145.10284
A41: Amount Financed | B41: 10338839 | C41: 11583637 | D41: 21544150 | E41: 14690858 | F41: 13097760 | G41: 12138090 | H41: 12341721 | I41: 14023961 | J41: 16268242 | K41: 16171909 | L41: 13413464 | M41: 13425760 | N41: 12367358 | O41: 19125484 | P41: 30391574 | Q41: 20947460 | R41: 17281542 | S41: 14943408 | T41: 14633500 | U41: 9744764.8 | V41: 9028399.8
A42: Weighted LTV | B42: 1.3638709 | C42: 1.3915568 | D42: 1.3856748 | E42: 1.425745 | F42: 1.4199286 | G42: 1.4050608 | H42: 1.4204071 | I42: 1.4193274 | J42: 1.4111197 | K42: 1.4011392 | L42: 1.4000195 | M42: 1.4405465 | N42: 1.4907917 | O42: 1.4507174 | P42: 1.4700856 | Q42: 1.4936702 | R42: 1.475055 | S42: 1.4736857 | T42: 1.5205582 | U42: 1.4933825 | V42: 1.5293616
A43: Weighted APR | B43: 0.24165314 | C43: 0.23926664 | D43: 0.24229093 | E43: 0.24172712 | F43: 0.24232425 | G43: 0.24314091 | H43: 0.2443647 | I43: 0.24148568 | J43: 0.24160469 | K43: 0.24226899 | L43: 0.24070696 | M43: 0.24283856 | N43: 0.24325202 | O43: 0.24189039 | P43: 0.23920945 | Q43: 0.23752075 | R43: 0.24129254 | S43: 0.23919283 | T43: 0.24217133 | U43: 0.24418165 | V43: 0.24407656
...

Sheet Data Tables (M)
A1: AN | B1: 2025 M01 | C1: 2025 M02 | D1: 2025 M03 | E1: 2025 M04 | F1: 2025 M05 | G1: 2025 M06 | H1: 2025 M07 | I1: 2025 M08 | J1: 2025 M09 | K1: 2025 M10 | L1: 2025 M11 | M1: 2025 M12 | N1: 2026 M01 | O1: 2026 M02 | P1: 2026 M03 | Q1: 2026 M04 | R1: 2026 M05 | S1: 2026 M06 | T1: 2026 M07 | U1: 2026 M08 | V1: 2026 M09
A2: Model Score | B2: 136.8238 | C2: 137.05184 | D2: 136.62074 | E2: 137.56525 | F2: 138.3001 | G2: 138.20068 | H2: 138.46662 | I2: 138.33462 | J2: 138.84728 | K2: 138.8122 | L2: 138.99432 | M2: 140.30637 | N2: 140.39662 | O2: 140.16702 | P2: 140.29641 | Q2: 140.73976 | R2: 140.87262 | S2: 141.15513 | T2: 140.93325 | U2: 141.9218 | V2: 141.92009
A3: Expected Gross Loss Impact | B3: 0.65857303 | C3: 0.90503912 | D3: 0.48805493 | E3: 1.4296355 | F3: 1.7635856 | G3: 2.0577964 | H3: 1.8826712 | I3: 2.1242921 | J3: 2.0685196 | K3: 1.749286 | L3: 1.4429464 | M3: 2.297466 | N3: 2.456733 | O3: 1.9711656 | P3: 1.8026736 | Q3: 2.2531594 | R3: 2.3533041 | S3: 2.647665 | T3: 2.6668549 | U3: 2.561879 | V3: 2.912388
A4: Recovery Impact | B4: 1.9746689 | C4: 0.43116201 | D4: 0.48902895 | E4: 1.1957043 | F4: 1.2908073 | G4: 1.9260857 | H4: 3.2155034 | I4: 2.4000032 | J4: 2.3476642 | K4: 3.4357149 | L4: 2.452209 | M4: 2.4194561 | N4: 3.6774583 | O4: 2.0041749 | P4: 1.3442249 | Q4: 2.4762026 | R4: 3.846999 | S4: 3.1803764 | T4: 3.4741022 | U4: 3.7037212 | V4: 2.9033879
A5: LTV Impact | B5: 3.5360655 | C5: 3.4404769 | D5: 3.4756953 | E5: 3.9608328 | F5: 4.3794468 | G5: 3.8948186 | H5: 3.6808772 | I5: 3.9114945 | J5: 4.276292 | K5: 4.7198108 | L5: 4.0870223 | M5: 3.8974914 | N5: 3.8620431 | O5: 4.2823007 | P5: 4.3673661 | Q5: 3.7221668 | R5: 4.5859825 | S5: 4.1143036 | T5: 4.3268183 | U5: 3.9855194 | V5: 4.0102852
A6: APR Impact | B6: 0.0073273183 | C6: -0.2741314 | D6: -0.03308957 | E6: 0.27780104 | F6: 0.44710486 | G6: 0.43484576 | H6: 0.67828337 | I6: 0.56777665 | J6: 0.85284911 | K6: 0.62903513 | L6: 0.43625937 | M6: 0.55781854 | N6: 0.68336776 | O6: 0.42747144 | P6: 0.5893034 | Q6: 0.89468483 | R6: 1.4356481 | S6: 1.5235799 | T6: 1.6076206 | U6: 1.3028677 | V6: 1.2279752
A7: RAGU Score | B7: 143.00044 | C7: 141.55439 | D7: 141.04043 | E7: 144.42922 | F7: 146.18104 | G7: 146.51423 | H7: 147.92395 | I7: 147.33819 | J7: 148.3926 | K7: 149.34605 | L7: 147.41276 | M7: 149.4786 | N7: 151.07622 | O7: 148.85213 | P7: 148.39997 | Q7: 150.08597 | R7: 153.09455 | S7: 152.62105 | T7: 153.00865 | U7: 153.47579 | V7: 152.97413
A8: Amount Financed | B8: 13864427 | C8: 14750081 | D8: 26969070 | E8: 20832746 | F8: 20015885 | G8: 16944617 | H8: 17583715 | I8: 17009856 | J8: 16644481 | K8: 14256427 | L8: 11610681 | M8: 13454665 | N8: 13296244 | O8: 15280721 | P8: 24336516 | Q8: 20618796 | R8: 22261812 | S8: 23382324 | T8: 25967503 | U8: 19891359 | V8: 16878056
A9: Weighted LTV | B9: 1.6059551 | C9: 1.6134653 | D9: 1.6106901 | E9: 1.5734108 | F9: 1.5426031 | G9: 1.5783817 | H9: 1.5947099 | I9: 1.577123 | J9: 1.5500821 | K9: 1.5184294 | L9: 1.5639951 | M9: 1.5781799 | N9: 1.5808615 | O9: 1.5496445 | P9: 1.5434752 | Q9: 1.5915324 | R9: 1.5278434 | S9: 1.5619743 | T9: 1.5464098 | U9: 1.5715599 | V9: 1.5697074
A10: Weighted APR | B10: 0.24989532 | C10: 0.25391616 | D10: 0.25047271 | E10: 0.24603141 | F10: 0.24361279 | G10: 0.24378792 | H10: 0.24031024 | I10: 0.24188891 | J10: 0.23781644 | K10: 0.24101378 | L10: 0.24376772 | M10: 0.24203116 | N10: 0.2402376 | O10: 0.24389327 | P10: 0.24158138 | Q10: 0.23721879 | R10: 0.22949074 | S10: 0.22823457 | T10: 0.22703399 | U10: 0.2313876 | V10: 0.2324575
A12: FRN | B12: 2025 M01 | C12: 2025 M02 | D12: 2025 M03 | E12: 2025 M04 | F12: 2025 M05 | G12: 2025 M06 | H12: 2025 M07 | I12: 2025 M08 | J12: 2025 M09 | K12: 2025 M10 | L12: 2025 M11 | M12: 2025 M12 | N12: 2026 M01 | O12: 2026 M02 | P12: 2026 M03 | Q12: 2026 M04 | R12: 2026 M05 | S12: 2026 M06 | T12: 2026 M07 | U12: 2026 M08 | V12: 2026 M09
A13: Model Score | B13: 139.70466 | C13: 140.03934 | D13: 139.75818 | E13: 140.29098 | F13: 140.83949 | G13: 140.68426 | H13: 140.85961 | I13: 140.67207 | J13: 141.28166 | K13: 141.57876 | L13: 141.49384 | M13: 142.15471 | N13: 142.79799 | O13: 142.81556 | P13: 142.76467 | Q13: 143.1151 | R13: 142.88262 | S13: 143.30723 | T13: 143.79752 | U13: 143.58337 | V13: 143.57358
A14: Expected Gross Loss Impact | B14: -0.1483152 | C14: -0.30252811 | D14: -0.32311339 | E14: -0.091534276 | F14: 0.50220742 | G14: 0.83070769 | H14: 0.23542067 | I14: 0.90991819 | J14: 1.5134824 | K14: 1.5939884 | L14: 1.4396478 | M14: 1.7310805 | N14: 1.7312207 | O14: 1.5239499 | P14: 1.7769345 | Q14: 1.9125454 | R14: 2.1818041 | S14: 2.0430917 | T14: 2.363278 | U14: 2.0804909 | V14: 2.3543462
A15: Recovery Impact | B15: 1.6409623 | C15: 1.1590094 | D15: 1.3441761 | E15: 1.4567602 | F15: 1.5565722 | G15: 2.1682424 | H15: 2.1580407 | I15: 2.390364 | J15: 2.681845 | K15: 3.7588136 | L15: 3.5257819 | M15: 4.1036883 | N15: 3.6229964 | O15: 2.6594225 | P15: 2.287928 | Q15: 2.5210568 | R15: 3.0901668 | S15: 2.699367 | T15: 2.5965452 | U15: 2.7780806 | V15: 3.1547556
A16: LTV Impact | B16: 5.1359331 | C16: 4.8367189 | D16: 5.2615285 | E16: 5.7215807 | F16: 6.0772589 | G16: 6.3721426 | H16: 6.0246689 | I16: 6.0084558 | J16: 6.3884775 | K16: 6.3013327 | L16: 6.1736283 | M16: 5.6586498 | N16: 5.5458849 | O16: 4.7408599 | P16: 5.0156904 | Q16: 5.0782548 | R16: 5.0288466 | S16: 4.9238666 | T16: 4.7524702 | U16: 4.8406008 | V16: 5.0188232
A17: APR Impact | B17: -0.46855032 | C17: -0.5772574 | D17: -0.45199749 | E17: -0.43881648 | F17: -0.38905562 | G17: -0.35788947 | H17: -0.35305074 | I17: -0.45726211 | J17: -0.65907718 | K17: -0.58621544 | L17: -0.50619865 | M17: -0.54536463 | N17: -0.44666112 | O17: -0.44745465 | P17: -0.31545524 | Q17: -0.29322249 | R17: -0.24132865 | S17: -0.49691876 | T17: -0.36244858 | U17: -0.51156446 | V17: -0.42994997
A18: RAGU Score | B18: 145.86469 | C18: 145.15528 | D18: 145.58878 | E18: 146.93897 | F18: 148.58647 | G18: 149.69747 | H18: 148.92469 | I18: 149.52354 | J18: 151.20639 | K18: 152.64668 | L18: 152.1267 | M18: 153.10277 | N18: 153.25143 | O18: 151.29234 | P18: 151.52977 | Q18: 152.33373 | R18: 152.9421 | S18: 152.47663 | T18: 153.14737 | U18: 152.77097 | V18: 153.67155
A19: Amount Financed | B19: 46629489 | C19: 44395004 | D19: 82482577 | E19: 64340727 | F19: 58591900 | G19: 54123525 | H19: 57224280 | I19: 48510745 | J19: 44347400 | K19: 42795868 | L19: 33149878 | M19: 39734134 | N19: 35860313 | O19: 45446165 | P19: 80134279 | Q19: 62030567 | R19: 57906818 | S19: 51136838 | T19: 43767001 | U19: 39670224 | V19: 37342616
A20: Weighted LTV | B20: 1.4898852 | C20: 1.5103002 | D20: 1.4814796 | E20: 1.4514835 | F20: 1.4291125 | G20: 1.4110816 | H20: 1.4323767 | I20: 1.4333861 | J20: 1.4100961 | K20: 1.4153697 | L20: 1.4231695 | M20: 1.4555148 | N20: 1.4627947 | O20: 1.5169593 | P20: 1.4980225 | Q20: 1.4937775 | R20: 1.4971279 | S20: 1.5042967 | T20: 1.5161496 | U20: 1.5100317 | V20: 1.4978094
A21: Weighted APR | B21: 0.25669358 | C21: 0.25824653 | D21: 0.25645711 | E21: 0.25626881 | F21: 0.25555794 | G21: 0.25511271 | H21: 0.25504358 | I21: 0.25653232 | J21: 0.25941539 | K21: 0.25837451 | L21: 0.25723141 | M21: 0.25779092 | N21: 0.25638087 | O21: 0.25639221 | P21: 0.2545065 | Q21: 0.25418889 | R21: 0.25344755 | S21: 0.25709884 | T21: 0.25517784 | U21: 0.25730806 | V21: 0.25614214
A23: STG | B23: 2025 M01 | C23: 2025 M02 | D23: 2025 M03 | E23: 2025 M04 | F23: 2025 M05 | G23: 2025 M06 | H23: 2025 M07 | I23: 2025 M08 | J23: 2025 M09 | K23: 2025 M10 | L23: 2025 M11 | M23: 2025 M12 | N23: 2026 M01 | O23: 2026 M02 | P23: 2026 M03 | Q23: 2026 M04 | R23: 2026 M05 | S23: 2026 M06 | T23: 2026 M07 | U23: 2026 M08 | V23: 2026 M09
A24: Model Score | B24: 136.76546 | C24: 136.49588 | D24: 136.63459 | E24: 137.44887 | F24: 137.91026 | G24: 138.37186 | H24: 138.44857 | I24: 138.18615 | J24: 138.96646 | K24: 139.13507 | L24: 139.52681 | M24: 141.36722 | N24: 141.59339 | O24: 140.87523 | P24: 140.75014 | Q24: 141.03059 | R24: 141.28067 | S24: 141.15557 | T24: 141.23072 | U24: 141.42943 | V24: 141.47931
A25: Expected Gross Loss Impact | B25: 1.5115474 | C25: 1.2335533 | D25: 0.82123203 | E25: 1.0431505 | F25: 1.224939 | G25: 1.6302081 | H25: 1.2893164 | I25: 1.3265735 | J25: 1.6605623 | K25: 1.3501027 | L25: 1.6187045 | M25: 1.8588685 | N25: 2.0363339 | O25: 1.9841186 | P25: 1.7916331 | Q25: 2.0695903 | R25: 2.2308377 | S25: 2.0903225 | T25: 1.964131 | U25: 2.066768 | V25: 2.0848639
A26: Recovery Impact | B26: 2.1482451 | C26: 2.0306592 | D26: 1.7614246 | E26: 2.3620674 | F26: 2.7760481 | G26: 3.0224931 | H26: 3.0701557 | I26: 2.3540325 | J26: 3.0970669 | K26: 3.872151 | L26: 3.9992586 | M26: 4.0969297 | N26: 4.1776028 | O26: 2.946834 | P26: 3.0822068 | Q26: 3.5228216 | R26: 4.6214207 | S26: 4.2786555 | T26: 3.984622 | U26: 3.9723604 | V26: 4.5593917
A27: LTV Impact | B27: 5.2936374 | C27: 4.8202722 | D27: 5.3425885 | E27: 5.5661707 | F27: 6.2202053 | G27: 6.5428405 | H27: 5.7277696 | I27: 6.001373 | J27: 6.2080411 | K27: 6.789336 | L27: 5.9907228 | M27: 5.7387811 | N27: 5.1065572 | O27: 5.348444 | P27: 5.2172521 | Q27: 5.3905287 | R27: 5.7781771 | S27: 5.1683993 | T27: 5.1585567 | U27: 5.0759836 | V27: 5.0770865
A28: APR Impact | B28: 0.068654282 | C28: -0.12280433 | D28: 0.034857358 | E28: 0.24803634 | F28: 0.29062065 | G28: 0.41398896 | H28: 0.30480541 | I28: 0.11650396 | J28: 0.33420422 | K28: 0.42436823 | L28: 0.33334888 | M28: 0.60775068 | N28: 0.84333886 | O28: 0.53073501 | P28: 0.77593181 | Q28: 0.77318014 | R28: 1.0975092 | S28: 0.94639933 | T28: 1.0247001 | U28: 0.84369476 | V28: 0.99746613
A29: RAGU Score | B29: 145.78754 | C29: 144.45756 | D29: 144.59469 | E29: 146.6683 | F29: 148.42207 | G29: 149.98139 | H29: 148.84062 | I29: 147.98463 | J29: 150.26633 | K29: 151.57103 | L29: 151.46885 | M29: 153.66955 | N29: 153.75722 | O29: 151.68537 | P29: 151.61716 | Q29: 152.78671 | R29: 155.00862 | S29: 153.63935 | T29: 153.36273 | U29: 153.38823 | V29: 154.19812
A30: Amount Financed | B30: 29229078 | C30: 28704211 | D30: 50928689 | E30: 43617937 | F30: 37509619 | G30: 34174059 | H30: 33269283 | I30: 29007288 | J30: 27004751 | K30: 28852206 | L30: 19064751 | M30: 22918901 | N30: 23856936 | O30: 30556521 | P30: 52672959 | Q30: 41738203 | R30: 38774211 | S30: 38016709 | T30: 39889591 | U30: 34101717 | V30: 31569890
A31: Weighted LTV | B31: 1.4793459 | C31: 1.5114385 | D31: 1.4761047 | E31: 1.4614797 | F31: 1.4203147 | G31: 1.4008505 | H31: 1.4510883 | I31: 1.4338274 | J31: 1.4210592 | K31: 1.3863355 | L31: 1.4344917 | M31: 1.4503856 | N31: 1.491865 | O31: 1.475718 | P31: 1.484432 | Q31: 1.4729442 | R31: 1.4478771 | S31: 1.4877033 | T31: 1.4883641 | U31: 1.4939312 | V31: 1.4938565
A32: Weighted APR | B32: 0.24901922 | C32: 0.25175435 | D32: 0.24950204 | E32: 0.24645662 | F32: 0.24584828 | G32: 0.24408587 | H32: 0.24564564 | I32: 0.24833566 | J32: 0.24522565 | K32: 0.2439376 | L32: 0.24523787 | M32: 0.24131785 | N32: 0.2379523 | O32: 0.24241807 | P32: 0.23891526 | Q32: 0.23895457 | R32: 0.2343213 | S32: 0.23648001 | T32: 0.23536143 | U32: 0.23794722 | V32: 0.23575048
A34: FLD | B34: 2025 M01 | C34: 2025 M02 | D34: 2025 M03 | E34: 2025 M04 | F34: 2025 M05 | G34: 2025 M06 | H34: 2025 M07 | I34: 2025 M08 | J34: 2025 M09 | K34: 2025 M10 | L34: 2025 M11 | M34: 2025 M12 | N34: 2026 M01 | O34: 2026 M02 | P34: 2026 M03 | Q34: 2026 M04 | R34: 2026 M05 | S34: 2026 M06 | T34: 2026 M07 | U34: 2026 M08 | V34: 2026 M09
A35: Model Score | B35: 136.2976 | C35: 136.46221 | D35: 136.9609 | E35: 138.18726 | F35: 138.63591 | G35: 138.10457 | H35: 138.48578 | I35: 137.63944 | J35: 137.98696 | K35: 137.87612 | L35: 138.54181 | M35: 140.28364 | N35: 140.94091 | O35: 140.84271 | P35: 141.11749 | Q35: 141.54083 | R35: 141.70634 | S35: 142.3425 | T35: 142.27061 | U35: 142.64297 | V35: 143.80178
