Workbook

Sheet Data Tables (Q) 3pm
A1: AN | B1: 2025Q1 | C1: 2025Q2 | D1: 2025Q3 | E1: 2025Q4 | F1: 2026Q1
A2: Model Score | B2: 136.83702 | C2: 138.03382 | D2: 138.55808 | E2: 139.3761 | F2: 140.3242
A3: Gross Loss Impact | B3: 1.4592694 | C3: 2.4660669 | D3: 2.9266817 | E3: 2.9196016 | F3: 3.1264617
A4: Recovery Impact | B4: -0.27746484 | C4: 3.7521851 | D4: 5.0310015 | E4: 5.1855907 | F4: 4.6061338
A5: LTV Impact | B5: 3.4856685 | C5: 4.0041969 | D5: 3.9673791 | E5: 4.2368849 | F5: 4.2899933
A6: RAGU Score | B6: 141.5045 | C6: 148.25627 | D6: 150.48314 | E6: 151.71818 | F6: 152.34679
A7: Amount Financed | B7: 56035847 | C7: 58135224 | D7: 51413759 | E7: 39424320 | F7: 44425981
A9: FRN | B9: 2025Q1 | C9: 2025Q2 | D9: 2025Q3 | E9: 2025Q4 | F9: 2026Q1
A10: Model Score | B10: 139.83315 | C10: 140.63434 | D10: 140.96388 | E10: 141.85749 | F10: 142.77028
A11: Gross Loss Impact | B11: 0.66791062 | C11: 1.2781424 | D11: 1.7965359 | E11: 2.7808561 | F11: 2.864459
A12: Recovery Impact | B12: -2.4759445 | C12: 0.89891578 | D12: 1.4860074 | E12: 2.8270298 | F12: 1.6807668
A13: LTV Impact | B13: 5.1640304 | C13: 6.0914913 | D13: 6.1324359 | E13: 6.2175066 | F13: 5.1796676
A14: RAGU Score | B14: 143.18915 | C14: 148.90289 | D14: 150.37886 | E14: 153.68288 | F14: 152.49518
A15: Amount Financed | B15: 1.7489509e+08 | C15: 1.7780391e+08 | D15: 1.5110941e+08 | E15: 1.1798551e+08 | F15: 1.3358561e+08
A17: STG | B17: 2025Q1 | C17: 2025Q2 | D17: 2025Q3 | E17: 2025Q4 | F17: 2026Q1
A18: Model Score | B18: 136.6684 | C18: 137.94719 | D18: 138.66055 | E18: 140.03752 | F18: 141.05246
A19: Gross Loss Impact | B19: 1.8384507 | C19: 2.0356619 | D19: 2.2451501 | E19: 2.7851197 | F19: 3.1250191
A20: Recovery Impact | B20: 0.96038629 | C20: 6.9318211 | D20: 7.0053773 | E20: 8.4000971 | F20: 7.3704562
A21: LTV Impact | B21: 5.185486 | C21: 6.1161461 | D21: 6.0276231 | E21: 6.2563256 | F21: 5.2715924
A22: RAGU Score | B22: 144.65272 | C22: 153.03082 | D22: 153.9387 | E22: 157.47906 | F22: 156.81953
A23: Amount Financed | B23: 1.0977812e+08 | C23: 1.1799764e+08 | D23: 91351165 | E23: 72109323 | F23: 88330639
A25: FLD | B25: 2025Q1 | C25: 2025Q2 | D25: 2025Q3 | E25: 2025Q4 | F25: 2026Q1
A26: Model Score | B26: 136.70743 | C26: 138.3478 | D26: 138.1021 | E26: 138.94555 | F26: 140.96244
A27: Gross Loss Impact | B27: 2.4078901 | C27: 2.4910068 | D27: 3.0095789 | E27: 1.8551298 | F27: 2.3630141
A28: Recovery Impact | B28: -0.95127693 | C28: 0.73656265 | D28: 1.4219801 | E28: 1.7823428 | F28: 0.15573719
A29: LTV Impact | B29: 6.8963129 | C29: 6.3926311 | D29: 6.3479797 | E29: 6.3986759 | F29: 5.5219227
A30: RAGU Score | B30: 145.06036 | C30: 147.968 | D30: 148.88163 | E30: 148.9817 | F30: 149.00312
A31: Amount Financed | B31: 43623019 | C31: 40763731 | D31: 43230820 | E31: 43342019 | F31: 51820832
A33: ENT | B33: 2025Q1 | C33: 2025Q2 | D33: 2025Q3 | E33: 2025Q4 | F33: 2026Q1
A34: Model Score | B34: 134.57148 | C34: 136.41792 | D34: 137.0063 | E34: 137.20721 | F34: 139.79524
A35: Gross Loss Impact | B35: -0.97599678 | C35: 0.20518067 | D35: 0.17963091 | E35: 1.0649609 | F35: 1.253817
A36: Recovery Impact | B36: 1.264732 | C36: 3.6984811 | D36: 3.7671272 | E36: 4.7206982 | F36: 3.7286384
A37: LTV Impact | B37: 1.5163974 | C37: 1.9250701 | D37: 1.8505382 | E37: 1.6939213 | F37: 1.5030084
A38: RAGU Score | B38: 136.37661 | C38: 142.24665 | D38: 142.80359 | E38: 144.6868 | F38: 146.28071
A39: Amount Financed | B39: 1.5118227e+08 | C39: 1.3025102e+08 | D39: 1.0868468e+08 | E39: 91451649 | F39: 85452589
A41: KMX | B41: 2025Q1 | C41: 2025Q2 | D41: 2025Q3 | E41: 2025Q4 | F41: 2026Q1
A42: Model Score | B42: 139.70877 | C42: 139.86672 | D42: 139.91791 | E42: 140.94205 | F42: 142.02678
A43: Gross Loss Impact | B43: -0.59293677 | C43: 1.0908332 | D43: 0.95995222 | E43: 0.99951176 | F43: 0.49224522
A44: Recovery Impact | B44: -1.037986 | C44: -0.039833427 | D44: 0.39669237 | E44: 0.69322784 | F44: 0.47530718
A45: LTV Impact | B45: -0.78475247 | C45: -0.3892245 | D45: -0.57494632 | E45: -0.30261364 | F45: 0.37818019
...

Sheet Friday
A1: AN | B1: 2016 | C1: 2017 | D1: 2018 | E1: 2019 | F1: 2020 Q1 | G1: 2020 Q2 | H1: 2020 Q3 | I1: 2020 Q4 | J1: 2021 Q1 | K1: 2021 Q2 | L1: 2021 Q3 | M1: 2021 Q4 | N1: 2022 Q1 | O1: 2022 Q2 | P1: 2022 Q3 | Q1: 2022 Q4 | R1: 2023 Q1 | S1: 2023 Q2 | T1: 2023 Q3 | U1: 2023 Q4 | V1: 2024 Q1 | W1: 2024 Q2 | X1: 2024 Q3 | Y1: 2024 Q4 | Z1: 2025 Q1 | AA1: 2025 Q2 | AB1: 2025 Q3 | AC1: 2025 Q4
A2: Contract Model Score | B2: 130.07861 | C2: 132.83039 | D2: 132.99375 | E2: 132.11029 | F2: 131.79764 | G2: 133.71059 | H2: 135.28557 | I2: 135.79608 | J2: 134.60179 | K2: 135.14257 | L2: 135.36265 | M2: 134.41538 | N2: 134.0686 | O2: 135.89246 | P2: 136.14781 | Q2: 136.75155 | R2: 136.66305 | S2: 136.90907 | T2: 136.43849 | U2: 137.02135 | V2: 136.37212 | W2: 137.12198 | X2: 138.09052 | Y2: 136.80136 | Z2: 136.83702 | AA2: 138.03382 | AB2: 138.55808 | AC2: 139.3761 | AD2: 140.35811
A3: Model Score | B3: 0 | C3: 0 | D3: 0 | E3: 0 | F3: 0 | G3: 0 | H3: 0 | I3: 0 | J3: 0 | K3: 0 | L3: 0 | M3: 0 | N3: 0 | O3: 0 | P3: 0 | Q3: 0 | R3: 0 | S3: 0 | T3: 0 | U3: 0 | V3: 0 | W3: 0 | X3: 0 | Y3: 0 | Z3: 0 | AA3: 0 | AB3: 0 | AC3: 0 | AD3: 0
A4: Gross Loss Adjustments (Dealer level, high PTI, etc.) | B4: 0.66100206 | C4: 1.0383634 | D4: 1.1335416 | E4: 1.057243 | F4: 1.4123341 | G4: 1.3083797 | H4: 0.58221869 | I4: 1.0822147 | J4: 1.3206171 | K4: 1.3559535 | L4: 1.3112364 | M4: 1.2138028 | N4: 1.6338939 | O4: 1.3966256 | P4: 1.2658425 | Q4: 1.2408405 | R4: 0.79430529 | S4: 1.2228347 | T4: 0.70121599 | U4: 0.83461733 | V4: 0.66242898 | W4: 1.1867832 | X4: 0.97810535 | Y4: 1.1748893 | Z4: 1.4592694 | AA4: 2.4660669 | AB4: 2.9266817 | AC4: 2.9196016 | AD4: 3.1024219
A5: Recovery Adjustments excluding LTV (Mileage, vehicle type, etc.) | B5: -0.054409067 | C5: 0.70005236 | D5: 0.67202736 | E5: 0.47448415 | F5: 0.30912709 | G5: 0.21724112 | H5: 0.74289438 | I5: 0.70952244 | J5: 0.67145042 | K5: 0.50632617 | L5: 0.26596726 | M5: -0.28347851 | N5: -0.67418374 | O5: -1.0045925 | P5: -1.1216422 | Q5: -0.74577294 | R5: -0.85024309 | S5: -0.68592821 | T5: -1.2611827 | U5: -0.66822787 | V5: -1.4532558 | W5: -0.49934091 | X5: -0.60058587 | Y5: 0.46835393 | Z5: 0.39957502 | AA5: 0.3029111 | AB5: 1.1079276 | AC5: 2.0640683 | AD5: 0.69046435
A6: LTV Adjustments | B6: 0.054409067 | C6: -0.70005236 | D6: -0.67202736 | E6: -0.47448415 | F6: -0.30912709 | G6: -0.21724112 | H6: -0.74289438 | I6: -0.70952244 | J6: -0.67145042 | K6: -0.50632617 | L6: -0.26596726 | M6: 0.28347851 | N6: 0.67418374 | O6: 1.0045925 | P6: 1.1216422 | Q6: 0.74577294 | R6: 0.85024309 | S6: 0.68592821 | T6: 1.2611827 | U6: 0.66822787 | V6: 1.4532558 | W6: 0.49934091 | X6: 0.60058587 | Y6: -0.46835393 | Z6: -0.39957502 | AA6: -0.3029111 | AB6: -1.1079276 | AC6: -2.0640683 | AD6: -0.69046435
A7: RAGU Score | B7: 130.73961 | C7: 133.86875 | D7: 134.12729 | E7: 133.16753 | F7: 133.20997 | G7: 135.01897 | H7: 135.86779 | I7: 136.8783 | J7: 135.92241 | K7: 136.49853 | L7: 136.67389 | M7: 135.62918 | N7: 135.70249 | O7: 137.28909 | P7: 137.41365 | Q7: 137.99239 | R7: 137.45735 | S7: 138.1319 | T7: 137.13971 | U7: 137.85597 | V7: 137.03455 | W7: 138.30877 | X7: 139.06863 | Y7: 137.97624 | Z7: 138.29629 | AA7: 140.49989 | AB7: 141.48476 | AC7: 142.2957 | AD7: 143.46053
A8: LTV | B8: 1.9101927 | C8: 1.9033588 | D8: 1.9123152 | E8: 1.9528892 | F8: 1.9038189 | G8: 1.9494936 | H8: 1.6770808 | I8: 1.664423 | J8: 1.6924912 | K8: 1.5180062 | L8: 1.5882537 | M8: 1.5848062 | N8: 1.6190206 | O8: 1.7180658 | P8: 1.753261 | Q8: 1.8148918 | R8: 1.8290827 | S8: 1.7198073 | T8: 1.6761533 | U8: 1.7123719 | V8: 1.7359703 | W8: 1.6835907 | X8: 1.5949825 | Y8: 1.6188285 | Z8: 1.6088885 | AA8: 1.5694662 | AB8: 1.573298 | AC8: 1.5514636 | AD8: 1.5496695
A10: FLD | F10: 2020 Q1 | G10: 2020 Q2 | H10: 2020 Q3 | I10: 2020 Q4 | J10: 2021 Q1 | K10: 2021 Q2 | L10: 2021 Q3 | M10: 2021 Q4 | N10: 2022 Q1 | O10: 2022 Q2 | P10: 2022 Q3 | Q10: 2022 Q4 | R10: 2023 Q1 | S10: 2023 Q2 | T10: 2023 Q3 | U10: 2023 Q4 | V10: 2024 Q1 | W10: 2024 Q2 | X10: 2024 Q3 | Y10: 2024 Q4 | Z10: 2025 Q1 | AA10: 2025 Q2 | AB10: 2025 Q3 | AC10: 2025 Q4
A11: Contract Model Score | F11: 131.95039 | G11: 135.66547 | H11: 137.78086 | I11: 140.37625 | J11: 136.75685 | K11: 136.18261 | L11: 135.63105 | M11: 134.62935 | N11: 134.17392 | O11: 135.83718 | P11: 136.96375 | Q11: 138.77228 | R11: 141.32316 | S11: 138.86319 | T11: 137.95666 | U11: 139.5662 | V11: 138.5244 | W11: 138.40978 | X11: 140.36331 | Y11: 138.38769 | Z11: 136.70743 | AA11: 138.3478 | AB11: 138.1021 | AC11: 138.94555 | AD11: 140.97177
A12: Model Score | F12: 0 | G12: 0 | H12: 0 | I12: 0 | J12: 0 | K12: 0 | L12: 0 | M12: 0 | N12: 0 | O12: 0 | P12: 0 | Q12: 0 | R12: 0 | S12: 0 | T12: 0 | U12: 0 | V12: 0 | W12: 0 | X12: 0 | Y12: 0 | Z12: 0 | AA12: 0 | AB12: 0 | AC12: 0 | AD12: 0
A13: Gross Loss Adjustments (Dealer level, high PTI, etc.) | F13: -1.7103216 | G13: -1.3620012 | H13: -0.82270063 | I13: 0.67937377 | J13: 1.8207974 | K13: -0.22282408 | L13: -0.34270651 | M13: 0.75425033 | N13: 0.49117725 | O13: 0.57506675 | P13: 0.94006829 | Q13: 0.98133634 | R13: 1.1637723 | S13: 0.76651233 | T13: 1.0512261 | U13: 1.3906266 | V13: 1.5536976 | W13: 2.4436111 | X13: 3.2853416 | Y13: 2.9736339 | Z13: 2.4078901 | AA13: 2.4910068 | AB13: 3.0095789 | AC13: 1.8551298 | AD13: 2.3319267
A14: Recovery Adjustments excluding LTV (Mileage, vehicle type, etc.) | F14: 0.023124101 | G14: -0.099685801 | H14: 0.22494839 | I14: 0.80838437 | J14: 0.69008016 | K14: 0.44701898 | L14: 0.39655896 | M14: -0.01210726 | N14: -0.55783536 | O14: -1.0422641 | P14: -1.1424868 | Q14: -0.17638707 | R14: -0.62023186 | S14: -1.2375384 | T14: -0.97157633 | U14: -1.7143126 | V14: -1.3255697 | W14: -0.79912119 | X14: -0.11852831 | Y14: 0.32035449 | Z14: 0.43211964 | AA14: 0.76100218 | AB14: 0.82991687 | AC14: 1.4964658 | AD14: 0.16371332
A15: LTV Adjustments | F15: -0.023124101 | G15: 0.099685801 | H15: -0.22494839 | I15: -0.80838437 | J15: -0.69008016 | K15: -0.44701898 | L15: -0.39655896 | M15: 0.01210726 | N15: 0.55783536 | O15: 1.0422641 | P15: 1.1424868 | Q15: 0.17638707 | R15: 0.62023186 | S15: 1.2375384 | T15: 0.97157633 | U15: 1.7143126 | V15: 1.3255697 | W15: 0.79912119 | X15: 0.11852831 | Y15: -0.32035449 | Z15: -0.43211964 | AA15: -0.76100218 | AB15: -0.82991687 | AC15: -1.4964658 | AD15: -0.16371332
A16: RAGU Score | F16: 130.24007 | G16: 134.30347 | H16: 136.95816 | I16: 141.05562 | J16: 138.57764 | K16: 135.95979 | L16: 135.28834 | M16: 135.3836 | N16: 134.6651 | O16: 136.41225 | P16: 137.90382 | Q16: 139.75362 | R16: 142.48693 | S16: 139.6297 | T16: 139.00788 | U16: 140.95683 | V16: 140.0781 | W16: 140.85339 | X16: 143.64865 | Y16: 141.36132 | Z16: 139.11532 | AA16: 140.8388 | AB16: 141.11168 | AC16: 140.80068 | AD16: 143.30369
A17: LTV | F17: 1.4221399 | G17: 1.3722282 | H17: 1.2228557 | I17: 1.2691963 | J17: 1.3327275 | K17: 1.2326635 | L17: 1.2757828 | M17: 1.3349712 | N17: 1.3422822 | O17: 1.3349194 | P17: 1.3215161 | Q17: 1.3238593 | R17: 1.2734391 | S17: 1.3071443 | T17: 1.2660861 | U17: 1.2843422 | V17: 1.3825942 | W17: 1.3651666 | X17: 1.3457689 | Y17: 1.3402466 | Z17: 1.3808658 | AA17: 1.4104061 | AB17: 1.4124083 | AC17: 1.4092603 | AD17: 1.4629259
A19: FRN | B19: 2016 | C19: 2017 | D19: 2018 | E19: 2019 | F19: 2020 Q1 | G19: 2020 Q2 | H19: 2020 Q3 | I19: 2020 Q4 | J19: 2021 Q1 | K19: 2021 Q2 | L19: 2021 Q3 | M19: 2021 Q4 | N19: 2022 Q1 | O19: 2022 Q2 | P19: 2022 Q3 | Q19: 2022 Q4 | R19: 2023 Q1 | S19: 2023 Q2 | T19: 2023 Q3 | U19: 2023 Q4 | V19: 2024 Q1 | W19: 2024 Q2 | X19: 2024 Q3 | Y19: 2024 Q4 | Z19: 2025 Q1 | AA19: 2025 Q2 | AB19: 2025 Q3 | AC19: 2025 Q4
A20: Contract Model Score | B20: 131.16747 | C20: 136.73823 | D20: 136.80259 | E20: 132.54767 | F20: 131.13303 | G20: 132.90504 | H20: 133.93048 | I20: 132.80381 | J20: 135.44811 | K20: 135.18735 | L20: 134.94602 | M20: 132.89928 | N20: 134.06325 | O20: 136.81721 | P20: 138.00243 | Q20: 139.77793 | R20: 141.27719 | S20: 140.58734 | T20: 140.72103 | U20: 139.02514 | V20: 138.13163 | W20: 140.17356 | X20: 141.55375 | Y20: 139.97097 | Z20: 139.83315 | AA20: 140.63434 | AB20: 140.96388 | AC20: 141.85749 | AD20: 142.779
A21: Model Score | B21: 0 | C21: 0 | D21: 0 | E21: 0 | F21: 0 | G21: 0 | H21: 0 | I21: 0 | J21: 0 | K21: 0 | L21: 0 | M21: 0 | N21: 0 | O21: 0 | P21: 0 | Q21: 0 | R21: 0 | S21: 0 | T21: 0 | U21: 0 | V21: 0 | W21: 0 | X21: 0 | Y21: 0 | Z21: 0 | AA21: 0 | AB21: 0 | AC21: 0 | AD21: 0
A22: Gross Loss Adjustments (Dealer level, high PTI, etc.) | B22: -0.086531737 | C22: 0.56457952 | D22: 0.097990972 | E22: 0.65117725 | F22: 1.3091096 | G22: 1.5067007 | H22: 0.54845206 | I22: 0.003989095 | J22: 0.52413776 | K22: 0.89828531 | L22: 0.69221704 | M22: -0.39544921 | N22: -0.23544014 | O22: 0.72599632 | P22: 0.58262346 | Q22: 0.31311591 | R22: 0.93723355 | S22: 1.5645409 | T22: 1.6212334 | U22: 0.89293024 | V22: -0.19717966 | W22: 0.30351544 | X22: 0.75919793 | Y22: 0.53146185 | Z22: 0.66791062 | AA22: 1.2781424 | AB22: 1.7965359 | AC22: 2.7808561 | AD22: 2.8426225
A23: Recovery Adjustments excluding LTV (Mileage, vehicle type, etc.) | B23: -0.34957323 | C23: 0.53915686 | D23: 0.9457154 | E23: 0.17382504 | F23: 0.52242077 | G23: 0.37549313 | H23: 0.22327722 | I23: 0.97254445 | J23: 0.63940265 | K23: 0.40699231 | L23: 0.31059881 | M23: -0.21772404 | N23: -0.84848183 | O23: -0.91051986 | P23: -1.1274987 | Q23: -0.88900089 | R23: -0.73527945 | S23: -1.1082916 | T23: -1.3951448 | U23: -1.0241195 | V23: -1.469728 | W23: -0.89756939 | X23: -0.42888308 | Y23: 0.51363052 | Z23: 0.29524401 | AA23: 0.76044825 | AB23: 1.1323438 | AC23: 1.6648451 | AD23: 0.93089782
A24: LTV Adjustments | B24: 0.34957323 | C24: -0.53915686 | D24: -0.9457154 | E24: -0.17382504 | F24: -0.52242077 | G24: -0.37549313 | H24: -0.22327722 | I24: -0.97254445 | J24: -0.63940265 | K24: -0.40699231 | L24: -0.31059881 | M24: 0.21772404 | N24: 0.84848183 | O24: 0.91051986 | P24: 1.1274987 | Q24: 0.88900089 | R24: 0.73527945 | S24: 1.1082916 | T24: 1.3951448 | U24: 1.0241195 | V24: 1.469728 | W24: 0.89756939 | X24: 0.42888308 | Y24: -0.51363052 | Z24: -0.29524401 | AA24: -0.76044825 | AB24: -1.1323438 | AC24: -1.6648451 | AD24: -0.93089782
A25: RAGU Score | B25: 131.08094 | C25: 137.30281 | D25: 136.90058 | E25: 133.19885 | F25: 132.44214 | G25: 134.41174 | H25: 134.47893 | I25: 132.8078 | J25: 135.97225 | K25: 136.08564 | L25: 135.63823 | M25: 132.50383 | N25: 133.82781 | O25: 137.5432 | P25: 138.58506 | Q25: 140.09105 | R25: 142.21442 | S25: 142.15188 | T25: 142.34226 | U25: 139.91807 | V25: 137.93446 | W25: 140.47708 | X25: 142.31295 | Y25: 140.50244 | Z25: 140.50106 | AA25: 141.91248 | AB25: 142.76042 | AC25: 144.63834 | AD25: 145.62163
A26: LTV | B26: 2.1588362 | C26: 2.2065357 | D26: 2.1158734 | E26: 2.09243 | F26: 1.9393233 | G26: 1.9441554 | H26: 1.9016888 | I26: 2.032051 | J26: 1.7355409 | K26: 1.5130107 | L26: 1.6177635 | M26: 1.6852642 | N26: 1.6609436 | O26: 1.6670626 | P26: 1.6833356 | Q26: 1.6853941 | R26: 1.7304846 | S26: 1.5415358 | T26: 1.5005377 | U26: 1.4615654 | V26: 1.4841217 | W26: 1.477298 | X26: 1.4908119 | Y26: 1.4856955 | Z26: 1.4883673 | AA26: 1.4290012 | AB26: 1.425504 | AC26: 1.4203813 | AD26: 1.4858585
A28: STG | B28: 2016 | C28: 2017 | D28: 2018 | E28: 2019 | F28: 2020 Q1 | G28: 2020 Q2 | H28: 2020 Q3 | I28: 2020 Q4 | J28: 2021 Q1 | K28: 2021 Q2 | L28: 2021 Q3 | M28: 2021 Q4 | N28: 2022 Q1 | O28: 2022 Q2 | P28: 2022 Q3 | Q28: 2022 Q4 | R28: 2023 Q1 | S28: 2023 Q2 | T28: 2023 Q3 | U28: 2023 Q4 | V28: 2024 Q1 | W28: 2024 Q2 | X28: 2024 Q3 | Y28: 2024 Q4 | Z28: 2025 Q1 | AA28: 2025 Q2 | AB28: 2025 Q3 | AC28: 2025 Q4
A29: Contract Model Score | B29: 129.64154 | C29: 131.65563 | D29: 131.56832 | E29: 129.50597 | F29: 130.0304 | G29: 133.13562 | H29: 135.5242 | I29: 135.28733 | J29: 135.28771 | K29: 135.49901 | L29: 135.05653 | M29: 133.65336 | N29: 134.55 | O29: 136.72731 | P29: 137.27114 | Q29: 138.30195 | R29: 139.23035 | S29: 137.71584 | T29: 138.53984 | U29: 137.48747 | V29: 136.76023 | W29: 137.47802 | X29: 138.54354 | Y29: 137.20905 | Z29: 136.6684 | AA29: 137.94719 | AB29: 138.66055 | AC29: 140.03752 | AD29: 141.07253
A30: Model Score | B30: 0 | C30: 0 | D30: 0 | E30: 0 | F30: 0 | G30: 0 | H30: 0 | I30: 0 | J30: 0 | K30: 0 | L30: 0 | M30: 0 | N30: 0 | O30: 0 | P30: 0 | Q30: 0 | R30: 0 | S30: 0 | T30: 0 | U30: 0 | V30: 0 | W30: 0 | X30: 0 | Y30: 0 | Z30: 0 | AA30: 0 | AB30: 0 | AC30: 0 | AD30: 0
A31: Gross Loss Adjustments (Dealer level, high PTI, etc.) | B31: 0.80451042 | C31: 0.93531319 | D31: 0.87019855 | E31: 0.78525767 | F31: 0.62627011 | G31: 0.56124754 | H31: 0.90101305 | I31: 0.8428326 | J31: 1.6574384 | K31: 1.8158511 | L31: 1.5016646 | M31: 1.1834961 | N31: 0.56607344 | O31: 0.62303432 | P31: -0.014227399 | Q31: 0.60880416 | R31: 0.26065132 | S31: 0.32381303 | T31: 1.4742954 | U31: 1.2647051 | V31: 1.0139279 | W31: 2.0228001 | X31: 2.2786498 | Y31: 2.0632355 | Z31: 1.8384507 | AA31: 2.0356619 | AB31: 2.2451501 | AC31: 2.7851197 | AD31: 3.1128337
A32: Recovery Adjustments excluding LTV (Mileage, vehicle type, etc.) | B32: 0.038871781 | C32: 0.73613395 | D32: 0.58170063 | E32: 0.46287386 | F32: 0.22331471 | G32: 0.10075895 | H32: 0.41100916 | I32: 0.85848503 | J32: 0.62447165 | K32: 0.63147985 | L32: 0.28314243 | M32: -0.41238527 | N32: -1.0433667 | O32: -0.60440352 | P32: -1.1042254 | Q32: -0.73889841 | R32: -0.44086227 | S32: -0.97274042 | T32: -1.0454229 | U32: -1.2079618 | V32: -1.4540589 | W32: -1.137462 | X32: -0.035229793 | Y32: 0.5700101 | Z32: 0.50656547 | AA32: 0.65025191 | AB32: 1.0876569 | AC32: 1.9194278 | AD32: 0.64487394
A33: LTV Adjustments | B33: -0.038871781 | C33: -0.73613395 | D33: -0.58170063 | E33: -0.46287386 | F33: -0.22331471 | G33: -0.10075895 | H33: -0.41100916 | I33: -0.85848503 | J33: -0.62447165 | K33: -0.63147985 | L33: -0.28314243 | M33: 0.41238527 | N33: 1.0433667 | O33: 0.60440352 | P33: 1.1042254 | Q33: 0.73889841 | R33: 0.44086227 | S33: 0.97274042 | T33: 1.0454229 | U33: 1.2079618 | V33: 1.4540589 | W33: 1.137462 | X33: 0.035229793 | Y33: -0.5700101 | Z33: -0.50656547 | AA33: -0.65025191 | AB33: -1.0876569 | AC33: -1.9194278 | AD33: -0.64487394
A34: RAGU Score | B34: 130.44605 | C34: 132.59094 | D34: 132.43852 | E34: 130.29123 | F34: 130.65667 | G34: 133.69687 | H34: 136.42521 | I34: 136.13016 | J34: 136.94515 | K34: 137.31486 | L34: 136.5582 | M34: 134.83686 | N34: 135.11607 | O34: 137.35035 | P34: 137.25692 | Q34: 138.91076 | R34: 139.491 | S34: 138.03965 | T34: 140.01413 | U34: 138.75218 | V34: 137.77416 | W34: 139.50082 | X34: 140.82219 | Y34: 139.27228 | Z34: 138.50685 | AA34: 139.98285 | AB34: 140.9057 | AC34: 142.82264 | AD34: 144.18537
A35: LTV | B35: 1.9506243 | C35: 1.9398596 | D35: 1.9893738 | E35: 2.0866595 | F35: 2.0894836 | G35: 2.1082303 | H35: 1.8230661 | I35: 1.8044767 | J35: 1.7000351 | K35: 1.5707098 | L35: 1.5939441 | M35: 1.6156902 | N35: 1.5718352 | O35: 1.519652 | P35: 1.536806 | Q35: 1.4821458 | R35: 1.4795919 | S35: 1.5163861 | T35: 1.4273243 | U35: 1.4313978 | V35: 1.5302432 | W35: 1.4910126 | X35: 1.45301 | Y35: 1.4632665 | Z35: 1.4858925 | AA35: 1.4269815 | AB35: 1.4322616 | AC35: 1.4179012 | AD35: 1.4831895
A37: ENT | F37: 2020 Q1 | G37: 2020 Q2 | H37: 2020 Q3 | I37: 2020 Q4 | J37: 2021 Q1 | K37: 2021 Q2 | L37: 2021 Q3 | M37: 2021 Q4 | N37: 2022 Q1 | O37: 2022 Q2 | P37: 2022 Q3 | Q37: 2022 Q4 | R37: 2023 Q1 | S37: 2023 Q2 | T37: 2023 Q3 | U37: 2023 Q4 | V37: 2024 Q1 | W37: 2024 Q2 | X37: 2024 Q3 | Y37: 2024 Q4 | Z37: 2025 Q1 | AA37: 2025 Q2 | AB37: 2025 Q3 | AC37: 2025 Q4
A38: Contract Model Score | F38: 132.38307 | G38: 133.22864 | H38: 136.30166 | I38: 135.38242 | J38: 133.8357 | K38: 131.8749 | L38: 131.13569 | M38: 129.4723 | N38: 129.34473 | O38: 131.45349 | P38: 131.71553 | Q38: 131.25851 | R38: 132.73385 | S38: 133.4422 | T38: 133.76755 | U38: 135.31367 | V38: 136.17456 | W38: 136.8171 | X38: 136.69241 | Y38: 134.94875 | Z38: 134.57148 | AA38: 136.41792 | AB38: 137.0063 | AC38: 137.20721 | AD38: 139.78392
A39: Model Score | F39: 0 | G39: 0 | H39: 0 | I39: 0 | J39: 0 | K39: 0 | L39: 0 | M39: 0 | N39: 0 | O39: 0 | P39: 0 | Q39: 0 | R39: 0 | S39: 0 | T39: 0 | U39: 0 | V39: 0 | W39: 0 | X39: 0 | Y39: 0 | Z39: 0 | AA39: 0 | AB39: 0 | AC39: 0 | AD39: 0
A40: Gross Loss Adjustments (Dealer level, high PTI, etc.) | F40: 0.53733727 | G40: 0.6114489 | H40: 0.32319334 | I40: -0.89774632 | J40: -0.38175502 | K40: -0.59152797 | L40: -0.80097815 | M40: -0.57952409 | N40: -0.12187674 | O40: -0.57677921 | P40: -1.5631581 | Q40: -1.3928785 | R40: -1.7516348 | S40: -1.0557538 | T40: -0.70981925 | U40: 0.45637312 | V40: -0.59196155 | W40: -0.32963785 | X40: -0.49424107 | Y40: -0.28560818 | Z40: -0.97599678 | AA40: 0.20518067 | AB40: 0.17963091 | AC40: 1.0649609 | AD40: 1.232904
A41: Recovery Adjustments excluding LTV (Mileage, vehicle type, etc.) | F41: -1.1415244 | G41: -0.8514428 | H41: -0.43661837 | I41: -0.55641526 | J41: -0.49662092 | K41: 0.11718027 | L41: -0.437745 | M41: -0.36445296 | N41: -1.3075132 | O41: -1.6113288 | P41: -2.3543305 | Q41: -2.5707845 | R41: -2.2856497 | S41: -2.2622105 | T41: -1.7989997 | U41: -1.1567416 | V41: -1.8790409 | W41: -1.4112415 | X41: -0.48973089 | Y41: 2.2143246 | Z41: 3.2384867 | AA41: 2.1064982 | AB41: 2.420684 | AC41: 3.3393899 | AD41: 2.63809
A42: LTV Adjustments | F42: 1.1415244 | G42: 0.8514428 | H42: 0.43661837 | I42: 0.55641526 | J42: 0.49662092 | K42: -0.11718027 | L42: 0.437745 | M42: 0.36445296 | N42: 1.3075132 | O42: 1.6113288 | P42: 2.3543305 | Q42: 2.5707845 | R42: 2.2856497 | S42: 2.2622105 | T42: 1.7989997 | U42: 1.1567416 | V42: 1.8790409 | W42: 1.4112415 | X42: 0.48973089 | Y42: -2.2143246 | Z42: -3.2384867 | AA42: -2.1064982 | AB42: -2.420684 | AC42: -3.3393899 | AD42: -2.63809
A43: RAGU Score | F43: 132.92041 | G43: 133.84009 | H43: 136.62485 | I43: 134.48468 | J43: 133.45395 | K43: 131.28337 | L43: 130.33471 | M43: 128.89278 | N43: 129.22285 | O43: 130.87671 | P43: 130.15238 | Q43: 129.86564 | R43: 130.98221 | S43: 132.38644 | T43: 133.05774 | U43: 135.77004 | V43: 135.5826 | W43: 136.48746 | X43: 136.19817 | Y43: 134.66314 | Z43: 133.59548 | AA43: 136.6231 | AB43: 137.18593 | AC43: 138.27218 | AD43: 141.01682
A44: LTV | F44: 1.4713395 | G44: 1.4484379 | H44: 1.2685054 | I44: 1.3692404 | J44: 1.3589856 | K44: 1.2616075 | L44: 1.3410244 | M44: 1.3740428 | N44: 1.3946426 | O44: 1.3463624 | P44: 1.2927129 | Q44: 1.3475097 | R44: 1.3825699 | S44: 1.3325832 | T44: 1.2570081 | U44: 1.3077675 | V44: 1.3170153 | W44: 1.3000395 | X44: 1.3144672 | Y44: 1.3452338 | Z44: 1.3309705 | AA44: 1.3026223 | AB44: 1.307922 | AC44: 1.3182126 | AD44: 1.3322288
...

Sheet Monday pre-lunch
A1: AN | B1: 2016 | C1: 2017 | D1: 2018 | E1: 2019 | F1: 2020 Q1 | G1: 2020 Q2 | H1: 2020 Q3 | I1: 2020 Q4 | J1: 2021 Q1 | K1: 2021 Q2 | L1: 2021 Q3 | M1: 2021 Q4 | N1: 2022 Q1 | O1: 2022 Q2 | P1: 2022 Q3 | Q1: 2022 Q4 | R1: 2023 Q1 | S1: 2023 Q2 | T1: 2023 Q3 | U1: 2023 Q4 | V1: 2024 Q1 | W1: 2024 Q2 | X1: 2024 Q3 | Y1: 2024 Q4 | Z1: 2025 Q1 | AA1: 2025 Q2 | AB1: 2025 Q3 | AC1: 2025 Q4
A2: Contract Model Score | B2: 130.07861 | C2: 132.83039 | D2: 132.99375 | E2: 132.11029 | F2: 131.79764 | G2: 133.71059 | H2: 135.28557 | I2: 135.79608 | J2: 134.60179 | K2: 135.14257 | L2: 135.36265 | M2: 134.41538 | N2: 134.0686 | O2: 135.89246 | P2: 136.14781 | Q2: 136.75155 | R2: 136.66305 | S2: 136.90907 | T2: 136.43849 | U2: 137.02135 | V2: 136.37212 | W2: 137.12198 | X2: 138.09052 | Y2: 136.80136 | Z2: 136.83702 | AA2: 138.03382 | AB2: 138.55808 | AC2: 139.3761 | AD2: 140.32155
A3: Model Score | B3: 0 | C3: 0 | D3: 0 | E3: 0 | F3: 0 | G3: 0 | H3: 0 | I3: 0 | J3: 0 | K3: 0 | L3: 0 | M3: 0 | N3: 0 | O3: 0 | P3: 0 | Q3: 0 | R3: 0 | S3: 0 | T3: 0 | U3: 0 | V3: 0 | W3: 0 | X3: 0 | Y3: 0 | Z3: 0 | AA3: 0 | AB3: 0 | AC3: 0 | AD3: 0
A4: Gross Loss Adjustments (Dealer level, high PTI, etc.) | B4: 0.66100206 | C4: 1.0383634 | D4: 1.1335416 | E4: 1.057243 | F4: 1.4123341 | G4: 1.3083797 | H4: 0.58221869 | I4: 1.0822147 | J4: 1.3206171 | K4: 1.3559535 | L4: 1.3112364 | M4: 1.2138028 | N4: 1.6338939 | O4: 1.3966256 | P4: 1.2658425 | Q4: 1.2408405 | R4: 0.79430529 | S4: 1.2228347 | T4: 0.70121599 | U4: 0.83461733 | V4: 0.66242898 | W4: 1.1867832 | X4: 0.97810535 | Y4: 1.1748893 | Z4: 1.4592694 | AA4: 2.4660669 | AB4: 2.9266817 | AC4: 2.9196016 | AD4: 3.1264617
A5: Recovery Adjustments excluding LTV (Mileage, vehicle type, etc.) | B5: 0.040639159 | C5: 0.69500046 | D5: 0.67755368 | E5: 0.42086809 | F5: 0.21389965 | G5: -0.063961463 | H5: 0.12674062 | I5: 1.1083249 | J5: 0.73789405 | K5: 0.66345891 | L5: 0.13645001 | M5: -0.3134521 | N5: -0.84207443 | O5: -0.59712741 | P5: -1.020476 | Q5: -0.81505756 | R5: -1.0819684 | S5: -0.86060122 | T5: -0.82434928 | U5: -0.96054829 | V5: -1.5450464 | W5: -0.95315995 | X5: -0.164701 | Y5: 0.3523825 | Z5: 0.4368203 | AA5: 0.72033179 | AB5: 1.18049 | AC5: 1.1525343 | AD5: 0.5215806
A6: LTV Adjustments | B6: -0.040639159 | C6: -0.69500046 | D6: -0.67755368 | E6: -0.42086809 | F6: -0.21389965 | G6: 0.063961463 | H6: -0.12674062 | I6: -1.1083249 | J6: -0.73789405 | K6: -0.66345891 | L6: -0.13645001 | M6: 0.3134521 | N6: 0.84207443 | O6: 0.59712741 | P6: 1.020476 | Q6: 0.81505756 | R6: 1.0819684 | S6: 0.86060122 | T6: 0.82434928 | U6: 0.96054829 | V6: 1.5450464 | W6: 0.95315995 | X6: 0.164701 | Y6: -0.3523825 | Z6: -0.4368203 | AA6: -0.72033179 | AB6: -1.18049 | AC6: -1.1525343 | AD6: -0.5215806
A7: RAGU Score | B7: 130.73961 | C7: 133.86875 | D7: 134.12729 | E7: 133.16753 | F7: 133.20997 | G7: 135.01897 | H7: 135.86779 | I7: 136.8783 | J7: 135.92241 | K7: 136.49853 | L7: 136.67389 | M7: 135.62918 | N7: 135.70249 | O7: 137.28909 | P7: 137.41365 | Q7: 137.99239 | R7: 137.45735 | S7: 138.1319 | T7: 137.13971 | U7: 137.85597 | V7: 137.03455 | W7: 138.30877 | X7: 139.06863 | Y7: 137.97624 | Z7: 138.29629 | AA7: 140.49989 | AB7: 141.48476 | AC7: 142.2957 | AD7: 143.44801
A8: LTV | B8: 1.909624 | C8: 1.9036638 | D8: 1.911999 | E8: 1.9526841 | F8: 1.9044985 | G8: 1.9485739 | H8: 1.6764056 | I8: 1.664423 | J8: 1.6924912 | K8: 1.5166949 | L8: 1.5884002 | M8: 1.5848716 | N8: 1.6172698 | O8: 1.7180658 | P8: 1.7529717 | Q8: 1.8148918 | R8: 1.8294105 | S8: 1.7172854 | T8: 1.6747687 | U8: 1.712079 | V8: 1.7379145 | W8: 1.6849116 | X8: 1.5938866 | Y8: 1.6194247 | Z8: 1.6099331 | AA8: 1.5698617 | AB8: 1.5725637 | AC8: 1.5526097 | AD8: 1.5522131
A10: FLD | F10: 2020 Q1 | G10: 2020 Q2 | H10: 2020 Q3 | I10: 2020 Q4 | J10: 2021 Q1 | K10: 2021 Q2 | L10: 2021 Q3 | M10: 2021 Q4 | N10: 2022 Q1 | O10: 2022 Q2 | P10: 2022 Q3 | Q10: 2022 Q4 | R10: 2023 Q1 | S10: 2023 Q2 | T10: 2023 Q3 | U10: 2023 Q4 | V10: 2024 Q1 | W10: 2024 Q2 | X10: 2024 Q3 | Y10: 2024 Q4 | Z10: 2025 Q1 | AA10: 2025 Q2 | AB10: 2025 Q3 | AC10: 2025 Q4
A11: Contract Model Score | F11: 131.95039 | G11: 135.66547 | H11: 137.78086 | I11: 140.37625 | J11: 136.75685 | K11: 136.18261 | L11: 135.63105 | M11: 134.62935 | N11: 134.17392 | O11: 135.83718 | P11: 136.96375 | Q11: 138.77228 | R11: 141.32316 | S11: 138.86319 | T11: 137.95666 | U11: 139.5662 | V11: 138.5244 | W11: 138.40978 | X11: 140.36331 | Y11: 138.38769 | Z11: 136.70743 | AA11: 138.3478 | AB11: 138.1021 | AC11: 138.94555 | AD11: 140.9645
A12: Model Score | F12: 0 | G12: 0 | H12: 0 | I12: 0 | J12: 0 | K12: 0 | L12: 0 | M12: 0 | N12: 0 | O12: 0 | P12: 0 | Q12: 0 | R12: 0 | S12: 0 | T12: 0 | U12: 0 | V12: 0 | W12: 0 | X12: 0 | Y12: 0 | Z12: 0 | AA12: 0 | AB12: 0 | AC12: 0 | AD12: 0
A13: Gross Loss Adjustments (Dealer level, high PTI, etc.) | F13: -1.7103216 | G13: -1.3620012 | H13: -0.82270063 | I13: 0.67937377 | J13: 1.8207974 | K13: -0.22282408 | L13: -0.34270651 | M13: 0.75425033 | N13: 0.49117725 | O13: 0.57506675 | P13: 0.94006829 | Q13: 0.98065555 | R13: 1.1637723 | S13: 0.76651233 | T13: 1.0512261 | U13: 1.3906266 | V13: 1.5536976 | W13: 2.4436111 | X13: 3.2853416 | Y13: 2.9736339 | Z13: 2.4078901 | AA13: 2.4910068 | AB13: 3.0095789 | AC13: 1.8551298 | AD13: 2.3630141
A14: Recovery Adjustments excluding LTV (Mileage, vehicle type, etc.) | F14: 0.32441377 | G14: -0.0095467241 | H14: 0.45471768 | I14: 0.67866406 | J14: 1.174554 | K14: 0.49286732 | L14: 0.40526522 | M14: -0.50481234 | N14: -0.90136184 | O14: -1.0082651 | P14: -1.1851302 | Q14: -0.65797497 | R14: -0.31490492 | S14: -1.5345245 | T14: -1.1079904 | U14: -1.7173528 | V14: -1.5308681 | W14: -1.1260146 | X14: 0.39959495 | Y14: 0.27248085 | Z14: 0.7382144 | AA14: 0.25616759 | AB14: 1.2398641 | AC14: 1.6367415 | AD14: 0.31950211
A15: LTV Adjustments | F15: -0.32441377 | G15: 0.0095467241 | H15: -0.45471768 | I15: -0.67866406 | J15: -1.174554 | K15: -0.49286732 | L15: -0.40526522 | M15: 0.50481234 | N15: 0.90136184 | O15: 1.0082651 | P15: 1.1851302 | Q15: 0.65797497 | R15: 0.31490492 | S15: 1.5345245 | T15: 1.1079904 | U15: 1.7173528 | V15: 1.5308681 | W15: 1.1260146 | X15: -0.39959495 | Y15: -0.27248085 | Z15: -0.7382144 | AA15: -0.25616759 | AB15: -1.2398641 | AC15: -1.6367415 | AD15: -0.31950211
A16: RAGU Score | F16: 130.24007 | G16: 134.30347 | H16: 136.95816 | I16: 141.05562 | J16: 138.57764 | K16: 135.95979 | L16: 135.28834 | M16: 135.3836 | N16: 134.6651 | O16: 136.41225 | P16: 137.90382 | Q16: 139.75294 | R16: 142.48693 | S16: 139.6297 | T16: 139.00788 | U16: 140.95683 | V16: 140.0781 | W16: 140.85339 | X16: 143.64865 | Y16: 141.36132 | Z16: 139.11532 | AA16: 140.8388 | AB16: 141.11168 | AC16: 140.80068 | AD16: 143.32752
A17: LTV | F17: 1.4222519 | G17: 1.3722716 | H17: 1.2228312 | I17: 1.2691963 | J17: 1.3323695 | K17: 1.2326635 | L17: 1.2754213 | M17: 1.3349712 | N17: 1.3422608 | O17: 1.3349194 | P17: 1.3215161 | Q17: 1.3240934 | R17: 1.2734391 | S17: 1.3071443 | T17: 1.2660861 | U17: 1.2841699 | V17: 1.3828362 | W17: 1.3654095 | X17: 1.3456576 | Y17: 1.3397406 | Z17: 1.3803025 | AA17: 1.4105826 | AB17: 1.4121637 | AC17: 1.409784 | AD17: 1.4642883
A19: FRN | B19: 2016 | C19: 2017 | D19: 2018 | E19: 2019 | F19: 2020 Q1 | G19: 2020 Q2 | H19: 2020 Q3 | I19: 2020 Q4 | J19: 2021 Q1 | K19: 2021 Q2 | L19: 2021 Q3 | M19: 2021 Q4 | N19: 2022 Q1 | O19: 2022 Q2 | P19: 2022 Q3 | Q19: 2022 Q4 | R19: 2023 Q1 | S19: 2023 Q2 | T19: 2023 Q3 | U19: 2023 Q4 | V19: 2024 Q1 | W19: 2024 Q2 | X19: 2024 Q3 | Y19: 2024 Q4 | Z19: 2025 Q1 | AA19: 2025 Q2 | AB19: 2025 Q3 | AC19: 2025 Q4
A20: Contract Model Score | B20: 131.16747 | C20: 136.73823 | D20: 136.80259 | E20: 132.54767 | F20: 131.13303 | G20: 132.90504 | H20: 133.93048 | I20: 132.80381 | J20: 135.44811 | K20: 135.18735 | L20: 134.94602 | M20: 132.89928 | N20: 134.06325 | O20: 136.81721 | P20: 138.00243 | Q20: 139.77793 | R20: 141.27719 | S20: 140.58734 | T20: 140.72103 | U20: 139.02514 | V20: 138.13163 | W20: 140.17356 | X20: 141.55375 | Y20: 139.97097 | Z20: 139.83315 | AA20: 140.63434 | AB20: 140.96388 | AC20: 141.85749 | AD20: 142.77194
A21: Model Score | B21: 0 | C21: 0 | D21: 0 | E21: 0 | F21: 0 | G21: 0 | H21: 0 | I21: 0 | J21: 0 | K21: 0 | L21: 0 | M21: 0 | N21: 0 | O21: 0 | P21: 0 | Q21: 0 | R21: 0 | S21: 0 | T21: 0 | U21: 0 | V21: 0 | W21: 0 | X21: 0 | Y21: 0 | Z21: 0 | AA21: 0 | AB21: 0 | AC21: 0 | AD21: 0
A22: Gross Loss Adjustments (Dealer level, high PTI, etc.) | B22: -0.086531737 | C22: 0.56457952 | D22: 0.097990972 | E22: 0.65117725 | F22: 1.3091096 | G22: 1.5067007 | H22: 0.54845206 | I22: 0.003989095 | J22: 0.52413776 | K22: 0.89828531 | L22: 0.69221704 | M22: -0.39544921 | N22: -0.23544014 | O22: 0.72599632 | P22: 0.58262346 | Q22: 0.31311591 | R22: 0.93883725 | S22: 1.5645409 | T22: 1.6212334 | U22: 0.89293024 | V22: -0.19717966 | W22: 0.30351544 | X22: 0.75919793 | Y22: 0.53146185 | Z22: 0.66791062 | AA22: 1.2781424 | AB22: 1.7965359 | AC22: 2.7808561 | AD22: 2.864459
A23: Recovery Adjustments excluding LTV (Mileage, vehicle type, etc.) | B23: -0.22794787 | C23: 0.80538246 | D23: 0.19486095 | E23: 0.51372907 | F23: 0.35468851 | G23: 0.056925161 | H23: 0.27349318 | I23: 0.88921253 | J23: 0.44970513 | K23: 0.36076781 | L23: 0.29423118 | M23: -0.37072562 | N23: -0.82876904 | O23: -0.81985689 | P23: -1.1309709 | Q23: -0.873009 | R23: -0.57733486 | S23: -1.0984774 | T23: -1.4145298 | U23: -1.1347367 | V23: -1.1658807 | W23: -0.8766247 | X23: -0.42109334 | Y23: 0.55769209 | Z23: 0.4939827 | AA23: 0.69139225 | AB23: 1.1527107 | AC23: 1.5477495 | AD23: 0.72638593
A24: LTV Adjustments | B24: 0.22794787 | C24: -0.80538246 | D24: -0.19486095 | E24: -0.51372907 | F24: -0.35468851 | G24: -0.056925161 | H24: -0.27349318 | I24: -0.88921253 | J24: -0.44970513 | K24: -0.36076781 | L24: -0.29423118 | M24: 0.37072562 | N24: 0.82876904 | O24: 0.81985689 | P24: 1.1309709 | Q24: 0.873009 | R24: 0.57733486 | S24: 1.0984774 | T24: 1.4145298 | U24: 1.1347367 | V24: 1.1658807 | W24: 0.8766247 | X24: 0.42109334 | Y24: -0.55769209 | Z24: -0.4939827 | AA24: -0.69139225 | AB24: -1.1527107 | AC24: -1.5477495 | AD24: -0.72638593
A25: RAGU Score | B25: 131.08094 | C25: 137.30281 | D25: 136.90058 | E25: 133.19885 | F25: 132.44214 | G25: 134.41174 | H25: 134.47893 | I25: 132.8078 | J25: 135.97225 | K25: 136.08564 | L25: 135.63823 | M25: 132.50383 | N25: 133.82781 | O25: 137.5432 | P25: 138.58506 | Q25: 140.09105 | R25: 142.21603 | S25: 142.15188 | T25: 142.34226 | U25: 139.91807 | V25: 137.93446 | W25: 140.47708 | X25: 142.31295 | Y25: 140.50244 | Z25: 140.50106 | AA25: 141.91248 | AB25: 142.76042 | AC25: 144.63834 | AD25: 145.6364
A26: LTV | B26: 2.1590977 | C26: 2.2135986 | D26: 2.1161834 | E26: 2.0918812 | F26: 1.9400761 | G26: 1.9426253 | H26: 1.9008371 | I26: 2.03215 | J26: 1.7351144 | K26: 1.5133037 | L26: 1.6178619 | M26: 1.6849504 | N26: 1.6597874 | O26: 1.6660357 | P26: 1.683305 | Q26: 1.6858457 | R26: 1.7337778 | S26: 1.5422985 | T26: 1.5007865 | U26: 1.4616944 | V26: 1.4827336 | W26: 1.4771501 | X26: 1.4910847 | Y26: 1.4850829 | Z26: 1.4880099 | AA26: 1.4284132 | AB26: 1.4256353 | AC26: 1.4205648 | AD26: 1.4868418
A28: STG | B28: 2016 | C28: 2017 | D28: 2018 | E28: 2019 | F28: 2020 Q1 | G28: 2020 Q2 | H28: 2020 Q3 | I28: 2020 Q4 | J28: 2021 Q1 | K28: 2021 Q2 | L28: 2021 Q3 | M28: 2021 Q4 | N28: 2022 Q1 | O28: 2022 Q2 | P28: 2022 Q3 | Q28: 2022 Q4 | R28: 2023 Q1 | S28: 2023 Q2 | T28: 2023 Q3 | U28: 2023 Q4 | V28: 2024 Q1 | W28: 2024 Q2 | X28: 2024 Q3 | Y28: 2024 Q4 | Z28: 2025 Q1 | AA28: 2025 Q2 | AB28: 2025 Q3 | AC28: 2025 Q4
A29: Contract Model Score | B29: 129.64154 | C29: 131.65563 | D29: 131.56832 | E29: 129.50597 | F29: 130.0304 | G29: 133.13562 | H29: 135.5242 | I29: 135.28733 | J29: 135.28771 | K29: 135.49901 | L29: 135.05653 | M29: 133.65336 | N29: 134.55 | O29: 136.72731 | P29: 137.27114 | Q29: 138.30195 | R29: 139.23035 | S29: 137.71584 | T29: 138.53984 | U29: 137.48747 | V29: 136.76023 | W29: 137.47802 | X29: 138.54354 | Y29: 137.20905 | Z29: 136.6684 | AA29: 137.94719 | AB29: 138.66055 | AC29: 140.03752 | AD29: 141.05806
A30: Model Score | B30: 0 | C30: 0 | D30: 0 | E30: 0 | F30: 0 | G30: 0 | H30: 0 | I30: 0 | J30: 0 | K30: 0 | L30: 0 | M30: 0 | N30: 0 | O30: 0 | P30: 0 | Q30: 0 | R30: 0 | S30: 0 | T30: 0 | U30: 0 | V30: 0 | W30: 0 | X30: 0 | Y30: 0 | Z30: 0 | AA30: 0 | AB30: 0 | AC30: 0 | AD30: 0
A31: Gross Loss Adjustments (Dealer level, high PTI, etc.) | B31: 0.80451042 | C31: 0.93531319 | D31: 0.87019855 | E31: 0.78525767 | F31: 0.62627011 | G31: 0.56124754 | H31: 0.90101305 | I31: 0.8428326 | J31: 1.6574384 | K31: 1.8158511 | L31: 1.5016646 | M31: 1.1834961 | N31: 0.56607344 | O31: 0.62303432 | P31: -0.014227399 | Q31: 0.60880416 | R31: 0.26065132 | S31: 0.32381303 | T31: 1.4742954 | U31: 1.2647051 | V31: 1.0139279 | W31: 2.0228001 | X31: 2.2786498 | Y31: 2.0632355 | Z31: 1.8384507 | AA31: 2.0356619 | AB31: 2.2451501 | AC31: 2.7851197 | AD31: 3.1250191
A32: Recovery Adjustments excluding LTV (Mileage, vehicle type, etc.) | B32: -0.050455572 | C32: 0.75720385 | D32: 0.64947209 | E32: 0.43955009 | F32: 0.15936929 | G32: 0.2047825 | H32: 0.33580172 | I32: 0.63952476 | J32: 0.68712666 | K32: 0.56200971 | L32: 0.36259082 | M32: -0.21347617 | N32: -0.90647246 | O32: -1.1616512 | P32: -0.80402292 | Q32: -0.69565536 | R32: -0.6319643 | S32: -1.1689321 | T32: -1.0810718 | U32: -1.2889426 | V32: -1.6513592 | W32: -0.73387217 | X32: -0.1838068 | Y32: 0.73542112 | Z32: 0.23261972 | AA32: 0.25429475 | AB32: 1.0324709 | AC32: 1.8647753 | AD32: 0.7044151
A33: LTV Adjustments | B33: 0.050455572 | C33: -0.75720385 | D33: -0.64947209 | E33: -0.43955009 | F33: -0.15936929 | G33: -0.2047825 | H33: -0.33580172 | I33: -0.63952476 | J33: -0.68712666 | K33: -0.56200971 | L33: -0.36259082 | M33: 0.21347617 | N33: 0.90647246 | O33: 1.1616512 | P33: 0.80402292 | Q33: 0.69565536 | R33: 0.6319643 | S33: 1.1689321 | T33: 1.0810718 | U33: 1.2889426 | V33: 1.6513592 | W33: 0.73387217 | X33: 0.1838068 | Y33: -0.73542112 | Z33: -0.23261972 | AA33: -0.25429475 | AB33: -1.0324709 | AC33: -1.8647753 | AD33: -0.7044151
A34: RAGU Score | B34: 130.44605 | C34: 132.59094 | D34: 132.43852 | E34: 130.29123 | F34: 130.65667 | G34: 133.69687 | H34: 136.42521 | I34: 136.13016 | J34: 136.94515 | K34: 137.31486 | L34: 136.5582 | M34: 134.83686 | N34: 135.11607 | O34: 137.35035 | P34: 137.25692 | Q34: 138.91076 | R34: 139.491 | S34: 138.03965 | T34: 140.01413 | U34: 138.75218 | V34: 137.77416 | W34: 139.50082 | X34: 140.82219 | Y34: 139.27228 | Z34: 138.50685 | AA34: 139.98285 | AB34: 140.9057 | AC34: 142.82264 | AD34: 144.18308
A35: LTV | B35: 1.9504805 | C35: 1.9400051 | D35: 1.9886924 | E35: 2.0879173 | F35: 2.0811849 | G35: 2.108274 | H35: 1.8208212 | I35: 1.8044695 | J35: 1.7000302 | K35: 1.5710507 | L35: 1.5936037 | M35: 1.6156902 | N35: 1.5718352 | O35: 1.5196343 | P35: 1.5368932 | Q35: 1.4821458 | R35: 1.4795919 | S35: 1.5164709 | T35: 1.4303354 | U35: 1.4317844 | V35: 1.5305405 | W35: 1.4910964 | X35: 1.4551093 | Y35: 1.4637304 | Z35: 1.4860665 | AA35: 1.4267407 | AB35: 1.4321746 | AC35: 1.4175453 | AD35: 1.4813417
A37: ENT | F37: 2020 Q1 | G37: 2020 Q2 | H37: 2020 Q3 | I37: 2020 Q4 | J37: 2021 Q1 | K37: 2021 Q2 | L37: 2021 Q3 | M37: 2021 Q4 | N37: 2022 Q1 | O37: 2022 Q2 | P37: 2022 Q3 | Q37: 2022 Q4 | R37: 2023 Q1 | S37: 2023 Q2 | T37: 2023 Q3 | U37: 2023 Q4 | V37: 2024 Q1 | W37: 2024 Q2 | X37: 2024 Q3 | Y37: 2024 Q4 | Z37: 2025 Q1 | AA37: 2025 Q2 | AB37: 2025 Q3 | AC37: 2025 Q4
A38: Contract Model Score | F38: 132.38307 | G38: 133.22864 | H38: 136.30166 | I38: 135.38242 | J38: 133.8357 | K38: 131.8749 | L38: 131.13569 | M38: 129.4723 | N38: 129.34473 | O38: 131.45349 | P38: 131.71553 | Q38: 131.25851 | R38: 132.73385 | S38: 133.4422 | T38: 133.76755 | U38: 135.31367 | V38: 136.17456 | W38: 136.8171 | X38: 136.69241 | Y38: 134.94875 | Z38: 134.57148 | AA38: 136.41792 | AB38: 137.0063 | AC38: 137.20721 | AD38: 139.79558
A39: Model Score | F39: 0 | G39: 0 | H39: 0 | I39: 0 | J39: 0 | K39: 0 | L39: 0 | M39: 0 | N39: 0 | O39: 0 | P39: 0 | Q39: 0 | R39: 0 | S39: 0 | T39: 0 | U39: 0 | V39: 0 | W39: 0 | X39: 0 | Y39: 0 | Z39: 0 | AA39: 0 | AB39: 0 | AC39: 0 | AD39: 0
A40: Gross Loss Adjustments (Dealer level, high PTI, etc.) | F40: 0.53733727 | G40: 0.6114489 | H40: 0.32319334 | I40: -0.89774632 | J40: -0.38175502 | K40: -0.59152797 | L40: -0.80097815 | M40: -0.57952409 | N40: -0.12187674 | O40: -0.57677921 | P40: -1.5631581 | Q40: -1.3928785 | R40: -1.7516348 | S40: -1.0557538 | T40: -0.70981925 | U40: 0.45637312 | V40: -0.59196155 | W40: -0.32963785 | X40: -0.49424107 | Y40: -0.28560818 | Z40: -0.97599678 | AA40: 0.20518067 | AB40: 0.17963091 | AC40: 1.0649609 | AD40: 1.253817
A41: Recovery Adjustments excluding LTV (Mileage, vehicle type, etc.) | F41: -1.1642651 | G41: -0.81485182 | H41: -0.481487 | I41: -0.59479581 | J41: -0.482186 | K41: 0.16898009 | L41: -0.42276794 | M41: -0.40506854 | N41: -1.2976314 | O41: -1.6241319 | P41: -2.3556075 | Q41: -2.5734446 | R41: -2.3027034 | S41: -2.1905732 | T41: -1.7447651 | U41: -1.0790471 | V41: -1.8270188 | W41: -1.4413707 | X41: -0.50297646 | Y41: 2.1980088 | Z41: 3.1841854 | AA41: 1.9939988 | AB41: 2.483344 | AC41: 3.3182452 | AD41: 2.5770995
A42: LTV Adjustments | F42: 1.1642651 | G42: 0.81485182 | H42: 0.481487 | I42: 0.59479581 | J42: 0.482186 | K42: -0.16898009 | L42: 0.42276794 | M42: 0.40506854 | N42: 1.2976314 | O42: 1.6241319 | P42: 2.3556075 | Q42: 2.5734446 | R42: 2.3027034 | S42: 2.1905732 | T42: 1.7447651 | U42: 1.0790471 | V42: 1.8270188 | W42: 1.4413707 | X42: 0.50297646 | Y42: -2.1980088 | Z42: -3.1841854 | AA42: -1.9939988 | AB42: -2.483344 | AC42: -3.3182452 | AD42: -2.5770995
A43: RAGU Score | F43: 132.92041 | G43: 133.84009 | H43: 136.62485 | I43: 134.48468 | J43: 133.45395 | K43: 131.28337 | L43: 130.33471 | M43: 128.89278 | N43: 129.22285 | O43: 130.87671 | P43: 130.15238 | Q43: 129.86564 | R43: 130.98221 | S43: 132.38644 | T43: 133.05774 | U43: 135.77004 | V43: 135.5826 | W43: 136.48746 | X43: 136.19817 | Y43: 134.66314 | Z43: 133.59548 | AA43: 136.6231 | AB43: 137.18593 | AC43: 138.27218 | AD43: 141.0494
A44: LTV | F44: 1.4714815 | G44: 1.4470178 | H44: 1.268966 | I44: 1.3695106 | J44: 1.3591646 | K44: 1.2615696 | L44: 1.3408036 | M44: 1.3739169 | N44: 1.394577 | O44: 1.3464535 | P44: 1.2927277 | Q44: 1.3475433 | R44: 1.3825684 | S44: 1.332697 | T44: 1.2563731 | U44: 1.3078529 | V44: 1.3170421 | W44: 1.3000146 | X44: 1.314683 | Y44: 1.3450747 | Z44: 1.3308241 | AA44: 1.302375 | AB44: 1.307357 | AC44: 1.318429 | AD44: 1.3321689
...

Sheet post lunch 1
A1: AN | B1: 2016 | C1: 2017 | D1: 2018 | E1: 2019 | F1: 2020 Q1 | G1: 2020 Q2 | H1: 2020 Q3 | I1: 2020 Q4 | J1: 2021 Q1 | K1: 2021 Q2 | L1: 2021 Q3 | M1: 2021 Q4 | N1: 2022 Q1 | O1: 2022 Q2 | P1: 2022 Q3 | Q1: 2022 Q4 | R1: 2023 Q1 | S1: 2023 Q2 | T1: 2023 Q3 | U1: 2023 Q4 | V1: 2024 Q1 | W1: 2024 Q2 | X1: 2024 Q3 | Y1: 2024 Q4 | Z1: 2025 Q1 | AA1: 2025 Q2 | AB1: 2025 Q3 | AC1: 2025 Q4
A2: Contract Model Score | B2: 130.07861 | C2: 132.83039 | D2: 132.99375 | E2: 132.11029 | F2: 131.79764 | G2: 133.71059 | H2: 135.28557 | I2: 135.79608 | J2: 134.60179 | K2: 135.14257 | L2: 135.36265 | M2: 134.41538 | N2: 134.0686 | O2: 135.89246 | P2: 136.14781 | Q2: 136.75155 | R2: 136.66305 | S2: 136.90907 | T2: 136.43849 | U2: 137.02135 | V2: 136.37212 | W2: 137.12198 | X2: 138.09052 | Y2: 136.80136 | Z2: 136.83702 | AA2: 138.03382 | AB2: 138.55808 | AC2: 139.3761 | AD2: 140.32155
A3: Model Score | B3: 0 | C3: 0 | D3: 0 | E3: 0 | F3: 0 | G3: 0 | H3: 0 | I3: 0 | J3: 0 | K3: 0 | L3: 0 | M3: 0 | N3: 0 | O3: 0 | P3: 0 | Q3: 0 | R3: 0 | S3: 0 | T3: 0 | U3: 0 | V3: 0 | W3: 0 | X3: 0 | Y3: 0 | Z3: 0 | AA3: 0 | AB3: 0 | AC3: 0 | AD3: 0
A4: Gross Loss Adjustments (Dealer level, high PTI, etc.) | B4: 0.66100206 | C4: 1.0383634 | D4: 1.1335416 | E4: 1.057243 | F4: 1.4123341 | G4: 1.3083797 | H4: 0.58221869 | I4: 1.0822147 | J4: 1.3206171 | K4: 1.3559535 | L4: 1.3112364 | M4: 1.2138028 | N4: 1.6338939 | O4: 1.3966256 | P4: 1.2658425 | Q4: 1.2408405 | R4: 0.79430529 | S4: 1.2228347 | T4: 0.70121599 | U4: 0.83461733 | V4: 0.66242898 | W4: 1.1867832 | X4: 0.97810535 | Y4: 1.1748893 | Z4: 1.4592694 | AA4: 2.4660669 | AB4: 2.9266817 | AC4: 2.9196016 | AD4: 3.1264617
A5: Recovery Adjustments excluding LTV (Mileage, vehicle type, etc.) | B5: -0.046581734 | C5: 0.68289025 | D5: 0.75224894 | E5: 0.36545618 | F5: 0.19835498 | G5: 0.021594693 | H5: 0.35604222 | I5: 0.56673572 | J5: 0.77580156 | K5: 0.53341099 | L5: 0.30687986 | M5: -0.28196698 | N5: -0.81047879 | O5: -1.0476364 | P5: -1.0559405 | Q5: -0.73866768 | R5: -0.67738952 | S5: -1.0046495 | T5: -1.142437 | U5: -1.0986338 | V5: -1.2916803 | W5: -0.60334894 | X5: -0.24272007 | Y5: 0.31405301 | Z5: 0.31102417 | AA5: 0.4504423 | AB5: 0.98864284 | AC5: 1.8030397 | AD5: 0.510204
A6: LTV Adjustments | B6: 0.046581734 | C6: -0.68289025 | D6: -0.75224894 | E6: -0.36545618 | F6: -0.19835498 | G6: -0.021594693 | H6: -0.35604222 | I6: -0.56673572 | J6: -0.77580156 | K6: -0.53341099 | L6: -0.30687986 | M6: 0.28196698 | N6: 0.81047879 | O6: 1.0476364 | P6: 1.0559405 | Q6: 0.73866768 | R6: 0.67738952 | S6: 1.0046495 | T6: 1.142437 | U6: 1.0986338 | V6: 1.2916803 | W6: 0.60334894 | X6: 0.24272007 | Y6: -0.31405301 | Z6: -0.31102417 | AA6: -0.4504423 | AB6: -0.98864284 | AC6: -1.8030397 | AD6: -0.510204
A7: RAGU Score | B7: 130.73961 | C7: 133.86875 | D7: 134.12729 | E7: 133.16753 | F7: 133.20997 | G7: 135.01897 | H7: 135.86779 | I7: 136.8783 | J7: 135.92241 | K7: 136.49853 | L7: 136.67389 | M7: 135.62918 | N7: 135.70249 | O7: 137.28909 | P7: 137.41365 | Q7: 137.99239 | R7: 137.45735 | S7: 138.1319 | T7: 137.13971 | U7: 137.85597 | V7: 137.03455 | W7: 138.30877 | X7: 139.06863 | Y7: 137.97624 | Z7: 138.29629 | AA7: 140.49989 | AB7: 141.48476 | AC7: 142.2957 | AD7: 143.44801
A8: LTV | B8: 1.9095583 | C8: 1.9033855 | D8: 1.9125326 | E8: 1.9530195 | F8: 1.904356 | G8: 1.9485415 | H8: 1.6765028 | I8: 1.6638656 | J8: 1.6924912 | K8: 1.5180362 | L8: 1.5882537 | M8: 1.5848716 | N8: 1.6198143 | O8: 1.7180658 | P8: 1.7529717 | Q8: 1.8148918 | R8: 1.8294105 | S8: 1.7158357 | T8: 1.67628 | U8: 1.7132773 | V8: 1.7367719 | W8: 1.6830278 | X8: 1.5949394 | Y8: 1.6183686 | Z8: 1.608955 | AA8: 1.568939 | AB8: 1.5722629 | AC8: 1.5526006 | AD8: 1.5519734
A10: FLD | F10: 2020 Q1 | G10: 2020 Q2 | H10: 2020 Q3 | I10: 2020 Q4 | J10: 2021 Q1 | K10: 2021 Q2 | L10: 2021 Q3 | M10: 2021 Q4 | N10: 2022 Q1 | O10: 2022 Q2 | P10: 2022 Q3 | Q10: 2022 Q4 | R10: 2023 Q1 | S10: 2023 Q2 | T10: 2023 Q3 | U10: 2023 Q4 | V10: 2024 Q1 | W10: 2024 Q2 | X10: 2024 Q3 | Y10: 2024 Q4 | Z10: 2025 Q1 | AA10: 2025 Q2 | AB10: 2025 Q3 | AC10: 2025 Q4
A11: Contract Model Score | F11: 131.95039 | G11: 135.66547 | H11: 137.78086 | I11: 140.37625 | J11: 136.75685 | K11: 136.18261 | L11: 135.63105 | M11: 134.62935 | N11: 134.17392 | O11: 135.83718 | P11: 136.96375 | Q11: 138.77228 | R11: 141.32316 | S11: 138.86319 | T11: 137.95666 | U11: 139.5662 | V11: 138.5244 | W11: 138.40978 | X11: 140.36331 | Y11: 138.38769 | Z11: 136.70743 | AA11: 138.3478 | AB11: 138.1021 | AC11: 138.94555 | AD11: 140.9645
A12: Model Score | F12: 0 | G12: 0 | H12: 0 | I12: 0 | J12: 0 | K12: 0 | L12: 0 | M12: 0 | N12: 0 | O12: 0 | P12: 0 | Q12: 0 | R12: 0 | S12: 0 | T12: 0 | U12: 0 | V12: 0 | W12: 0 | X12: 0 | Y12: 0 | Z12: 0 | AA12: 0 | AB12: 0 | AC12: 0 | AD12: 0
A13: Gross Loss Adjustments (Dealer level, high PTI, etc.) | F13: -1.7103216 | G13: -1.3620012 | H13: -0.82270063 | I13: 0.67937377 | J13: 1.8207974 | K13: -0.22282408 | L13: -0.34270651 | M13: 0.75425033 | N13: 0.49117725 | O13: 0.57506675 | P13: 0.94006829 | Q13: 0.98065555 | R13: 1.1637723 | S13: 0.76651233 | T13: 1.0512261 | U13: 1.3906266 | V13: 1.5536976 | W13: 2.4436111 | X13: 3.2853416 | Y13: 2.9736339 | Z13: 2.4078901 | AA13: 2.4910068 | AB13: 3.0095789 | AC13: 1.8551298 | AD13: 2.3630141
A14: Recovery Adjustments excluding LTV (Mileage, vehicle type, etc.) | F14: 0.30636157 | G14: 0.30230861 | H14: 0.35858452 | I14: 0.96095769 | J14: 0.68365243 | K14: 0.4592414 | L14: 0.38957375 | M14: -0.6751848 | N14: -1.203926 | O14: -1.2151646 | P14: -0.76363517 | Q14: -0.7297471 | R14: -0.61145056 | S14: -1.167968 | T14: -1.4690418 | U14: -0.88532733 | V14: -1.392029 | W14: -0.96576154 | X14: 0.10838686 | Y14: 0.60058922 | Z14: 0.44345803 | AA14: 0.49331051 | AB14: 1.071182 | AC14: 1.5202819 | AD14: 0.86837256
A15: LTV Adjustments | F15: -0.30636157 | G15: -0.30230861 | H15: -0.35858452 | I15: -0.96095769 | J15: -0.68365243 | K15: -0.4592414 | L15: -0.38957375 | M15: 0.6751848 | N15: 1.203926 | O15: 1.2151646 | P15: 0.76363517 | Q15: 0.7297471 | R15: 0.61145056 | S15: 1.167968 | T15: 1.4690418 | U15: 0.88532733 | V15: 1.392029 | W15: 0.96576154 | X15: -0.10838686 | Y15: -0.60058922 | Z15: -0.44345803 | AA15: -0.49331051 | AB15: -1.071182 | AC15: -1.5202819 | AD15: -0.86837256
A16: RAGU Score | F16: 130.24007 | G16: 134.30347 | H16: 136.95816 | I16: 141.05562 | J16: 138.57764 | K16: 135.95979 | L16: 135.28834 | M16: 135.3836 | N16: 134.6651 | O16: 136.41225 | P16: 137.90382 | Q16: 139.75294 | R16: 142.48693 | S16: 139.6297 | T16: 139.00788 | U16: 140.95683 | V16: 140.0781 | W16: 140.85339 | X16: 143.64865 | Y16: 141.36132 | Z16: 139.11532 | AA16: 140.8388 | AB16: 141.11168 | AC16: 140.80068 | AD16: 143.32752
A17: LTV | F17: 1.4222684 | G17: 1.3722716 | H17: 1.2228557 | I17: 1.2698228 | J17: 1.3323695 | K17: 1.2326635 | L17: 1.2767099 | M17: 1.3349712 | N17: 1.3422608 | O17: 1.3349194 | P17: 1.3215161 | Q17: 1.3240934 | R17: 1.2734391 | S17: 1.3071443 | T17: 1.2660861 | U17: 1.2843422 | V17: 1.3827827 | W17: 1.3648145 | X17: 1.3461371 | Y17: 1.3398676 | Z17: 1.3802088 | AA17: 1.4110825 | AB17: 1.4119989 | AC17: 1.4094062 | AD17: 1.4635862
A19: FRN | B19: 2016 | C19: 2017 | D19: 2018 | E19: 2019 | F19: 2020 Q1 | G19: 2020 Q2 | H19: 2020 Q3 | I19: 2020 Q4 | J19: 2021 Q1 | K19: 2021 Q2 | L19: 2021 Q3 | M19: 2021 Q4 | N19: 2022 Q1 | O19: 2022 Q2 | P19: 2022 Q3 | Q19: 2022 Q4 | R19: 2023 Q1 | S19: 2023 Q2 | T19: 2023 Q3 | U19: 2023 Q4 | V19: 2024 Q1 | W19: 2024 Q2 | X19: 2024 Q3 | Y19: 2024 Q4 | Z19: 2025 Q1 | AA19: 2025 Q2 | AB19: 2025 Q3 | AC19: 2025 Q4
A20: Contract Model Score | B20: 131.16747 | C20: 136.73823 | D20: 136.80259 | E20: 132.54767 | F20: 131.13303 | G20: 132.90504 | H20: 133.93048 | I20: 132.80381 | J20: 135.44811 | K20: 135.18735 | L20: 134.94602 | M20: 132.89928 | N20: 134.06325 | O20: 136.81721 | P20: 138.00243 | Q20: 139.77793 | R20: 141.27719 | S20: 140.58734 | T20: 140.72103 | U20: 139.02514 | V20: 138.13163 | W20: 140.17356 | X20: 141.55375 | Y20: 139.97097 | Z20: 139.83315 | AA20: 140.63434 | AB20: 140.96388 | AC20: 141.85749 | AD20: 142.77194
A21: Model Score | B21: 0 | C21: 0 | D21: 0 | E21: 0 | F21: 0 | G21: 0 | H21: 0 | I21: 0 | J21: 0 | K21: 0 | L21: 0 | M21: 0 | N21: 0 | O21: 0 | P21: 0 | Q21: 0 | R21: 0 | S21: 0 | T21: 0 | U21: 0 | V21: 0 | W21: 0 | X21: 0 | Y21: 0 | Z21: 0 | AA21: 0 | AB21: 0 | AC21: 0 | AD21: 0
A22: Gross Loss Adjustments (Dealer level, high PTI, etc.) | B22: -0.086531737 | C22: 0.56457952 | D22: 0.097990972 | E22: 0.65117725 | F22: 1.3091096 | G22: 1.5067007 | H22: 0.54845206 | I22: 0.003989095 | J22: 0.52413776 | K22: 0.89828531 | L22: 0.69221704 | M22: -0.39544921 | N22: -0.23544014 | O22: 0.72599632 | P22: 0.58262346 | Q22: 0.31311591 | R22: 0.93883725 | S22: 1.5645409 | T22: 1.6212334 | U22: 0.89293024 | V22: -0.19717966 | W22: 0.30351544 | X22: 0.75919793 | Y22: 0.53146185 | Z22: 0.66791062 | AA22: 1.2781424 | AB22: 1.7965359 | AC22: 2.7808561 | AD22: 2.864459
A23: Recovery Adjustments excluding LTV (Mileage, vehicle type, etc.) | B23: -0.17908036 | C23: 0.79370024 | D23: 0.48653147 | E23: 0.28554476 | F23: 0.20251189 | G23: 0.061227886 | H23: 0.37542201 | I23: 0.72847101 | J23: 0.67570086 | K23: 0.5442661 | L23: 0.14241659 | M23: -0.22920703 | N23: -0.78168021 | O23: -0.85473742 | P23: -0.8717973 | Q23: -0.90205939 | R23: -0.84700803 | S23: -1.1370854 | T23: -1.3880605 | U23: -1.1438787 | V23: -1.4427949 | W23: -0.95218585 | X23: -0.3731169 | Y23: 0.52569823 | Z23: 0.41648514 | AA23: 0.71413028 | AB23: 0.9304299 | AC23: 1.7451633 | AD23: 0.65468889
A24: LTV Adjustments | B24: 0.17908036 | C24: -0.79370024 | D24: -0.48653147 | E24: -0.28554476 | F24: -0.20251189 | G24: -0.061227886 | H24: -0.37542201 | I24: -0.72847101 | J24: -0.67570086 | K24: -0.5442661 | L24: -0.14241659 | M24: 0.22920703 | N24: 0.78168021 | O24: 0.85473742 | P24: 0.8717973 | Q24: 0.90205939 | R24: 0.84700803 | S24: 1.1370854 | T24: 1.3880605 | U24: 1.1438787 | V24: 1.4427949 | W24: 0.95218585 | X24: 0.3731169 | Y24: -0.52569823 | Z24: -0.41648514 | AA24: -0.71413028 | AB24: -0.9304299 | AC24: -1.7451633 | AD24: -0.65468889
A25: RAGU Score | B25: 131.08094 | C25: 137.30281 | D25: 136.90058 | E25: 133.19885 | F25: 132.44214 | G25: 134.41174 | H25: 134.47893 | I25: 132.8078 | J25: 135.97225 | K25: 136.08564 | L25: 135.63823 | M25: 132.50383 | N25: 133.82781 | O25: 137.5432 | P25: 138.58506 | Q25: 140.09105 | R25: 142.21603 | S25: 142.15188 | T25: 142.34226 | U25: 139.91807 | V25: 137.93446 | W25: 140.47708 | X25: 142.31295 | Y25: 140.50244 | Z25: 140.50106 | AA25: 141.91248 | AB25: 142.76042 | AC25: 144.63834 | AD25: 145.6364
A26: LTV | B26: 2.1589323 | C26: 2.2068198 | D26: 2.1159962 | E26: 2.0919992 | F26: 1.9398981 | G26: 1.943269 | H26: 1.9007312 | I26: 2.0314244 | J26: 1.7350805 | K26: 1.5137652 | L26: 1.6176819 | M26: 1.6847804 | N26: 1.6595351 | O26: 1.6664296 | P26: 1.683305 | Q26: 1.6850615 | R26: 1.7340577 | S26: 1.5425955 | T26: 1.5004554 | U26: 1.4623082 | V26: 1.4838174 | W26: 1.4770607 | X26: 1.490936 | Y26: 1.4850275 | Z26: 1.4879441 | AA26: 1.4278375 | AB26: 1.425119 | AC26: 1.4212108 | AD26: 1.48664
A28: STG | B28: 2016 | C28: 2017 | D28: 2018 | E28: 2019 | F28: 2020 Q1 | G28: 2020 Q2 | H28: 2020 Q3 | I28: 2020 Q4 | J28: 2021 Q1 | K28: 2021 Q2 | L28: 2021 Q3 | M28: 2021 Q4 | N28: 2022 Q1 | O28: 2022 Q2 | P28: 2022 Q3 | Q28: 2022 Q4 | R28: 2023 Q1 | S28: 2023 Q2 | T28: 2023 Q3 | U28: 2023 Q4 | V28: 2024 Q1 | W28: 2024 Q2 | X28: 2024 Q3 | Y28: 2024 Q4 | Z28: 2025 Q1 | AA28: 2025 Q2 | AB28: 2025 Q3 | AC28: 2025 Q4
A29: Contract Model Score | B29: 129.64154 | C29: 131.65563 | D29: 131.56832 | E29: 129.50597 | F29: 130.0304 | G29: 133.13562 | H29: 135.5242 | I29: 135.28733 | J29: 135.28771 | K29: 135.49901 | L29: 135.05653 | M29: 133.65336 | N29: 134.55 | O29: 136.72731 | P29: 137.27114 | Q29: 138.30195 | R29: 139.23035 | S29: 137.71584 | T29: 138.53984 | U29: 137.48747 | V29: 136.76023 | W29: 137.47802 | X29: 138.54354 | Y29: 137.20905 | Z29: 136.6684 | AA29: 137.94719 | AB29: 138.66055 | AC29: 140.03752 | AD29: 141.05806
A30: Model Score | B30: 0 | C30: 0 | D30: 0 | E30: 0 | F30: 0 | G30: 0 | H30: 0 | I30: 0 | J30: 0 | K30: 0 | L30: 0 | M30: 0 | N30: 0 | O30: 0 | P30: 0 | Q30: 0 | R30: 0 | S30: 0 | T30: 0 | U30: 0 | V30: 0 | W30: 0 | X30: 0 | Y30: 0 | Z30: 0 | AA30: 0 | AB30: 0 | AC30: 0 | AD30: 0
A31: Gross Loss Adjustments (Dealer level, high PTI, etc.) | B31: 0.80451042 | C31: 0.93531319 | D31: 0.87019855 | E31: 0.78525767 | F31: 0.62627011 | G31: 0.56124754 | H31: 0.90101305 | I31: 0.8428326 | J31: 1.6574384 | K31: 1.8158511 | L31: 1.5016646 | M31: 1.1834961 | N31: 0.56607344 | O31: 0.62303432 | P31: -0.014227399 | Q31: 0.60880416 | R31: 0.26065132 | S31: 0.32381303 | T31: 1.4742954 | U31: 1.2647051 | V31: 1.0139279 | W31: 2.0228001 | X31: 2.2786498 | Y31: 2.0632355 | Z31: 1.8384507 | AA31: 2.0356619 | AB31: 2.2451501 | AC31: 2.7851197 | AD31: 3.1250191
A32: Recovery Adjustments excluding LTV (Mileage, vehicle type, etc.) | B32: 0.0096922742 | C32: 0.72983218 | D32: 0.6121512 | E32: 0.43106277 | F32: 0.16214307 | G32: 0.064071236 | H32: 0.28692087 | I32: 1.0400756 | J32: 0.54162063 | K32: 0.46779075 | L32: 0.48633153 | M32: -0.20105135 | N32: -0.83242226 | O32: -0.91864714 | P32: -1.1783171 | Q32: -0.65686014 | R32: -1.0236673 | S32: -0.91099356 | T32: -1.3360114 | U32: -1.0111437 | V32: -1.533795 | W32: -0.65699548 | X32: -0.18254275 | Y32: 0.64801558 | Z32: 0.62660937 | AA32: 0.6202912 | AB32: 1.015985 | AC32: 1.6439859 | AD32: 0.74305719
A33: LTV Adjustments | B33: -0.0096922742 | C33: -0.72983218 | D33: -0.6121512 | E33: -0.43106277 | F33: -0.16214307 | G33: -0.064071236 | H33: -0.28692087 | I33: -1.0400756 | J33: -0.54162063 | K33: -0.46779075 | L33: -0.48633153 | M33: 0.20105135 | N33: 0.83242226 | O33: 0.91864714 | P33: 1.1783171 | Q33: 0.65686014 | R33: 1.0236673 | S33: 0.91099356 | T33: 1.3360114 | U33: 1.0111437 | V33: 1.533795 | W33: 0.65699548 | X33: 0.18254275 | Y33: -0.64801558 | Z33: -0.62660937 | AA33: -0.6202912 | AB33: -1.015985 | AC33: -1.6439859 | AD33: -0.74305719
A34: RAGU Score | B34: 130.44605 | C34: 132.59094 | D34: 132.43852 | E34: 130.29123 | F34: 130.65667 | G34: 133.69687 | H34: 136.42521 | I34: 136.13016 | J34: 136.94515 | K34: 137.31486 | L34: 136.5582 | M34: 134.83686 | N34: 135.11607 | O34: 137.35035 | P34: 137.25692 | Q34: 138.91076 | R34: 139.491 | S34: 138.03965 | T34: 140.01413 | U34: 138.75218 | V34: 137.77416 | W34: 139.50082 | X34: 140.82219 | Y34: 139.27228 | Z34: 138.50685 | AA34: 139.98285 | AB34: 140.9057 | AC34: 142.82264 | AD34: 144.18308
A35: LTV | B35: 1.9505024 | C35: 1.9401029 | D35: 1.9893459 | E35: 2.0870093 | F35: 2.0890887 | G35: 2.1081045 | H35: 1.8211832 | I35: 1.8044757 | J35: 1.6999269 | K35: 1.5705909 | L35: 1.5939441 | M35: 1.6198602 | N35: 1.5718352 | O35: 1.5190995 | P35: 1.5368932 | Q35: 1.4821458 | R35: 1.4795919 | S35: 1.5171672 | T35: 1.428349 | U35: 1.4319631 | V35: 1.5305618 | W35: 1.4917754 | X35: 1.4541668 | Y35: 1.4645932 | Z35: 1.4858994 | AA35: 1.4259223 | AB35: 1.4335938 | AC35: 1.4174465 | AD35: 1.4811423
A37: ENT | F37: 2020 Q1 | G37: 2020 Q2 | H37: 2020 Q3 | I37: 2020 Q4 | J37: 2021 Q1 | K37: 2021 Q2 | L37: 2021 Q3 | M37: 2021 Q4 | N37: 2022 Q1 | O37: 2022 Q2 | P37: 2022 Q3 | Q37: 2022 Q4 | R37: 2023 Q1 | S37: 2023 Q2 | T37: 2023 Q3 | U37: 2023 Q4 | V37: 2024 Q1 | W37: 2024 Q2 | X37: 2024 Q3 | Y37: 2024 Q4 | Z37: 2025 Q1 | AA37: 2025 Q2 | AB37: 2025 Q3 | AC37: 2025 Q4
A38: Contract Model Score | F38: 132.38307 | G38: 133.22864 | H38: 136.30166 | I38: 135.38242 | J38: 133.8357 | K38: 131.8749 | L38: 131.13569 | M38: 129.4723 | N38: 129.34473 | O38: 131.45349 | P38: 131.71553 | Q38: 131.25851 | R38: 132.73385 | S38: 133.4422 | T38: 133.76755 | U38: 135.31367 | V38: 136.17456 | W38: 136.8171 | X38: 136.69241 | Y38: 134.94875 | Z38: 134.57148 | AA38: 136.41792 | AB38: 137.0063 | AC38: 137.20721 | AD38: 139.79558
A39: Model Score | F39: 0 | G39: 0 | H39: 0 | I39: 0 | J39: 0 | K39: 0 | L39: 0 | M39: 0 | N39: 0 | O39: 0 | P39: 0 | Q39: 0 | R39: 0 | S39: 0 | T39: 0 | U39: 0 | V39: 0 | W39: 0 | X39: 0 | Y39: 0 | Z39: 0 | AA39: 0 | AB39: 0 | AC39: 0 | AD39: 0
A40: Gross Loss Adjustments (Dealer level, high PTI, etc.) | F40: 0.53733727 | G40: 0.6114489 | H40: 0.32319334 | I40: -0.89774632 | J40: -0.38175502 | K40: -0.59152797 | L40: -0.80097815 | M40: -0.57952409 | N40: -0.12187674 | O40: -0.57677921 | P40: -1.5631581 | Q40: -1.3928785 | R40: -1.7516348 | S40: -1.0557538 | T40: -0.70981925 | U40: 0.45637312 | V40: -0.59196155 | W40: -0.32963785 | X40: -0.49424107 | Y40: -0.28560818 | Z40: -0.97599678 | AA40: 0.20518067 | AB40: 0.17963091 | AC40: 1.0649609 | AD40: 1.253817
A41: Recovery Adjustments excluding LTV (Mileage, vehicle type, etc.) | F41: -1.1920172 | G41: -0.86783265 | H41: -0.40157717 | I41: -0.63189371 | J41: -0.55970644 | K41: 0.12477537 | L41: -0.43895099 | M41: -0.38499619 | N41: -1.2866433 | O41: -1.5946688 | P41: -2.356237 | Q41: -2.603939 | R41: -2.3045013 | S41: -2.2299169 | T41: -1.7922493 | U41: -1.0827342 | V41: -1.8617645 | W41: -1.4476694 | X41: -0.53113097 | Y41: 2.2414072 | Z41: 3.2551663 | AA41: 2.0802295 | AB41: 2.4133143 | AC41: 3.5191802 | AD41: 2.6152842
A42: LTV Adjustments | F42: 1.1920172 | G42: 0.86783265 | H42: 0.40157717 | I42: 0.63189371 | J42: 0.55970644 | K42: -0.12477537 | L42: 0.43895099 | M42: 0.38499619 | N42: 1.2866433 | O42: 1.5946688 | P42: 2.356237 | Q42: 2.603939 | R42: 2.3045013 | S42: 2.2299169 | T42: 1.7922493 | U42: 1.0827342 | V42: 1.8617645 | W42: 1.4476694 | X42: 0.53113097 | Y42: -2.2414072 | Z42: -3.2551663 | AA42: -2.0802295 | AB42: -2.4133143 | AC42: -3.5191802 | AD42: -2.6152842
A43: RAGU Score | F43: 132.92041 | G43: 133.84009 | H43: 136.62485 | I43: 134.48468 | J43: 133.45395 | K43: 131.28337 | L43: 130.33471 | M43: 128.89278 | N43: 129.22285 | O43: 130.87671 | P43: 130.15238 | Q43: 129.86564 | R43: 130.98221 | S43: 132.38644 | T43: 133.05774 | U43: 135.77004 | V43: 135.5826 | W43: 136.48746 | X43: 136.19817 | Y43: 134.66314 | Z43: 133.59548 | AA43: 136.6231 | AB43: 137.18593 | AC43: 138.27218 | AD43: 141.0494
A44: LTV | F44: 1.4714846 | G44: 1.448717 | H44: 1.2685319 | I44: 1.3691838 | J44: 1.3590324 | K44: 1.2617019 | L44: 1.3407663 | M44: 1.3742468 | N44: 1.3946749 | O44: 1.3456753 | P44: 1.2927065 | Q44: 1.3475355 | R44: 1.3821314 | S44: 1.3320948 | T44: 1.2573045 | U44: 1.3078825 | V44: 1.3167976 | W44: 1.3001206 | X44: 1.3145132 | Y44: 1.3455132 | Z44: 1.330887 | AA44: 1.3028832 | AB44: 1.3079653 | AC44: 1.3179371 | AD44: 1.3324939
...

Sheet post lucnh 2

Sheet Data Tables (Q) 3.14
A1: AN | B1: 2025Q1 | C1: 2025Q2 | D1: 2025Q3 | E1: 2025Q4 | F1: 2026Q1
A2: Model Score | B2: 136.83702 | C2: 138.03382 | D2: 138.55808 | E2: 139.3761 | F2: 140.32332
