Workbook

Sheet Data Tables (Q)
A1: AN | B1: 2016 | C1: 2017 | D1: 2018 | E1: 2019 | F1: 2020 Q1 | G1: 2020 Q2 | H1: 2020 Q3 | I1: 2020 Q4 | J1: 2021 Q1 | K1: 2021 Q2 | L1: 2021 Q3 | M1: 2021 Q4 | N1: 2022 Q1 | O1: 2022 Q2 | P1: 2022 Q3 | Q1: 2022 Q4 | R1: 2023 Q1 | S1: 2023 Q2 | T1: 2023 Q3 | U1: 2023 Q4 | V1: 2024 Q1 | W1: 2024 Q2 | X1: 2024 Q3 | Y1: 2024 Q4 | Z1: 2025 Q1 | AA1: 2025 Q2 | AB1: 2025 Q3 | AC1: 2025 Q4
A2: Contract Model Score | B2: 130.07704 | C2: 132.82918 | D2: 132.99304 | E2: 132.10911 | F2: 131.79764 | G2: 133.71059 | H2: 135.28557 | I2: 135.79608 | J2: 134.60179 | K2: 135.14257 | L2: 135.36265 | M2: 134.41538 | N2: 134.0686 | O2: 135.89246 | P2: 136.14781 | Q2: 136.75155 | R2: 136.66305 | S2: 136.90907 | T2: 136.43849 | U2: 137.02135 | V2: 136.37212 | W2: 137.12198 | X2: 138.09052 | Y2: 136.80136 | Z2: 136.83702 | AA2: 138.03382 | AB2: 138.55808 | AC2: 139.3761 | AD2: 140.36297
A3: Model Score | B3: 0 | C3: 0 | D3: 0 | E3: 0 | F3: 0 | G3: 0 | H3: 0 | I3: 0 | J3: 0 | K3: 0 | L3: 0 | M3: 0 | N3: 0 | O3: 0 | P3: 0 | Q3: 0 | R3: 0 | S3: 0 | T3: 0 | U3: 0 | V3: 0 | W3: 0 | X3: 0 | Y3: 0 | Z3: 0 | AA3: 0 | AB3: 0 | AC3: 0 | AD3: 0
A4: Gross Loss Adjustments (Dealer level, high PTI, etc.) | B4: 0.36824634 | C4: 0.64268496 | D4: 0.73760946 | E4: 0.54113333 | F4: 0.64749521 | G4: 0.51566419 | H4: -0.19174308 | I4: 0.2567337 | J4: 0.53917167 | K4: 0.53578838 | L4: 0.54503838 | M4: 0.45373656 | N4: 0.86176791 | O4: 0.80063115 | P4: 0.87451807 | Q4: 0.86438829 | R4: 0.55900216 | S4: 0.92010091 | T4: 0.38592112 | U4: 0.33895356 | V4: 0.58664147 | W4: 1.0236504 | X4: 0.82057154 | Y4: 1.3243079 | Z4: 1.8938718 | AA4: 2.556068 | AB4: 3.0998623 | AC4: 3.5696834 | AD4: 2.6503283
A5: Recovery Adjustments excluding LTV (Mileage, vehicle type, etc.) | B5: -0.42682491 | C5: -0.49101527 | D5: -0.33145102 | E5: -0.46825812 | F5: -0.40547259 | G5: -0.82009987 | H5: -0.44087336 | I5: -0.031352964 | J5: -0.43522926 | K5: -0.66882046 | L5: -0.64378361 | M5: -0.94080084 | N5: -1.4183381 | O5: -2.6459525 | P5: -3.5505797 | Q5: -3.8736194 | R5: -3.150067 | S5: -2.7477242 | T5: -2.6814291 | U5: -2.4647213 | V5: -2.0924894 | W5: -1.8339517 | X5: -1.2461937 | Y5: -1.631803 | Z5: -0.06672953 | AA5: 0.54524695 | AB5: 1.1256274 | AC5: 1.2013578 | AD5: 2.1993762
A6: LTV Adjustments | B6: 0.42682491 | C6: 0.49101527 | D6: 0.33145102 | E6: 0.46825812 | F6: 0.40547259 | G6: 0.82009987 | H6: 0.44087336 | I6: 0.031352964 | J6: 0.43522926 | K6: 0.66882046 | L6: 0.64378361 | M6: 0.94080084 | N6: 1.4183381 | O6: 2.6459525 | P6: 3.5505797 | Q6: 3.8736194 | R6: 3.150067 | S6: 2.7477242 | T6: 2.6814291 | U6: 2.4647213 | V6: 2.0924894 | W6: 1.8339517 | X6: 1.2461937 | Y6: 1.631803 | Z6: 0.06672953 | AA6: -0.54524695 | AB6: -1.1256274 | AC6: -1.2013578 | AD6: -2.1993762
A7: RAGU Score | B7: 130.44529 | C7: 133.47187 | D7: 133.73065 | E7: 132.65024 | F7: 132.44513 | G7: 134.22626 | H7: 135.09383 | I7: 136.05282 | J7: 135.14096 | K7: 135.67836 | L7: 135.90769 | M7: 134.86912 | N7: 134.93036 | O7: 136.69309 | P7: 137.02232 | Q7: 137.61594 | R7: 137.22205 | S7: 137.82917 | T7: 136.82441 | U7: 137.3603 | V7: 136.95876 | W7: 138.14563 | X7: 138.91109 | Y7: 138.12566 | Z7: 138.7309 | AA7: 140.58989 | AB7: 141.65794 | AC7: 142.94578 | AD7: 143.01329
A8: LTV | B8: 1.9087244 | C8: 1.9020945 | D8: 1.9108652 | E8: 1.9482717 | F8: 1.902826 | G8: 1.9471127 | H8: 1.6704441 | I8: 1.6601973 | J8: 1.6894127 | K8: 1.515447 | L8: 1.5852082 | M8: 1.5827355 | N8: 1.6171228 | O8: 1.7022851 | P8: 1.7576372 | Q8: 1.81575 | R8: 1.8234154 | S8: 1.7206772 | T8: 1.6794167 | U8: 1.7109657 | V8: 1.7394377 | W8: 1.68966 | X8: 1.6017589 | Y8: 1.6130967 | Z8: 1.612319 | AA8: 1.570741 | AB8: 1.5773568 | AC8: 1.5580138 | AD8: 1.5879691
A10: FLD | F10: 2020 Q1 | G10: 2020 Q2 | H10: 2020 Q3 | I10: 2020 Q4 | J10: 2021 Q1 | K10: 2021 Q2 | L10: 2021 Q3 | M10: 2021 Q4 | N10: 2022 Q1 | O10: 2022 Q2 | P10: 2022 Q3 | Q10: 2022 Q4 | R10: 2023 Q1 | S10: 2023 Q2 | T10: 2023 Q3 | U10: 2023 Q4 | V10: 2024 Q1 | W10: 2024 Q2 | X10: 2024 Q3 | Y10: 2024 Q4 | Z10: 2025 Q1 | AA10: 2025 Q2 | AB10: 2025 Q3 | AC10: 2025 Q4
A11: Contract Model Score | F11: 131.95039 | G11: 135.66547 | H11: 137.78086 | I11: 140.37625 | J11: 136.75685 | K11: 136.18261 | L11: 135.63105 | M11: 134.62935 | N11: 134.17392 | O11: 135.83718 | P11: 136.96375 | Q11: 138.77228 | R11: 141.32316 | S11: 138.86319 | T11: 137.95666 | U11: 139.5662 | V11: 138.5244 | W11: 138.40978 | X11: 140.36331 | Y11: 138.38769 | Z11: 136.70743 | AA11: 138.3478 | AB11: 138.1021 | AC11: 138.94555 | AD11: 140.92699
A12: Model Score | F12: 0 | G12: 0 | H12: 0 | I12: 0 | J12: 0 | K12: 0 | L12: 0 | M12: 0 | N12: 0 | O12: 0 | P12: 0 | Q12: 0 | R12: 0 | S12: 0 | T12: 0 | U12: 0 | V12: 0 | W12: 0 | X12: 0 | Y12: 0 | Z12: 0 | AA12: 0 | AB12: 0 | AC12: 0 | AD12: 0
A13: Gross Loss Adjustments (Dealer level, high PTI, etc.) | F13: -2.5958615 | G13: -2.2718375 | H13: -1.6417215 | I13: -0.13010911 | J13: 1.0953963 | K13: -0.99165458 | L13: -1.0619348 | M13: 0.042055432 | N13: -0.21227366 | O13: 0.043550408 | P13: 0.48750697 | Q13: 0.45836499 | R13: 0.55308505 | S13: 0.29722802 | T13: 0.7107683 | U13: 0.98705958 | V13: 1.384667 | W13: 2.2016267 | X13: 3.1096998 | Y13: 3.0472917 | Z13: 3.0958106 | AA13: 2.6191118 | AB13: 3.4186632 | AC13: 2.2568239 | AD13: 1.8759566
A14: Recovery Adjustments excluding LTV (Mileage, vehicle type, etc.) | F14: 1.6480712 | G14: 1.6389226 | H14: 1.9811857 | I14: 2.0823456 | J14: 1.585956 | K14: 0.95962335 | L14: 0.61921158 | M14: 0.45613646 | N14: 0.48726161 | O14: -1.3199594 | P14: -2.6343136 | Q14: -2.5252511 | R14: -2.3959284 | S14: -1.8747561 | T14: -2.8208717 | U14: 0.14966026 | V14: -0.85316181 | W14: -1.3454548 | X14: -0.28346707 | Y14: -0.3487306 | Z14: 1.9955828 | AA14: 1.608932 | AB14: 2.1800694 | AC14: 2.4945801 | AD14: 1.957943
A15: LTV Adjustments | F15: -1.6480712 | G15: -1.6389226 | H15: -1.9811857 | I15: -2.0823456 | J15: -1.585956 | K15: -0.95962335 | L15: -0.61921158 | M15: -0.45613646 | N15: -0.48726161 | O15: 1.3199594 | P15: 2.6343136 | Q15: 2.5252511 | R15: 2.3959284 | S15: 1.8747561 | T15: 2.8208717 | U15: -0.14966026 | V15: 0.85316181 | W15: 1.3454548 | X15: 0.28346707 | Y15: 0.3487306 | Z15: -1.9955828 | AA15: -1.608932 | AB15: -2.1800694 | AC15: -2.4945801 | AD15: -1.957943
A16: RAGU Score | F16: 129.35453 | G16: 133.39363 | H16: 136.13914 | I16: 140.24614 | J16: 137.85224 | K16: 135.19096 | L16: 134.56911 | M16: 134.6714 | N16: 133.96165 | O16: 135.88073 | P16: 137.45126 | Q16: 139.23064 | R16: 141.87625 | S16: 139.16042 | T16: 138.66743 | U16: 140.55326 | V16: 139.90907 | W16: 140.61141 | X16: 143.47301 | Y16: 141.43498 | Z16: 139.80324 | AA16: 140.96691 | AB16: 141.52076 | AC16: 141.20238 | AD16: 142.80294
A17: LTV | F17: 1.4205628 | G17: 1.3731628 | H17: 1.2237836 | I17: 1.2677232 | J17: 1.3305309 | K17: 1.2336043 | L17: 1.2737699 | M17: 1.3338379 | N17: 1.3410876 | O17: 1.3387478 | P17: 1.3202801 | Q17: 1.3151241 | R17: 1.2676963 | S17: 1.3059301 | T17: 1.268125 | U17: 1.2894164 | V17: 1.3845444 | W17: 1.3691063 | X17: 1.3486685 | Y17: 1.3458292 | Z17: 1.3919187 | AA17: 1.4211805 | AB17: 1.4236177 | AC17: 1.421859 | AD17: 1.4738286
A19: FRN | B19: 2016 | C19: 2017 | D19: 2018 | E19: 2019 | F19: 2020 Q1 | G19: 2020 Q2 | H19: 2020 Q3 | I19: 2020 Q4 | J19: 2021 Q1 | K19: 2021 Q2 | L19: 2021 Q3 | M19: 2021 Q4 | N19: 2022 Q1 | O19: 2022 Q2 | P19: 2022 Q3 | Q19: 2022 Q4 | R19: 2023 Q1 | S19: 2023 Q2 | T19: 2023 Q3 | U19: 2023 Q4 | V19: 2024 Q1 | W19: 2024 Q2 | X19: 2024 Q3 | Y19: 2024 Q4 | Z19: 2025 Q1 | AA19: 2025 Q2 | AB19: 2025 Q3 | AC19: 2025 Q4
A20: Contract Model Score | B20: 131.17685 | C20: 136.73938 | D20: 136.80349 | E20: 132.53803 | F20: 131.13303 | G20: 132.90504 | H20: 133.93048 | I20: 132.80381 | J20: 135.44811 | K20: 135.18735 | L20: 134.94602 | M20: 132.89928 | N20: 134.06325 | O20: 136.81721 | P20: 138.00243 | Q20: 139.77793 | R20: 141.27719 | S20: 140.58734 | T20: 140.72103 | U20: 139.02514 | V20: 138.13163 | W20: 140.17356 | X20: 141.55375 | Y20: 139.97097 | Z20: 139.83315 | AA20: 140.63434 | AB20: 140.96388 | AC20: 141.85749 | AD20: 142.86763
A21: Model Score | B21: 0 | C21: 0 | D21: 0 | E21: 0 | F21: 0 | G21: 0 | H21: 0 | I21: 0 | J21: 0 | K21: 0 | L21: 0 | M21: 0 | N21: 0 | O21: 0 | P21: 0 | Q21: 0 | R21: 0 | S21: 0 | T21: 0 | U21: 0 | V21: 0 | W21: 0 | X21: 0 | Y21: 0 | Z21: 0 | AA21: 0 | AB21: 0 | AC21: 0 | AD21: 0
A22: Gross Loss Adjustments (Dealer level, high PTI, etc.) | B22: -0.3279542 | C22: 0.20210618 | D22: -0.19413065 | E22: 0.046002039 | F22: 0.53224606 | G22: 0.71345069 | H22: -0.27007229 | I22: -0.83970892 | J22: -0.28336522 | K22: 0.096546832 | L22: -0.09886035 | M22: -1.1380306 | N22: -1.0378799 | O22: 0.16751634 | P22: 0.29304325 | Q22: 0.031937011 | R22: 0.88138219 | S22: 1.4130578 | T22: 1.5239239 | U22: 0.72677022 | V22: 0.19579402 | W22: 0.25599345 | X22: 0.60350981 | Y22: 0.50464667 | Z22: 1.0655629 | AA22: 1.3018963 | AB22: 1.96225 | AC22: 2.9079781 | AD22: 2.5590043
A23: Recovery Adjustments excluding LTV (Mileage, vehicle type, etc.) | B23: -1.9652969 | C23: -2.2572101 | D23: -2.386967 | E23: -1.7982709 | F23: -1.2897912 | G23: -1.221421 | H23: -1.3451157 | I23: -1.0354668 | J23: -1.4612729 | K23: -1.3011568 | L23: -1.5164168 | M23: -1.901103 | N23: -2.1482385 | O23: -3.674188 | P23: -4.898855 | Q23: -5.2674839 | R23: -5.0410015 | S23: -4.6319201 | T23: -4.9097476 | U23: -4.2870588 | V23: -3.8100794 | W23: -4.1440132 | X23: -4.0810625 | Y23: -3.1606832 | Z23: -0.76388961 | AA23: -0.53897732 | AB23: -0.11087951 | AC23: 0.55000966 | AD23: 0.81415691
A24: LTV Adjustments | B24: 1.9652969 | C24: 2.2572101 | D24: 2.386967 | E24: 1.7982709 | F24: 1.2897912 | G24: 1.221421 | H24: 1.3451157 | I24: 1.0354668 | J24: 1.4612729 | K24: 1.3011568 | L24: 1.5164168 | M24: 1.901103 | N24: 2.1482385 | O24: 3.674188 | P24: 4.898855 | Q24: 5.2674839 | R24: 5.0410015 | S24: 4.6319201 | T24: 4.9097476 | U24: 4.2870588 | V24: 3.8100794 | W24: 4.1440132 | X24: 4.0810625 | Y24: 3.1606832 | Z24: 0.76388961 | AA24: 0.53897732 | AB24: 0.11087951 | AC24: -0.55000966 | AD24: -0.81415691
A25: RAGU Score | B25: 130.8489 | C25: 136.94149 | D25: 136.60936 | E25: 132.58403 | F25: 131.66528 | G25: 133.61849 | H25: 133.66041 | I25: 131.9641 | J25: 135.16475 | K25: 135.2839 | L25: 134.84716 | M25: 131.76125 | N25: 133.02537 | O25: 136.98472 | P25: 138.29548 | Q25: 139.80987 | R25: 142.15857 | S25: 142.0004 | T25: 142.24495 | U25: 139.75191 | V25: 138.32743 | W25: 140.42956 | X25: 142.15726 | Y25: 140.47562 | Z25: 140.89871 | AA25: 141.93623 | AB25: 142.92613 | AC25: 144.76547 | AD25: 145.42663
A26: LTV | B26: 2.1505904 | C26: 2.2073907 | D26: 2.1097029 | E26: 2.0875659 | F26: 1.9401142 | G26: 1.9433066 | H26: 1.9003889 | I26: 2.0278102 | J26: 1.7335845 | K26: 1.5120635 | L26: 1.6173419 | M26: 1.6867925 | N26: 1.6567267 | O26: 1.6631521 | P26: 1.6853642 | Q26: 1.6837623 | R26: 1.7260875 | S26: 1.5326979 | T26: 1.4887795 | U26: 1.4569228 | V26: 1.480038 | W26: 1.4758266 | X26: 1.4883312 | Y26: 1.4862274 | Z26: 1.484936 | AA26: 1.4354276 | AB26: 1.4298704 | AC26: 1.4260417 | AD26: 1.416614
A28: STG | B28: 2016 | C28: 2017 | D28: 2018 | E28: 2019 | F28: 2020 Q1 | G28: 2020 Q2 | H28: 2020 Q3 | I28: 2020 Q4 | J28: 2021 Q1 | K28: 2021 Q2 | L28: 2021 Q3 | M28: 2021 Q4 | N28: 2022 Q1 | O28: 2022 Q2 | P28: 2022 Q3 | Q28: 2022 Q4 | R28: 2023 Q1 | S28: 2023 Q2 | T28: 2023 Q3 | U28: 2023 Q4 | V28: 2024 Q1 | W28: 2024 Q2 | X28: 2024 Q3 | Y28: 2024 Q4 | Z28: 2025 Q1 | AA28: 2025 Q2 | AB28: 2025 Q3 | AC28: 2025 Q4
A29: Contract Model Score | B29: 129.64201 | C29: 131.65669 | D29: 131.56906 | E29: 129.50527 | F29: 130.0304 | G29: 133.13562 | H29: 135.5242 | I29: 135.28733 | J29: 135.28771 | K29: 135.49901 | L29: 135.05653 | M29: 133.65336 | N29: 134.55 | O29: 136.72731 | P29: 137.27114 | Q29: 138.30195 | R29: 139.23035 | S29: 137.71584 | T29: 138.53984 | U29: 137.48747 | V29: 136.76023 | W29: 137.47802 | X29: 138.54354 | Y29: 137.20905 | Z29: 136.6684 | AA29: 137.94719 | AB29: 138.66055 | AC29: 140.03752 | AD29: 141.71991
A30: Model Score | B30: 0 | C30: 0 | D30: 0 | E30: 0 | F30: 0 | G30: 0 | H30: 0 | I30: 0 | J30: 0 | K30: 0 | L30: 0 | M30: 0 | N30: 0 | O30: 0 | P30: 0 | Q30: 0 | R30: 0 | S30: 0 | T30: 0 | U30: 0 | V30: 0 | W30: 0 | X30: 0 | Y30: 0 | Z30: 0 | AA30: 0 | AB30: 0 | AC30: 0 | AD30: 0
A31: Gross Loss Adjustments (Dealer level, high PTI, etc.) | B31: 0.55168785 | C31: 0.53745688 | D31: 0.47283336 | E31: 0.26299826 | F31: -0.17705346 | G31: -0.23517459 | H31: 0.1178712 | I31: 0.041467995 | J31: 0.88577009 | K31: 1.0419584 | L31: 0.74064638 | M31: 0.42910054 | N31: -0.22394537 | O31: -0.019170193 | P31: -0.41911667 | Q31: 0.094722292 | R31: -0.06193691 | S31: 0.13109853 | T31: 1.1009589 | U31: 0.80118596 | V31: 1.1138993 | W31: 1.8836723 | X31: 2.1660502 | Y31: 2.1477406 | Z31: 2.2898541 | AA31: 2.0219847 | AB31: 2.3634477 | AC31: 3.1078509 | AD31: 2.787071
A32: Recovery Adjustments excluding LTV (Mileage, vehicle type, etc.) | B32: 0.12094838 | C32: 0.72195889 | D32: 0.25083049 | E32: 0.20393168 | F32: 0.11503546 | G32: 0.084406228 | H32: 0.29693969 | I32: 0.42110284 | J32: 0.31989764 | K32: 0.22431458 | L32: 0.23964494 | M32: 0.35702916 | N32: 0.26645598 | O32: -1.8569201 | P32: -2.5305798 | Q32: -2.4101186 | R32: -2.26922 | S32: -1.2760946 | T32: -1.0852773 | U32: -0.77288919 | V32: -0.93816727 | W32: -0.41542577 | X32: -0.10584601 | Y32: 0.20872339 | Z32: 2.2774923 | AA32: 2.9990137 | AB32: 2.9834456 | AC32: 3.4583655 | AD32: 3.7723243
A33: LTV Adjustments | B33: -0.12094838 | C33: -0.72195889 | D33: -0.25083049 | E33: -0.20393168 | F33: -0.11503546 | G33: -0.084406228 | H33: -0.29693969 | I33: -0.42110284 | J33: -0.31989764 | K33: -0.22431458 | L33: -0.23964494 | M33: -0.35702916 | N33: -0.26645598 | O33: 1.8569201 | P33: 2.5305798 | Q33: 2.4101186 | R33: 2.26922 | S33: 1.2760946 | T33: 1.0852773 | U33: 0.77288919 | V33: 0.93816727 | W33: 0.41542577 | X33: 0.10584601 | Y33: -0.20872339 | Z33: -2.2774923 | AA33: -2.9990137 | AB33: -2.9834456 | AC33: -3.4583655 | AD33: -3.7723243
A34: RAGU Score | B34: 130.1937 | C34: 132.19415 | D34: 132.0419 | E34: 129.76827 | F34: 129.85334 | G34: 132.90045 | H34: 135.64207 | I34: 135.32879 | J34: 136.17348 | K34: 136.54097 | L34: 135.79718 | M34: 134.08246 | N34: 134.32605 | O34: 136.70814 | P34: 136.85203 | Q34: 138.39667 | R34: 139.16841 | S34: 137.84694 | T34: 139.6408 | U34: 138.28866 | V34: 137.87413 | W34: 139.3617 | X34: 140.70959 | Y34: 139.35679 | Z34: 138.95825 | AA34: 139.96918 | AB34: 141.02399 | AC34: 143.14537 | AD34: 144.50698
A35: LTV | B35: 1.9469756 | C35: 1.9399714 | D35: 1.9874143 | E35: 2.0859967 | F35: 2.0790161 | G35: 2.1024128 | H35: 1.8209696 | I35: 1.8042176 | J35: 1.7006093 | K35: 1.5705129 | L35: 1.5917275 | M35: 1.6099823 | N35: 1.5700251 | O35: 1.519388 | P35: 1.5322192 | Q35: 1.4830261 | R35: 1.4792593 | S35: 1.5231119 | T35: 1.4212296 | U35: 1.4249082 | V35: 1.5339126 | W35: 1.4939963 | X35: 1.4531544 | Y35: 1.4626914 | Z35: 1.482253 | AA35: 1.4273906 | AB35: 1.431232 | AC35: 1.4246205 | AD35: 1.5008016
A37: ENT | F37: 2020 Q1 | G37: 2020 Q2 | H37: 2020 Q3 | I37: 2020 Q4 | J37: 2021 Q1 | K37: 2021 Q2 | L37: 2021 Q3 | M37: 2021 Q4 | N37: 2022 Q1 | O37: 2022 Q2 | P37: 2022 Q3 | Q37: 2022 Q4 | R37: 2023 Q1 | S37: 2023 Q2 | T37: 2023 Q3 | U37: 2023 Q4 | V37: 2024 Q1 | W37: 2024 Q2 | X37: 2024 Q3 | Y37: 2024 Q4 | Z37: 2025 Q1 | AA37: 2025 Q2 | AB37: 2025 Q3 | AC37: 2025 Q4
A38: Contract Model Score | F38: 132.38307 | G38: 133.22864 | H38: 136.30166 | I38: 135.38242 | J38: 133.8357 | K38: 131.8749 | L38: 131.13569 | M38: 129.4723 | N38: 129.34473 | O38: 131.45349 | P38: 131.71553 | Q38: 131.25851 | R38: 132.73385 | S38: 133.4422 | T38: 133.76755 | U38: 135.31367 | V38: 136.17456 | W38: 136.8171 | X38: 136.69241 | Y38: 134.94875 | Z38: 134.57148 | AA38: 136.41792 | AB38: 137.0063 | AC38: 137.20721 | AD38: 139.6199
A39: Model Score | F39: 0 | G39: 0 | H39: 0 | I39: 0 | J39: 0 | K39: 0 | L39: 0 | M39: 0 | N39: 0 | O39: 0 | P39: 0 | Q39: 0 | R39: 0 | S39: 0 | T39: 0 | U39: 0 | V39: 0 | W39: 0 | X39: 0 | Y39: 0 | Z39: 0 | AA39: 0 | AB39: 0 | AC39: 0 | AD39: 0
A40: Gross Loss Adjustments (Dealer level, high PTI, etc.) | F40: -0.32633691 | G40: -0.24531305 | H40: -0.51478673 | I40: -1.7810736 | J40: -1.1663098 | K40: -1.3644154 | L40: -1.5978945 | M40: -1.4141434 | N40: -0.94903172 | O40: -1.1360738 | P40: -1.6427646 | Q40: -1.4880232 | R40: -1.7934902 | S40: -1.2033484 | T40: -0.91964396 | U40: -0.029048574 | V40: -0.40067639 | W40: -0.30823236 | X40: -0.49476074 | Y40: 0.0030303055 | Z40: -0.11906764 | AA40: 0.49512343 | AB40: 0.49812475 | AC40: 1.8580984 | AD40: 2.1306717
A41: Recovery Adjustments excluding LTV (Mileage, vehicle type, etc.) | F41: -0.027081459 | G41: 0.12046618 | H41: 0.12293285 | I41: 0.1395859 | J41: 0.11321541 | K41: -0.13067199 | L41: -0.5798504 | M41: -0.82793303 | N41: -1.1634258 | O41: -1.1529434 | P41: -1.4743423 | Q41: -1.6760795 | R41: -1.7055951 | S41: -1.5804189 | T41: -1.606686 | U41: -1.5128964 | V41: -1.6522724 | W41: -1.413304 | X41: -1.0054698 | Y41: -0.33440007 | Z41: 0.16022976 | AA41: -0.076335538 | AB41: -0.036450372 | AC41: 0.22347571 | AD41: 0.32558553
A42: LTV Adjustments | F42: 0.027081459 | G42: -0.12046618 | H42: -0.12293285 | I42: -0.1395859 | J42: -0.11321541 | K42: 0.13067199 | L42: 0.5798504 | M42: 0.82793303 | N42: 1.1634258 | O42: 1.1529434 | P42: 1.4743423 | Q42: 1.6760795 | R42: 1.7055951 | S42: 1.5804189 | T42: 1.606686 | U42: 1.5128964 | V42: 1.6522724 | W42: 1.413304 | X42: 1.0054698 | Y42: 0.33440007 | Z42: -0.16022976 | AA42: 0.076335538 | AB42: 0.036450372 | AC42: -0.22347571 | AD42: -0.32558553
A43: RAGU Score | F43: 132.05673 | G43: 132.98333 | H43: 135.78687 | I43: 133.60135 | J43: 132.66939 | K43: 130.51048 | L43: 129.5378 | M43: 128.05816 | N43: 128.3957 | O43: 130.31741 | P43: 130.07277 | Q43: 129.77049 | R43: 130.94036 | S43: 132.23885 | T43: 132.84791 | U43: 135.28462 | V43: 135.77389 | W43: 136.50887 | X43: 136.19765 | Y43: 134.95178 | Z43: 134.45241 | AA43: 136.91305 | AB43: 137.50442 | AC43: 139.06531 | AD43: 141.75057
A44: LTV | F44: 1.4714253 | G44: 1.447645 | H44: 1.2670158 | I44: 1.3699695 | J44: 1.3586296 | K44: 1.2606936 | L44: 1.3395636 | M44: 1.3730102 | N44: 1.3886269 | O44: 1.3453919 | P44: 1.2914488 | Q44: 1.3464781 | R44: 1.3778236 | S44: 1.3216275 | T44: 1.2590349 | U44: 1.3089899 | V44: 1.3236306 | W44: 1.3018836 | X44: 1.3184884 | Y44: 1.3477314 | Z44: 1.3381453 | AA44: 1.3094736 | AB44: 1.310731 | AC44: 1.325224 | AD44: 1.3525404
...

Sheet Data Tables (M)
A1: AN | B1: 2016 | C1: 2017 | D1: 2018 | E1: 2019 | F1: 2020 M01 | G1: 2020 M02 | H1: 2020 M03 | I1: 2020 M04 | J1: 2020 M05 | K1: 2020 M06 | L1: 2020 M07 | M1: 2020 M08 | N1: 2020 M09 | O1: 2020 M10 | P1: 2020 M11 | Q1: 2020 M12 | R1: 2021 M01 | S1: 2021 M02 | T1: 2021 M03 | U1: 2021 M04 | V1: 2021 M05 | W1: 2021 M06 | X1: 2021 M07 | Y1: 2021 M08 | Z1: 2021 M09 | AA1: 2021 M10 | AB1: 2021 M11 | AC1: 2021 M12 | AD1: 2022 M01 | AE1: 2022 M02 | AF1: 2022 M03 | AG1: 2022 M04 | AH1: 2022 M05 | AI1: 2022 M06 | AJ1: 2022 M07 | AK1: 2022 M08 | AL1: 2022 M09 | AM1: 2022 M10 | AN1: 2022 M11 | AO1: 2022 M12 | AP1: 2023 M01 | AQ1: 2023 M02 | AR1: 2023 M03 | AS1: 2023 M04 | AT1: 2023 M05 | AU1: 2023 M06 | AV1: 2023 M07 | AW1: 2023 M08 | AX1: 2023 M09 | AY1: 2023 M10 | AZ1: 2023 M11 | BA1: 2023 M12 | BB1: 2024 M01 | BC1: 2024 M02 | BD1: 2024 M03 | BE1: 2024 M04 | BF1: 2024 M05 | BG1: 2024 M06 | BH1: 2024 M07 | BI1: 2024 M08 | BJ1: 2024 M09 | BK1: 2024 M10 | BL1: 2024 M11 | BM1: 2024 M12 | BN1: 2025 M01 | BO1: 2025 M02 | BP1: 2025 M03 | BQ1: 2025 M04 | BR1: 2025 M05 | BS1: 2025 M06 | BT1: 2025 M07 | BU1: 2025 M08 | BV1: 2025 M09 | BW1: 2025 M10
A2: Contract Model Score | B2: 130.07638 | C2: 132.82981 | D2: 132.99275 | E2: 132.10946 | F2: 132.25849 | G2: 131.7487 | H2: 131.54256 | I2: 132.18971 | J2: 133.74885 | K2: 134.65103 | L2: 134.80159 | M2: 135.32143 | N2: 135.83703 | O2: 135.63732 | P2: 136.60482 | Q2: 135.25698 | R2: 135.3746 | S2: 135.08197 | T2: 134.04131 | U2: 134.85769 | V2: 135.429 | W2: 135.23156 | X2: 135.14534 | Y2: 136.06332 | Z2: 134.88069 | AA2: 134.92486 | AB2: 133.43768 | AC2: 134.76745 | AD2: 134.0616 | AE2: 133.46247 | AF2: 134.42836 | AG2: 135.32861 | AH2: 136.27415 | AI2: 136.14209 | AJ2: 136.0539 | AK2: 136.18039 | AL2: 136.20134 | AM2: 136.40054 | AN2: 137.34655 | AO2: 136.56024 | AP2: 137.35433 | AQ2: 136.77652 | AR2: 136.20403 | AS2: 137.32635 | AT2: 136.6899 | AU2: 136.75897 | AV2: 135.57234 | AW2: 136.72241 | AX2: 136.99429 | AY2: 137.341 | AZ2: 136.64692 | BA2: 137.19306 | BB2: 136.53374 | BC2: 136.58082 | BD2: 136.14985 | BE2: 137.03472 | BF2: 137.23467 | BG2: 137.10824 | BH2: 137.80106 | BI2: 138.46466 | BJ2: 138.07105 | BK2: 137.16197 | BL2: 136.31058 | BM2: 136.80042 | BN2: 136.83707 | BO2: 137.09434 | BP2: 136.69472 | BQ2: 137.57439 | BR2: 138.31007 | BS2: 138.27075 | BT2: 138.46662 | BU2: 138.34761 | BV2: 138.86903 | BW2: 138.81179 | BX2: 138.98924 | BY2: 140.30771 | BZ2: 141.16539
A3: Model Score | B3: 0 | C3: 0 | D3: 0 | E3: 0 | F3: 0 | G3: 0 | H3: 0 | I3: 0 | J3: 0 | K3: 0 | L3: 0 | M3: 0 | N3: 0 | O3: 0 | P3: 0 | Q3: 0 | R3: 0 | S3: 0 | T3: 0 | U3: 0 | V3: 0 | W3: 0 | X3: 0 | Y3: 0 | Z3: 0 | AA3: 0 | AB3: 0 | AC3: 0 | AD3: 0 | AE3: 0 | AF3: 0 | AG3: 0 | AH3: 0 | AI3: 0 | AJ3: 0 | AK3: 0 | AL3: 0 | AM3: 0 | AN3: 0 | AO3: 0 | AP3: 0 | AQ3: 0 | AR3: 0 | AS3: 0 | AT3: 0 | AU3: 0 | AV3: 0 | AW3: 0 | AX3: 0 | AY3: 0 | AZ3: 0 | BA3: 0 | BB3: 0 | BC3: 0 | BD3: 0 | BE3: 0 | BF3: 0 | BG3: 0 | BH3: 0 | BI3: 0 | BJ3: 0 | BK3: 0 | BL3: 0 | BM3: 0 | BN3: 0 | BO3: 0 | BP3: 0 | BQ3: 0 | BR3: 0 | BS3: 0 | BT3: 0 | BU3: 0 | BV3: 0 | BW3: 0 | BX3: 0 | BY3: 0 | BZ3: 0
A4: Gross Loss Adjustments (Dealer level, high PTI, etc.) | B4: 0.36824634 | C4: 0.64268496 | D4: 0.73760946 | E4: 0.54113333 | F4: 0.57165568 | G4: 0.69223442 | H4: 0.66883208 | I4: 0.12577 | J4: 0.64293784 | K4: 0.6643347 | L4: -0.17959572 | M4: -0.22631531 | N4: -0.17144155 | O4: 0.44803125 | P4: 0.38710147 | Q4: -0.039322186 | R4: 0.39465574 | S4: 0.46579813 | T4: 0.63813941 | U4: 0.87198097 | V4: 0.41573185 | W4: 0.22462946 | X4: 0.28258114 | Y4: 0.6200191 | Z4: 0.80979511 | AA4: 0.79932473 | AB4: 0.14845733 | AC4: 0.37063471 | AD4: 0.56398924 | AE4: 0.7861633 | AF4: 1.0561092 | AG4: 0.94025801 | AH4: 1.0571489 | AI4: 0.39892033 | AJ4: 0.640879 | AK4: 1.0413283 | AL4: 0.91169964 | AM4: 0.76213814 | AN4: 0.23943546 | AO4: 1.7098234 | AP4: 0.09158671 | AQ4: 0.80965966 | AR4: 0.78264112 | AS4: 0.50236752 | AT4: 0.94864848 | AU4: 0.97152034 | AV4: 0.28283895 | AW4: 0.28028629 | AX4: 0.61430211 | AY4: 0.85373043 | AZ4: -0.045155873 | BA4: 0.34233267 | BB4: 0.67568085 | BC4: 0.27299915 | BD4: 0.7432554 | BE4: 0.74268419 | BF4: 1.1666023 | BG4: 1.2551317 | BH4: 0.92266646 | BI4: 0.68851694 | BJ4: 0.83186138 | BK4: 1.1778896 | BL4: 1.2394094 | BM4: 1.5142589 | BN4: 1.6919738 | BO4: 1.9706517 | BP4: 1.9634127 | BQ4: 2.4180891 | BR4: 2.5340921 | BS4: 2.7462237 | BT4: 3.1017721 | BU4: 3.2140242 | BV4: 2.9831598 | BW4: 3.4666306 | BX4: 3.3749094 | BY4: 3.829675 | BZ4: 2.4651877
A5: Recovery Adjustments excluding LTV (Mileage, vehicle type, etc.) | B5: -0.42373409 | C5: -0.48874114 | D5: -0.32970888 | E5: -0.46809162 | F5: -0.26081624 | G5: -0.55894617 | H5: -0.40693332 | I5: -1.0451672 | J5: -0.91310193 | K5: -0.59544101 | L5: -0.59041094 | M5: -0.34566215 | N5: -0.35413793 | O5: -0.052312778 | P5: -0.099655718 | Q5: 0.046838666 | R5: -0.0068603896 | S5: -0.31879126 | T5: -0.68157655 | U5: -0.79987972 | V5: -0.51695191 | W5: -0.64621622 | X5: -0.76762862 | Y5: -0.60930554 | Z5: -0.51578181 | AA5: -0.97236119 | AB5: -1.0343443 | AC5: -0.82191547 | AD5: -1.3744011 | AE5: -1.3925048 | AF5: -1.455756 | AG5: -2.3625146 | AH5: -2.3686331 | AI5: -3.2032867 | AJ5: -3.3612438 | AK5: -3.3852506 | AL5: -3.9176595 | AM5: -3.8737766 | AN5: -4.5025 | AO5: -3.0821413 | AP5: -3.1391933 | AQ5: -3.5031374 | AR5: -2.7888434 | AS5: -1.3751811 | AT5: -2.6029269 | AU5: -3.1349278 | AV5: -2.9838855 | AW5: -2.3454054 | AX5: -2.776363 | AY5: -3.1919903 | AZ5: -2.4842227 | BA5: -1.6979352 | BB5: -2.1031094 | BC5: -2.0066516 | BD5: -2.1427992 | BE5: -2.1275859 | BF5: -1.7907941 | BG5: -1.4442518 | BH5: -0.67312087 | BI5: -1.5518085 | BJ5: -1.6476181 | BK5: -2.4488304 | BL5: -1.2804253 | BM5: -1.0640987 | BN5: 0.28368992 | BO5: -0.29183328 | BP5: -0.13020809 | BQ5: 0.43098919 | BR5: 0.52244481 | BS5: 0.70917434 | BT5: 1.3330113 | BU5: 1.1416425 | BV5: 0.87944886 | BW5: 1.5408932 | BX5: 0.98003521 | BY5: 1.044294 | BZ5: 1.3274132
A6: LTV Adjustments | B6: 0.42373409 | C6: 0.48874114 | D6: 0.32970888 | E6: 0.46809162 | F6: 0.26081624 | G6: 0.55894617 | H6: 0.40693332 | I6: 1.0451672 | J6: 0.91310193 | K6: 0.59544101 | L6: 0.59041094 | M6: 0.34566215 | N6: 0.35413793 | O6: 0.052312778 | P6: 0.099655718 | Q6: -0.046838666 | R6: 0.0068603896 | S6: 0.31879126 | T6: 0.68157655 | U6: 0.79987972 | V6: 0.51695191 | W6: 0.64621622 | X6: 0.76762862 | Y6: 0.60930554 | Z6: 0.51578181 | AA6: 0.97236119 | AB6: 1.0343443 | AC6: 0.82191547 | AD6: 1.3744011 | AE6: 1.3925048 | AF6: 1.455756 | AG6: 2.3625146 | AH6: 2.3686331 | AI6: 3.2032867 | AJ6: 3.3612438 | AK6: 3.3852506 | AL6: 3.9176595 | AM6: 3.8737766 | AN6: 4.5025 | AO6: 3.0821413 | AP6: 3.1391933 | AQ6: 3.5031374 | AR6: 2.7888434 | AS6: 1.3751811 | AT6: 2.6029269 | AU6: 3.1349278 | AV6: 2.9838855 | AW6: 2.3454054 | AX6: 2.776363 | AY6: 3.1919903 | AZ6: 2.4842227 | BA6: 1.6979352 | BB6: 2.1031094 | BC6: 2.0066516 | BD6: 2.1427992 | BE6: 2.1275859 | BF6: 1.7907941 | BG6: 1.4442518 | BH6: 0.67312087 | BI6: 1.5518085 | BJ6: 1.6476181 | BK6: 2.4488304 | BL6: 1.2804253 | BM6: 1.0640987 | BN6: -0.28368992 | BO6: 0.29183328 | BP6: 0.13020809 | BQ6: -0.43098919 | BR6: -0.52244481 | BS6: -0.70917434 | BT6: -1.3330113 | BU6: -1.1416425 | BV6: -0.87944886 | BW6: -1.5408932 | BX6: -0.98003521 | BY6: -1.044294 | BZ6: -1.3274132
A7: RAGU Score | B7: 130.44463 | C7: 133.47249 | D7: 133.73036 | E7: 132.6506 | F7: 132.83015 | G7: 132.44094 | H7: 132.21139 | I7: 132.31548 | J7: 134.39179 | K7: 135.31536 | L7: 134.622 | M7: 135.09511 | N7: 135.66559 | O7: 136.08535 | P7: 136.99192 | Q7: 135.21766 | R7: 135.76925 | S7: 135.54777 | T7: 134.67945 | U7: 135.72967 | V7: 135.84474 | W7: 135.45618 | X7: 135.42792 | Y7: 136.68334 | Z7: 135.69048 | AA7: 135.72418 | AB7: 133.58613 | AC7: 135.13808 | AD7: 134.62559 | AE7: 134.24863 | AF7: 135.48447 | AG7: 136.26886 | AH7: 137.33129 | AI7: 136.54101 | AJ7: 136.69478 | AK7: 137.22172 | AL7: 137.11304 | AM7: 137.16268 | AN7: 137.58599 | AO7: 138.27006 | AP7: 137.44592 | AQ7: 137.58618 | AR7: 136.98667 | AS7: 137.82872 | AT7: 137.63855 | AU7: 137.73049 | AV7: 135.85518 | AW7: 137.0027 | AX7: 137.60859 | AY7: 138.19474 | AZ7: 136.60177 | BA7: 137.53539 | BB7: 137.20942 | BC7: 136.85382 | BD7: 136.89311 | BE7: 137.77741 | BF7: 138.40128 | BG7: 138.36337 | BH7: 138.72372 | BI7: 139.15317 | BJ7: 138.90291 | BK7: 138.33986 | BL7: 137.54999 | BM7: 138.31468 | BN7: 138.52905 | BO7: 139.06499 | BP7: 138.65813 | BQ7: 139.99248 | BR7: 140.84416 | BS7: 141.01698 | BT7: 141.56839 | BU7: 141.56163 | BV7: 141.85219 | BW7: 142.27843 | BX7: 142.36415 | BY7: 144.13738 | BZ7: 143.63057
A8: LTV | B8: 1.9087244 | C8: 1.902091 | D8: 1.9108937 | E8: 1.9483136 | F8: 1.9743248 | G8: 1.9082235 | H8: 1.856177 | I8: 2.0421645 | J8: 1.9635875 | K8: 1.8734483 | L8: 1.7480386 | M8: 1.6307556 | N8: 1.6169849 | O8: 1.627103 | P8: 1.6162566 | Q8: 1.7297385 | R8: 1.7569392 | S8: 1.7395328 | T8: 1.6369949 | U8: 1.5676004 | V8: 1.4987905 | W8: 1.465296 | X8: 1.5741537 | Y8: 1.5370213 | Z8: 1.6529071 | AA8: 1.573601 | AB8: 1.5776981 | AC8: 1.5967355 | AD8: 1.6223278 | AE8: 1.5998584 | AF8: 1.6208823 | AG8: 1.6254256 | AH8: 1.7275354 | AI8: 1.7659015 | AJ8: 1.7710768 | AK8: 1.7458196 | AL8: 1.7580864 | AM8: 1.7706581 | AN8: 1.8249991 | AO8: 1.8664803 | AP8: 1.8553202 | AQ8: 1.8110606 | AR8: 1.8031962 | AS8: 2.2124736 | AT8: 1.7122764 | AU8: 1.6336149 | AV8: 1.651872 | AW8: 1.6689601 | AX8: 1.7189757 | AY8: 1.7444615 | AZ8: 1.6596403 | BA8: 1.7449293 | BB8: 1.7600159 | BC8: 1.7378801 | BD8: 1.7289584 | BE8: 1.7354878 | BF8: 1.6971948 | BG8: 1.6132392 | BH8: 1.5355618 | BI8: 1.6337418 | BJ8: 1.6548874 | BK8: 1.633333 | BL8: 1.6344019 | BM8: 1.5806312 | BN8: 1.6133944 | BO8: 1.6092359 | BP8: 1.6135305 | BQ8: 1.5849707 | BR8: 1.5457949 | BS8: 1.58286 | BT8: 1.610135 | BU8: 1.5759432 | BV8: 1.5422471 | BW8: 1.5285302 | BX8: 1.5754634 | BY8: 1.5733703 | BZ8: 1.575951
A10: FLD | B10: 2016 | C10: 2017 | D10: 2018 | E10: 2019 | F10: 2020 M01 | G10: 2020 M02 | H10: 2020 M03 | I10: 2020 M04 | J10: 2020 M05 | K10: 2020 M06 | L10: 2020 M07 | M10: 2020 M08 | N10: 2020 M09 | O10: 2020 M10 | P10: 2020 M11 | Q10: 2020 M12 | R10: 2021 M01 | S10: 2021 M02 | T10: 2021 M03 | U10: 2021 M04 | V10: 2021 M05 | W10: 2021 M06 | X10: 2021 M07 | Y10: 2021 M08 | Z10: 2021 M09 | AA10: 2021 M10 | AB10: 2021 M11 | AC10: 2021 M12 | AD10: 2022 M01 | AE10: 2022 M02 | AF10: 2022 M03 | AG10: 2022 M04 | AH10: 2022 M05 | AI10: 2022 M06 | AJ10: 2022 M07 | AK10: 2022 M08 | AL10: 2022 M09 | AM10: 2022 M10 | AN10: 2022 M11 | AO10: 2022 M12 | AP10: 2023 M01 | AQ10: 2023 M02 | AR10: 2023 M03 | AS10: 2023 M04 | AT10: 2023 M05 | AU10: 2023 M06 | AV10: 2023 M07 | AW10: 2023 M08 | AX10: 2023 M09 | AY10: 2023 M10 | AZ10: 2023 M11 | BA10: 2023 M12 | BB10: 2024 M01 | BC10: 2024 M02 | BD10: 2024 M03 | BE10: 2024 M04 | BF10: 2024 M05 | BG10: 2024 M06 | BH10: 2024 M07 | BI10: 2024 M08 | BJ10: 2024 M09 | BK10: 2024 M10 | BL10: 2024 M11 | BM10: 2024 M12 | BN10: 2025 M01 | BO10: 2025 M02 | BP10: 2025 M03 | BQ10: 2025 M04 | BR10: 2025 M05 | BS10: 2025 M06 | BT10: 2025 M07 | BU10: 2025 M08 | BV10: 2025 M09 | BW10: 2025 M10
A11: Contract Model Score | F11: 131.69826 | G11: 133.05465 | H11: 131.44449 | I11: 132.48641 | J11: 135.78589 | K11: 137.67459 | L11: 137.63211 | M11: 137.41028 | N11: 138.50084 | O11: 138.38307 | P11: 141.10563 | Q11: 142.82581 | R11: 139.61141 | S11: 137.15928 | T11: 135.9438 | U11: 136.43445 | V11: 136.59572 | W11: 135.44515 | X11: 134.80733 | Y11: 136.84616 | Z11: 135.30382 | AA11: 135.50762 | AB11: 134.08635 | AC11: 134.22879 | AD11: 134.31941 | AE11: 133.67712 | AF11: 134.40763 | AG11: 135.82593 | AH11: 135.4639 | AI11: 136.28085 | AJ11: 136.94589 | AK11: 136.9564 | AL11: 136.99007 | AM11: 136.88364 | AN11: 139.40723 | AO11: 140.81079 | AP11: 141.68261 | AQ11: 142.38723 | AR11: 140.53336 | AS11: 139.72135 | AT11: 139.3661 | AU11: 137.91442 | AV11: 137.55925 | AW11: 137.86885 | AX11: 138.47342 | AY11: 139.44975 | AZ11: 139.906 | BA11: 139.26533 | BB11: 139.00234 | BC11: 138.84908 | BD11: 138.16068 | BE11: 138.56896 | BF11: 138.04076 | BG11: 138.62568 | BH11: 139.01469 | BI11: 140.94279 | BJ11: 141.91136 | BK11: 140.46816 | BL11: 137.69296 | BM11: 137.35406 | BN11: 136.42157 | BO11: 136.41165 | BP11: 137.00481 | BQ11: 138.24833 | BR11: 138.66846 | BS11: 138.12845 | BT11: 138.59134 | BU11: 137.62711 | BV11: 138.14099 | BW11: 137.97814 | BX11: 138.55363 | BY11: 140.497 | BZ11: 140.50887
A12: Model Score | F12: 0 | G12: 0 | H12: 0 | I12: 0 | J12: 0 | K12: 0 | L12: 0 | M12: 0 | N12: 0 | O12: 0 | P12: 0 | Q12: 0 | R12: 0 | S12: 0 | T12: 0 | U12: 0 | V12: 0 | W12: 0 | X12: 0 | Y12: 0 | Z12: 0 | AA12: 0 | AB12: 0 | AC12: 0 | AD12: 0 | AE12: 0 | AF12: 0 | AG12: 0 | AH12: 0 | AI12: 0 | AJ12: 0 | AK12: 0 | AL12: 0 | AM12: 0 | AN12: 0 | AO12: 0 | AP12: 0 | AQ12: 0 | AR12: 0 | AS12: 0 | AT12: 0 | AU12: 0 | AV12: 0 | AW12: 0 | AX12: 0 | AY12: 0 | AZ12: 0 | BA12: 0 | BB12: 0 | BC12: 0 | BD12: 0 | BE12: 0 | BF12: 0 | BG12: 0 | BH12: 0 | BI12: 0 | BJ12: 0 | BK12: 0 | BL12: 0 | BM12: 0 | BN12: 0 | BO12: 0 | BP12: 0 | BQ12: 0 | BR12: 0 | BS12: 0 | BT12: 0 | BU12: 0 | BV12: 0 | BW12: 0 | BX12: 0 | BY12: 0 | BZ12: 0
A13: Gross Loss Adjustments (Dealer level, high PTI, etc.) | F13: -2.618575 | G13: -2.6624902 | H13: -2.5389513 | I13: -2.1830018 | J13: -1.9586573 | K13: -2.5707701 | L13: -1.6067569 | M13: -1.6606386 | N13: -1.6765047 | O13: -0.90522889 | P13: 0.36024613 | Q13: 0.66551943 | R13: 1.0371936 | S13: 1.0320993 | T13: 1.1273939 | U13: -0.72660418 | V13: -0.57187697 | W13: -1.7458607 | X13: -1.4396365 | Y13: -0.62671148 | Z13: -1.0999659 | AA13: 0.15266976 | AB13: 0.34156609 | AC13: -0.37692429 | AD13: -0.95914248 | AE13: 0.47156739 | AF13: -0.19542609 | AG13: 0.055371689 | AH13: -0.071605105 | AI13: 0.16413733 | AJ13: 0.65410285 | AK13: 0.62547319 | AL13: 0.16909963 | AM13: -0.14477349 | AN13: 0.58187573 | AO13: 1.2493131 | AP13: 0.23431445 | AQ13: 0.67631668 | AR13: 0.70833313 | AS13: -0.25253448 | AT13: 1.1425682 | AU13: -0.26808274 | AV13: 0.991446 | AW13: 1.2426692 | AX13: -0.19114949 | AY13: 0.89586973 | AZ13: 1.1787151 | BA13: 0.85292392 | BB13: 0.95865681 | BC13: 1.2223759 | BD13: 1.6502528 | BE13: 2.0845649 | BF13: 2.3110549 | BG13: 2.2344407 | BH13: 3.1494852 | BI13: 3.1046769 | BJ13: 3.0523775 | BK13: 3.3850368 | BL13: 3.2175223 | BM13: 2.670848 | BN13: 2.9369339 | BO13: 3.3899991 | BP13: 3.0108809 | BQ13: 2.3547494 | BR13: 2.6220427 | BS13: 2.9199365 | BT13: 3.1501689 | BU13: 3.4133049 | BV13: 3.6318685 | BW13: 1.8941598 | BX13: 2.1301768 | BY13: 2.8158702 | BZ13: 1.8121339
A14: Recovery Adjustments excluding LTV (Mileage, vehicle type, etc.) | F14: 1.8148448 | G14: 1.6026328 | H14: 1.562453 | I14: 1.3433097 | J14: 1.5864083 | K14: 1.8821582 | L14: 1.9656491 | M14: 1.9372469 | N14: 2.0645328 | O14: 1.7585422 | P14: 2.1473351 | Q14: 2.5543385 | R14: 2.1666251 | S14: 2.0072317 | T14: 1.3350477 | U14: 0.46112401 | V14: 1.1099199 | W14: 1.4146927 | X14: 1.1603245 | Y14: 0.74029744 | Z14: 0.0068205341 | AA14: 0.10197372 | AB14: 0.47718063 | AC14: 0.83318927 | AD14: 0.7206186 | AE14: 0.35193717 | AF14: 0.43036388 | AG14: -0.42704619 | AH14: -1.6006461 | AI14: -1.9895013 | AJ14: -1.809273 | AK14: -3.3023049 | AL14: -2.6425905 | AM14: -1.3418471 | AN14: -3.9047791 | AO14: -2.4849803 | AP14: -3.1981012 | AQ14: -0.85268756 | AR14: -3.1238051 | AS14: -2.7270648 | AT14: -1.1046641 | AU14: -2.2924481 | AV14: -2.4715076 | AW14: -2.3011928 | AX14: -3.7039286 | AY14: 0.19557174 | AZ14: 0.3144631 | BA14: -0.087560064 | BB14: -0.66780964 | BC14: -1.0347384 | BD14: -0.83075605 | BE14: -1.4648811 | BF14: -1.3652133 | BG14: -1.1534177 | BH14: -0.12819333 | BI14: -0.055719087 | BJ14: -0.76931086 | BK14: -0.45520256 | BL14: -0.27666099 | BM14: -0.32161283 | BN14: 2.524388 | BO14: 2.4857602 | BP14: 1.4356227 | BQ14: 1.5286053 | BR14: 1.4357785 | BS14: 1.8939837 | BT14: 2.0282036 | BU14: 2.0625761 | BV14: 2.3986336 | BW14: 2.2605458 | BX14: 2.5923597 | BY14: 2.6789998 | BZ14: 2.5098952
A15: LTV Adjustments | F15: -1.8148448 | G15: -1.6026328 | H15: -1.562453 | I15: -1.3433097 | J15: -1.5864083 | K15: -1.8821582 | L15: -1.9656491 | M15: -1.9372469 | N15: -2.0645328 | O15: -1.7585422 | P15: -2.1473351 | Q15: -2.5543385 | R15: -2.1666251 | S15: -2.0072317 | T15: -1.3350477 | U15: -0.46112401 | V15: -1.1099199 | W15: -1.4146927 | X15: -1.1603245 | Y15: -0.74029744 | Z15: -0.0068205341 | AA15: -0.10197372 | AB15: -0.47718063 | AC15: -0.83318927 | AD15: -0.7206186 | AE15: -0.35193717 | AF15: -0.43036388 | AG15: 0.42704619 | AH15: 1.6006461 | AI15: 1.9895013 | AJ15: 1.809273 | AK15: 3.3023049 | AL15: 2.6425905 | AM15: 1.3418471 | AN15: 3.9047791 | AO15: 2.4849803 | AP15: 3.1981012 | AQ15: 0.85268756 | AR15: 3.1238051 | AS15: 2.7270648 | AT15: 1.1046641 | AU15: 2.2924481 | AV15: 2.4715076 | AW15: 2.3011928 | AX15: 3.7039286 | AY15: -0.19557174 | AZ15: -0.3144631 | BA15: 0.087560064 | BB15: 0.66780964 | BC15: 1.0347384 | BD15: 0.83075605 | BE15: 1.4648811 | BF15: 1.3652133 | BG15: 1.1534177 | BH15: 0.12819333 | BI15: 0.055719087 | BJ15: 0.76931086 | BK15: 0.45520256 | BL15: 0.27666099 | BM15: 0.32161283 | BN15: -2.524388 | BO15: -2.4857602 | BP15: -1.4356227 | BQ15: -1.5286053 | BR15: -1.4357785 | BS15: -1.8939837 | BT15: -2.0282036 | BU15: -2.0625761 | BV15: -2.3986336 | BW15: -2.2605458 | BX15: -2.5923597 | BY15: -2.6789998 | BZ15: -2.5098952
A16: RAGU Score | F16: 129.07969 | G16: 130.39216 | H16: 128.90554 | I16: 130.30341 | J16: 133.82723 | K16: 135.10382 | L16: 136.02535 | M16: 135.74965 | N16: 136.82434 | O16: 137.47784 | P16: 141.46587 | Q16: 143.49133 | R16: 140.6486 | S16: 138.19138 | T16: 137.0712 | U16: 135.70784 | V16: 136.02385 | W16: 133.69929 | X16: 133.36769 | Y16: 136.21945 | Z16: 134.20385 | AA16: 135.66029 | AB16: 134.42791 | AC16: 133.85187 | AD16: 133.36027 | AE16: 134.14868 | AF16: 134.2122 | AG16: 135.8813 | AH16: 135.39229 | AI16: 136.44499 | AJ16: 137.59999 | AK16: 137.58187 | AL16: 137.15917 | AM16: 136.73887 | AN16: 139.98911 | AO16: 142.0601 | AP16: 141.91692 | AQ16: 143.06355 | AR16: 141.24169 | AS16: 139.46882 | AT16: 140.50866 | AU16: 137.64633 | AV16: 138.55069 | AW16: 139.11152 | AX16: 138.28227 | AY16: 140.34562 | AZ16: 141.08472 | BA16: 140.11826 | BB16: 139.961 | BC16: 140.07145 | BD16: 139.81093 | BE16: 140.65352 | BF16: 140.35181 | BG16: 140.86012 | BH16: 142.16418 | BI16: 144.04747 | BJ16: 144.96374 | BK16: 143.85319 | BL16: 140.91048 | BM16: 140.02491 | BN16: 139.35851 | BO16: 139.80165 | BP16: 140.01569 | BQ16: 140.60308 | BR16: 141.2905 | BS16: 141.04839 | BT16: 141.74151 | BU16: 141.04042 | BV16: 141.77286 | BW16: 139.8723 | BX16: 140.68381 | BY16: 143.31287 | BZ16: 142.321
A17: LTV | F17: 1.4633833 | G17: 1.4328789 | H17: 1.3835412 | I17: 1.3987303 | J17: 1.3783667 | K17: 1.3524544 | L17: 1.2508309 | M17: 1.21004 | N17: 1.1957329 | O17: 1.2530861 | P17: 1.3173324 | Q17: 1.2499791 | R17: 1.3737717 | S17: 1.3001825 | T17: 1.3285323 | U17: 1.2297302 | V17: 1.2119803 | W17: 1.2606704 | X17: 1.246185 | Y17: 1.2991607 | Z17: 1.2768913 | AA17: 1.3598356 | AB17: 1.321942 | AC17: 1.3166955 | AD17: 1.3759183 | AE17: 1.3415726 | AF17: 1.3186163 | AG17: 1.335758 | AH17: 1.3348466 | AI17: 1.346843 | AJ17: 1.3131393 | AK17: 1.26462 | AL17: 1.3894416 | AM17: 1.3936065 | AN17: 1.3072397 | AO17: 1.2021165 | AP17: 1.1990727 | AQ17: 1.2737711 | AR17: 1.3224622 | AS17: 1.688119 | AT17: 1.3001563 | AU17: 1.2582054 | AV17: 1.2687651 | AW17: 1.2539488 | AX17: 1.2839291 | AY17: 1.300465 | AZ17: 1.2636814 | BA17: 1.3086419 | BB17: 1.376199 | BC17: 1.3809875 | BD17: 1.3899521 | BE17: 1.3966715 | BF17: 1.356895 | BG17: 1.3452953 | BH17: 1.3392665 | BI17: 1.37763 | BJ17: 1.3322489 | BK17: 1.3359242 | BL17: 1.3871049 | BM17: 1.3236894 | BN17: 1.3656786 | BO17: 1.3961017 | BP17: 1.40358 | BQ17: 1.4338248 | BR17: 1.4206952 | BS17: 1.4071696 | BT17: 1.4259149 | BU17: 1.4255266 | BV17: 1.4202431 | BW17: 1.4132778 | BX17: 1.4049737 | BY17: 1.447947 | BZ17: 1.438111
A19: FRN | B19: 2016 | C19: 2017 | D19: 2018 | E19: 2019 | F19: 2020 M01 | G19: 2020 M02 | H19: 2020 M03 | I19: 2020 M04 | J19: 2020 M05 | K19: 2020 M06 | L19: 2020 M07 | M19: 2020 M08 | N19: 2020 M09 | O19: 2020 M10 | P19: 2020 M11 | Q19: 2020 M12 | R19: 2021 M01 | S19: 2021 M02 | T19: 2021 M03 | U19: 2021 M04 | V19: 2021 M05 | W19: 2021 M06 | X19: 2021 M07 | Y19: 2021 M08 | Z19: 2021 M09 | AA19: 2021 M10 | AB19: 2021 M11 | AC19: 2021 M12 | AD19: 2022 M01 | AE19: 2022 M02 | AF19: 2022 M03 | AG19: 2022 M04 | AH19: 2022 M05 | AI19: 2022 M06 | AJ19: 2022 M07 | AK19: 2022 M08 | AL19: 2022 M09 | AM19: 2022 M10 | AN19: 2022 M11 | AO19: 2022 M12 | AP19: 2023 M01 | AQ19: 2023 M02 | AR19: 2023 M03 | AS19: 2023 M04 | AT19: 2023 M05 | AU19: 2023 M06 | AV19: 2023 M07 | AW19: 2023 M08 | AX19: 2023 M09 | AY19: 2023 M10 | AZ19: 2023 M11 | BA19: 2023 M12 | BB19: 2024 M01 | BC19: 2024 M02 | BD19: 2024 M03 | BE19: 2024 M04 | BF19: 2024 M05 | BG19: 2024 M06 | BH19: 2024 M07 | BI19: 2024 M08 | BJ19: 2024 M09 | BK19: 2024 M10 | BL19: 2024 M11 | BM19: 2024 M12 | BN19: 2025 M01 | BO19: 2025 M02 | BP19: 2025 M03 | BQ19: 2025 M04 | BR19: 2025 M05 | BS19: 2025 M06 | BT19: 2025 M07 | BU19: 2025 M08 | BV19: 2025 M09 | BW19: 2025 M10
A20: Contract Model Score | B20: 131.18489 | C20: 136.72146 | D20: 136.81942 | E20: 132.54318 | F20: 131.2656 | G20: 131.24734 | H20: 131.00099 | I20: 131.49953 | J20: 133.24754 | K20: 133.3984 | L20: 134.41536 | M20: 134.0819 | N20: 133.20621 | O20: 132.62511 | P20: 131.11674 | Q20: 135.00101 | R20: 135.45485 | S20: 135.55568 | T20: 135.39896 | U20: 135.35416 | V20: 135.51119 | W20: 134.67649 | X20: 134.23647 | Y20: 135.97528 | Z20: 134.5695 | AA20: 134.42803 | AB20: 132.01635 | AC20: 132.29985 | AD20: 134.01481 | AE20: 133.66105 | AF20: 134.31365 | AG20: 135.70242 | AH20: 137.3415 | AI20: 137.64811 | AJ20: 138.18701 | AK20: 137.99667 | AL20: 137.85245 | AM20: 138.34232 | AN20: 140.94633 | AO20: 141.0318 | AP20: 141.07216 | AQ20: 141.68378 | AR20: 141.17134 | AS20: 140.558 | AT20: 140.54313 | AU20: 140.65163 | AV20: 139.52303 | AW20: 141.17927 | AX20: 141.16169 | AY20: 140.12829 | AZ20: 138.55401 | BA20: 138.66844 | BB20: 139.04265 | BC20: 138.51156 | BD20: 137.58847 | BE20: 139.37221 | BF20: 140.53108 | BG20: 140.72018 | BH20: 141.1387 | BI20: 141.99905 | BJ20: 141.69762 | BK20: 140.62793 | BL20: 139.96452 | BM20: 139.29146 | BN20: 139.70528 | BO20: 140.12303 | BP20: 139.74747 | BQ20: 140.31399 | BR20: 140.88037 | BS20: 140.75094 | BT20: 140.87437 | BU20: 140.73303 | BV20: 141.33269 | BW20: 141.69552 | BX20: 141.57111 | BY20: 142.27606 | BZ20: 143.13141
A21: Model Score | B21: 0 | C21: 0 | D21: 0 | E21: 0 | F21: 0 | G21: 0 | H21: 0 | I21: 0 | J21: 0 | K21: 0 | L21: 0 | M21: 0 | N21: 0 | O21: 0 | P21: 0 | Q21: 0 | R21: 0 | S21: 0 | T21: 0 | U21: 0 | V21: 0 | W21: 0 | X21: 0 | Y21: 0 | Z21: 0 | AA21: 0 | AB21: 0 | AC21: 0 | AD21: 0 | AE21: 0 | AF21: 0 | AG21: 0 | AH21: 0 | AI21: 0 | AJ21: 0 | AK21: 0 | AL21: 0 | AM21: 0 | AN21: 0 | AO21: 0 | AP21: 0 | AQ21: 0 | AR21: 0 | AS21: 0 | AT21: 0 | AU21: 0 | AV21: 0 | AW21: 0 | AX21: 0 | AY21: 0 | AZ21: 0 | BA21: 0 | BB21: 0 | BC21: 0 | BD21: 0 | BE21: 0 | BF21: 0 | BG21: 0 | BH21: 0 | BI21: 0 | BJ21: 0 | BK21: 0 | BL21: 0 | BM21: 0 | BN21: 0 | BO21: 0 | BP21: 0 | BQ21: 0 | BR21: 0 | BS21: 0 | BT21: 0 | BU21: 0 | BV21: 0 | BW21: 0 | BX21: 0 | BY21: 0 | BZ21: 0
A22: Gross Loss Adjustments (Dealer level, high PTI, etc.) | B22: -0.3279542 | C22: 0.20210618 | D22: -0.19413065 | E22: 0.046002039 | F22: 0.20894198 | G22: 0.68967077 | H22: 0.58006475 | I22: 0.78299466 | J22: 0.89891075 | K22: 0.54373793 | L22: -0.13643966 | M22: -0.25963901 | N22: -0.43965845 | O22: -1.0434957 | P22: -0.96327644 | Q22: -0.42262724 | R22: -0.521399 | S22: -0.21157282 | T22: -0.2161873 | U22: 0.11286327 | V22: 0.17191358 | W22: 0.001116978 | X22: -0.14946234 | Y22: -0.026524873 | Z22: -0.12457301 | AA22: -1.0385091 | AB22: -1.1368363 | AC22: -1.2443844 | AD22: -1.1831245 | AE22: -0.93602081 | AF22: -1.0153112 | AG22: -0.22657864 | AH22: 0.38735503 | AI22: 0.45232977 | AJ22: 0.61673918 | AK22: 0.40253296 | AL22: -0.092616345 | AM22: -0.14469933 | AN22: 0.35704152 | AO22: -0.060778089 | AP22: 0.62320541 | AQ22: 1.116869 | AR22: 0.93617837 | AS22: 0.44328767 | AT22: 1.4618212 | AU22: 1.6028527 | AV22: 1.8758773 | AW22: 1.3662616 | AX22: 1.4187327 | AY22: 0.94445742 | AZ22: 0.6824844 | BA22: 0.5955368 | BB22: 0.33511498 | BC22: 0.45476969 | BD22: -0.00090710823 | BE22: 0.073872436 | BF22: 0.47551786 | BG22: 0.23938814 | BH22: 0.52694693 | BI22: 0.70563261 | BJ22: 0.60852798 | BK22: 0.46896912 | BL22: 0.49669736 | BM22: 0.54916671 | BN22: 0.92679308 | BO22: 0.97399083 | BP22: 1.2081372 | BQ22: 0.98342701 | BR22: 1.4151719 | BS22: 1.5388387 | BT22: 1.1650482 | BU22: 2.2476351 | BV22: 2.7273791 | BW22: 2.7269527 | BX22: 2.8403056 | BY22: 3.1705305 | BZ22: 2.5083411
A23: Recovery Adjustments excluding LTV (Mileage, vehicle type, etc.) | B23: -1.9643152 | C23: -2.2549576 | D23: -2.3856371 | E23: -1.7974164 | F23: -1.3477151 | G23: -1.3081554 | H23: -1.2512549 | I23: -1.1845604 | J23: -1.4273071 | K23: -1.0905543 | L23: -1.4595002 | M23: -1.2372835 | N23: -1.309006 | O23: -1.340571 | P23: -1.2596264 | Q23: -0.3165767 | R23: -1.1915423 | S23: -1.0293345 | T23: -1.7482472 | U23: -1.570213 | V23: -0.9290697 | W23: -1.3849273 | X23: -1.2159223 | Y23: -1.594781 | Z23: -1.7502689 | AA23: -1.8532889 | AB23: -1.8203 | AC23: -2.0417508 | AD23: -2.0294067 | AE23: -2.0618875 | AF23: -2.2601404 | AG23: -3.3579094 | AH23: -3.2712737 | AI23: -4.4422727 | AJ23: -4.8135765 | AK23: -4.8697254 | AL23: -4.9976015 | AM23: -4.6856454 | AN23: -6.1201927 | AO23: -5.1105897 | AP23: -5.3078688 | AQ23: -5.023231 | AR23: -4.7155575 | AS23: -5.4879546 | AT23: -4.5002181 | AU23: -4.5173068 | AV23: -4.8156357 | AW23: -4.8797624 | AX23: -5.0086899 | AY23: -4.0039358 | AZ23: -4.5114913 | BA23: -4.2325631 | BB23: -3.8087918 | BC23: -4.3043927 | BD23: -3.5302766 | BE23: -4.2702909 | BF23: -4.0961827 | BG23: -4.0513363 | BH23: -3.7572002 | BI23: -4.1822751 | BJ23: -4.4279506 | BK23: -3.7060484 | BL23: -3.5448495 | BM23: -2.1655407 | BN23: -0.73329709 | BO23: -0.8383779 | BP23: -0.74024632 | BQ23: -0.6614938 | BR23: -0.63467556 | BS23: -0.29674043 | BT23: -0.33023497 | BU23: -0.060033507 | BV23: 0.13756168 | BW23: 0.47130716 | BX23: 0.48063936 | BY23: 0.69454008 | BZ23: -0.0073534138
A24: LTV Adjustments | B24: 1.9643152 | C24: 2.2549576 | D24: 2.3856371 | E24: 1.7974164 | F24: 1.3477151 | G24: 1.3081554 | H24: 1.2512549 | I24: 1.1845604 | J24: 1.4273071 | K24: 1.0905543 | L24: 1.4595002 | M24: 1.2372835 | N24: 1.309006 | O24: 1.340571 | P24: 1.2596264 | Q24: 0.3165767 | R24: 1.1915423 | S24: 1.0293345 | T24: 1.7482472 | U24: 1.570213 | V24: 0.9290697 | W24: 1.3849273 | X24: 1.2159223 | Y24: 1.594781 | Z24: 1.7502689 | AA24: 1.8532889 | AB24: 1.8203 | AC24: 2.0417508 | AD24: 2.0294067 | AE24: 2.0618875 | AF24: 2.2601404 | AG24: 3.3579094 | AH24: 3.2712737 | AI24: 4.4422727 | AJ24: 4.8135765 | AK24: 4.8697254 | AL24: 4.9976015 | AM24: 4.6856454 | AN24: 6.1201927 | AO24: 5.1105897 | AP24: 5.3078688 | AQ24: 5.023231 | AR24: 4.7155575 | AS24: 5.4879546 | AT24: 4.5002181 | AU24: 4.5173068 | AV24: 4.8156357 | AW24: 4.8797624 | AX24: 5.0086899 | AY24: 4.0039358 | AZ24: 4.5114913 | BA24: 4.2325631 | BB24: 3.8087918 | BC24: 4.3043927 | BD24: 3.5302766 | BE24: 4.2702909 | BF24: 4.0961827 | BG24: 4.0513363 | BH24: 3.7572002 | BI24: 4.1822751 | BJ24: 4.4279506 | BK24: 3.7060484 | BL24: 3.5448495 | BM24: 2.1655407 | BN24: 0.73329709 | BO24: 0.8383779 | BP24: 0.74024632 | BQ24: 0.6614938 | BR24: 0.63467556 | BS24: 0.29674043 | BT24: 0.33023497 | BU24: 0.060033507 | BV24: -0.13756168 | BW24: -0.47130716 | BX24: -0.48063936 | BY24: -0.69454008 | BZ24: 0.0073534138
A25: RAGU Score | B25: 130.85693 | C25: 136.92357 | D25: 136.62529 | E25: 132.58918 | F25: 131.47454 | G25: 131.93701 | H25: 131.58106 | I25: 132.28252 | J25: 134.14645 | K25: 133.94214 | L25: 134.27892 | M25: 133.82226 | N25: 132.76655 | O25: 131.58161 | P25: 130.15347 | Q25: 134.57838 | R25: 134.93345 | S25: 135.34411 | T25: 135.18277 | U25: 135.46703 | V25: 135.6831 | W25: 134.67761 | X25: 134.08701 | Y25: 135.94875 | Z25: 134.44493 | AA25: 133.38952 | AB25: 130.87951 | AC25: 131.05547 | AD25: 132.83169 | AE25: 132.72503 | AF25: 133.29834 | AG25: 135.47584 | AH25: 137.72886 | AI25: 138.10044 | AJ25: 138.80375 | AK25: 138.3992 | AL25: 137.75983 | AM25: 138.19762 | AN25: 141.30338 | AO25: 140.97102 | AP25: 141.69537 | AQ25: 142.80065 | AR25: 142.10751 | AS25: 141.00128 | AT25: 142.00495 | AU25: 142.25449 | AV25: 141.39891 | AW25: 142.54553 | AX25: 142.58042 | AY25: 141.07275 | AZ25: 139.23649 | BA25: 139.26398 | BB25: 139.37776 | BC25: 138.96633 | BD25: 137.58756 | BE25: 139.44608 | BF25: 141.0066 | BG25: 140.95957 | BH25: 141.66565 | BI25: 142.70468 | BJ25: 142.30615 | BK25: 141.09689 | BL25: 140.46122 | BM25: 139.84062 | BN25: 140.63207 | BO25: 141.09702 | BP25: 140.95561 | BQ25: 141.29742 | BR25: 142.29554 | BS25: 142.28978 | BT25: 142.03941 | BU25: 142.98067 | BV25: 144.06007 | BW25: 144.42248 | BX25: 144.41142 | BY25: 145.44659 | BZ25: 145.63975
A26: LTV | B26: 2.1505904 | C26: 2.2076014 | D26: 2.1097029 | E26: 2.0875659 | F26: 2.0194091 | G26: 1.9185204 | H26: 1.9174761 | I26: 1.8742113 | J26: 2.0008174 | K26: 1.9375934 | L26: 1.8542445 | M26: 1.9186936 | N26: 1.9378022 | O26: 2.0427444 | P26: 2.1737498 | Q26: 1.8361932 | R26: 1.8609857 | S26: 1.7791028 | T26: 1.6618226 | U26: 1.5607826 | V26: 1.4615419 | W26: 1.5105506 | X26: 1.5517052 | Y26: 1.610812 | Z26: 1.695937 | AA26: 1.67477 | AB26: 1.6795947 | AC26: 1.7077679 | AD26: 1.6418182 | AE26: 1.6727076 | AF26: 1.655978 | AG26: 1.665526 | AH26: 1.6904076 | AI26: 1.6318661 | AJ26: 1.7179344 | AK26: 1.6719485 | AL26: 1.6712705 | AM26: 1.6946157 | AN26: 1.6429487 | AO26: 1.7191114 | AP26: 1.7145931 | AQ26: 1.6492207 | AR26: 1.8258084 | AS26: 1.9137278 | AT26: 1.5680408 | AU26: 1.4119283 | AV26: 1.4010296 | AW26: 1.4783569 | AX26: 1.5641979 | AY26: 1.5003224 | AZ26: 1.4327012 | BA26: 1.4500527 | BB26: 1.4829097 | BC26: 1.4694373 | BD26: 1.4846876 | BE26: 1.4864752 | BF26: 1.4733606 | BG26: 1.4668326 | BH26: 1.478489 | BI26: 1.4858089 | BJ26: 1.5051471 | BK26: 1.5165136 | BL26: 1.4747937 | BM26: 1.4654566 | BN26: 1.4897119 | BO26: 1.4928432 | BP26: 1.4773369 | BQ26: 1.4487366 | BR26: 1.4408087 | BS26: 1.4148339 | BT26: 1.4380338 | BU26: 1.4321141 | BV26: 1.4164798 | BW26: 1.4135773 | BX26: 1.412653 | BY26: 1.4506468 | BZ26: 1.4247754
A28: STG | B28: 2016 | C28: 2017 | D28: 2018 | E28: 2019 | F28: 2020 M01 | G28: 2020 M02 | H28: 2020 M03 | I28: 2020 M04 | J28: 2020 M05 | K28: 2020 M06 | L28: 2020 M07 | M28: 2020 M08 | N28: 2020 M09 | O28: 2020 M10 | P28: 2020 M11 | Q28: 2020 M12 | R28: 2021 M01 | S28: 2021 M02 | T28: 2021 M03 | U28: 2021 M04 | V28: 2021 M05 | W28: 2021 M06 | X28: 2021 M07 | Y28: 2021 M08 | Z28: 2021 M09 | AA28: 2021 M10 | AB28: 2021 M11 | AC28: 2021 M12 | AD28: 2022 M01 | AE28: 2022 M02 | AF28: 2022 M03 | AG28: 2022 M04 | AH28: 2022 M05 | AI28: 2022 M06 | AJ28: 2022 M07 | AK28: 2022 M08 | AL28: 2022 M09 | AM28: 2022 M10 | AN28: 2022 M11 | AO28: 2022 M12 | AP28: 2023 M01 | AQ28: 2023 M02 | AR28: 2023 M03 | AS28: 2023 M04 | AT28: 2023 M05 | AU28: 2023 M06 | AV28: 2023 M07 | AW28: 2023 M08 | AX28: 2023 M09 | AY28: 2023 M10 | AZ28: 2023 M11 | BA28: 2023 M12 | BB28: 2024 M01 | BC28: 2024 M02 | BD28: 2024 M03 | BE28: 2024 M04 | BF28: 2024 M05 | BG28: 2024 M06 | BH28: 2024 M07 | BI28: 2024 M08 | BJ28: 2024 M09 | BK28: 2024 M10 | BL28: 2024 M11 | BM28: 2024 M12 | BN28: 2025 M01 | BO28: 2025 M02 | BP28: 2025 M03 | BQ28: 2025 M04 | BR28: 2025 M05 | BS28: 2025 M06 | BT28: 2025 M07 | BU28: 2025 M08 | BV28: 2025 M09 | BW28: 2025 M10
A29: Contract Model Score | B29: 129.63955 | C29: 131.6541 | D29: 131.56964 | E29: 129.50608 | F29: 129.78439 | G29: 130.3194 | H29: 130.01813 | I29: 130.28186 | J29: 133.55242 | K29: 134.9074 | L29: 135.24459 | M29: 135.85773 | N29: 135.50069 | O29: 135.75132 | P29: 135.13958 | Q29: 134.89594 | R29: 135.56415 | S29: 135.05332 | T29: 135.26623 | U29: 135.39571 | V29: 135.36165 | W29: 135.74131 | X29: 135.03843 | Y29: 135.73405 | Z29: 134.33915 | AA29: 134.68261 | AB29: 132.94521 | AC29: 133.34441 | AD29: 134.2864 | AE29: 134.70284 | AF29: 134.6113 | AG29: 136.26908 | AH29: 136.73318 | AI29: 137.23263 | AJ29: 136.95716 | AK29: 137.63345 | AL29: 137.23928 | AM29: 137.73629 | AN29: 139.05852 | AO29: 138.44604 | AP29: 139.96787 | AQ29: 138.75376 | AR29: 139.11148 | AS29: 137.41883 | AT29: 138.17301 | AU29: 137.51063 | AV29: 137.68289 | AW29: 138.42609 | AX29: 139.23481 | AY29: 138.36256 | AZ29: 137.34161 | BA29: 136.90455 | BB29: 137.3486 | BC29: 136.85059 | BD29: 136.43852 | BE29: 137.16962 | BF29: 137.44545 | BG29: 137.85018 | BH29: 138.12378 | BI29: 138.88324 | BJ29: 138.78355 | BK29: 137.96917 | BL29: 136.82707 | BM29: 136.74566 | BN29: 136.75775 | BO29: 136.52401 | BP29: 136.69779 | BQ29: 137.49793 | BR29: 137.93118 | BS29: 138.5378 | BT29: 138.60141 | BU29: 138.34121 | BV29: 139.08055 | BW29: 139.19216 | BX29: 139.60755 | BY29: 141.45995 | BZ29: 141.41083
A30: Model Score | B30: 0 | C30: 0 | D30: 0 | E30: 0 | F30: 0 | G30: 0 | H30: 0 | I30: 0 | J30: 0 | K30: 0 | L30: 0 | M30: 0 | N30: 0 | O30: 0 | P30: 0 | Q30: 0 | R30: 0 | S30: 0 | T30: 0 | U30: 0 | V30: 0 | W30: 0 | X30: 0 | Y30: 0 | Z30: 0 | AA30: 0 | AB30: 0 | AC30: 0 | AD30: 0 | AE30: 0 | AF30: 0 | AG30: 0 | AH30: 0 | AI30: 0 | AJ30: 0 | AK30: 0 | AL30: 0 | AM30: 0 | AN30: 0 | AO30: 0 | AP30: 0 | AQ30: 0 | AR30: 0 | AS30: 0 | AT30: 0 | AU30: 0 | AV30: 0 | AW30: 0 | AX30: 0 | AY30: 0 | AZ30: 0 | BA30: 0 | BB30: 0 | BC30: 0 | BD30: 0 | BE30: 0 | BF30: 0 | BG30: 0 | BH30: 0 | BI30: 0 | BJ30: 0 | BK30: 0 | BL30: 0 | BM30: 0 | BN30: 0 | BO30: 0 | BP30: 0 | BQ30: 0 | BR30: 0 | BS30: 0 | BT30: 0 | BU30: 0 | BV30: 0 | BW30: 0 | BX30: 0 | BY30: 0 | BZ30: 0
A31: Gross Loss Adjustments (Dealer level, high PTI, etc.) | B31: 0.55168785 | C31: 0.53745688 | D31: 0.47283336 | E31: 0.26299826 | F31: -0.14006327 | G31: -0.39696846 | H31: -0.054755614 | I31: -0.39040148 | J31: -0.25670413 | K31: -0.10090749 | L31: 0.037085538 | M31: 0.14030278 | N31: 0.20053176 | O31: 0.15018009 | P31: -0.058178669 | Q31: 0.018703212 | R31: 0.84907177 | S31: 0.94076465 | T31: 0.87702519 | U31: 1.0645563 | V31: 1.12465 | W31: 0.94081331 | X31: 0.70136914 | Y31: 0.8162152 | Z31: 0.70350256 | AA31: 0.35252759 | AB31: 0.52507361 | AC31: 0.41387917 | AD31: -0.28584588 | AE31: -0.42993155 | AF31: -0.017080394 | AG31: 0.02254805 | AH31: -0.074616006 | AI31: -0.0050332041 | AJ31: -0.078831581 | AK31: -0.6660321 | AL31: -0.53108413 | AM31: -0.080976064 | AN31: 0.19272576 | AO31: 0.28530912 | AP31: -0.52586668 | AQ31: -0.14058154 | AR31: 0.6149757 | AS31: -0.68925461 | AT31: 0.25991305 | AU31: 0.15895285 | AV31: 0.55954348 | AW31: 1.2530053 | AX31: 1.3334224 | AY31: 0.90841471 | AZ31: 0.61489963 | BA31: 0.91881009 | BB31: 1.047711 | BC31: 1.0422704 | BD31: 1.1860229 | BE31: 1.7359825 | BF31: 1.887161 | BG31: 2.0356688 | BH31: 2.1908535 | BI31: 1.9882855 | BJ31: 2.3083132 | BK31: 1.9504804 | BL31: 2.11595 | BM31: 2.3825183 | BN31: 2.3034933 | BO31: 2.289166 | BP31: 2.2805958 | BQ31: 2.0584523 | BR31: 1.904943 | BS31: 2.1110437 | BT31: 1.9557382 | BU31: 2.4279503 | BV31: 2.8233177 | BW31: 2.7007742 | BX31: 3.2512251 | BY31: 3.4440448 | BZ31: 2.7714897
A32: Recovery Adjustments excluding LTV (Mileage, vehicle type, etc.) | B32: 0.12590696 | C32: 0.72276277 | D32: 0.25150527 | E32: 0.20410717 | F32: 0.12772351 | G32: 0.16975296 | H32: 0.068162662 | I32: 0.054417779 | J32: -0.017957023 | K32: 0.1984117 | L32: 0.20104804 | M32: 0.34233737 | N32: 0.37334445 | O32: 0.6065326 | P32: 0.12767472 | Q32: 0.52106741 | R32: 0.59516867 | S32: 0.43574637 | T32: 0.13091405 | U32: 0.098670235 | V32: 0.62379281 | W32: -0.0012999195 | X32: 0.23316057 | Y32: 0.067441631 | Z32: 0.43409215 | AA32: 0.29324585 | AB32: 0.033588986 | AC32: 0.70632738 | AD32: 0.76704646 | AE32: 0.36208167 | AF32: -0.14846 | AG32: -1.2482881 | AH32: -1.9835576 | AI32: -2.4014186 | AJ32: -2.2481105 | AK32: -2.8353402 | AL32: -2.5060836 | AM32: -2.0207203 | AN32: -3.7666575 | AO32: -1.5400497 | AP32: -2.9676535 | AQ32: -2.03527 | AR32: -1.6245168 | AS32: -1.2182386 | AT32: -1.6391814 | AU32: -0.9455072 | AV32: -1.4364215 | AW32: -0.78256604 | AX32: -1.1055028 | AY32: -0.83763994 | AZ32: -0.85028619 | BA32: -0.62850762 | BB32: -1.2947901 | BC32: -1.0175751 | BD32: -0.7232226 | BE32: -0.88443501 | BF32: -0.39978238 | BG32: 0.082186193 | BH32: 0.5107734 | BI32: 0.13306039 | BJ32: -1.1399635 | BK32: -0.65827321 | BL32: 0.12592197 | BM32: 1.2497366 | BN32: 2.453559 | BO32: 2.1887686 | BP32: 2.2212716 | BQ32: 2.7315838 | BR32: 3.1096159 | BS32: 3.2137301 | BT32: 3.0244134 | BU32: 2.7796861 | BV32: 3.1545589 | BW32: 3.3276938 | BX32: 3.4204206 | BY32: 3.6541647 | BZ32: 4.1962148
A33: LTV Adjustments | B33: -0.12590696 | C33: -0.72276277 | D33: -0.25150527 | E33: -0.20410717 | F33: -0.12772351 | G33: -0.16975296 | H33: -0.068162662 | I33: -0.054417779 | J33: 0.017957023 | K33: -0.1984117 | L33: -0.20104804 | M33: -0.34233737 | N33: -0.37334445 | O33: -0.6065326 | P33: -0.12767472 | Q33: -0.52106741 | R33: -0.59516867 | S33: -0.43574637 | T33: -0.13091405 | U33: -0.098670235 | V33: -0.62379281 | W33: 0.0012999195 | X33: -0.23316057 | Y33: -0.067441631 | Z33: -0.43409215 | AA33: -0.29324585 | AB33: -0.033588986 | AC33: -0.70632738 | AD33: -0.76704646 | AE33: -0.36208167 | AF33: 0.14846 | AG33: 1.2482881 | AH33: 1.9835576 | AI33: 2.4014186 | AJ33: 2.2481105 | AK33: 2.8353402 | AL33: 2.5060836 | AM33: 2.0207203 | AN33: 3.7666575 | AO33: 1.5400497 | AP33: 2.9676535 | AQ33: 2.03527 | AR33: 1.6245168 | AS33: 1.2182386 | AT33: 1.6391814 | AU33: 0.9455072 | AV33: 1.4364215 | AW33: 0.78256604 | AX33: 1.1055028 | AY33: 0.83763994 | AZ33: 0.85028619 | BA33: 0.62850762 | BB33: 1.2947901 | BC33: 1.0175751 | BD33: 0.7232226 | BE33: 0.88443501 | BF33: 0.39978238 | BG33: -0.082186193 | BH33: -0.5107734 | BI33: -0.13306039 | BJ33: 1.1399635 | BK33: 0.65827321 | BL33: -0.12592197 | BM33: -1.2497366 | BN33: -2.453559 | BO33: -2.1887686 | BP33: -2.2212716 | BQ33: -2.7315838 | BR33: -3.1096159 | BS33: -3.2137301 | BT33: -3.0244134 | BU33: -2.7796861 | BV33: -3.1545589 | BW33: -3.3276938 | BX33: -3.4204206 | BY33: -3.6541647 | BZ33: -4.1962148
A34: RAGU Score | B34: 130.19124 | C34: 132.19156 | D34: 132.04247 | E34: 129.76908 | F34: 129.64432 | G34: 129.92243 | H34: 129.96337 | I34: 129.89146 | J34: 133.29572 | K34: 134.80649 | L34: 135.28167 | M34: 135.99803 | N34: 135.70122 | O34: 135.9015 | P34: 135.0814 | Q34: 134.91464 | R34: 136.41322 | S34: 135.99408 | T34: 136.14325 | U34: 136.46026 | V34: 136.4863 | W34: 136.68212 | X34: 135.7398 | Y34: 136.55026 | Z34: 135.04265 | AA34: 135.03514 | AB34: 133.47028 | AC34: 133.75829 | AD34: 134.00055 | AE34: 134.27291 | AF34: 134.59422 | AG34: 136.29163 | AH34: 136.65857 | AI34: 137.2276 | AJ34: 136.87832 | AK34: 136.96742 | AL34: 136.7082 | AM34: 137.65531 | AN34: 139.25125 | AO34: 138.73135 | AP34: 139.442 | AQ34: 138.61318 | AR34: 139.72646 | AS34: 136.72957 | AT34: 138.43292 | AU34: 137.66958 | AV34: 138.24243 | AW34: 139.6791 | AX34: 140.56823 | AY34: 139.27097 | AZ34: 137.95651 | BA34: 137.82336 | BB34: 138.39631 | BC34: 137.89287 | BD34: 137.62454 | BE34: 138.9056 | BF34: 139.33261 | BG34: 139.88584 | BH34: 140.31464 | BI34: 140.87153 | BJ34: 141.09187 | BK34: 139.91965 | BL34: 138.94302 | BM34: 139.12818 | BN34: 139.06124 | BO34: 138.81317 | BP34: 138.97839 | BQ34: 139.55638 | BR34: 139.83613 | BS34: 140.64884 | BT34: 140.55715 | BU34: 140.76916 | BV34: 141.90387 | BW34: 141.89293 | BX34: 142.85878 | BY34: 144.90399 | BZ34: 144.18232
A35: LTV | B35: 1.9471721 | C35: 1.9398222 | D35: 1.9871149 | E35: 2.085943 | F35: 2.0676889 | G35: 2.1290235 | H35: 2.0534122 | I35: 2.0944388 | J35: 2.1513491 | K35: 2.0657497 | L35: 1.8646704 | M35: 1.8045241 | N35: 1.774196 | O35: 1.7618149 | P35: 1.8444218 | Q35: 1.8116717 | R35: 1.8007957 | S35: 1.7048222 | T35: 1.649114 | U35: 1.6103487 | V35: 1.5547197 | W35: 1.5416426 | X35: 1.5257625 | Y35: 1.6111285 | Z35: 1.6459911 | AA35: 1.5697149 | AB35: 1.6688367 | AC35: 1.5946037 | AD35: 1.5834516 | AE35: 1.5721565 | AF35: 1.55897 | AG35: 1.5276832 | AH35: 1.5498877 | AI35: 1.474718 | AJ35: 1.5033621 | AK35: 1.5408392 | AL35: 1.5550565 | AM35: 1.4801122 | AN35: 1.5291428 | AO35: 1.4411967 | AP35: 1.4602523 | AQ35: 1.36991 | AR35: 1.6344753 | AS35: 2.0992586 | AT35: 1.5630749 | AU35: 1.3831632 | AV35: 1.3438099 | AW35: 1.4197733 | AX35: 1.4749354 | AY35: 1.4229092 | AZ35: 1.3855038 | BA35: 1.4712579 | BB35: 1.5184988 | BC35: 1.5346803 | BD35: 1.5406465 | BE35: 1.5329424 | BF35: 1.4988061 | BG35: 1.4468925 | BH35: 1.43139 | BI35: 1.4419955 | BJ35: 1.4942001 | BK35: 1.4719013 | BL35: 1.4590342 | BM35: 1.4558992 | BN35: 1.4802801 | BO35: 1.5097722 | BP35: 1.467235 | BQ35: 1.4576647 | BR35: 1.4188994 | BS35: 1.3993251 | BT35: 1.4441489 | BU35: 1.4203144 | BV35: 1.4269758 | BW35: 1.3912911 | BX35: 1.4423315 | BY35: 1.4510303 | BZ35: 1.5713354
