Workbook

Sheet Data Tables (Q)
A1: AN | B1: 2016 | C1: 2017 | D1: 2018 | E1: 2019 | F1: 2020 Q1 | G1: 2020 Q2 | H1: 2020 Q3 | I1: 2020 Q4 | J1: 2021 Q1 | K1: 2021 Q2 | L1: 2021 Q3 | M1: 2021 Q4 | N1: 2022 Q1 | O1: 2022 Q2 | P1: 2022 Q3 | Q1: 2022 Q4 | R1: 2023 Q1 | S1: 2023 Q2 | T1: 2023 Q3 | U1: 2023 Q4 | V1: 2024 Q1 | W1: 2024 Q2 | X1: 2024 Q3 | Y1: 2024 Q4 | Z1: 2025 Q1 | AA1: 2025 Q2 | AB1: 2025 Q3 | AC1: 2025 Q4
A2: Contract Model Score | B2: 130.07704 | C2: 132.82918 | D2: 132.99304 | E2: 132.10911 | F2: 131.79764 | G2: 133.71059 | H2: 135.28557 | I2: 135.79608 | J2: 134.60179 | K2: 135.14257 | L2: 135.36265 | M2: 134.41538 | N2: 134.0686 | O2: 135.89246 | P2: 136.14781 | Q2: 136.75155 | R2: 136.66305 | S2: 136.90907 | T2: 136.43849 | U2: 137.02135 | V2: 136.37212 | W2: 137.12198 | X2: 138.09052 | Y2: 136.80136 | Z2: 136.83702 | AA2: 138.03382 | AB2: 138.55808 | AC2: 139.3761 | AD2: 140.46038
A3: Model Score | B3: 0 | C3: 0 | D3: 0 | E3: 0 | F3: 0 | G3: 0 | H3: 0 | I3: 0 | J3: 0 | K3: 0 | L3: 0 | M3: 0 | N3: 0 | O3: 0 | P3: 0 | Q3: 0 | R3: 0 | S3: 0 | T3: 0 | U3: 0 | V3: 0 | W3: 0 | X3: 0 | Y3: 0 | Z3: 0 | AA3: 0 | AB3: 0 | AC3: 0 | AD3: 0
A4: Gross Loss Adjustments (Dealer level, high PTI, etc.) | B4: 0.36824634 | C4: 0.64268496 | D4: 0.73760946 | E4: 0.54113333 | F4: 0.64749521 | G4: 0.51566419 | H4: -0.19174308 | I4: 0.2567337 | J4: 0.53917167 | K4: 0.53578838 | L4: 0.54503838 | M4: 0.45373656 | N4: 0.86176791 | O4: 0.76242484 | P4: 0.84667111 | Q4: 0.87913297 | R4: 0.57044205 | S4: 0.53802473 | T4: -0.091428861 | U4: 0.10384027 | V4: 0.58774847 | W4: 0.9875169 | X4: 0.73459088 | Y4: 1.3084266 | Z4: 1.905738 | AA4: 2.4385938 | AB4: 3.0483132 | AC4: 3.2623198 | AD4: 1.914656
A5: Recovery Adjustments excluding LTV (Mileage, vehicle type, etc.) | B5: -0.39258197 | C5: 0.31810502 | D5: 0.19702468 | E5: 0.1634963 | F5: -0.10819935 | G5: -0.56943614 | H5: -0.21425416 | I5: 0.68058865 | J5: 0.22441002 | K5: 0.2090722 | L5: -0.07596809 | M5: -0.50481626 | N5: -1.1464984 | O5: -0.99272578 | P5: -1.3374362 | Q5: -1.1137921 | R5: -1.2742672 | S5: -1.3069658 | T5: -1.5595382 | U5: -1.0846185 | V5: -1.7417311 | W5: -1.1027639 | X5: -0.63328552 | Y5: 0.18345643 | Z5: 0.080554239 | AA5: 0.55716861 | AB5: 0.84213839 | AC5: 1.31387 | AD5: 1.8234979
A6: LTV Adjustments | B6: 0.39258197 | C6: -0.31810502 | D6: -0.19702468 | E6: -0.1634963 | F6: 0.10819935 | G6: 0.56943614 | H6: 0.21425416 | I6: -0.68058865 | J6: -0.22441002 | K6: -0.2090722 | L6: 0.07596809 | M6: 0.50481626 | N6: 1.1464984 | O6: 0.99272578 | P6: 1.3374362 | Q6: 1.1137921 | R6: 1.2742672 | S6: 1.3069658 | T6: 1.5595382 | U6: 1.0846185 | V6: 1.7417311 | W6: 1.1027639 | X6: 0.63328552 | Y6: -0.18345643 | Z6: -0.080554239 | AA6: -0.55716861 | AB6: -0.84213839 | AC6: -1.31387 | AD6: -1.8234979
A7: RAGU Score | B7: 130.44529 | C7: 133.47187 | D7: 133.73065 | E7: 132.65024 | F7: 132.44513 | G7: 134.22626 | H7: 135.09383 | I7: 136.05282 | J7: 135.14096 | K7: 135.67836 | L7: 135.90769 | M7: 134.86912 | N7: 134.93036 | O7: 136.65488 | P7: 136.99448 | Q7: 137.63069 | R7: 137.23349 | S7: 137.44709 | T7: 136.34706 | U7: 137.12519 | V7: 136.95987 | W7: 138.1095 | X7: 138.82511 | Y7: 138.10978 | Z7: 138.74276 | AA7: 140.47241 | AB7: 141.60639 | AC7: 142.63842 | AD7: 142.37504
A8: LTV | B8: 1.9087244 | C8: 1.9022428 | D8: 1.9108901 | E8: 1.9482127 | F8: 1.902826 | G8: 1.9471127 | H8: 1.670784 | I8: 1.6601973 | J8: 1.6894127 | K8: 1.515447 | L8: 1.5852082 | M8: 1.5827355 | N8: 1.615349 | O8: 1.7131948 | P8: 1.7509586 | Q8: 1.815336 | R8: 1.8260098 | S8: 1.7142071 | T8: 1.6734988 | U8: 1.7098679 | V8: 1.735541 | W8: 1.683241 | X8: 1.5898075 | Y8: 1.6176035 | Z8: 1.6082016 | AA8: 1.5674695 | AB8: 1.5727056 | AC8: 1.5517231 | AD8: 1.5674185
A10: FLD | F10: 2020 Q1 | G10: 2020 Q2 | H10: 2020 Q3 | I10: 2020 Q4 | J10: 2021 Q1 | K10: 2021 Q2 | L10: 2021 Q3 | M10: 2021 Q4 | N10: 2022 Q1 | O10: 2022 Q2 | P10: 2022 Q3 | Q10: 2022 Q4 | R10: 2023 Q1 | S10: 2023 Q2 | T10: 2023 Q3 | U10: 2023 Q4 | V10: 2024 Q1 | W10: 2024 Q2 | X10: 2024 Q3 | Y10: 2024 Q4 | Z10: 2025 Q1 | AA10: 2025 Q2 | AB10: 2025 Q3 | AC10: 2025 Q4
A11: Contract Model Score | F11: 131.95039 | G11: 135.66547 | H11: 137.78086 | I11: 140.37625 | J11: 136.75685 | K11: 136.18261 | L11: 135.63105 | M11: 134.62935 | N11: 134.17392 | O11: 135.83718 | P11: 136.96375 | Q11: 138.77228 | R11: 141.32316 | S11: 138.86319 | T11: 137.95666 | U11: 139.5662 | V11: 138.5244 | W11: 138.40978 | X11: 140.36331 | Y11: 138.38769 | Z11: 136.70743 | AA11: 138.3478 | AB11: 138.1021 | AC11: 138.94555 | AD11: 141.12585
A12: Model Score | F12: 0 | G12: 0 | H12: 0 | I12: 0 | J12: 0 | K12: 0 | L12: 0 | M12: 0 | N12: 0 | O12: 0 | P12: 0 | Q12: 0 | R12: 0 | S12: 0 | T12: 0 | U12: 0 | V12: 0 | W12: 0 | X12: 0 | Y12: 0 | Z12: 0 | AA12: 0 | AB12: 0 | AC12: 0 | AD12: 0
A13: Gross Loss Adjustments (Dealer level, high PTI, etc.) | F13: -2.5958615 | G13: -2.2718375 | H13: -1.6417215 | I13: -0.13010911 | J13: 1.0953963 | K13: -0.99165458 | L13: -1.0619348 | M13: 0.042055432 | N13: -0.21227366 | O13: -0.013263308 | P13: 0.42673181 | Q13: 0.52563162 | R13: 0.66118191 | S13: -0.18861412 | T13: 0.32152445 | U13: 0.67156911 | V13: 1.443778 | W13: 2.2613562 | X13: 3.1268281 | Y13: 3.1597805 | Z13: 3.2253291 | AA13: 2.7901567 | AB13: 3.4402208 | AC13: 1.8901157 | AD13: 1.229186
A14: Recovery Adjustments excluding LTV (Mileage, vehicle type, etc.) | F14: -0.1173702 | G14: -0.20492955 | H14: 0.0032451687 | I14: 0.18043505 | J14: -0.25831759 | K14: -0.28531198 | L14: -0.093966231 | M14: -0.57675673 | N14: -1.2876293 | O14: -1.300891 | P14: -1.6502648 | Q14: -0.83079473 | R14: -1.382572 | S14: -1.5799359 | T14: -1.0542949 | U14: -1.3557994 | V14: -1.4970812 | W14: -0.6577689 | X14: -0.46079243 | Y14: 0.78463273 | Z14: 0.047183501 | AA14: 0.5632265 | AB14: 0.93591851 | AC14: 1.7099785 | AD14: 0.85639536
A15: LTV Adjustments | F15: 0.1173702 | G15: 0.20492955 | H15: -0.0032451687 | I15: -0.18043505 | J15: 0.25831759 | K15: 0.28531198 | L15: 0.093966231 | M15: 0.57675673 | N15: 1.2876293 | O15: 1.300891 | P15: 1.6502648 | Q15: 0.83079473 | R15: 1.382572 | S15: 1.5799359 | T15: 1.0542949 | U15: 1.3557994 | V15: 1.4970812 | W15: 0.6577689 | X15: 0.46079243 | Y15: -0.78463273 | Z15: -0.047183501 | AA15: -0.5632265 | AB15: -0.93591851 | AC15: -1.7099785 | AD15: -0.85639536
A16: RAGU Score | F16: 129.35453 | G16: 133.39363 | H16: 136.13914 | I16: 140.24614 | J16: 137.85224 | K16: 135.19096 | L16: 134.56911 | M16: 134.6714 | N16: 133.96165 | O16: 135.82392 | P16: 137.39048 | Q16: 139.29791 | R16: 141.98434 | S16: 138.67458 | T16: 138.27818 | U16: 140.23777 | V16: 139.96818 | W16: 140.67114 | X16: 143.49014 | Y16: 141.54747 | Z16: 139.93276 | AA16: 141.13795 | AB16: 141.54232 | AC16: 140.83567 | AD16: 142.35504
A17: LTV | F17: 1.4205628 | G17: 1.3731628 | H17: 1.2237836 | I17: 1.2677232 | J17: 1.3305309 | K17: 1.2336043 | L17: 1.2737699 | M17: 1.3338379 | N17: 1.3410876 | O17: 1.3363956 | P17: 1.3222392 | Q17: 1.3185246 | R17: 1.2673155 | S17: 1.2983826 | T17: 1.2656128 | U17: 1.2867607 | V17: 1.3826943 | W17: 1.3642501 | X17: 1.3452332 | Y17: 1.3398438 | Z17: 1.3796912 | AA17: 1.4106684 | AB17: 1.4121804 | AC17: 1.40963 | AD17: 1.4745501
A19: FRN | B19: 2016 | C19: 2017 | D19: 2018 | E19: 2019 | F19: 2020 Q1 | G19: 2020 Q2 | H19: 2020 Q3 | I19: 2020 Q4 | J19: 2021 Q1 | K19: 2021 Q2 | L19: 2021 Q3 | M19: 2021 Q4 | N19: 2022 Q1 | O19: 2022 Q2 | P19: 2022 Q3 | Q19: 2022 Q4 | R19: 2023 Q1 | S19: 2023 Q2 | T19: 2023 Q3 | U19: 2023 Q4 | V19: 2024 Q1 | W19: 2024 Q2 | X19: 2024 Q3 | Y19: 2024 Q4 | Z19: 2025 Q1 | AA19: 2025 Q2 | AB19: 2025 Q3 | AC19: 2025 Q4
A20: Contract Model Score | B20: 131.17685 | C20: 136.73938 | D20: 136.80349 | E20: 132.53803 | F20: 131.13303 | G20: 132.90504 | H20: 133.93048 | I20: 132.80381 | J20: 135.44811 | K20: 135.18735 | L20: 134.94602 | M20: 132.89928 | N20: 134.06325 | O20: 136.81721 | P20: 138.00243 | Q20: 139.77793 | R20: 141.27719 | S20: 140.58734 | T20: 140.72103 | U20: 139.02514 | V20: 138.13163 | W20: 140.17356 | X20: 141.55375 | Y20: 139.97097 | Z20: 139.83315 | AA20: 140.63434 | AB20: 140.96388 | AC20: 141.85749 | AD20: 142.8984
A21: Model Score | B21: 0 | C21: 0 | D21: 0 | E21: 0 | F21: 0 | G21: 0 | H21: 0 | I21: 0 | J21: 0 | K21: 0 | L21: 0 | M21: 0 | N21: 0 | O21: 0 | P21: 0 | Q21: 0 | R21: 0 | S21: 0 | T21: 0 | U21: 0 | V21: 0 | W21: 0 | X21: 0 | Y21: 0 | Z21: 0 | AA21: 0 | AB21: 0 | AC21: 0 | AD21: 0
A22: Gross Loss Adjustments (Dealer level, high PTI, etc.) | B22: -0.3279542 | C22: 0.20210618 | D22: -0.19413065 | E22: 0.046002039 | F22: 0.53224606 | G22: 0.71345069 | H22: -0.27007229 | I22: -0.83970892 | J22: -0.28336522 | K22: 0.096546832 | L22: -0.09886035 | M22: -1.1380306 | N22: -1.0378799 | O22: 0.13115547 | P22: 0.19142619 | Q22: -0.073111643 | R22: 0.7503485 | S22: 0.82560056 | T22: 0.86082024 | U22: 0.25128083 | V22: -0.094949442 | W22: 0.006680112 | X22: 0.37649879 | Y22: 0.43243354 | Z22: 1.0053154 | AA22: 1.111758 | AB22: 1.8168113 | AC22: 2.6050902 | AD22: 2.0098245
A23: Recovery Adjustments excluding LTV (Mileage, vehicle type, etc.) | B23: -0.48077299 | C23: 0.29742497 | D23: 0.28839507 | E23: 0.13368594 | F23: -0.35590629 | G23: -0.39916326 | H23: 0.015803735 | I23: 0.29142926 | J23: 0.22685781 | K23: 0.15910038 | L23: -0.16651055 | M23: -0.64123411 | N23: -1.406421 | O23: -1.3721178 | P23: -1.3559362 | Q23: -1.2985672 | R23: -1.2296732 | S23: -1.4790928 | T23: -1.4399127 | U23: -1.4356336 | V23: -1.4637224 | W23: -1.106972 | X23: -0.63836717 | Y23: 0.44202526 | Z23: 0.2294098 | AA23: 0.23943624 | AB23: 0.95567212 | AC23: 1.5113807 | AD23: 1.5112986
A24: LTV Adjustments | B24: 0.48077299 | C24: -0.29742497 | D24: -0.28839507 | E24: -0.13368594 | F24: 0.35590629 | G24: 0.39916326 | H24: -0.015803735 | I24: -0.29142926 | J24: -0.22685781 | K24: -0.15910038 | L24: 0.16651055 | M24: 0.64123411 | N24: 1.406421 | O24: 1.3721178 | P24: 1.3559362 | Q24: 1.2985672 | R24: 1.2296732 | S24: 1.4790928 | T24: 1.4399127 | U24: 1.4356336 | V24: 1.4637224 | W24: 1.106972 | X24: 0.63836717 | Y24: -0.44202526 | Z24: -0.2294098 | AA24: -0.23943624 | AB24: -0.95567212 | AC24: -1.5113807 | AD24: -1.5112986
A25: RAGU Score | B25: 130.8489 | C25: 136.94149 | D25: 136.60936 | E25: 132.58403 | F25: 131.66528 | G25: 133.61849 | H25: 133.66041 | I25: 131.9641 | J25: 135.16475 | K25: 135.2839 | L25: 134.84716 | M25: 131.76125 | N25: 133.02537 | O25: 136.94836 | P25: 138.19386 | Q25: 139.70482 | R25: 142.02754 | S25: 141.41294 | T25: 141.58185 | U25: 139.27642 | V25: 138.03669 | W25: 140.18024 | X25: 141.93025 | Y25: 140.40341 | Z25: 140.83847 | AA25: 141.74609 | AB25: 142.7807 | AC25: 144.46258 | AD25: 144.90822
A26: LTV | B26: 2.1505528 | C26: 2.2073907 | D26: 2.1097029 | E26: 2.0875659 | F26: 1.9401142 | G26: 1.9433066 | H26: 1.9003889 | I26: 2.0282542 | J26: 1.7336042 | K26: 1.5122458 | L26: 1.6173146 | M26: 1.6867925 | N26: 1.6567267 | O26: 1.6662777 | P26: 1.6871017 | Q26: 1.687404 | R26: 1.7328819 | S26: 1.5404666 | T26: 1.4968258 | U26: 1.4613721 | V26: 1.4832384 | W26: 1.4770275 | X26: 1.4906501 | Y26: 1.4849278 | Z26: 1.4878209 | AA26: 1.4286425 | AB26: 1.424556 | AC26: 1.4210557 | AD26: 1.4520697
A28: STG | B28: 2016 | C28: 2017 | D28: 2018 | E28: 2019 | F28: 2020 Q1 | G28: 2020 Q2 | H28: 2020 Q3 | I28: 2020 Q4 | J28: 2021 Q1 | K28: 2021 Q2 | L28: 2021 Q3 | M28: 2021 Q4 | N28: 2022 Q1 | O28: 2022 Q2 | P28: 2022 Q3 | Q28: 2022 Q4 | R28: 2023 Q1 | S28: 2023 Q2 | T28: 2023 Q3 | U28: 2023 Q4 | V28: 2024 Q1 | W28: 2024 Q2 | X28: 2024 Q3 | Y28: 2024 Q4 | Z28: 2025 Q1 | AA28: 2025 Q2 | AB28: 2025 Q3 | AC28: 2025 Q4
A29: Contract Model Score | B29: 129.64201 | C29: 131.65669 | D29: 131.56906 | E29: 129.50527 | F29: 130.0304 | G29: 133.13562 | H29: 135.5242 | I29: 135.28733 | J29: 135.28771 | K29: 135.49901 | L29: 135.05653 | M29: 133.65336 | N29: 134.55 | O29: 136.72731 | P29: 137.27114 | Q29: 138.30195 | R29: 139.23035 | S29: 137.71584 | T29: 138.53984 | U29: 137.48747 | V29: 136.76023 | W29: 137.47802 | X29: 138.54354 | Y29: 137.20905 | Z29: 136.6684 | AA29: 137.94719 | AB29: 138.66055 | AC29: 140.03752 | AD29: 141.52846
A30: Model Score | B30: 0 | C30: 0 | D30: 0 | E30: 0 | F30: 0 | G30: 0 | H30: 0 | I30: 0 | J30: 0 | K30: 0 | L30: 0 | M30: 0 | N30: 0 | O30: 0 | P30: 0 | Q30: 0 | R30: 0 | S30: 0 | T30: 0 | U30: 0 | V30: 0 | W30: 0 | X30: 0 | Y30: 0 | Z30: 0 | AA30: 0 | AB30: 0 | AC30: 0 | AD30: 0
A31: Gross Loss Adjustments (Dealer level, high PTI, etc.) | B31: 0.55168785 | C31: 0.53745688 | D31: 0.47283336 | E31: 0.26299826 | F31: -0.17705346 | G31: -0.23517459 | H31: 0.1178712 | I31: 0.041467995 | J31: 0.88577009 | K31: 1.0419584 | L31: 0.74064638 | M31: 0.42910054 | N31: -0.22394537 | O31: -0.040705244 | P31: -0.48924385 | Q31: 0.14118108 | R31: -0.038606969 | S31: -0.33664797 | T31: 0.57101574 | U31: 0.4741766 | V31: 0.95904886 | W31: 1.7697237 | X31: 2.0103731 | Y31: 2.1616877 | Z31: 2.2549256 | AA31: 1.949069 | AB31: 2.2586722 | AC31: 2.800372 | AD31: 2.1336389
A32: Recovery Adjustments excluding LTV (Mileage, vehicle type, etc.) | B32: -0.51258551 | C32: 0.27300264 | D32: 0.28674551 | E32: 0.0087854085 | F32: -0.0579634 | G32: -0.23514923 | H32: -0.17763246 | I32: 0.39104339 | J32: 0.16365721 | K32: 0.14110014 | L32: -0.19682375 | M32: -0.69220439 | N32: -1.0157167 | O32: -1.5663499 | P32: -1.5843627 | Q32: -1.3083488 | R32: -1.0537594 | S32: -0.95726796 | T32: -1.3703764 | U32: -1.3584952 | V32: -1.6674839 | W32: -1.1614308 | X32: -0.66741054 | Y32: 0.10374512 | Z32: 0.33099157 | AA32: 0.40683462 | AB32: 0.67784691 | AC32: 1.6772277 | AD32: 0.91825423
A33: LTV Adjustments | B33: 0.51258551 | C33: -0.27300264 | D33: -0.28674551 | E33: -0.0087854085 | F33: 0.0579634 | G33: 0.23514923 | H33: 0.17763246 | I33: -0.39104339 | J33: -0.16365721 | K33: -0.14110014 | L33: 0.19682375 | M33: 0.69220439 | N33: 1.0157167 | O33: 1.5663499 | P33: 1.5843627 | Q33: 1.3083488 | R33: 1.0537594 | S33: 0.95726796 | T33: 1.3703764 | U33: 1.3584952 | V33: 1.6674839 | W33: 1.1614308 | X33: 0.66741054 | Y33: -0.10374512 | Z33: -0.33099157 | AA33: -0.40683462 | AB33: -0.67784691 | AC33: -1.6772277 | AD33: -0.91825423
A34: RAGU Score | B34: 130.1937 | C34: 132.19415 | D34: 132.0419 | E34: 129.76827 | F34: 129.85334 | G34: 132.90045 | H34: 135.64207 | I34: 135.32879 | J34: 136.17348 | K34: 136.54097 | L34: 135.79718 | M34: 134.08246 | N34: 134.32605 | O34: 136.68661 | P34: 136.7819 | Q34: 138.44313 | R34: 139.19174 | S34: 137.37919 | T34: 139.11085 | U34: 137.96165 | V34: 137.71928 | W34: 139.24775 | X34: 140.55391 | Y34: 139.37074 | Z34: 138.92332 | AA34: 139.89626 | AB34: 140.91922 | AC34: 142.83789 | AD34: 143.66209
A35: LTV | B35: 1.9469756 | C35: 1.940031 | D35: 1.9871149 | E35: 2.0859933 | F35: 2.0792979 | G35: 2.1024128 | H35: 1.8205477 | I35: 1.8048166 | J35: 1.7006093 | K35: 1.5705129 | L35: 1.5917275 | M35: 1.6099823 | N35: 1.5700251 | O35: 1.5217243 | P35: 1.5389668 | Q35: 1.4816615 | R35: 1.4752199 | S35: 1.5151542 | T35: 1.4255162 | U35: 1.4294535 | V35: 1.5282342 | W35: 1.4897571 | X35: 1.4524382 | Y35: 1.4626335 | Z35: 1.4844701 | AA35: 1.4252153 | AB35: 1.4315317 | AC35: 1.4182828 | AD35: 1.4850732
A37: ENT | F37: 2020 Q1 | G37: 2020 Q2 | H37: 2020 Q3 | I37: 2020 Q4 | J37: 2021 Q1 | K37: 2021 Q2 | L37: 2021 Q3 | M37: 2021 Q4 | N37: 2022 Q1 | O37: 2022 Q2 | P37: 2022 Q3 | Q37: 2022 Q4 | R37: 2023 Q1 | S37: 2023 Q2 | T37: 2023 Q3 | U37: 2023 Q4 | V37: 2024 Q1 | W37: 2024 Q2 | X37: 2024 Q3 | Y37: 2024 Q4 | Z37: 2025 Q1 | AA37: 2025 Q2 | AB37: 2025 Q3 | AC37: 2025 Q4
A38: Contract Model Score | F38: 132.38307 | G38: 133.22864 | H38: 136.30166 | I38: 135.38242 | J38: 133.8357 | K38: 131.8749 | L38: 131.13569 | M38: 129.4723 | N38: 129.34473 | O38: 131.45349 | P38: 131.71553 | Q38: 131.25851 | R38: 132.73385 | S38: 133.4422 | T38: 133.76755 | U38: 135.31367 | V38: 136.17456 | W38: 136.8171 | X38: 136.69241 | Y38: 134.94875 | Z38: 134.57148 | AA38: 136.41792 | AB38: 137.0063 | AC38: 137.20721 | AD38: 139.55396
A39: Model Score | F39: 0 | G39: 0 | H39: 0 | I39: 0 | J39: 0 | K39: 0 | L39: 0 | M39: 0 | N39: 0 | O39: 0 | P39: 0 | Q39: 0 | R39: 0 | S39: 0 | T39: 0 | U39: 0 | V39: 0 | W39: 0 | X39: 0 | Y39: 0 | Z39: 0 | AA39: 0 | AB39: 0 | AC39: 0 | AD39: 0
A40: Gross Loss Adjustments (Dealer level, high PTI, etc.) | F40: -0.32633691 | G40: -0.24531305 | H40: -0.51478673 | I40: -1.7810736 | J40: -1.1663098 | K40: -1.3644154 | L40: -1.5978945 | M40: -1.4141434 | N40: -0.94809964 | O40: -1.1552447 | P40: -1.6752459 | Q40: -1.4947023 | R40: -1.8407645 | S40: -1.7181969 | T40: -1.5143745 | U40: -0.26488858 | V40: -0.33797291 | W40: -0.25306573 | X40: -0.34387396 | Y40: 0.25808423 | Z40: 0.1260553 | AA40: 0.68736219 | AB40: 0.6230396 | AC40: 1.6196659 | AD40: 1.5639228
A41: Recovery Adjustments excluding LTV (Mileage, vehicle type, etc.) | F41: -2.8893777 | G41: -2.6973233 | H41: -2.44732 | I41: -2.4631079 | J41: -2.4101873 | K41: -1.821715 | L41: -2.3608023 | M41: -2.2364697 | N41: -3.0902909 | O41: -3.435407 | P41: -4.1052264 | Q41: -4.2753205 | R41: -4.0226523 | S41: -3.8170759 | T41: -3.5395621 | U41: -2.9965075 | V41: -3.5568879 | W41: -3.2301753 | X41: -2.3887581 | Y41: 0.096156654 | Z41: 1.1548546 | AA41: 0.11886128 | AB41: 0.3810541 | AC41: 1.1634511 | AD41: 0.67722626
A42: LTV Adjustments | F42: 2.8893777 | G42: 2.6973233 | H42: 2.44732 | I42: 2.4631079 | J42: 2.4101873 | K42: 1.821715 | L42: 2.3608023 | M42: 2.2364697 | N42: 3.0902909 | O42: 3.435407 | P42: 4.1052264 | Q42: 4.2753205 | R42: 4.0226523 | S42: 3.8170759 | T42: 3.5395621 | U42: 2.9965075 | V42: 3.5568879 | W42: 3.2301753 | X42: 2.3887581 | Y42: -0.096156654 | Z42: -1.1548546 | AA42: -0.11886128 | AB42: -0.3810541 | AC42: -1.1634511 | AD42: -0.67722626
A43: RAGU Score | F43: 132.05673 | G43: 132.98333 | H43: 135.78687 | I43: 133.60135 | J43: 132.66939 | K43: 130.51048 | L43: 129.5378 | M43: 128.05816 | N43: 128.39663 | O43: 130.29824 | P43: 130.04029 | Q43: 129.76381 | R43: 130.89308 | S43: 131.724 | T43: 132.25318 | U43: 135.04878 | V43: 135.83659 | W43: 136.56403 | X43: 136.34854 | Y43: 135.20683 | Z43: 134.69754 | AA43: 137.10528 | AB43: 137.62934 | AC43: 138.82688 | AD43: 141.11789
A44: LTV | F44: 1.4714253 | G44: 1.4474478 | H44: 1.2669384 | I44: 1.3700476 | J44: 1.3586296 | K44: 1.2606972 | L44: 1.3395636 | M44: 1.3730102 | N44: 1.3911187 | O44: 1.3447795 | P44: 1.2919485 | Q44: 1.3472724 | R44: 1.375607 | S44: 1.3232001 | T44: 1.2558985 | U44: 1.3078145 | V44: 1.3169814 | W44: 1.2999196 | X44: 1.3145308 | Y44: 1.3452644 | Z44: 1.331159 | AA44: 1.3027503 | AB44: 1.3078482 | AC44: 1.3184408 | AD44: 1.3537993
...

Sheet Data Tables (M)
A1: AN | B1: 2016 | C1: 2017 | D1: 2018 | E1: 2019 | F1: 2020 M01 | G1: 2020 M02 | H1: 2020 M03 | I1: 2020 M04 | J1: 2020 M05 | K1: 2020 M06 | L1: 2020 M07 | M1: 2020 M08 | N1: 2020 M09 | O1: 2020 M10 | P1: 2020 M11 | Q1: 2020 M12 | R1: 2021 M01 | S1: 2021 M02 | T1: 2021 M03 | U1: 2021 M04 | V1: 2021 M05 | W1: 2021 M06 | X1: 2021 M07 | Y1: 2021 M08 | Z1: 2021 M09 | AA1: 2021 M10 | AB1: 2021 M11 | AC1: 2021 M12 | AD1: 2022 M01 | AE1: 2022 M02 | AF1: 2022 M03 | AG1: 2022 M04 | AH1: 2022 M05 | AI1: 2022 M06 | AJ1: 2022 M07 | AK1: 2022 M08 | AL1: 2022 M09 | AM1: 2022 M10 | AN1: 2022 M11 | AO1: 2022 M12 | AP1: 2023 M01 | AQ1: 2023 M02 | AR1: 2023 M03 | AS1: 2023 M04 | AT1: 2023 M05 | AU1: 2023 M06 | AV1: 2023 M07 | AW1: 2023 M08 | AX1: 2023 M09 | AY1: 2023 M10 | AZ1: 2023 M11 | BA1: 2023 M12 | BB1: 2024 M01 | BC1: 2024 M02 | BD1: 2024 M03 | BE1: 2024 M04 | BF1: 2024 M05 | BG1: 2024 M06 | BH1: 2024 M07 | BI1: 2024 M08 | BJ1: 2024 M09 | BK1: 2024 M10 | BL1: 2024 M11 | BM1: 2024 M12 | BN1: 2025 M01 | BO1: 2025 M02 | BP1: 2025 M03 | BQ1: 2025 M04 | BR1: 2025 M05 | BS1: 2025 M06 | BT1: 2025 M07 | BU1: 2025 M08 | BV1: 2025 M09 | BW1: 2025 M10 | BX1: 2025 M11 | BY1: 2025 M12 | BZ1: 2026 M01
A2: Contract Model Score | B2: 130.07638 | C2: 132.82981 | D2: 132.99275 | E2: 132.10946 | F2: 132.25849 | G2: 131.7487 | H2: 131.54256 | I2: 132.18971 | J2: 133.74885 | K2: 134.65103 | L2: 134.80159 | M2: 135.32143 | N2: 135.83703 | O2: 135.63732 | P2: 136.60482 | Q2: 135.25698 | R2: 135.3746 | S2: 135.08197 | T2: 134.04131 | U2: 134.85769 | V2: 135.429 | W2: 135.23156 | X2: 135.14534 | Y2: 136.06332 | Z2: 134.88069 | AA2: 134.92486 | AB2: 133.43768 | AC2: 134.76745 | AD2: 134.0616 | AE2: 133.46247 | AF2: 134.42836 | AG2: 135.32861 | AH2: 136.27415 | AI2: 136.14209 | AJ2: 136.0539 | AK2: 136.18039 | AL2: 136.20134 | AM2: 136.40054 | AN2: 137.34655 | AO2: 136.56024 | AP2: 137.35433 | AQ2: 136.77652 | AR2: 136.20403 | AS2: 137.32635 | AT2: 136.6899 | AU2: 136.75897 | AV2: 135.57234 | AW2: 136.72241 | AX2: 136.99429 | AY2: 137.19306 | AZ2: 136.53374 | BA2: 136.58082 | BB2: 136.14985 | BC2: 137.03472 | BD2: 137.23467 | BE2: 137.10824 | BF2: 137.80106 | BG2: 138.46466 | BH2: 138.07105 | BI2: 137.16197 | BJ2: 136.31058 | BK2: 136.80042 | BL2: 136.83707 | BM2: 137.09434 | BN2: 136.69472 | BO2: 137.57439 | BP2: 138.31007 | BQ2: 138.27075 | BR2: 138.46662 | BS2: 138.34761 | BT2: 138.86903 | BU2: 138.81179 | BV2: 138.98924 | BW2: 140.30771 | BX2: 140.4025 | BY2: 137.341 | BZ2: 136.64692 | CA2: 140.81499
A3: Model Score | B3: 0 | C3: 0 | D3: 0 | E3: 0 | F3: 0 | G3: 0 | H3: 0 | I3: 0 | J3: 0 | K3: 0 | L3: 0 | M3: 0 | N3: 0 | O3: 0 | P3: 0 | Q3: 0 | R3: 0 | S3: 0 | T3: 0 | U3: 0 | V3: 0 | W3: 0 | X3: 0 | Y3: 0 | Z3: 0 | AA3: 0 | AB3: 0 | AC3: 0 | AD3: 0 | AE3: 0 | AF3: 0 | AG3: 0 | AH3: 0 | AI3: 0 | AJ3: 0 | AK3: 0 | AL3: 0 | AM3: 0 | AN3: 0 | AO3: 0 | AP3: 0 | AQ3: 0 | AR3: 0 | AS3: 0 | AT3: 0 | AU3: 0 | AV3: 0 | AW3: 0 | AX3: 0 | AY3: 0 | AZ3: 0 | BA3: 0 | BB3: 0 | BC3: 0 | BD3: 0 | BE3: 0 | BF3: 0 | BG3: 0 | BH3: 0 | BI3: 0 | BJ3: 0 | BK3: 0 | BL3: 0 | BM3: 0 | BN3: 0 | BO3: 0 | BP3: 0 | BQ3: 0 | BR3: 0 | BS3: 0 | BT3: 0 | BU3: 0 | BV3: 0 | BW3: 0 | BX3: 0
A4: Gross Loss Adjustments (Dealer level, high PTI, etc.) | B4: 0.66321459 | C4: 1.0385795 | D4: 1.1380113 | E4: 1.1999234 | F4: 1.363498 | G4: 1.4890326 | H4: 1.4551035 | I4: 0.95163864 | J4: 1.4384026 | K4: 1.4548572 | L4: 0.6330598 | M4: 0.57072414 | N4: 0.63123428 | O4: 1.2672486 | P4: 1.2015072 | Q4: 0.78183178 | R4: 1.202423 | S4: 1.2781026 | T4: 1.4387594 | U4: 1.6599887 | V4: 1.2247999 | W4: 1.0389789 | X4: 1.0486893 | Y4: 1.3860844 | Z4: 1.5658651 | AA4: 1.5637281 | AB4: 0.9553726 | AC4: 1.1725708 | AD4: 1.3500946 | AE4: 1.5398787 | AF4: 1.8252304 | AG4: 1.8290847 | AH4: 2.5043044 | AI4: 0.8989561 | AJ4: 0.91030944 | AK4: -0.33803067 | AL4: 1.6979652 | AM4: -1.812468 | AN4: 1.5911042 | AO4: -0.85166303 | AP4: 1.47558 | AQ4: 1.1167384 | AR4: 0.08872574 | AS4: 3.1185061 | AT4: -1.4776426 | AU4: -1.2971092 | AV4: -1.8509514 | AW4: 1.1530122 | AX4: 4.3341447 | AY4: 1.8896377 | AZ4: 0.98233763 | BA4: 1.0913693 | BB4: 0.90847572 | BC4: 1.1475105 | BD4: 1.4501609 | BE4: 1.5039823 | BF4: 1.5817047 | BG4: 0.93728365 | BH4: 0.97573692 | BI4: 0.94632961 | BJ4: 1.1939329 | BK4: 0.98178419 | BL4: 1.7335169 | BM4: 1.5894201 | BN4: 0.7650227 | BO4: 1.9688479 | BP4: 1.4714886 | BQ4: 2.7699838 | BR4: 2.7445103 | BS4: 2.9079804 | BT4: 3.1276505 | BU4: 3.0665305 | BV4: 3.0046783 | BW4: 3.3612264 | BX4: 1.6742972
A5: Recovery Adjustments excluding LTV (Mileage, vehicle type, etc.) | B5: -0.43387446 | C5: 0.25208665 | D5: 0.23835097 | E5: 0.083969258 | F5: -0.16900385 | G5: -0.066268575 | H5: -0.37281442 | I5: -0.55892049 | J5: -0.42429522 | K5: -0.16532972 | L5: -0.39771018 | M5: 0.023328623 | N5: 0.17751563 | O5: 0.24090843 | P5: -0.073562787 | Q5: 0.89192764 | R5: 1.0585003 | S5: -0.20632461 | T5: -0.29325404 | U5: -0.019292746 | V5: 0.29077176 | W5: 0.17819197 | X5: -0.28841322 | Y5: -0.47832537 | Z5: -0.36451377 | AA5: -0.3124721 | AB5: -1.5628734 | AC5: -1.1041396 | AD5: 0.242783 | AE5: -0.66124799 | AF5: -1.2296851 | AG5: -2.271026 | AH5: -0.086659548 | AI5: 0.55523182 | AJ5: -2.6532631 | AK5: -0.85788277 | AL5: -3.2618726 | AM5: 4.5268125 | AN5: 0.13955307 | AO5: -0.68617029 | AP5: -2.2350777 | AQ5: -3.1453828 | AR5: -1.3145268 | AS5: -5.3223482 | AT5: -0.98840288 | AU5: -2.8654298 | AV5: -0.91046055 | AW5: -2.8747319 | AX5: -4.1975832 | AY5: -0.85144109 | AZ5: -2.1919821 | BA5: -0.54056974 | BB5: -1.7836194 | BC5: -2.0063219 | BD5: -1.2370276 | BE5: -0.20553532 | BF5: -0.11813114 | BG5: -1.094554 | BH5: -1.1770372 | BI5: -0.33003849 | BJ5: -0.13258979 | BK5: 1.9015271 | BL5: 1.5940937 | BM5: 1.1338343 | BN5: -0.19350888 | BO5: 0.17929852 | BP5: 0.46934362 | BQ5: 1.3796446 | BR5: 0.080108917 | BS5: 0.18026339 | BT5: 1.7756142 | BU5: 1.7362769 | BV5: 0.16131662 | BW5: 0.23263656 | BX5: 0.89607298
A6: LTV Adjustments | B6: 0.43387446 | C6: -0.25208665 | D6: -0.23835097 | E6: -0.083969258 | F6: 0.16900385 | G6: 0.066268575 | H6: 0.37281442 | I6: 0.55892049 | J6: 0.42429522 | K6: 0.16532972 | L6: 0.39771018 | M6: -0.023328623 | N6: -0.17751563 | O6: -0.24090843 | P6: 0.073562787 | Q6: -0.89192764 | R6: -1.0585003 | S6: 0.20632461 | T6: 0.29325404 | U6: 0.019292746 | V6: -0.29077176 | W6: -0.17819197 | X6: 0.28841322 | Y6: 0.47832537 | Z6: 0.36451377 | AA6: 0.3124721 | AB6: 1.5628734 | AC6: 1.1041396 | AD6: -0.242783 | AE6: 0.66124799 | AF6: 1.2296851 | AG6: 2.271026 | AH6: 0.086659548 | AI6: -0.55523182 | AJ6: 2.6532631 | AK6: 0.85788277 | AL6: 3.2618726 | AM6: -4.5268125 | AN6: -0.13955307 | AO6: 0.68617029 | AP6: 2.2350777 | AQ6: 3.1453828 | AR6: 1.3145268 | AS6: 5.3223482 | AT6: 0.98840288 | AU6: 2.8654298 | AV6: 0.91046055 | AW6: 2.8747319 | AX6: 4.1975832 | AY6: 0.85144109 | AZ6: 2.1919821 | BA6: 0.54056974 | BB6: 1.7836194 | BC6: 2.0063219 | BD6: 1.2370276 | BE6: 0.20553532 | BF6: 0.11813114 | BG6: 1.094554 | BH6: 1.1770372 | BI6: 0.33003849 | BJ6: 0.13258979 | BK6: -1.9015271 | BL6: -1.5940937 | BM6: -1.1338343 | BN6: 0.19350888 | BO6: -0.17929852 | BP6: -0.46934362 | BQ6: -1.3796446 | BR6: -0.080108917 | BS6: -0.18026339 | BT6: -1.7756142 | BU6: -1.7362769 | BV6: -0.16131662 | BW6: -0.23263656 | BX6: -0.89607298
A7: RAGU Score | B7: 130.73959 | C7: 133.86839 | D7: 134.13076 | E7: 133.30939 | F7: 133.62199 | G7: 133.23774 | H7: 132.99766 | I7: 133.14135 | J7: 135.18725 | K7: 136.10589 | L7: 135.43465 | M7: 135.89215 | N7: 136.46827 | O7: 136.90457 | P7: 137.80633 | Q7: 136.03881 | R7: 136.57702 | S7: 136.36007 | T7: 135.48007 | U7: 136.51767 | V7: 136.6538 | W7: 136.27053 | X7: 136.19403 | Y7: 137.44941 | Z7: 136.44655 | AA7: 136.48859 | AB7: 134.39305 | AC7: 135.94002 | AD7: 135.4117 | AE7: 135.00235 | AF7: 136.25359 | AG7: 137.15769 | AH7: 138.77845 | AI7: 137.04105 | AJ7: 136.96421 | AK7: 135.84236 | AL7: 137.89931 | AM7: 134.58807 | AN7: 138.93766 | AO7: 135.70858 | AP7: 138.82991 | AQ7: 137.89326 | AR7: 136.29276 | AS7: 140.44486 | AT7: 135.21226 | AU7: 135.46186 | AV7: 133.72139 | AW7: 137.87542 | AX7: 141.32843 | AY7: 139.0827 | AZ7: 137.51608 | BA7: 137.67219 | BB7: 137.05833 | BC7: 138.18223 | BD7: 138.68483 | BE7: 138.61222 | BF7: 139.38276 | BG7: 139.40194 | BH7: 139.04679 | BI7: 138.1083 | BJ7: 137.50451 | BK7: 137.78221 | BL7: 138.57059 | BM7: 138.68376 | BN7: 137.45974 | BO7: 139.54324 | BP7: 139.78155 | BQ7: 141.04074 | BR7: 141.21113 | BS7: 141.25559 | BT7: 141.99669 | BU7: 141.87833 | BV7: 141.99392 | BW7: 143.66893 | BX7: 142.07679
A8: LTV | B8: 1.9087244 | C8: 1.902091 | D8: 1.9108901 | E8: 1.9482277 | F8: 1.9743248 | G8: 1.9082235 | H8: 1.856177 | I8: 2.0421645 | J8: 1.9635875 | K8: 1.8734483 | L8: 1.7480386 | M8: 1.6307556 | N8: 1.6161995 | O8: 1.627103 | P8: 1.6162566 | Q8: 1.7297385 | R8: 1.7569392 | S8: 1.7395328 | T8: 1.6369949 | U8: 1.5676004 | V8: 1.4987905 | W8: 1.465296 | X8: 1.5741537 | Y8: 1.5370213 | Z8: 1.6529071 | AA8: 1.573601 | AB8: 1.5776981 | AC8: 1.5967355 | AD8: 1.6223278 | AE8: 1.5998584 | AF8: 1.624587 | AG8: 1.6364888 | AH8: 2.0755362 | AI8: 2.2403166 | AJ8: 1.676993 | AK8: 1.7609987 | AL8: 1.8527636 | AM8: 1.5283483 | AN8: 1.9048561 | AO8: 2.0039267 | AP8: 1.8622775 | AQ8: 1.9348544 | AR8: 1.6267681 | AS8: 5.1897588 | AT8: 2.3546434 | AU8: 1.5797646 | AV8: 1.8767694 | AW8: 1.6518024 | AX8: 1.8714843 | AY8: 1.9250555 | AZ8: 1.8325892 | BA8: 1.7607486 | BB8: 1.697528 | BC8: 1.7896662 | BD8: 1.6368387 | BE8: 1.5935566 | BF8: 1.5326083 | BG8: 1.7243401 | BH8: 1.5915305 | BI8: 1.6797055 | BJ8: 1.6056774 | BK8: 1.6168399 | BL8: 1.5025317 | BM8: 1.5982709 | BN8: 1.6194769 | BO8: 1.5877404 | BP8: 1.5365227 | BQ8: 1.5535723 | BR8: 1.5932123 | BS8: 1.5539282 | BT8: 1.5224133 | BU8: 1.5716474 | BV8: 1.6168236 | BW8: 1.5274442 | BX8: 1.5637771
A10: FLD | B10: 2016 | C10: 2017 | D10: 2018 | E10: 2019 | F10: 2020 M01 | G10: 2020 M02 | H10: 2020 M03 | I10: 2020 M04 | J10: 2020 M05 | K10: 2020 M06 | L10: 2020 M07 | M10: 2020 M08 | N10: 2020 M09 | O10: 2020 M10 | P10: 2020 M11 | Q10: 2020 M12 | R10: 2021 M01 | S10: 2021 M02 | T10: 2021 M03 | U10: 2021 M04 | V10: 2021 M05 | W10: 2021 M06 | X10: 2021 M07 | Y10: 2021 M08 | Z10: 2021 M09 | AA10: 2021 M10 | AB10: 2021 M11 | AC10: 2021 M12 | AD10: 2022 M01 | AE10: 2022 M02 | AF10: 2022 M03 | AG10: 2022 M04 | AH10: 2022 M05 | AI10: 2022 M06 | AJ10: 2022 M07 | AK10: 2022 M08 | AL10: 2022 M09 | AM10: 2022 M10 | AN10: 2022 M11 | AO10: 2022 M12 | AP10: 2023 M01 | AQ10: 2023 M02 | AR10: 2023 M03 | AS10: 2023 M04 | AT10: 2023 M05 | AU10: 2023 M06 | AV10: 2023 M07 | AW10: 2023 M08 | AX10: 2023 M09 | AY10: 2023 M10 | AZ10: 2023 M11 | BA10: 2023 M12 | BB10: 2024 M01 | BC10: 2024 M02 | BD10: 2024 M03 | BE10: 2024 M04 | BF10: 2024 M05 | BG10: 2024 M06 | BH10: 2024 M07 | BI10: 2024 M08 | BJ10: 2024 M09 | BK10: 2024 M10 | BL10: 2024 M11 | BM10: 2024 M12 | BN10: 2025 M01 | BO10: 2025 M02 | BP10: 2025 M03 | BQ10: 2025 M04 | BR10: 2025 M05 | BS10: 2025 M06 | BT10: 2025 M07 | BU10: 2025 M08 | BV10: 2025 M09 | BW10: 2025 M10 | BX10: 2025 M11 | BY10: 2025 M12 | BZ10: 2026 M01
A11: Contract Model Score | F11: 131.69826 | G11: 133.05465 | H11: 131.44449 | I11: 132.48641 | J11: 135.78589 | K11: 137.67459 | L11: 137.63211 | M11: 137.41028 | N11: 138.50084 | O11: 138.38307 | P11: 141.10563 | Q11: 142.82581 | R11: 139.61141 | S11: 137.15928 | T11: 135.9438 | U11: 136.43445 | V11: 136.59572 | W11: 135.44515 | X11: 134.80733 | Y11: 136.84616 | Z11: 135.30382 | AA11: 135.50762 | AB11: 134.08635 | AC11: 134.22879 | AD11: 134.31941 | AE11: 133.67712 | AF11: 134.40763 | AG11: 135.82593 | AH11: 135.4639 | AI11: 136.28085 | AJ11: 136.94589 | AK11: 136.9564 | AL11: 136.99007 | AM11: 136.88364 | AN11: 139.40723 | AO11: 140.81079 | AP11: 141.68261 | AQ11: 142.38723 | AR11: 139.72135 | AS11: 139.3661 | AT11: 137.91442 | AU11: 137.55925 | AV11: 137.86885 | AW11: 139.26533 | AX11: 139.00234 | AY11: 138.84908 | AZ11: 138.16068 | BA11: 138.56896 | BB11: 138.04076 | BC11: 138.62568 | BD11: 139.01469 | BE11: 140.94279 | BF11: 141.91136 | BG11: 140.46816 | BH11: 137.69296 | BI11: 137.35406 | BJ11: 136.42157 | BK11: 136.41165 | BL11: 137.00481 | BM11: 138.24833 | BN11: 138.66846 | BO11: 138.12845 | BP11: 138.59134 | BQ11: 137.62711 | BR11: 138.14099 | BS11: 137.97814 | BT11: 138.55363 | BU11: 140.497 | BV11: 140.95712 | BW11: 140.53336 | BX11: 138.47342 | BY11: 139.44975 | BZ11: 139.906 | CA11: 140.27371
A12: Model Score | F12: 0 | G12: 0 | H12: 0 | I12: 0 | J12: 0 | K12: 0 | L12: 0 | M12: 0 | N12: 0 | O12: 0 | P12: 0 | Q12: 0 | R12: 0 | S12: 0 | T12: 0 | U12: 0 | V12: 0 | W12: 0 | X12: 0 | Y12: 0 | Z12: 0 | AA12: 0 | AB12: 0 | AC12: 0 | AD12: 0 | AE12: 0 | AF12: 0 | AG12: 0 | AH12: 0 | AI12: 0 | AJ12: 0 | AK12: 0 | AL12: 0 | AM12: 0 | AN12: 0 | AO12: 0 | AP12: 0 | AQ12: 0 | AR12: 0 | AS12: 0 | AT12: 0 | AU12: 0 | AV12: 0 | AW12: 0 | AX12: 0 | AY12: 0 | AZ12: 0 | BA12: 0 | BB12: 0 | BC12: 0 | BD12: 0 | BE12: 0 | BF12: 0 | BG12: 0 | BH12: 0 | BI12: 0 | BJ12: 0 | BK12: 0 | BL12: 0 | BM12: 0 | BN12: 0 | BO12: 0 | BP12: 0 | BQ12: 0 | BR12: 0 | BS12: 0 | BT12: 0 | BU12: 0 | BV12: 0
A13: Gross Loss Adjustments (Dealer level, high PTI, etc.) | F13: -1.7373722 | G13: -1.7682932 | H13: -1.6529277 | I13: -1.3030934 | J13: -1.0779784 | K13: -1.6965029 | L13: -0.75865575 | M13: -0.81339298 | N13: -0.8738907 | O13: -0.1282815 | P13: 1.1625912 | Q13: 1.4586807 | R13: 1.7413121 | S13: 1.7447552 | T13: 1.8633974 | U13: 0.01567843 | V13: 0.1746438 | W13: -0.98139609 | X13: -0.75002454 | Y13: 0.035125271 | Z13: -0.37976676 | AA13: 0.83082329 | AB13: 1.0277881 | AC13: 0.30039834 | AD13: -0.24235921 | AE13: 1.1461668 | AF13: 0.50274448 | AG13: 1.3914212 | AH13: -2.7876062 | AI13: 1.598522 | AJ13: -1.6446668 | AK13: 1.8056091 | AL13: 2.8774126 | AM13: 2.7745654 | AN13: 3.829454 | AO13: 4.0233398 | AP13: 1.4636107 | AQ13: 3.0169226 | AR13: 7.434023 | AS13: 3.2980094 | AT13: 0.86624726 | AU13: 0.13328613 | AV13: 2.7758939 | AW13: 0.43246278 | AX13: 1.7243706 | AY13: 2.2109081 | AZ13: 3.0459566 | BA13: 3.1397674 | BB13: 2.6673478 | BC13: 3.3425122 | BD13: 3.7915011 | BE13: 4.0317794 | BF13: 4.4562698 | BG13: 3.3965137 | BH13: 3.2409935 | BI13: 2.7337418 | BJ13: 2.3621841 | BK13: 2.5799921 | BL13: 2.1403075 | BM13: 1.8790669 | BN13: 2.8567136 | BO13: 3.2222441 | BP13: 2.8667787 | BQ13: 2.9253432 | BR13: 2.962984 | BS13: 1.6061097 | BT13: 1.3448314 | BU13: 1.4541099 | BV13: 1.2513006
A14: Recovery Adjustments excluding LTV (Mileage, vehicle type, etc.) | F14: 0.35942655 | G14: -0.050127184 | H14: -0.3137726 | I14: -0.50408555 | J14: -0.22432408 | K14: -0.49510039 | L14: -0.55419498 | M14: 0.32762561 | N14: 0.40507979 | O14: 0.076148375 | P14: 0.79886416 | Q14: 1.3534816 | R14: 0.27780611 | S14: -0.57126316 | T14: -0.34752137 | U14: 0.13841611 | V14: 0.016224391 | W14: 0.75700717 | X14: 0.43477555 | Y14: -0.094845458 | Z14: -0.15566479 | AA14: -1.0170333 | AB14: -0.44847924 | AC14: -0.89548706 | AD14: -1.1297844 | AE14: -1.5451233 | AF14: -1.5978422 | AG14: -1.9049101 | AH14: -0.31753543 | AI14: -1.4514564 | AJ14: -1.2506444 | AK14: -2.9904916 | AL14: -3.9118968 | AM14: -3.5947953 | AN14: -1.7457099 | AO14: -3.9333088 | AP14: -4.3545049 | AQ14: 0.22438971 | AR14: -5.6767479 | AS14: -2.468277 | AT14: -1.7091528 | AU14: -1.2407166 | AV14: 1.6085841 | AW14: 0.75525786 | AX14: -2.0174631 | AY14: -1.6035247 | AZ14: -1.4915808 | BA14: -2.0271994 | BB14: -0.63790238 | BC14: -1.5258409 | BD14: -0.39595406 | BE14: -1.5189043 | BF14: 0.01851038 | BG14: 0.41494536 | BH14: -1.2281996 | BI14: 2.1886028 | BJ14: 0.18756286 | BK14: 0.33515863 | BL14: -0.78005684 | BM14: 0.48911342 | BN14: 0.42784479 | BO14: -0.53193379 | BP14: 0.74093627 | BQ14: 0.06371616 | BR14: -0.41171436 | BS14: 1.4761491 | BT14: 0.0031092168 | BU14: 2.101889 | BV14: 2.2212356
A15: LTV Adjustments | F15: -0.35942655 | G15: 0.050127184 | H15: 0.3137726 | I15: 0.50408555 | J15: 0.22432408 | K15: 0.49510039 | L15: 0.55419498 | M15: -0.32762561 | N15: -0.40507979 | O15: -0.076148375 | P15: -0.79886416 | Q15: -1.3534816 | R15: -0.27780611 | S15: 0.57126316 | T15: 0.34752137 | U15: -0.13841611 | V15: -0.016224391 | W15: -0.75700717 | X15: -0.43477555 | Y15: 0.094845458 | Z15: 0.15566479 | AA15: 1.0170333 | AB15: 0.44847924 | AC15: 0.89548706 | AD15: 1.1297844 | AE15: 1.5451233 | AF15: 1.5978422 | AG15: 1.9049101 | AH15: 0.31753543 | AI15: 1.4514564 | AJ15: 1.2506444 | AK15: 2.9904916 | AL15: 3.9118968 | AM15: 3.5947953 | AN15: 1.7457099 | AO15: 3.9333088 | AP15: 4.3545049 | AQ15: -0.22438971 | AR15: 5.6767479 | AS15: 2.468277 | AT15: 1.7091528 | AU15: 1.2407166 | AV15: -1.6085841 | AW15: -0.75525786 | AX15: 2.0174631 | AY15: 1.6035247 | AZ15: 1.4915808 | BA15: 2.0271994 | BB15: 0.63790238 | BC15: 1.5258409 | BD15: 0.39595406 | BE15: 1.5189043 | BF15: -0.01851038 | BG15: -0.41494536 | BH15: 1.2281996 | BI15: -2.1886028 | BJ15: -0.18756286 | BK15: -0.33515863 | BL15: 0.78005684 | BM15: -0.48911342 | BN15: -0.42784479 | BO15: 0.53193379 | BP15: -0.74093627 | BQ15: -0.06371616 | BR15: 0.41171436 | BS15: -1.4761491 | BT15: -0.0031092168 | BU15: -2.101889 | BV15: -2.2212356
A16: RAGU Score | F16: 129.96089 | G16: 131.28636 | H16: 129.79156 | I16: 131.18332 | J16: 134.70791 | K16: 135.97809 | L16: 136.87346 | M16: 136.59689 | N16: 137.62695 | O16: 138.25479 | P16: 142.26822 | Q16: 144.28449 | R16: 141.35272 | S16: 138.90403 | T16: 137.8072 | U16: 136.45013 | V16: 136.77037 | W16: 134.46376 | X16: 134.0573 | Y16: 136.88128 | Z16: 134.92405 | AA16: 136.33845 | AB16: 135.11413 | AC16: 134.52919 | AD16: 134.07705 | AE16: 134.82328 | AF16: 134.91037 | AG16: 137.21735 | AH16: 132.67629 | AI16: 137.87937 | AJ16: 135.30122 | AK16: 138.76201 | AL16: 139.86749 | AM16: 139.65821 | AN16: 143.23669 | AO16: 144.83413 | AP16: 143.14622 | AQ16: 145.40416 | AR16: 147.15538 | AS16: 142.6641 | AT16: 138.78066 | AU16: 137.69253 | AV16: 140.64475 | AW16: 139.6978 | AX16: 140.72671 | AY16: 141.05999 | AZ16: 141.20663 | BA16: 141.70872 | BB16: 140.7081 | BC16: 141.9682 | BD16: 142.80619 | BE16: 144.97457 | BF16: 146.36763 | BG16: 143.86467 | BH16: 140.93395 | BI16: 140.08781 | BJ16: 138.78376 | BK16: 138.99164 | BL16: 139.14512 | BM16: 140.12739 | BN16: 141.52517 | BO16: 141.3507 | BP16: 141.45812 | BQ16: 140.55246 | BR16: 141.10398 | BS16: 139.58425 | BT16: 139.89846 | BU16: 141.95111 | BV16: 142.20842
A17: LTV | F17: 1.4633833 | G17: 1.4328789 | H17: 1.3835412 | I17: 1.3987303 | J17: 1.3782717 | K17: 1.3524544 | L17: 1.2508309 | M17: 1.21004 | N17: 1.1957329 | O17: 1.2530861 | P17: 1.3173324 | Q17: 1.2499791 | R17: 1.3737717 | S17: 1.3001825 | T17: 1.3285323 | U17: 1.2297302 | V17: 1.2119803 | W17: 1.2606704 | X17: 1.246185 | Y17: 1.2991607 | Z17: 1.2768913 | AA17: 1.3598356 | AB17: 1.321942 | AC17: 1.3166955 | AD17: 1.3759183 | AE17: 1.3415726 | AF17: 1.3186163 | AG17: 1.3312274 | AH17: 1.3375786 | AI17: 1.3787396 | AJ17: 1.3692844 | AK17: 1.3280318 | AL17: 1.6929744 | AM17: 1.4141001 | AN17: 1.4592922 | AO17: 1.2674946 | AP17: 1.0157032 | AQ17: 1.2871118 | AR17: 1.4262285 | AS17: 1.3644385 | AT17: 1.2197282 | AU17: 1.3848582 | AV17: 1.4189847 | AW17: 1.3149134 | AX17: 1.3392866 | AY17: 1.3450408 | AZ17: 1.3709559 | BA17: 1.4149511 | BB17: 1.3246312 | BC17: 1.3784484 | BD17: 1.3175541 | BE17: 1.3235298 | BF17: 1.3460769 | BG17: 1.2261802 | BH17: 1.3539596 | BI17: 1.3451356 | BJ17: 1.3387531 | BK17: 1.3910422 | BL17: 1.3702807 | BM17: 1.4432888 | BN17: 1.386518 | BO17: 1.4267052 | BP17: 1.3679674 | BQ17: 1.4169798 | BR17: 1.4090583 | BS17: 1.3528876 | BT17: 1.379123 | BU17: 1.3880331 | BV17: 1.479477
A19: FRN | B19: 2016 | C19: 2017 | D19: 2018 | E19: 2019 | F19: 2020 M01 | G19: 2020 M02 | H19: 2020 M03 | I19: 2020 M04 | J19: 2020 M05 | K19: 2020 M06 | L19: 2020 M07 | M19: 2020 M08 | N19: 2020 M09 | O19: 2020 M10 | P19: 2020 M11 | Q19: 2020 M12 | R19: 2021 M01 | S19: 2021 M02 | T19: 2021 M03 | U19: 2021 M04 | V19: 2021 M05 | W19: 2021 M06 | X19: 2021 M07 | Y19: 2021 M08 | Z19: 2021 M09 | AA19: 2021 M10 | AB19: 2021 M11 | AC19: 2021 M12 | AD19: 2022 M01 | AE19: 2022 M02 | AF19: 2022 M03 | AG19: 2022 M04 | AH19: 2022 M05 | AI19: 2022 M06 | AJ19: 2022 M07 | AK19: 2022 M08 | AL19: 2022 M09 | AM19: 2022 M10 | AN19: 2022 M11 | AO19: 2022 M12 | AP19: 2023 M01 | AQ19: 2023 M02 | AR19: 2023 M03 | AS19: 2023 M04 | AT19: 2023 M05 | AU19: 2023 M06 | AV19: 2023 M07 | AW19: 2023 M08 | AX19: 2023 M09 | AY19: 2023 M10 | AZ19: 2023 M11 | BA19: 2023 M12 | BB19: 2024 M01 | BC19: 2024 M02 | BD19: 2024 M03 | BE19: 2024 M04 | BF19: 2024 M05 | BG19: 2024 M06 | BH19: 2024 M07 | BI19: 2024 M08 | BJ19: 2024 M09 | BK19: 2024 M10 | BL19: 2024 M11 | BM19: 2024 M12 | BN19: 2025 M01 | BO19: 2025 M02 | BP19: 2025 M03 | BQ19: 2025 M04 | BR19: 2025 M05 | BS19: 2025 M06 | BT19: 2025 M07 | BU19: 2025 M08 | BV19: 2025 M09 | BW19: 2025 M10 | BX19: 2025 M11 | BY19: 2025 M12 | BZ19: 2026 M01
A20: Contract Model Score | B20: 131.18489 | C20: 136.72146 | D20: 136.81942 | E20: 132.54318 | F20: 131.2656 | G20: 131.24734 | H20: 131.00099 | I20: 131.49953 | J20: 133.24754 | K20: 133.3984 | L20: 134.41536 | M20: 134.0819 | N20: 133.20621 | O20: 132.62511 | P20: 131.11674 | Q20: 135.00101 | R20: 135.45485 | S20: 135.55568 | T20: 135.39896 | U20: 135.35416 | V20: 135.51119 | W20: 134.67649 | X20: 134.23647 | Y20: 135.97528 | Z20: 134.5695 | AA20: 134.42803 | AB20: 132.01635 | AC20: 132.29985 | AD20: 134.01481 | AE20: 133.66105 | AF20: 134.31365 | AG20: 135.70242 | AH20: 137.3415 | AI20: 137.64811 | AJ20: 138.18701 | AK20: 137.99667 | AL20: 137.85245 | AM20: 138.34232 | AN20: 140.94633 | AO20: 141.0318 | AP20: 141.07216 | AQ20: 141.68378 | AR20: 141.17134 | AS20: 140.558 | AT20: 140.54313 | AU20: 140.65163 | AV20: 139.52303 | AW20: 141.17927 | AX20: 141.16169 | AY20: 138.66844 | AZ20: 139.04265 | BA20: 138.51156 | BB20: 137.58847 | BC20: 139.37221 | BD20: 140.53108 | BE20: 140.72018 | BF20: 141.1387 | BG20: 141.99905 | BH20: 141.69762 | BI20: 140.62793 | BJ20: 139.96452 | BK20: 139.29146 | BL20: 139.70528 | BM20: 140.12303 | BN20: 139.74747 | BO20: 140.31399 | BP20: 140.88037 | BQ20: 140.75094 | BR20: 140.87437 | BS20: 140.73303 | BT20: 141.33269 | BU20: 141.69552 | BV20: 141.57111 | BW20: 142.27606 | BX20: 142.85904 | BY20: 140.12829 | BZ20: 138.55401 | CA20: 144.29157
A21: Model Score | B21: 0 | C21: 0 | D21: 0 | E21: 0 | F21: 0 | G21: 0 | H21: 0 | I21: 0 | J21: 0 | K21: 0 | L21: 0 | M21: 0 | N21: 0 | O21: 0 | P21: 0 | Q21: 0 | R21: 0 | S21: 0 | T21: 0 | U21: 0 | V21: 0 | W21: 0 | X21: 0 | Y21: 0 | Z21: 0 | AA21: 0 | AB21: 0 | AC21: 0 | AD21: 0 | AE21: 0 | AF21: 0 | AG21: 0 | AH21: 0 | AI21: 0 | AJ21: 0 | AK21: 0 | AL21: 0 | AM21: 0 | AN21: 0 | AO21: 0 | AP21: 0 | AQ21: 0 | AR21: 0 | AS21: 0 | AT21: 0 | AU21: 0 | AV21: 0 | AW21: 0 | AX21: 0 | AY21: 0 | AZ21: 0 | BA21: 0 | BB21: 0 | BC21: 0 | BD21: 0 | BE21: 0 | BF21: 0 | BG21: 0 | BH21: 0 | BI21: 0 | BJ21: 0 | BK21: 0 | BL21: 0 | BM21: 0 | BN21: 0 | BO21: 0 | BP21: 0 | BQ21: 0 | BR21: 0 | BS21: 0 | BT21: 0 | BU21: 0 | BV21: 0 | BW21: 0 | BX21: 0
A22: Gross Loss Adjustments (Dealer level, high PTI, etc.) | B22: -0.040003629 | C22: 0.57455492 | D22: 0.12243283 | E22: 0.78145362 | F22: 1.0141222 | G22: 1.4974347 | H22: 1.3924236 | I22: 1.590529 | J22: 1.691881 | K22: 1.3546638 | L22: 0.69064984 | M22: 0.57792768 | N22: 0.40205567 | O22: -0.19286348 | P22: -0.10964835 | Q22: 0.41701637 | R22: 0.29982442 | S22: 0.61940318 | T22: 0.60974748 | U22: 0.92003369 | V22: 0.98576779 | W22: 0.81739563 | X22: 0.65110737 | Y22: 0.76217447 | Z22: 0.67788991 | AA22: -0.27169981 | AB22: -0.356482 | AC22: -0.4689839 | AD22: -0.39979835 | AE22: -0.13521444 | AF22: -0.22183017 | AG22: 0.31944825 | AH22: 0.83388804 | AI22: 0.20709188 | AJ22: 0.26214958 | AK22: 0.95535432 | AL22: 0.26495611 | AM22: -1.1940459 | AN22: 0.94115709 | AO22: -1.1316226 | AP22: 0.93065374 | AQ22: 1.2148198 | AR22: 0.13674895 | AS22: -4.8428543 | AT22: 1.9101684 | AU22: 0.64726212 | AV22: 0.35689769 | AW22: 1.6365111 | AX22: -10 | AY22: -0.37965143 | AZ22: 0.17374082 | BA22: -0.6742371 | BB22: -0.37827903 | BC22: -0.028685022 | BD22: 0.55645953 | BE22: 0.09334272 | BF22: 0.25847951 | BG22: 0.64105215 | BH22: 0.52224182 | BI22: 1.1068606 | BJ22: 1.2512509 | BK22: 0.38033277 | BL22: 1.2882127 | BM22: 0.87304419 | BN22: 1.150892 | BO22: 1.302778 | BP22: 1.0747574 | BQ22: 1.8494632 | BR22: 1.6609088 | BS22: 1.5637332 | BT22: 2.1808531 | BU22: 2.9565227 | BV22: 3.316971 | BW22: 3.3633397 | BX22: 2.9825787
A23: Recovery Adjustments excluding LTV (Mileage, vehicle type, etc.) | B23: -0.44541836 | C23: 0.12151064 | D23: 0.12296463 | E23: -0.057485299 | F23: 0.86506221 | G23: 0.10089329 | H23: -0.40811267 | I23: -0.67737006 | J23: -0.1305448 | K23: -0.063980348 | L23: -0.29674852 | M23: -0.10384621 | N23: 0.14516574 | O23: 0.42438675 | P23: 0.15679778 | Q23: 0.70906288 | R23: 0.47152535 | S23: 0.36785036 | T23: 0.014881875 | U23: 0.31021904 | V23: 0.0079610051 | W23: -0.039474092 | X23: -0.37581342 | Y23: -0.40622575 | Z23: 0.1274192 | AA23: -0.35901536 | AB23: -0.70516925 | AC23: -0.31337673 | AD23: -0.97839603 | AE23: -0.89376823 | AF23: -1.5615412 | AG23: -1.1364871 | AH23: -2.1854589 | AI23: -2.3483223 | AJ23: -2.3383244 | AK23: -1.0929416 | AL23: -1.6651902 | AM23: 0.43487244 | AN23: -2.2542992 | AO23: -2.4107561 | AP23: 3.4819326 | AQ23: -3.1947126 | AR23: -1.6107774 | AS23: -3.6141104 | AT23: -2.1836762 | AU23: -0.94480217 | AV23: -4.6985486 | AW23: 0.7237003 | AX23: -4.4417319 | AY23: -1.7956886 | AZ23: -1.3072352 | BA23: -1.058562 | BB23: -1.7295122 | BC23: -1.4207238 | BD23: -0.97784348 | BE23: -1.7394157 | BF23: -0.69469879 | BG23: -0.76222417 | BH23: -0.77282432 | BI23: -0.93159796 | BJ23: 0.18195619 | BK23: 1.2602126 | BL23: 0.42315465 | BM23: 0.60791971 | BN23: 0.18218872 | BO23: 0.16518629 | BP23: 0.12935852 | BQ23: 0.16239567 | BR23: 0.14105996 | BS23: 0.2368658 | BT23: 1.4025926 | BU23: 1.187159 | BV23: 1.973283 | BW23: 2.4277931 | BX23: 2.9544591
A24: LTV Adjustments | B24: 0.44541836 | C24: -0.12151064 | D24: -0.12296463 | E24: 0.057485299 | F24: -0.86506221 | G24: -0.10089329 | H24: 0.40811267 | I24: 0.67737006 | J24: 0.1305448 | K24: 0.063980348 | L24: 0.29674852 | M24: 0.10384621 | N24: -0.14516574 | O24: -0.42438675 | P24: -0.15679778 | Q24: -0.70906288 | R24: -0.47152535 | S24: -0.36785036 | T24: -0.014881875 | U24: -0.31021904 | V24: -0.0079610051 | W24: 0.039474092 | X24: 0.37581342 | Y24: 0.40622575 | Z24: -0.1274192 | AA24: 0.35901536 | AB24: 0.70516925 | AC24: 0.31337673 | AD24: 0.97839603 | AE24: 0.89376823 | AF24: 1.5615412 | AG24: 1.1364871 | AH24: 2.1854589 | AI24: 2.3483223 | AJ24: 2.3383244 | AK24: 1.0929416 | AL24: 1.6651902 | AM24: -0.43487244 | AN24: 2.2542992 | AO24: 2.4107561 | AP24: -3.4819326 | AQ24: 3.1947126 | AR24: 1.6107774 | AS24: 3.6141104 | AT24: 2.1836762 | AU24: 0.94480217 | AV24: 4.6985486 | AW24: -0.7237003 | AX24: 4.4417319 | AY24: 1.7956886 | AZ24: 1.3072352 | BA24: 1.058562 | BB24: 1.7295122 | BC24: 1.4207238 | BD24: 0.97784348 | BE24: 1.7394157 | BF24: 0.69469879 | BG24: 0.76222417 | BH24: 0.77282432 | BI24: 0.93159796 | BJ24: -0.18195619 | BK24: -1.2602126 | BL24: -0.42315465 | BM24: -0.60791971 | BN24: -0.18218872 | BO24: -0.16518629 | BP24: -0.12935852 | BQ24: -0.16239567 | BR24: -0.14105996 | BS24: -0.2368658 | BT24: -1.4025926 | BU24: -1.187159 | BV24: -1.973283 | BW24: -2.4277931 | BX24: -2.9544591
A25: RAGU Score | B25: 131.14489 | C25: 137.29602 | D25: 136.94185 | E25: 133.32463 | F25: 132.27972 | G25: 132.74477 | H25: 132.39342 | I25: 133.09006 | J25: 134.93942 | K25: 134.75307 | L25: 135.10601 | M25: 134.65982 | N25: 133.60826 | O25: 132.43225 | P25: 131.0071 | Q25: 135.41802 | R25: 135.75467 | S25: 136.17509 | T25: 136.00871 | U25: 136.2742 | V25: 136.49696 | W25: 135.49389 | X25: 134.88758 | Y25: 136.73745 | Z25: 135.24739 | AA25: 134.15633 | AB25: 131.65987 | AC25: 131.83087 | AD25: 133.61502 | AE25: 133.52583 | AF25: 134.09182 | AG25: 136.02187 | AH25: 138.17539 | AI25: 137.8552 | AJ25: 138.44916 | AK25: 138.95202 | AL25: 138.11741 | AM25: 137.14827 | AN25: 141.88749 | AO25: 139.90017 | AP25: 142.00282 | AQ25: 142.8986 | AR25: 141.30808 | AS25: 135.71514 | AT25: 142.4533 | AU25: 141.2989 | AV25: 139.87993 | AW25: 142.81578 | AX25: 131.16169 | AY25: 138.28879 | AZ25: 139.21639 | BA25: 137.83732 | BB25: 137.21019 | BC25: 139.34352 | BD25: 141.08754 | BE25: 140.81352 | BF25: 141.39718 | BG25: 142.6401 | BH25: 142.21986 | BI25: 141.73479 | BJ25: 141.21578 | BK25: 139.67179 | BL25: 140.99349 | BM25: 140.99608 | BN25: 140.89836 | BO25: 141.61677 | BP25: 141.95512 | BQ25: 142.60041 | BR25: 142.53527 | BS25: 142.29677 | BT25: 143.51354 | BU25: 144.65205 | BV25: 144.88808 | BW25: 145.6394 | BX25: 145.84162
A26: LTV | B26: 2.1505528 | C26: 2.2073907 | D26: 2.1097029 | E26: 2.0875659 | F26: 2.0194091 | G26: 1.9185204 | H26: 1.9174761 | I26: 1.8742113 | J26: 2.0008174 | K26: 1.9375934 | L26: 1.8533141 | M26: 1.9186936 | N26: 1.9383992 | O26: 2.0427444 | P26: 2.1737347 | Q26: 1.8361932 | R26: 1.8609857 | S26: 1.7791028 | T26: 1.6618226 | U26: 1.5595819 | V26: 1.4615419 | W26: 1.5105506 | X26: 1.5517052 | Y26: 1.610812 | Z26: 1.695937 | AA26: 1.67477 | AB26: 1.6795947 | AC26: 1.7077679 | AD26: 1.6418182 | AE26: 1.6727076 | AF26: 1.655978 | AG26: 1.668858 | AH26: 1.7857036 | AI26: 1.6580934 | AJ26: 1.8637755 | AK26: 2.031157 | AL26: 1.6469266 | AM26: 1.666092 | AN26: 1.6759706 | AO26: 1.4921203 | AP26: 2.0740089 | AQ26: 1.3264035 | AR26: 1.9014931 | AS26: 3.0445155 | AT26: 1.9726026 | AU26: 1.554958 | AV26: 1.8467201 | AW26: 1.6511792 | AX26: 1.3457691 | AY26: 1.5262134 | AZ26: 1.5082192 | BA26: 1.4602687 | BB26: 1.4884281 | BC26: 1.4865341 | BD26: 1.5047788 | BE26: 1.4756972 | BF26: 1.4997432 | BG26: 1.5363732 | BH26: 1.4876361 | BI26: 1.5637789 | BJ26: 1.4645949 | BK26: 1.4505847 | BL26: 1.464124 | BM26: 1.4538271 | BN26: 1.4686109 | BO26: 1.4434687 | BP26: 1.3840699 | BQ26: 1.3761983 | BR26: 1.4057748 | BS26: 1.3921124 | BT26: 1.3984415 | BU26: 1.3543769 | BV26: 1.3899383 | BW26: 1.4384254 | BX26: 1.4802729
A28: STG | B28: 2016 | C28: 2017 | D28: 2018 | E28: 2019 | F28: 2020 M01 | G28: 2020 M02 | H28: 2020 M03 | I28: 2020 M04 | J28: 2020 M05 | K28: 2020 M06 | L28: 2020 M07 | M28: 2020 M08 | N28: 2020 M09 | O28: 2020 M10 | P28: 2020 M11 | Q28: 2020 M12 | R28: 2021 M01 | S28: 2021 M02 | T28: 2021 M03 | U28: 2021 M04 | V28: 2021 M05 | W28: 2021 M06 | X28: 2021 M07 | Y28: 2021 M08 | Z28: 2021 M09 | AA28: 2021 M10 | AB28: 2021 M11 | AC28: 2021 M12 | AD28: 2022 M01 | AE28: 2022 M02 | AF28: 2022 M03 | AG28: 2022 M04 | AH28: 2022 M05 | AI28: 2022 M06 | AJ28: 2022 M07 | AK28: 2022 M08 | AL28: 2022 M09 | AM28: 2022 M10 | AN28: 2022 M11 | AO28: 2022 M12 | AP28: 2023 M01 | AQ28: 2023 M02 | AR28: 2023 M03 | AS28: 2023 M04 | AT28: 2023 M05 | AU28: 2023 M06 | AV28: 2023 M07 | AW28: 2023 M08 | AX28: 2023 M09 | AY28: 2023 M10 | AZ28: 2023 M11 | BA28: 2023 M12 | BB28: 2024 M01 | BC28: 2024 M02 | BD28: 2024 M03 | BE28: 2024 M04 | BF28: 2024 M05 | BG28: 2024 M06 | BH28: 2024 M07 | BI28: 2024 M08 | BJ28: 2024 M09 | BK28: 2024 M10 | BL28: 2024 M11 | BM28: 2024 M12 | BN28: 2025 M01 | BO28: 2025 M02 | BP28: 2025 M03 | BQ28: 2025 M04 | BR28: 2025 M05 | BS28: 2025 M06 | BT28: 2025 M07 | BU28: 2025 M08 | BV28: 2025 M09 | BW28: 2025 M10 | BX28: 2025 M11 | BY28: 2025 M12 | BZ28: 2026 M01
A29: Contract Model Score | B29: 129.63955 | C29: 131.6541 | D29: 131.56964 | E29: 129.50608 | F29: 129.78439 | G29: 130.3194 | H29: 130.01813 | I29: 130.28186 | J29: 133.55242 | K29: 134.9074 | L29: 135.24459 | M29: 135.85773 | N29: 135.50069 | O29: 135.75132 | P29: 135.13958 | Q29: 134.89594 | R29: 135.56415 | S29: 135.05332 | T29: 135.26623 | U29: 135.39571 | V29: 135.36165 | W29: 135.74131 | X29: 135.03843 | Y29: 135.73405 | Z29: 134.33915 | AA29: 134.68261 | AB29: 132.94521 | AC29: 133.34441 | AD29: 134.2864 | AE29: 134.70284 | AF29: 134.6113 | AG29: 136.26908 | AH29: 136.73318 | AI29: 137.23263 | AJ29: 136.95716 | AK29: 137.63345 | AL29: 137.23928 | AM29: 137.73629 | AN29: 139.05852 | AO29: 138.44604 | AP29: 139.96787 | AQ29: 138.75376 | AR29: 139.11148 | AS29: 137.41883 | AT29: 138.17301 | AU29: 137.51063 | AV29: 137.68289 | AW29: 138.42609 | AX29: 139.23481 | AY29: 136.90455 | AZ29: 137.3486 | BA29: 136.85059 | BB29: 136.43852 | BC29: 137.16962 | BD29: 137.44545 | BE29: 137.85018 | BF29: 138.12378 | BG29: 138.88324 | BH29: 138.78355 | BI29: 137.96917 | BJ29: 136.82707 | BK29: 136.74566 | BL29: 136.75775 | BM29: 136.52401 | BN29: 136.69779 | BO29: 137.49793 | BP29: 137.93118 | BQ29: 138.5378 | BR29: 138.60141 | BS29: 138.34121 | BT29: 139.08055 | BU29: 139.19216 | BV29: 139.60755 | BW29: 141.45995 | BX29: 141.64596 | BY29: 138.36256 | BZ29: 137.34161 | CA29: 141.01662
A30: Model Score | B30: 0 | C30: 0 | D30: 0 | E30: 0 | F30: 0 | G30: 0 | H30: 0 | I30: 0 | J30: 0 | K30: 0 | L30: 0 | M30: 0 | N30: 0 | O30: 0 | P30: 0 | Q30: 0 | R30: 0 | S30: 0 | T30: 0 | U30: 0 | V30: 0 | W30: 0 | X30: 0 | Y30: 0 | Z30: 0 | AA30: 0 | AB30: 0 | AC30: 0 | AD30: 0 | AE30: 0 | AF30: 0 | AG30: 0 | AH30: 0 | AI30: 0 | AJ30: 0 | AK30: 0 | AL30: 0 | AM30: 0 | AN30: 0 | AO30: 0 | AP30: 0 | AQ30: 0 | AR30: 0 | AS30: 0 | AT30: 0 | AU30: 0 | AV30: 0 | AW30: 0 | AX30: 0 | AY30: 0 | AZ30: 0 | BA30: 0 | BB30: 0 | BC30: 0 | BD30: 0 | BE30: 0 | BF30: 0 | BG30: 0 | BH30: 0 | BI30: 0 | BJ30: 0 | BK30: 0 | BL30: 0 | BM30: 0 | BN30: 0 | BO30: 0 | BP30: 0 | BQ30: 0 | BR30: 0 | BS30: 0 | BT30: 0 | BU30: 0 | BV30: 0 | BW30: 0 | BX30: 0
A31: Gross Loss Adjustments (Dealer level, high PTI, etc.) | B31: 0.82200867 | C31: 0.94331678 | D31: 0.8732775 | E31: 0.94815913 | F31: 0.67803508 | G31: 0.41528649 | H31: 0.74987391 | I31: 0.43142049 | J31: 0.5519861 | K31: 0.70277859 | L31: 0.82669385 | M31: 0.93011174 | N31: 0.99300002 | O31: 0.94218232 | P31: 0.74733995 | Q31: 0.82287702 | R31: 1.6307511 | S31: 1.7202458 | T31: 1.6635727 | U31: 1.8395175 | V31: 1.908889 | W31: 1.7264935 | X31: 1.4791288 | Y31: 1.5973358 | Z31: 1.4824169 | AA31: 1.1204565 | AB31: 1.2908944 | AC31: 1.1923053 | AD31: 0.49474395 | AE31: 0.37581117 | AF31: 0.77009603 | AG31: 0.47569723 | AH31: 1.9082218 | AI31: 2.4529663 | AJ31: 1.432604 | AK31: 0.018182118 | AL31: -1.6039225 | AM31: 0.80705772 | AN31: 0.72028839 | AO31: 0.95564856 | AP31: 1.5559155 | AQ31: -5.4976385 | AR31: 3.8958982 | AS31: 3.2941837 | AT31: -1.5539318 | AU31: -0.53627028 | AV31: 1.2414827 | AW31: 1.9185926 | AX31: 0.687229 | AY31: 1.8467538 | AZ31: 1.7677956 | BA31: 0.31402868 | BB31: 0.7898659 | BC31: 1.9076542 | BD31: 2.2496134 | BE31: 2.536935 | BF31: 2.1349158 | BG31: 2.0094308 | BH31: 2.2206432 | BI31: 1.9681101 | BJ31: 1.7988874 | BK31: 1.2810308 | BL31: 1.4300117 | BM31: 1.5529908 | BN31: 1.1800563 | BO31: 1.733736 | BP31: 1.7240162 | BQ31: 2.2645703 | BR31: 1.865663 | BS31: 1.7808388 | BT31: 2.4208732 | BU31: 2.4373103 | BV31: 3.1042446 | BW31: 3.7259265 | BX31: 2.4731799
A32: Recovery Adjustments excluding LTV (Mileage, vehicle type, etc.) | B32: -0.47932338 | C32: 0.39115157 | D32: 0.2771793 | E32: 0.080689838 | F32: -0.25821088 | G32: -0.088448241 | H32: -0.36391365 | I32: -0.13476753 | J32: -0.50051884 | K32: -0.43257335 | L32: -0.29134712 | M32: -0.014379243 | N32: 0.036133011 | O32: 0.19985294 | P32: 0.29665909 | Q32: 0.6274533 | R32: 0.58881346 | S32: 0.58917334 | T32: 0.19857717 | U32: -0.029299117 | V32: -0.12092275 | W32: 0.078046436 | X32: 0.11288784 | Y32: -0.15754904 | Z32: -0.36432325 | AA32: -0.83840099 | AB32: -0.42988161 | AC32: -0.76597522 | AD32: -0.58293348 | AE32: -0.90818436 | AF32: -1.748248 | AG32: -0.93445967 | AH32: 1.0612811 | AI32: -2.4078632 | AJ32: -0.74508335 | AK32: -2.4905576 | AL32: -4.6129882 | AM32: -0.17280682 | AN32: 1.1888569 | AO32: -1.8674456 | AP32: -3.8253981 | AQ32: -0.7897144 | AR32: 0.4639765 | AS32: -4.4345162 | AT32: -1.7768972 | AU32: -3.8775635 | AV32: 0.82442004 | AW32: 0.97350816 | AX32: -1.5401931 | AY32: -1.8210804 | AZ32: -0.71113369 | BA32: -0.53444327 | BB32: -1.5072009 | BC32: -1.4880608 | BD32: -0.83286341 | BE32: -0.35286014 | BF32: 0.29517208 | BG32: -0.78186767 | BH32: -0.21896991 | BI32: -0.33982766 | BJ32: -0.23780951 | BK32: 1.6958971 | BL32: 1.4264151 | BM32: 1.0112008 | BN32: 0.30745822 | BO32: 0.83652629 | BP32: 0.057706203 | BQ32: -1.0329316 | BR32: 2.3276804 | BS32: 0.89173883 | BT32: 1.5090151 | BU32: 0.65393353 | BV32: 3.0232831 | BW32: 0.99974112 | BX32: 0.96045826
A33: LTV Adjustments | B33: 0.47932338 | C33: -0.39115157 | D33: -0.2771793 | E33: -0.080689838 | F33: 0.25821088 | G33: 0.088448241 | H33: 0.36391365 | I33: 0.13476753 | J33: 0.50051884 | K33: 0.43257335 | L33: 0.29134712 | M33: 0.014379243 | N33: -0.036133011 | O33: -0.19985294 | P33: -0.29665909 | Q33: -0.6274533 | R33: -0.58881346 | S33: -0.58917334 | T33: -0.19857717 | U33: 0.029299117 | V33: 0.12092275 | W33: -0.078046436 | X33: -0.11288784 | Y33: 0.15754904 | Z33: 0.36432325 | AA33: 0.83840099 | AB33: 0.42988161 | AC33: 0.76597522 | AD33: 0.58293348 | AE33: 0.90818436 | AF33: 1.748248 | AG33: 0.93445967 | AH33: -1.0612811 | AI33: 2.4078632 | AJ33: 0.74508335 | AK33: 2.4905576 | AL33: 4.6129882 | AM33: 0.17280682 | AN33: -1.1888569 | AO33: 1.8674456 | AP33: 3.8253981 | AQ33: 0.7897144 | AR33: -0.4639765 | AS33: 4.4345162 | AT33: 1.7768972 | AU33: 3.8775635 | AV33: -0.82442004 | AW33: -0.97350816 | AX33: 1.5401931 | AY33: 1.8210804 | AZ33: 0.71113369 | BA33: 0.53444327 | BB33: 1.5072009 | BC33: 1.4880608 | BD33: 0.83286341 | BE33: 0.35286014 | BF33: -0.29517208 | BG33: 0.78186767 | BH33: 0.21896991 | BI33: 0.33982766 | BJ33: 0.23780951 | BK33: -1.6958971 | BL33: -1.4264151 | BM33: -1.0112008 | BN33: -0.30745822 | BO33: -0.83652629 | BP33: -0.057706203 | BQ33: 1.0329316 | BR33: -2.3276804 | BS33: -0.89173883 | BT33: -1.5090151 | BU33: -0.65393353 | BV33: -3.0232831 | BW33: -0.99974112 | BX33: -0.96045826
A34: RAGU Score | B34: 130.46156 | C34: 132.59742 | D34: 132.44292 | E34: 130.45424 | F34: 130.46242 | G34: 130.73468 | H34: 130.768 | I34: 130.71328 | J34: 134.10441 | K34: 135.61017 | L34: 136.07128 | M34: 136.78784 | N34: 136.49369 | O34: 136.69351 | P34: 135.88692 | Q34: 135.71881 | R34: 137.1949 | S34: 136.77356 | T34: 136.9298 | U34: 137.23522 | V34: 137.27054 | W34: 137.4678 | X34: 136.51756 | Y34: 137.33138 | Z34: 135.82157 | AA34: 135.80307 | AB34: 134.2361 | AC34: 134.53671 | AD34: 134.78114 | AE34: 135.07865 | AF34: 135.3814 | AG34: 136.74478 | AH34: 138.6414 | AI34: 139.6856 | AJ34: 138.38976 | AK34: 137.65163 | AL34: 135.63536 | AM34: 138.54334 | AN34: 139.77881 | AO34: 139.40169 | AP34: 141.52378 | AQ34: 133.25612 | AR34: 143.00738 | AS34: 140.71301 | AT34: 136.61908 | AU34: 136.97436 | AV34: 138.92437 | AW34: 140.34469 | AX34: 139.92204 | AY34: 138.7513 | AZ34: 139.11639 | BA34: 137.16462 | BB34: 137.22838 | BC34: 139.07728 | BD34: 139.69506 | BE34: 140.38711 | BF34: 140.2587 | BG34: 140.89268 | BH34: 141.0042 | BI34: 139.93728 | BJ34: 138.62596 | BK34: 138.02669 | BL34: 138.18776 | BM34: 138.077 | BN34: 137.87785 | BO34: 139.23166 | BP34: 139.6552 | BQ34: 140.80237 | BR34: 140.46707 | BS34: 140.12205 | BT34: 141.50143 | BU34: 141.62947 | BV34: 142.7118 | BW34: 145.18587 | BX34: 144.11914
A35: LTV | B35: 1.9469756 | C35: 1.9399714 | D35: 1.9873601 | E35: 2.0859967 | F35: 2.0676889 | G35: 2.1290235 | H35: 2.0540996 | I35: 2.0944388 | J35: 2.1513491 | K35: 2.0657497 | L35: 1.8646704 | M35: 1.8045241 | N35: 1.774196 | O35: 1.763457 | P35: 1.8444218 | Q35: 1.8116717 | R35: 1.8007957 | S35: 1.7048222 | T35: 1.649114 | U35: 1.6103487 | V35: 1.5547197 | W35: 1.5493184 | X35: 1.5257625 | Y35: 1.6111285 | Z35: 1.6459911 | AA35: 1.5715921 | AB35: 1.6688367 | AC35: 1.5946037 | AD35: 1.5834516 | AE35: 1.5721565 | AF35: 1.55897 | AG35: 1.5365354 | AH35: 1.7429162 | AI35: 1.5592624 | AJ35: 1.7688528 | AK35: 1.5819754 | AL35: 1.6419623 | AM35: 1.3753977 | AN35: 1.3456268 | AO35: 2.1005117 | AP35: 0.85337384 | AQ35: 1.2910038 | AR35: 1.6395104 | AS35: 6.5609117 | AT35: 1.7781131 | AU35: 1.5592245 | AV35: 1.6482663 | AW35: 1.7437847 | AX35: 2.3904306 | AY35: 1.6198295 | AZ35: 1.4763011 | BA35: 1.507895 | BB35: 1.5198383 | BC35: 1.576527 | BD35: 1.4853391 | BE35: 1.4597719 | BF35: 1.4682441 | BG35: 1.4714205 | BH35: 1.5338191 | BI35: 1.497031 | BJ35: 1.4522129 | BK35: 1.5158906 | BL35: 1.4839641 | BM35: 1.4957652 | BN35: 1.4707445 | BO35: 1.4441365 | BP35: 1.4000733 | BQ35: 1.3586424 | BR35: 1.4664219 | BS35: 1.4125682 | BT35: 1.4054031 | BU35: 1.3857517 | BV35: 1.4433239 | BW35: 1.3866469 | BX35: 1.4819447
