Workbook

Sheet Main
A1: NONKMX LOB | B1: FLD
A2: Start | B2: 2025 Q1 | E2: SECTION 1: POS Breakdown (excl. STE)
A3: End | B3: 2025 Q4
E4: 1a. POS Ragu Breakdown
A5: nonKMX LOBs: | E5: =factory!U26 -> POS | F5: =B2 -> 2025 Q1 | G5: =B3 -> 2025 Q4 | H5: Delta
A6: AN | E6: Model Score | F6: =factory!V27 -> 138.29936 | G6: =factory!W27 -> 140.32 | H6: =G6-F6 -> 2.0206382
A7: STG | E7: Gross Loss | F7: =factory!V28 -> 0.21131625 | G7: =factory!W28 -> 1.9565456 | H7: =G7-F7 -> 1.7452294
A8: ENT | E8: Recovery + LTV | F8: =factory!V29 -> 2.1597741 | G8: =factory!W29 -> 3.7818078 | H8: =G8-F8 -> 1.6220337
A9: FLD | E9: RAGU Score | F9: =factory!V30 -> 140.67045 | G9: =factory!W30 -> 146.05835 | H9: =G9-F9 -> 5.3879013
A10: FRN
E11: 1b. POS Recovery Mix | J11: 1c. POS Gross-Loss Mix
E12: POS | F12: =B2 -> 2025 Q1 | G12: =B3 -> 2025 Q4 | H12: Delta | J12: POS | K12: =B2 -> 2025 Q1 | L12: =B3 -> 2025 Q4 | M12: Delta
E13: KMX | F13: =INDEX('POS decomp'!$I21:$S21,MATCH(F$12,'POS decomp'!$I$20:$S$20, 0)) -> -0.95588293 | G13: =INDEX('POS decomp'!$I21:$S21,MATCH(G$12,'POS decomp'!$I$20:$S$20, 0)) -> 0.02024678 | H13: =G13-F13 -> 0.97612971 | J13: KMX | K13: =INDEX('POS decomp'!$AB21:$AL21,MATCH(K$12,'POS decomp'!$AB$20:$AL$20, 0)) -> -0.15422945 | L13: =INDEX('POS decomp'!$AB21:$AL21,MATCH(L$12,'POS decomp'!$AB$20:$AL$20, 0)) -> 0.7223938 | M13: =L13-K13 -> 0.87662325
E14: AN | F14: =INDEX('POS decomp'!$I22:$S22,MATCH(F$12,'POS decomp'!$I$20:$S$20, 0)) -> 0.27284125 | G14: =INDEX('POS decomp'!$I22:$S22,MATCH(G$12,'POS decomp'!$I$20:$S$20, 0)) -> 0.40054145 | H14: =G14-F14 -> 0.1277002 | J14: AN | K14: =INDEX('POS decomp'!$AB22:$AL22,MATCH(K$12,'POS decomp'!$AB$20:$AL$20, 0)) -> 0.083317327 | L14: =INDEX('POS decomp'!$AB22:$AL22,MATCH(L$12,'POS decomp'!$AB$20:$AL$20, 0)) -> 0.18577643 | M14: =L14-K14 -> 0.1024591
E15: FRN | F15: =INDEX('POS decomp'!$I23:$S23,MATCH(F$12,'POS decomp'!$I$20:$S$20, 0)) -> 1.1738563 | G15: =INDEX('POS decomp'!$I23:$S23,MATCH(G$12,'POS decomp'!$I$20:$S$20, 0)) -> 1.5164243 | H15: =G15-F15 -> 0.34256796 | J15: FRN | K15: =INDEX('POS decomp'!$AB23:$AL23,MATCH(K$12,'POS decomp'!$AB$20:$AL$20, 0)) -> 0.1194035 | L15: =INDEX('POS decomp'!$AB23:$AL23,MATCH(L$12,'POS decomp'!$AB$20:$AL$20, 0)) -> 0.46468388 | M15: =L15-K15 -> 0.34528038
E16: STG | F16: =INDEX('POS decomp'!$I24:$S24,MATCH(F$12,'POS decomp'!$I$20:$S$20, 0)) -> 0.75299844 | G16: =INDEX('POS decomp'!$I24:$S24,MATCH(G$12,'POS decomp'!$I$20:$S$20, 0)) -> 0.92455929 | H16: =G16-F16 -> 0.17156085 | J16: STG | K16: =INDEX('POS decomp'!$AB24:$AL24,MATCH(K$12,'POS decomp'!$AB$20:$AL$20, 0)) -> 0.20623123 | L16: =INDEX('POS decomp'!$AB24:$AL24,MATCH(L$12,'POS decomp'!$AB$20:$AL$20, 0)) -> 0.30022634 | M16: =L16-K16 -> 0.093995118
E17: FLD | F17: =INDEX('POS decomp'!$I25:$S25,MATCH(F$12,'POS decomp'!$I$20:$S$20, 0)) -> 0.11460964 | G17: =INDEX('POS decomp'!$I25:$S25,MATCH(G$12,'POS decomp'!$I$20:$S$20, 0)) -> 0.21373009 | H17: =G17-F17 -> 0.099120451 | J17: FLD | K17: =INDEX('POS decomp'!$AB25:$AL25,MATCH(K$12,'POS decomp'!$AB$20:$AL$20, 0)) -> 0.10732218 | L17: =INDEX('POS decomp'!$AB25:$AL25,MATCH(L$12,'POS decomp'!$AB$20:$AL$20, 0)) -> 0.099445766 | M17: =L17-K17 -> -0.0078764126
E18: ENT | F18: =INDEX('POS decomp'!$I26:$S26,MATCH(F$12,'POS decomp'!$I$20:$S$20, 0)) -> 0.80243801 | G18: =INDEX('POS decomp'!$I26:$S26,MATCH(G$12,'POS decomp'!$I$20:$S$20, 0)) -> 0.7158481 | H18: =G18-F18 -> -0.086589916 | J18: ENT | K18: =INDEX('POS decomp'!$AB26:$AL26,MATCH(K$12,'POS decomp'!$AB$20:$AL$20, 0)) -> -0.15072853 | L18: =INDEX('POS decomp'!$AB26:$AL26,MATCH(L$12,'POS decomp'!$AB$20:$AL$20, 0)) -> 0.1840194 | M18: =L18-K18 -> 0.33474793
E19: POS | F19: =SUM(F13:F18) -> 2.1608607 | G19: =SUM(G13:G18) -> 3.79135 | H19: =G19-F19 -> 1.6304893 | J19: POS | K19: =SUM(K13:K18) -> 0.21131625 | L19: =SUM(L13:L18) -> 1.9565456 | M19: =L19-K19 -> 1.7452294
E23: SECTION 2: KMX Breakdown
E25: 2a. KMX Ragu Breakdown | J25: 2c. KMX Gross-Loss Breakdown
E26: =factory!Q26 -> KMX | F26: =B2 -> 2025 Q1 | G26: =B3 -> 2025 Q4 | H26: Delta | J26: KMX | K26: =B2 -> 2025 Q1 | L26: =B3 -> 2025 Q4 | M26: Delta
E27: Model Score | F27: =factory!R27 -> 139.70877 | G27: =factory!S27 -> 140.94205 | H27: =G27-F27 -> 1.2332866 | J27: Chime | K27: =factory!G116+factory!G102 -> -1.292241 | L27: =factory!H116+factory!H102 -> -1.1293258 | M27: =L27-K27 -> 0.16291519
E28: Gross Loss | F28: =factory!R28 -> -0.34039323 | G28: =factory!S28 -> 1.489745 | H28: =G28-F28 -> 1.8301382 | J28: population % | K28: =INDEX('KMX populations'!$B28:$L28,MATCH("KMX | "&K$26,'KMX populations'!$B$1:$L$1, 0)) -> 0.23263723 | L28: =INDEX('KMX populations'!$B28:$L28,MATCH("KMX | "&L$26,'KMX populations'!$B$1:$L$1, 0)) -> 0.15797197 | M28: =L28-K28 -> -0.074665257
E29: Recovery + LTV | F29: =factory!R29 -> -2.1096884 | G29: =factory!S29 -> 0.041753596 | H29: =G29-F29 -> 2.151442 | J29: Job Time | K29: =factory!G117 -> -0.63280526 | L29: =factory!H117 -> -0.49157282 | M29: =L29-K29 -> 0.14123244
E30: RAGU Score | F30: =factory!R30 -> 137.25869 | G30: =factory!S30 -> 142.47355 | H30: =G30-F30 -> 5.2148668 | J30: population % | K30: =INDEX('KMX populations'!B2:L2,MATCH("KMX | "&K$26,'KMX populations'!$B$1:$L$1, 0)) -> 0.16212339 | L30: =INDEX('KMX populations'!C2:M2,MATCH("KMX | "&L$26,'KMX populations'!$B$1:$L$1, 0)) -> 0.10980213 | M30: =L30-K30 -> -0.052321259
J31: Vehicle Age | K31: =factory!G107 -> 0.41491423 | L31: =factory!H107 -> 0.22464027 | M31: =L31-K31 -> -0.19027396
J32: Age | K32: =F38 -> 5.9169485 | L32: =G38 -> 6.1398487 | M32: =L32-K32 -> 0.22290017
J33: Soft Pull Factors | K33: =factory!G104+factory!G121 -> 0.046908282 | L33: =factory!H104+factory!H121 -> 1.2686239 | M33: =L33-K33 -> 1.2217157
J34: Low Vantage % | K34: =INDEX('KMX populations'!B29:L29,MATCH("KMX | "&K$26,'KMX populations'!$B$1:$L$1, 0)) -> 0.017535469 | L34: =INDEX('KMX populations'!C29:M29,MATCH("KMX | "&L$26,'KMX populations'!$B$1:$L$1, 0)) -> 0.0097220634 | M34: =L34-K34 -> -0.0078134061
E35: 2b. KMX Recovery Breakdown | J35: Low Cash Down % | K35: =INDEX('KMX populations'!B30:L30,MATCH("KMX | "&K$26,'KMX populations'!$B$1:$L$1, 0)) -> 0.089324619 | L35: =INDEX('KMX populations'!C30:M30,MATCH("KMX | "&L$26,'KMX populations'!$B$1:$L$1, 0)) -> 0.16184376 | M35: =L35-K35 -> 0.072519142
E36: KMX | F36: =B2 -> 2025 Q1 | G36: =B3 -> 2025 Q4 | H36: Delta | J36: State | K36: =factory!G112+factory!G113+factory!G114+factory!G115 -> -0.089100438 | L36: =factory!H112+factory!H113+factory!H114+factory!H115 -> 0.11138264 | M36: =L36-K36 -> 0.20048308
E37: LTV | F37: =INDEX(rec[ltv],MATCH($E$36&" "&F$36,rec[lookup], 0)) -> 1.6047279 | G37: =INDEX(rec[ltv],MATCH($E$36&" "&G$36,rec[lookup], 0)) -> 1.5761078 | H37: =G37-F37 -> -0.028620095 | J37: Louisiana % | K37: =INDEX('KMX populations'!B25:L25,MATCH("KMX | "&K$26,'KMX populations'!$B$1:$L$1, 0)) -> 0.0053137786 | L37: =INDEX('KMX populations'!C25:M25,MATCH("KMX | "&L$26,'KMX populations'!$B$1:$L$1, 0)) -> 0.0046894659 | M37: =L37-K37 -> -0.00062431277
E38: Age | F38: =INDEX(rec[age],MATCH($E$36&" "&F$36,rec[lookup], 0)) -> 5.9169485 | G38: =INDEX(rec[age],MATCH($E$36&" "&G$36,rec[lookup], 0)) -> 6.1398487 | H38: =G38-F38 -> 0.22290017 | J38: Georgia % | K38: =INDEX('KMX populations'!B26:L26,MATCH("KMX | "&K$26,'KMX populations'!$B$1:$L$1, 0)) -> 0.11584037 | L38: =INDEX('KMX populations'!C26:M26,MATCH("KMX | "&L$26,'KMX populations'!$B$1:$L$1, 0)) -> 0.077090244 | M38: =L38-K38 -> -0.03875013
E39: Mileage | F39: =INDEX(rec[mileage],MATCH($E$36&" "&F$36,rec[lookup], 0)) -> 60448 | G39: =INDEX(rec[mileage],MATCH($E$36&" "&G$36,rec[lookup], 0)) -> 60705 | H39: =G39-F39 -> 257 | J39: Texas/California % | K39: =INDEX('KMX populations'!B27:L27,MATCH("KMX | "&K$26,'KMX populations'!$B$1:$L$1, 0)) -> 0.25522079 | L39: =INDEX('KMX populations'!C27:M27,MATCH("KMX | "&L$26,'KMX populations'!$B$1:$L$1, 0)) -> 0.33752716 | M39: =L39-K39 -> 0.082306377
E40: Toyota/Honda | F40: =INDEX(rec[toyho],MATCH($E$36&" "&F$36,rec[lookup], 0)) -> 0.13852349 | G40: =INDEX(rec[toyho],MATCH($E$36&" "&G$36,rec[lookup], 0)) -> 0.23679363 | H40: =G40-F40 -> 0.098270144 | J40: Other Adjustments | K40: =SUM(factory!G98:G124)-K36-K33-K31-K29-K27 -> 1.2119309 | L40: =SUM(factory!H98:H124)-L36-L33-L31-L29-L27 -> 1.5059967 | M40: =L40-K40 -> 0.29406581
E41: Truck % | F41: =INDEX(rec[truck],MATCH($E$36&" "&F$36,rec[lookup], 0)) -> 0.053208054 | G41: =INDEX(rec[truck],MATCH($E$36&" "&G$36,rec[lookup], 0)) -> 0.068150004 | H41: =G41-F41 -> 0.01494195 | J41: Final Gross Loss | K41: =SUM(K27,K29,K31,K33,K36,K40) -> -0.34039323 | L41: =SUM(L27,L29,L31,L33,L36,L40) -> 1.489745 | M41: =L41-K41 -> 1.8301382
E42: Driver % | F42: =INDEX(rec[driver],MATCH($E$36&" "&F$36,rec[lookup], 0)) -> 0.0099865772 | G42: =INDEX(rec[driver],MATCH($E$36&" "&G$36,rec[lookup], 0)) -> 0.0087674059 | H42: =G42-F42 -> -0.0012191713
E46: SECTION 3: nonKMX LOB Breakdown
E48: =_xlfn.CONCAT("3a. ",B1," Ragu Breakdown") -> 3a. FLD Ragu Breakdown | J48: =_xlfn.CONCAT("3c. ",B1," Gross-Loss Breakdown") -> 3c. FLD Gross-Loss Breakdown
...

Sheet KMX populations
B1: KMX | 2023 Q3 | C1: KMX | 2023 Q4 | D1: KMX | 2024 Q1 | E1: KMX | 2024 Q2 | F1: KMX | 2024 Q3 | G1: KMX | 2024 Q4 | H1: KMX | 2025 Q1 | I1: KMX | 2025 Q2 | J1: KMX | 2025 Q3 | K1: KMX | 2025 Q4 | L1: KMX | 2026 Q1
A2: job_time_flag | B2: 0.23563763 | C2: 0.2236671 | D2: 0.18614265 | E2: 0.16362192 | F2: 0.18165758 | G2: 0.17851864 | H2: 0.16212339 | I2: 0.11662371 | J2: 0.12642773 | K2: 0.14219679 | L2: 0.10980213
A3: low_fico_flag | B3: 0.052872475 | C3: 0.046442504 | D3: 0.039245949 | E3: 0.032204491 | F3: 0.029495353 | G3: 0.03957957 | H3: 0.0013815824 | I3: 0 | J3: 0 | K3: 0 | L3: 0.00045750886
A4: high_model_score_flag | B4: 0.23484848 | C4: 0.24168679 | D4: 0.197718 | E4: 0.2465882 | F4: 0.23112374 | G4: 0.24092626 | H4: 0.23763218 | I4: 0.26823454 | J4: 0.25915715 | K4: 0.26619708 | L4: 0.29532197
A5: low_vantage_flag | B5: 0 | C5: 0 | D5: 0 | E5: 0 | F5: 0 | G5: 0.00073903761 | H5: 0.014666029 | I5: 0.013402062 | J5: 0.010502823 | K5: 0.011739673 | L5: 0.0083495368
A6: normal_pti_flag | B6: 0.83475379 | C6: 0.83559354 | D6: 0.86963951 | E6: 0.86417792 | F6: 0.86896075 | G6: 0.86804073 | H6: 0.85812211 | I6: 0.87177835 | J6: 0.87770776 | K6: 0.87563284 | L6: 0.89820428
A7: high_pti_tier_1_flag | B7: 0.11300505 | C7: 0.10013004 | D7: 0.081964502 | E7: 0.081449924 | F7: 0.077809356 | G7: 0.074314337 | H7: 0.084170253 | I7: 0.077963918 | J7: 0.073782329 | K7: 0.075647516 | L7: 0.065652522
A8: high_pti_tier_2_flag | B8: 0.046875 | C8: 0.056474085 | D8: 0.044592658 | E8: 0.047801285 | F8: 0.046240111 | G8: 0.048940713 | H8: 0.049311866 | I8: 0.046585052 | J8: 0.044833924 | K8: 0.044097146 | L8: 0.033398147
A9: high_pti_tier_3_flag | B9: 0.0053661616 | C9: 0.0078023407 | D9: 0.0038033293 | E9: 0.0065708715 | F9: 0.0069897842 | G9: 0.0087042207 | H9: 0.0083957702 | I9: 0.0036726804 | J9: 0.0036759879 | K9: 0.0046224961 | L9: 0.0027450532
A10: existing_dq_flag | B10: 0.068181818 | C10: 0.071335686 | D10: 0.081303054 | E10: 0.080077984 | F10: 0.073123896 | G10: 0.094678929 | H10: 0.13061268 | I10: 0.10199742 | J10: 0.10213995 | K10: 0.11387483 | L10: 0.088642342
A11: seasonal_employment_flag | B11: 0 | C11: 0 | D11: 0 | E11: 0 | F11: 0 | G11: 0 | H11: 0.0079706679 | I11: 0.0067654639 | J11: 0.0073519758 | K11: 0.0079242791 | L11: 0.0043463342
A12: secured_credit_flag | B12: 0.24447601 | C12: 0.22422441 | D12: 0.274887 | E12: 0.26196837 | F12: 0.26684077 | G12: 0.24954837 | H12: 0.32849779 | I12: 0.3125 | J12: 0.35906525 | K12: 0.35732629 | L12: 0.24259408
A13: kmx_auth_tradelines_flag | B13: 0.050978535 | C13: 0.040126324 | D13: 0.03318267 | E13: 0.039641851 | F13: 0.040095245 | G13: 0.040482838 | H13: 0.038206068 | I13: 0.041237113 | J13: 0.039779441 | K13: 0.043069924 | L13: 0.026878646
... A37: --- N_RECORDS | B37: 6336 | C37: 5383 | D37: 18142 | E37: 13849 | F37: 13019 | G37: 12178 | H37: 18819 | I37: 15520 | J37: 15234 | K37: 13629 | L37: 8743

Sheet ragu
A1: measures | B1: AN 2023 Q3 | C1: AN 2023 Q4 | D1: AN 2024 Q1 | E1: AN 2024 Q2 | F1: AN 2024 Q3 | G1: AN 2024 Q4 | H1: AN 2025 Q1 | I1: AN 2025 Q2 | J1: AN 2025 Q3 | K1: AN 2025 Q4 | L1: AN 2026 Q1 | M1: FRN 2023 Q3 | N1: FRN 2023 Q4 | O1: FRN 2024 Q1 | P1: FRN 2024 Q2 | Q1: FRN 2024 Q3 | R1: FRN 2024 Q4 | S1: FRN 2025 Q1 | T1: FRN 2025 Q2 | U1: FRN 2025 Q3 | V1: FRN 2025 Q4 | W1: FRN 2026 Q1 | X1: STG 2023 Q3 | Y1: STG 2023 Q4 | Z1: STG 2024 Q1 | AA1: STG 2024 Q2 | AB1: STG 2024 Q3 | AC1: STG 2024 Q4 | AD1: STG 2025 Q1 | AE1: STG 2025 Q2 | AF1: STG 2025 Q3 | AG1: STG 2025 Q4 | AH1: STG 2026 Q1 | AI1: FLD 2023 Q3 | AJ1: FLD 2023 Q4 | AK1: FLD 2024 Q1 | AL1: FLD 2024 Q2 | AM1: FLD 2024 Q3 | AN1: FLD 2024 Q4 | AO1: FLD 2025 Q1 | AP1: FLD 2025 Q2 | AQ1: FLD 2025 Q3 | AR1: FLD 2025 Q4 | AS1: FLD 2026 Q1 | AT1: ENT 2023 Q3 | AU1: ENT 2023 Q4 | AV1: ENT 2024 Q1 | AW1: ENT 2024 Q2 | AX1: ENT 2024 Q3 | AY1: ENT 2024 Q4 | AZ1: ENT 2025 Q1 | BA1: ENT 2025 Q2 | BB1: ENT 2025 Q3 | BC1: ENT 2025 Q4 | BD1: ENT 2026 Q1 | BE1: KMX 2023 Q3 | BF1: KMX 2023 Q4 | BG1: KMX 2024 Q1 | BH1: KMX 2024 Q2 | BI1: KMX 2024 Q3 | BJ1: KMX 2024 Q4 | BK1: KMX 2025 Q1 | BL1: KMX 2025 Q2 | BM1: KMX 2025 Q3 | BN1: KMX 2025 Q4 | BO1: KMX 2026 Q1 | BP1: POS 2023 Q3 | BQ1: POS 2023 Q4 | BR1: POS 2024 Q1 | BS1: POS 2024 Q2 | BT1: POS 2024 Q3 | BU1: POS 2024 Q4 | BV1: POS 2025 Q1 | BW1: POS 2025 Q2 | BX1: POS 2025 Q3 | BY1: POS 2025 Q4 | BZ1: POS 2026 Q1
A2: AN | B2: 2023 Q3 | C2: 2023 Q4 | D2: 2024 Q1 | E2: 2024 Q2 | F2: 2024 Q3 | G2: 2024 Q4 | H2: 2025 Q1 | I2: 2025 Q2 | J2: 2025 Q3 | K2: 2025 Q4 | L2: 2026 Q1 | M2: 2023 Q3 | N2: 2023 Q4 | O2: 2024 Q1 | P2: 2024 Q2 | Q2: 2024 Q3 | R2: 2024 Q4 | S2: 2025 Q1 | T2: 2025 Q2 | U2: 2025 Q3 | V2: 2025 Q4 | W2: 2026 Q1 | X2: 2023 Q3 | Y2: 2023 Q4 | Z2: 2024 Q1 | AA2: 2024 Q2 | AB2: 2024 Q3 | AC2: 2024 Q4 | AD2: 2025 Q1 | AE2: 2025 Q2 | AF2: 2025 Q3 | AG2: 2025 Q4 | AH2: 2026 Q1 | AI2: 2023 Q3 | AJ2: 2023 Q4 | AK2: 2024 Q1 | AL2: 2024 Q2 | AM2: 2024 Q3 | AN2: 2024 Q4 | AO2: 2025 Q1 | AP2: 2025 Q2 | AQ2: 2025 Q3 | AR2: 2025 Q4 | AS2: 2026 Q1 | AT2: 2023 Q3 | AU2: 2023 Q4 | AV2: 2024 Q1 | AW2: 2024 Q2 | AX2: 2024 Q3 | AY2: 2024 Q4 | AZ2: 2025 Q1 | BA2: 2025 Q2 | BB2: 2025 Q3 | BC2: 2025 Q4 | BD2: 2026 Q1 | BE2: 2023 Q3 | BF2: 2023 Q4 | BG2: 2024 Q1 | BH2: 2024 Q2 | BI2: 2024 Q3 | BJ2: 2024 Q4 | BK2: 2025 Q1 | BL2: 2025 Q2 | BM2: 2025 Q3 | BN2: 2025 Q4 | BO2: 2026 Q1 | BP2: 2023 Q3 | BQ2: 2023 Q4 | BR2: 2024 Q1 | BS2: 2024 Q2 | BT2: 2024 Q3 | BU2: 2024 Q4 | BV2: 2025 Q1 | BW2: 2025 Q2 | BX2: 2025 Q3 | BY2: 2025 Q4 | BZ2: 2026 Q1
A3: ms | B3: 136.43849 | C3: 137.02135 | D3: 136.37212 | E3: 137.12198 | F3: 138.09052 | G3: 136.80136 | H3: 136.83702 | I3: 138.03382 | J3: 138.55808 | K3: 139.3761 | L3: 140.32164 | M3: 140.72103 | N3: 139.02514 | O3: 138.13163 | P3: 140.17356 | Q3: 141.55375 | R3: 139.97097 | S3: 139.83315 | T3: 140.63434 | U3: 140.96388 | V3: 141.85749 | W3: 142.87187 | X3: 138.53984 | Y3: 137.48747 | Z3: 136.76023 | AA3: 137.47802 | AB3: 138.54354 | AC3: 137.20905 | AD3: 136.6684 | AE3: 137.94719 | AF3: 138.66055 | AG3: 140.03752 | AH3: 141.49333 | AI3: 137.95666 | AJ3: 139.5662 | AK3: 138.5244 | AL3: 138.40978 | AM3: 140.36331 | AN3: 138.38769 | AO3: 136.70743 | AP3: 138.3478 | AQ3: 138.1021 | AR3: 138.94555 | AS3: 140.98773 | AT3: 133.76755 | AU3: 135.31367 | AV3: 136.17456 | AW3: 136.8171 | AX3: 136.69241 | AY3: 134.94875 | AZ3: 134.57148 | BA3: 136.41792 | BB3: 137.0063 | BC3: 137.20721 | BD3: 139.53493 | BE3: 140.50459 | BF3: 140.56078 | BG3: 139.56825 | BH3: 140.43212 | BI3: 139.88511 | BJ3: 139.76782 | BK3: 139.70877 | BL3: 139.86672 | BM3: 139.91791 | BN3: 140.94205 | BO3: 141.86953 | BP3: 139.07412 | BQ3: 138.9461 | BR3: 138.34968 | BS3: 139.22436 | BT3: 139.53563 | BU3: 138.6092 | BV3: 138.29936 | BW3: 139.10189 | BX3: 139.41596 | BY3: 140.32 | BZ3: 141.6242
A4: gl | B4: 0.6947113 | C4: 0.83003342 | D4: 0.65750359 | E4: 1.1812862 | F4: 0.97222553 | G4: 1.180284 | H4: 1.4582901 | I4: 2.4723015 | J4: 2.9310683 | K4: 3.3295966 | L4: 2.1031239 | M4: 1.6245882 | N4: 0.89105376 | O4: -0.19253143 | P4: 0.30849242 | Q4: 0.75767443 | R4: 0.52844615 | S4: 0.66878042 | T4: 1.2730461 | U4: 1.7966555 | V4: 2.7856639 | W4: 2.4440368 | X4: 1.4591709 | Y4: 1.2751302 | Z4: 1.0228541 | AA4: 2.0236416 | AB4: 2.2713522 | AC4: 2.0658579 | AD4: 1.8397214 | AE4: 2.0295688 | AF4: 2.2461463 | AG4: 2.9427504 | AH4: 2.3362459 | AI4: 1.0312225 | AJ4: 1.5139703 | AK4: 1.5512225 | AL4: 2.4386011 | AM4: 3.2825892 | AN4: 2.9662031 | AO4: 2.4076495 | AP4: 2.4907613 | AQ4: 3.0095789 | AR4: 1.6204382 | AS4: 1.1822025 | AT4: -0.72060842 | AU4: 0.4554259 | AV4: -0.58479913 | AW4: -0.32981376 | AX4: -0.47903773 | AY4: -0.28282436 | AZ4: -0.97520672 | BA4: 0.20726925 | BB4: 0.17758706 | BC4: 1.4255253 | BD4: 1.653816 | BE4: 1.500187 | BF4: 1.7611724 | BG4: 1.326646 | BH4: 2.2203145 | BI4: 1.9527827 | BJ4: 0.88362919 | BK4: -0.34039323 | BL4: 1.3978451 | BM4: 1.3198684 | BN4: 1.489745 | BO4: 2.0379889 | BP4: 0.93343132 | BQ4: 1.162946 | BR4: 0.7294941 | BS4: 1.4238402 | BT4: 1.4538116 | BU4: 0.86334079 | BV4: 0.21131625 | BW4: 1.4023257 | BX4: 1.5483029 | BY4: 1.9565456 | BZ4: 2.0460009
A5: rec | B5: -0.5325065 | C5: -0.25281508 | D5: -0.51081514 | E5: -0.06446555 | F5: 0.40869613 | G5: 1.2565312 | H5: 1.2681184 | I5: 1.9615167 | J5: 1.9504711 | K5: 2.9249529 | L5: 2.6126789 | M5: -0.53513029 | N5: -0.29126158 | O5: -0.43501302 | P5: 0.12781075 | Q5: 0.68635613 | R5: 1.4450343 | S5: 1.4081364 | T5: 1.7577979 | U5: 2.3062475 | V5: 2.8824874 | W5: 2.5987195 | X5: -0.26484568 | Y5: -0.090781414 | Z5: -0.31181896 | AA5: -0.11172011 | AB5: 0.44366114 | AC5: 1.5712764 | AD5: 1.5005718 | AE5: 1.589614 | AF5: 2.0673227 | AG5: 2.8088479 | AH5: 2.3179109 | AI5: 0.077495249 | AJ5: 0.083209397 | AK5: -0.28108863 | AL5: 0.27026879 | AM5: 0.72383376 | AN5: 1.8740137 | AO5: 1.7048188 | AP5: 1.7517113 | AQ5: 2.3146098 | AR5: 2.9958084 | AS5: 2.0638714 | AT5: -1.6322343 | AU5: -0.95299059 | AV5: -1.610546 | AW5: -1.1654003 | AX5: -0.24395432 | AY5: 2.4662444 | AZ5: 3.6740393 | BA5: 2.5640409 | BB5: 2.8515548 | BC5: 3.8490643 | BD5: 3.2315254 | BE5: -1.1552307 | BF5: -0.26620532 | BG5: -0.55823831 | BH5: -0.24605374 | BI5: -0.88286085 | BJ5: -1.0127231 | BK5: -1.3841086 | BL5: -0.66998588 | BM5: -0.18604374 | BN5: 0.28406997 | BO5: 0.20388839 | BP5: -1.0013974 | BQ5: -0.38134586 | BR5: -0.65915819 | BS5: -0.24549331 | BT5: -0.24816513 | BU5: 0.47763897 | BV5: 0.50879879 | BW5: 0.83371984 | BX5: 1.1832471 | BY5: 1.7490713 | BZ5: 1.2862663
A6: ltv | B6: 2.7072148 | C6: 2.2880395 | D6: 2.0027207 | E6: 2.5931537 | F6: 3.7446502 | G6: 3.3881857 | H6: 3.5073793 | I6: 4.0402816 | J6: 3.9702313 | K6: 4.2537913 | L6: 3.9510615 | M6: 5.0332926 | N6: 5.5678321 | O6: 5.235131 | P6: 5.3286289 | Q6: 5.1245756 | R6: 5.2098344 | S6: 5.1666469 | T6: 6.0848516 | U6: 6.1510731 | V6: 6.2080978 | W6: 5.3992753 | X6: 6.1354791 | Y6: 6.0717535 | Z6: 4.5804624 | AA6: 5.1378366 | AB6: 5.7066459 | AC6: 5.5483695 | AD6: 5.2166813 | AE6: 6.1403637 | AF6: 6.0382608 | AG6: 6.2534723 | AH6: 5.4380796 | AI6: 2.4767312 | AJ6: 2.1566317 | AK6: 0.82751227 | AL6: 1.0685351 | AM6: 1.32396 | AN6: 1.3976667 | AO6: 0.86631646 | AP6: 0.47398655 | AQ6: 0.45527757 | AR6: 0.48685779 | AS6: -0.34927165 | AT6: 2.6273819 | AU6: 1.8482391 | AV6: 1.7170448 | AW6: 1.9627113 | AX6: 1.7519385 | AY6: 1.3235352 | AZ6: 1.517698 | BA6: 1.9215073 | BB6: 1.8477536 | BC6: 1.6963273 | BD6: 1.2281394 | BE6: -3.6348155 | BF6: -4.8715329 | BG6: -4.102263 | BH6: -0.95598475 | BI6: -1.5608471 | BJ6: -1.5029132 | BK6: -0.72557978 | BL6: -0.32987472 | BM6: -0.515438 | BN6: -0.24231637 | BO6: 0.42277832 | BP6: =BP7-BP5 -> 0.50648984 | BQ6: -0.12326585 | BR6: -0.36969668 | BS6: 1.7502492 | BT6: 1.2521387 | BU6: 1.3408715 | BV6: 1.6509753 | BW6: 2.3823476 | BX6: 2.0616616 | BY6: 2.0327365 | BZ6: 1.8643971
A7: recltv | B7: 2.1747083 | C7: 2.0352244 | D7: 1.4919056 | E7: 2.5286881 | F7: 4.1533463 | G7: 4.644717 | H7: 4.7754977 | I7: 6.0017983 | J7: 5.9207025 | K7: 7.1787442 | L7: 6.5637405 | M7: 4.4981623 | N7: 5.2765706 | O7: 4.800118 | P7: 5.4564396 | Q7: 5.8109318 | R7: 6.6548687 | S7: 6.5747833 | T7: 7.8426495 | U7: 8.4573206 | V7: 9.0905852 | W7: 7.9979948 | X7: 5.8706334 | Y7: 5.9809721 | Z7: 4.2686434 | AA7: 5.0261164 | AB7: 6.150307 | AC7: 7.1196459 | AD7: 6.717253 | AE7: 7.7299777 | AF7: 8.1055835 | AG7: 9.0623202 | AH7: 7.7559905 | AI7: 2.5542264 | AJ7: 2.2398411 | AK7: 0.54642364 | AL7: 1.3388039 | AM7: 2.0477938 | AN7: 3.2716804 | AO7: 2.5711353 | AP7: 2.2256978 | AQ7: 2.7698874 | AR7: 3.4826662 | AS7: 1.7145998 | AT7: 0.99514758 | AU7: 0.89524852 | AV7: 0.10649875 | AW7: 0.797311 | AX7: 1.5079842 | AY7: 3.7897796 | AZ7: 5.1917373 | BA7: 4.4855482 | BB7: 4.6993084 | BC7: 5.5453916 | BD7: 4.4596648 | BE7: -4.7900462 | BF7: -5.1377382 | BG7: -4.6605013 | BH7: -1.2020385 | BI7: -2.443708 | BJ7: -2.5156363 | BK7: -2.1096884 | BL7: -0.9998606 | BM7: -0.70148174 | BN7: 0.041753596 | BO7: 0.62666671 | BP7: -0.49490755 | BQ7: 0.50673926 | BR7: -1.0288549 | BS7: 1.5047559 | BT7: 1.0039736 | BU7: 1.8185104 | BV7: 2.1597741 | BW7: 3.2160674 | BX7: 3.2449087 | BY7: 3.7818078 | BZ7: 3.1506634
A8: RAGU Score | B8: 139.30791 | C8: 139.88661 | D8: 138.52153 | E8: 140.83196 | F8: 143.21609 | G8: 142.62636 | H8: 143.07081 | I8: 146.50792 | J8: 147.40985 | K8: 149.88444 | L8: 148.9885 | M8: 146.84378 | N8: 145.19277 | O8: 142.73922 | P8: 145.93849 | Q8: 148.12236 | R8: 147.15429 | S8: 147.07671 | T8: 149.75003 | U8: 151.21786 | V8: 153.73374 | W8: 153.3139 | X8: 145.86964 | Y8: 144.74358 | Z8: 142.05173 | AA8: 144.52778 | AB8: 146.96519 | AC8: 146.39455 | AD8: 145.22537 | AE8: 147.70674 | AF8: 149.01228 | AG8: 152.04259 | AH8: 151.58557 | AI8: 141.54211 | AJ8: 143.32001 | AK8: 140.62205 | AL8: 142.18719 | AM8: 145.69369 | AN8: 144.62557 | AO8: 141.68621 | AP8: 143.06426 | AQ8: 143.88156 | AR8: 144.04866 | AS8: 143.88453 | AT8: 134.04209 | AU8: 136.66434 | AV8: 135.69626 | AW8: 137.2846 | AX8: 137.72136 | AY8: 138.45571 | AZ8: 138.78801 | BA8: 141.11074 | BB8: 141.88319 | BC8: 144.17813 | BD8: 145.64841 | BE8: 137.21474 | BF8: 137.18421 | BG8: 136.2344 | BH8: 141.45039 | BI8: 139.39419 | BJ8: 138.13581 | BK8: 137.25869 | BL8: 140.26471 | BM8: 140.5363 | BN8: 142.47355 | BO8: 144.53418 | BP8: =SUM(BP3:BP6) -> 139.51265 | BQ8: =SUM(BQ3:BQ6) -> 139.60443 | BR8: 138.05032 | BS8: 142.15296 | BT8: 141.99342 | BU8: 141.29105 | BV8: 140.67045 | BW8: 143.72028 | BX8: 144.20917 | BY8: 146.05835 | BZ8: 146.82086
A11: FRN | B11: 2023 Q3 | C11: 2023 Q4 | D11: 2024 Q1 | E11: 2024 Q2 | F11: 2024 Q3 | G11: 2024 Q4 | H11: 2025 Q1 | I11: 2025 Q2 | J11: 2025 Q3 | K11: 2025 Q4 | L11: 2026 Q1
A12: Contract Model Score¹ | B12: 140.72103 | C12: 139.02514 | D12: 138.13163 | E12: 140.17356 | F12: 141.55375 | G12: 139.97097 | H12: 139.83315 | I12: 140.63434 | J12: 140.96388 | K12: 141.85749 | L12: 142.87187
A13: Shift to FRN 3.1 Score² | B13: 0 | C13: 0 | D13: 0 | E13: 0 | F13: 0 | G13: 0 | H13: 0 | I13: 0 | J13: 0 | K13: 0 | L13: 0
A14: Gross Loss Adjustments (Dealer Level, vehicle age, etc.)² | B14: 1.6245882 | C14: 0.89105376 | D14: -0.19253143 | E14: 0.30849242 | F14: 0.75767443 | G14: 0.52844615 | H14: 0.66878042 | I14: 1.2730461 | J14: 1.7966555 | K14: 2.7856639 | L14: 2.4440368
A15: Recovery Adjustments excluding LTV (Mileage, LOB, etc.)³ | B15: -0.53513029 | C15: -0.29126158 | D15: -0.43501302 | E15: 0.12781075 | F15: 0.68635613 | G15: 1.4450343 | H15: 1.4081364 | I15: 1.7577979 | J15: 2.3062475 | K15: 2.8824874 | L15: 2.5987195
A16: BBLTV Adjustments⁴ | B16: 5.0332926 | C16: 5.5678321 | D16: 5.235131 | E16: 5.3286289 | F16: 5.1245756 | G16: 5.2098344 | H16: 5.1666469 | I16: 6.0848516 | J16: 6.1510731 | K16: 6.2080978 | L16: 5.3992753
A17: RAGU Score | B17: 146.84378 | C17: 145.19277 | D17: 142.73922 | E17: 145.93849 | F17: 148.12236 | G17: 147.15429 | H17: 147.07671 | I17: 149.75003 | J17: 151.21786 | K17: 153.73374 | L17: 153.3139
B18: 142.34561 | C18: 139.9162 | D18: 137.9391 | E18: 140.48205 | F18: 142.31143 | G18: 140.49942 | H18: 140.50193 | I18: 141.90738 | J18: 142.76054 | K18: 144.64315 | L18: 145.3159
A21: STG
A22: Contract Model Score¹
A23: Shift to FRN 3.1 Score²
A24: Gross Loss Adjustments (Dealer Level, vehicle age, etc.)²
A25: Recovery Adjustments excluding LTV (Mileage, LOB, etc.)³
A26: BBLTV Adjustments⁴
A27: RAGU Score
A30: FLD
A31: Contract Model Score¹
A32: Shift to FRN 3.1 Score²
A33: Gross Loss Adjustments (Dealer Level, vehicle age, etc.)²
A34: Recovery Adjustments excluding LTV (Mileage, LOB, etc.)³
... A47: RAGU Score
A51: POS | B51: 2023 Q3 | C51: 2023 Q4 | D51: 2024 Q1 | E51: 2024 Q2 | F51: 2024 Q3 | G51: 2024 Q4 | H51: 2025 Q1 | I51: 2025 Q2 | J51: 2025 Q3 | K51: 2025 Q4 | L51: 2026 Q1
A52: Contract Model Score | B52: 139.07412 | C52: 138.9461 | D52: 138.34968 | E52: 139.22436 | F52: 139.53563 | G52: 138.6092 | H52: 138.29936 | I52: 139.10189 | J52: 139.41596 | K52: 140.32 | L52: 141.62088
A53: Model Score | B53: -0.63837415 | C53: -0.5046117 | D53: 0.0040064067 | E53: 0.0019423191 | F53: -0.0011499063 | G53: -0.0032891709 | H53: -0.0010866271 | I53: -0.011151167 | J53: -0.0091706184 | K53: -0.0095421664 | L53: -3.023251e-05
A54: Gross Loss Adjustments (Dealer level, high PTI, etc.) | B54: 0.93343132 | C54: 1.162946 | D54: 0.7294941 | E54: 1.4238402 | F54: 1.4538116 | G54: 0.86334079 | H54: 0.21131625 | I54: 1.4023257 | J54: 1.5483029 | K54: 1.9565456 | L54: 2.0743527
A55: Recovery Adjustments excluding LTV (Mileage, vehicle type, etc.) | B55: -3.0640587 | C55: -2.3321053 | D55: -2.8143854 | E55: -2.3144091 | F55: -2.3932679 | G55: -1.6793889 | H55: -1.5987119 | I55: -1.2958988 | J55: -1.0729186 | K55: -0.59155057 | L55: -1.1132246
A56: LTV Adjustments | B56: 3.0640587 | C56: 2.3321053 | D56: 2.8143854 | E56: 2.3144091 | F56: 2.3932679 | G56: 1.6793889 | H56: 1.5987119 | I56: 1.2958988 | J56: 1.0729186 | K56: 0.59155057 | L56: 1.1132246
A57: RAGU Score | B57: 139.36918 | C57: 139.60443 | D57: 139.08318 | E57: 140.65014 | F57: 140.98829 | G57: 139.46925 | H57: 138.50959 | I57: 140.49306 | J57: 140.95509 | K57: 142.267 | L57: 143.6952
A58: LTV
A65: KMX | B65: 2023 Q3 | C65: 2023 Q4 | D65: 2024 Q1 | E65: 2024 Q2 | F65: 2024 Q3 | G65: 2024 Q4 | H65: 2025 Q1 | I65: 2025 Q2 | J65: 2025 Q3 | K65: 2025 Q4 | L65: 2026 Q1
A66: Contract Model Score² | B66: 140.50459 | C66: 140.56078 | D66: 139.56825 | E66: 140.43212 | F66: 139.88511 | G66: 139.76782 | H66: 139.70877 | I66: 139.86672 | J66: 139.91791 | K66: 140.94205 | L66: 141.8801
A67: Shift to Mountain3 Score³ | B67: 0 | C67: 0 | F67: 0 | G67: 0 | H67: 0
...

Sheet POS decomp
A1: lookup | B1: time | C1: gl | D1: recltv | E1: RAGU Score | AN1: measures | AO1: AN 2023 Q3 | AP1: AN 2023 Q4 | AQ1: AN 2024 Q1 | AR1: AN 2024 Q2 | AS1: AN 2024 Q3 | AT1: AN 2024 Q4 | AU1: AN 2025 Q1 | AV1: AN 2025 Q2 | AW1: AN 2025 Q3 | AX1: AN 2025 Q4 | AY1: AN 2026 Q1
A2: AN 2023 Q3 | B2: 2023 Q3 | C2: 0.6947113 | D2: 2.1747083 | E2: 139.30791 | I2: 2023 Q3 | J2: 2023 Q4 | K2: 2024 Q1 | L2: 2024 Q2 | M2: 2024 Q3 | N2: 2024 Q4 | O2: 2025 Q1 | P2: 2025 Q2 | Q2: 2025 Q3 | R2: 2025 Q4 | S2: 2026 Q1 | AB2: 2023 Q3 | AC2: 2023 Q4 | AD2: 2024 Q1 | AE2: 2024 Q2 | AF2: 2024 Q3 | AG2: 2024 Q4 | AH2: 2025 Q1 | AI2: 2025 Q2 | AJ2: 2025 Q3 | AK2: 2025 Q4 | AL2: 2026 Q1 | AO2: 2023 Q3 | AP2: 2023 Q4 | AQ2: 2024 Q1 | AR2: 2024 Q2 | AS2: 2024 Q3 | AT2: 2024 Q4 | AU2: 2025 Q1 | AV2: 2025 Q2 | AW2: 2025 Q3 | AX2: 2025 Q4 | AY2: 2026 Q1
A3: AN 2023 Q4 | B3: 2023 Q4 | C3: 0.83003342 | D3: 2.0352244 | E3: 139.88661 | H3: AN | I3: 2.1747083 | J3: 2.0352244 | K3: 1.4919056 | L3: 2.5286881 | M3: 4.1533463 | N3: 4.644717 | O3: 4.7754977 | P3: 6.0017983 | Q3: 5.9207025 | R3: 7.1787442 | S3: 6.5637405 | AA3: AN | AB3: 0.6947113 | AC3: 0.83003342 | AD3: 0.65750359 | AE3: 1.1812862 | AF3: 0.97222553 | AG3: 1.180284 | AH3: 1.4582901 | AI3: 2.4723015 | AJ3: 2.9310683 | AK3: 3.3295966 | AL3: 2.1031239 | AN3: AN | AO3: 136.43849 | AP3: 137.02135 | AQ3: 136.37212 | AR3: 137.12198 | AS3: 138.09052 | AT3: 136.80136 | AU3: 136.83702 | AV3: 138.03382 | AW3: 138.55808 | AX3: 139.3761 | AY3: 140.32164
A4: AN 2024 Q1 | B4: 2024 Q1 | C4: 0.65750359 | D4: 1.4919056 | E4: 138.52153 | H4: FRN | I4: 4.4981623 | J4: 5.2765706 | K4: 4.800118 | L4: 5.4564396 | M4: 5.8109318 | N4: 6.6548687 | O4: 6.5747833 | P4: 7.8426495 | Q4: 8.4573206 | R4: 9.0905852 | S4: 7.9979948 | AA4: FRN | AB4: 1.6245882 | AC4: 0.89105376 | AD4: -0.19253143 | AE4: 0.30849242 | AF4: 0.75767443 | AG4: 0.52844615 | AH4: 0.66878042 | AI4: 1.2730461 | AJ4: 1.7966555 | AK4: 2.7856639 | AL4: 2.4440368 | AN4: FRN 2023 Q3 | AO4: 140.72103 | AP4: 139.02514 | AQ4: 138.13163 | AR4: 140.17356 | AS4: 141.55375 | AT4: 139.97097 | AU4: 139.83315 | AV4: 140.63434 | AW4: 140.96388 | AX4: 141.85749 | AY4: 142.87187
A5: AN 2024 Q2 | B5: 2024 Q2 | C5: 1.1812862 | D5: 2.5286881 | E5: 140.83196 | H5: STG | I5: 5.8706334 | J5: 5.9809721 | K5: 4.2686434 | L5: 5.0261164 | M5: 6.150307 | N5: 7.1196459 | O5: 6.717253 | P5: 7.7299777 | Q5: 8.1055835 | R5: 9.0623202 | S5: 7.7559905 | AA5: STG | AB5: 1.4591709 | AC5: 1.2751302 | AD5: 1.0228541 | AE5: 2.0236416 | AF5: 2.2713522 | AG5: 2.0658579 | AH5: 1.8397214 | AI5: 2.0295688 | AJ5: 2.2461463 | AK5: 2.9427504 | AL5: 2.3362459 | AN5: STG 2023 Q3 | AO5: 138.53984 | AP5: 137.48747 | AQ5: 136.76023 | AR5: 137.47802 | AS5: 138.54354 | AT5: 137.20905 | AU5: 136.6684 | AV5: 137.94719 | AW5: 138.66055 | AX5: 140.03752 | AY5: 141.49333
A6: AN 2024 Q3 | B6: 2024 Q3 | C6: 0.97222553 | D6: 4.1533463 | E6: 143.21609 | H6: FLD | I6: 2.5542264 | J6: 2.2398411 | K6: 0.54642364 | L6: 1.3388039 | M6: 2.0477938 | N6: 3.2716804 | O6: 2.5711353 | P6: 2.2256978 | Q6: 2.7698874 | R6: 3.4826662 | S6: 1.7145998 | AA6: FLD | AB6: 1.0312225 | AC6: 1.5139703 | AD6: 1.5512225 | AE6: 2.4386011 | AF6: 3.2825892 | AG6: 2.9662031 | AH6: 2.4076495 | AI6: 2.4907613 | AJ6: 3.0095789 | AK6: 1.6204382 | AL6: 1.1822025 | AN6: FLD 2023 Q3 | AO6: 137.95666 | AP6: 139.5662 | AQ6: 138.5244 | AR6: 138.40978 | AS6: 140.36331 | AT6: 138.38769 | AU6: 136.70743 | AV6: 138.3478 | AW6: 138.1021 | AX6: 138.94555 | AY6: 140.98773
A7: AN 2024 Q4 | B7: 2024 Q4 | C7: 1.180284 | D7: 4.644717 | E7: 142.62636 | H7: ENT | I7: 0.99514758 | J7: 0.89524852 | K7: 0.10649875 | L7: 0.797311 | M7: 1.5079842 | N7: 3.7897796 | O7: 5.1917373 | P7: 4.4855482 | Q7: 4.6993084 | R7: 5.5453916 | S7: 4.4596648 | AA7: ENT | AB7: -0.72060842 | AC7: 0.4554259 | AD7: -0.58479913 | AE7: -0.32981376 | AF7: -0.47903773 | AG7: -0.28282436 | AH7: -0.97520672 | AI7: 0.20726925 | AJ7: 0.17758706 | AK7: 1.4255253 | AL7: 1.653816 | AN7: ENT 2023 Q3 | AO7: 133.76755 | AP7: 135.31367 | AQ7: 136.17456 | AR7: 136.8171 | AS7: 136.69241 | AT7: 134.94875 | AU7: 134.57148 | AV7: 136.41792 | AW7: 137.0063 | AX7: 137.20721 | AY7: 139.53493
A8: AN 2025 Q1 | B8: 2025 Q1 | C8: 1.4582901 | D8: 4.7754977 | E8: 143.07081 | H8: KMX | I8: -4.7900462 | J8: -5.1377382 | K8: -4.6605013 | L8: -1.2020385 | M8: -2.443708 | N8: -2.5156363 | O8: -2.1096884 | P8: -0.9998606 | Q8: -0.70148174 | R8: 0.041753596 | S8: 0.62666671 | AA8: KMX | AB8: 1.500187 | AC8: 1.7611724 | AD8: 1.326646 | AE8: 2.2203145 | AF8: 1.9527827 | AG8: 0.88362919 | AH8: -0.34039323 | AI8: 1.3978451 | AJ8: 1.3198684 | AK8: 1.489745 | AL8: 2.0379889 | AN8: KMX 2023 Q3 | AO8: 140.50459 | AP8: 140.56078 | AQ8: 139.56825 | AR8: 140.43212 | AS8: 139.88511 | AT8: 139.76782 | AU8: 139.70877 | AV8: 139.86672 | AW8: 139.91791 | AX8: 140.94205 | AY8: 141.86953
A9: AN 2025 Q2 | B9: 2025 Q2 | C9: 2.4723015 | D9: 6.0017983 | E9: 146.50792 | H9: POS | I9: -0.49490755 | J9: 0.50673926 | K9: -1.0288549 | L9: 1.5047559 | M9: 1.0039736 | N9: 1.8185104 | O9: 2.1597741 | P9: 3.2160674 | Q9: 3.2449087 | R9: 3.7818078 | S9: 3.1506634 | AA9: POS | AB9: 0.93343132 | AC9: 1.162946 | AD9: 0.7294941 | AE9: 1.4238402 | AF9: 1.4538116 | AG9: 0.86334079 | AH9: 0.21131625 | AI9: 1.4023257 | AJ9: 1.5483029 | AK9: 1.9565456 | AL9: 2.0460009 | AN9: POS 2023 Q3 | AO9: 139.07412 | AP9: 138.9461 | AQ9: 138.34968 | AR9: 139.22436 | AS9: 139.53563 | AT9: 138.6092 | AU9: 138.29936 | AV9: 139.10189 | AW9: 139.41596 | AX9: 140.32 | AY9: 141.6242
A10: AN 2025 Q3 | B10: 2025 Q3 | C10: 2.9310683 | D10: 5.9207025 | E10: 147.40985
A11: AN 2025 Q4 | B11: 2025 Q4 | C11: 3.3295966 | D11: 7.1787442 | E11: 149.88444 | I11: 2023 Q3 | J11: 2023 Q4 | K11: 2024 Q1 | L11: 2024 Q2 | M11: 2024 Q3 | N11: 2024 Q4 | O11: 2025 Q1 | P11: 2025 Q2 | Q11: 2025 Q3 | R11: 2025 Q4 | S11: 2026 Q1 | AB11: 2023 Q3 | AC11: 2023 Q4 | AD11: 2024 Q1 | AE11: 2024 Q2 | AF11: 2024 Q3 | AG11: 2024 Q4 | AH11: 2025 Q1 | AI11: 2025 Q2 | AJ11: 2025 Q3 | AK11: 2025 Q4 | AL11: 2026 Q1 | AO11: 2023 Q3 | AP11: 2023 Q4 | AQ11: 2024 Q1 | AR11: 2024 Q2 | AS11: 2024 Q3 | AT11: 2024 Q4 | AU11: 2025 Q1 | AV11: 2025 Q2 | AW11: 2025 Q3 | AX11: 2025 Q4 | AY11: 2026 Q1
A12: AN 2026 Q1 | B12: 2026 Q1 | C12: 2.1031239 | D12: 6.5637405 | E12: 148.9885 | H12: AN | I12: 0.070929096 | J12: 0.074291945 | K12: 0.058184072 | L12: 0.058338772 | M12: 0.050205911 | N12: 0.051413163 | O12: 0.057133574 | P12: 0.063714886 | Q12: 0.062308989 | R12: 0.055795476 | S12: 0.050346189 | AA12: AN | AB12: 0.070929096 | AC12: 0.074291945 | AD12: 0.058184072 | AE12: 0.058338772 | AF12: 0.050205911 | AG12: 0.051413163 | AH12: 0.057133574 | AI12: 0.063714886 | AJ12: 0.062308989 | AK12: 0.055795476 | AL12: 0.050346189 | AN12: AN | AO12: 0.070929096 | AP12: 0.074291945 | AQ12: 0.058184072 | AR12: 0.058338772 | AS12: 0.050205911 | AT12: 0.051413163 | AU12: 0.057133574 | AV12: 0.063714886 | AW12: 0.062308989 | AX12: 0.055795476 | AY12: 0.050346189
A13: FRN 2023 Q3 | B13: 2023 Q3 | C13: 1.6245882 | D13: 4.4981623 | E13: 146.84378 | H13: FRN | I13: 0.13173055 | J13: 0.20736686 | K13: 0.16866511 | L13: 0.19601919 | M13: 0.17732092 | N13: 0.19095899 | O13: 0.17853916 | P13: 0.19503196 | Q13: 0.18284774 | R13: 0.16681261 | S13: 0.14858861 | AA13: FRN | AB13: 0.13173055 | AC13: 0.20736686 | AD13: 0.16866511 | AE13: 0.19601919 | AF13: 0.17732092 | AG13: 0.19095899 | AH13: 0.17853916 | AI13: 0.19503196 | AJ13: 0.18284774 | AK13: 0.16681261 | AL13: 0.14858861 | AN13: FRN | AO13: 0.13173055 | AP13: 0.20736686 | AQ13: 0.16866511 | AR13: 0.19601919 | AS13: 0.17732092 | AT13: 0.19095899 | AU13: 0.17853916 | AV13: 0.19503196 | AW13: 0.18284774 | AX13: 0.16681261 | AY13: 0.14858861
A14: FRN 2023 Q4 | B14: 2023 Q4 | C14: 0.89105376 | D14: 5.2765706 | E14: 145.19277 | H14: STG | I14: 0.087174269 | J14: 0.12225414 | K14: 0.088081451 | L14: 0.12671234 | M14: 0.11313255 | N14: 0.11311045 | O14: 0.11209916 | P14: 0.12922528 | Q14: 0.11076505 | R14: 0.10202236 | S14: 0.09685136 | AA14: STG | AB14: 0.087174269 | AC14: 0.12225414 | AD14: 0.088081451 | AE14: 0.12671234 | AF14: 0.11313255 | AG14: 0.11311045 | AH14: 0.11209916 | AI14: 0.12922528 | AJ14: 0.11076505 | AK14: 0.10202236 | AL14: 0.09685136 | AN14: STG | AO14: 0.087174269 | AP14: 0.12225414 | AQ14: 0.088081451 | AR14: 0.12671234 | AS14: 0.11313255 | AT14: 0.11311045 | AU14: 0.11209916 | AV14: 0.12922528 | AW14: 0.11076505 | AX14: 0.10202236 | AY14: 0.09685136
A15: FRN 2024 Q1 | B15: 2024 Q1 | C15: -0.19253143 | D15: 4.800118 | E15: 142.73922 | H15: FLD | I15: 0.04692546 | J15: 0.041137795 | K15: 0.034871177 | L15: 0.047661722 | M15: 0.035567417 | N15: 0.034023293 | O15: 0.044575499 | P15: 0.044732128 | Q15: 0.052429385 | R15: 0.061369675 | S15: 0.054321767 | AA15: FLD | AB15: 0.04692546 | AC15: 0.041137795 | AD15: 0.034871177 | AE15: 0.047661722 | AF15: 0.035567417 | AG15: 0.034023293 | AH15: 0.044575499 | AI15: 0.044732128 | AJ15: 0.052429385 | AK15: 0.061369675 | AL15: 0.054321767 | AN15: FLD | AO15: 0.04692546 | AP15: 0.041137795 | AQ15: 0.034871177 | AR15: 0.047661722 | AS15: 0.035567417 | AT15: 0.034023293 | AU15: 0.044575499 | AV15: 0.044732128 | AW15: 0.052429385 | AX15: 0.061369675 | AY15: 0.054321767
A16: FRN 2024 Q2 | B16: 2024 Q2 | C16: 0.30849242 | D16: 5.4564396 | E16: 145.93849 | H16: ENT | I16: 0.22533796 | J16: 0.21369115 | K16: 0.14808641 | L16: 0.13590997 | M16: 0.13206647 | N16: 0.14770705 | O16: 0.1545606 | P16: 0.14292378 | Q16: 0.13160231 | R16: 0.12908883 | S16: 0.098914219 | AA16: ENT | AB16: 0.22533796 | AC16: 0.21369115 | AD16: 0.14808641 | AE16: 0.13590997 | AF16: 0.13206647 | AG16: 0.14770705 | AH16: 0.1545606 | AI16: 0.14292378 | AJ16: 0.13160231 | AK16: 0.12908883 | AL16: 0.098914219 | AN16: ENT | AO16: 0.22533796 | AP16: 0.21369115 | AQ16: 0.14808641 | AR16: 0.13590997 | AS16: 0.13206647 | AT16: 0.14770705 | AU16: 0.1545606 | AV16: 0.14292378 | AW16: 0.13160231 | AX16: 0.12908883 | AY16: 0.098914219
A17: FRN 2024 Q3 | B17: 2024 Q3 | C17: 0.75767443 | D17: 5.8109318 | E17: 148.12236 | H17: KMX | I17: 0.43790266 | J17: 0.34125811 | K17: 0.50211178 | L17: 0.435358 | M17: 0.49170673 | N17: 0.46278705 | O17: 0.453092 | P17: 0.42437197 | Q17: 0.46004653 | R17: 0.48491105 | S17: 0.55097786 | AA17: KMX | AB17: 0.43790266 | AC17: 0.34125811 | AD17: 0.50211178 | AE17: 0.435358 | AF17: 0.49170673 | AG17: 0.46278705 | AH17: 0.453092 | AI17: 0.42437197 | AJ17: 0.46004653 | AK17: 0.48491105 | AL17: 0.55097786 | AN17: KMX | AO17: 0.43790266 | AP17: 0.34125811 | AQ17: 0.50211178 | AR17: 0.435358 | AS17: 0.49170673 | AT17: 0.46278705 | AU17: 0.453092 | AV17: 0.42437197 | AW17: 0.46004653 | AX17: 0.48491105 | AY17: 0.55097786
A18: FRN 2024 Q4 | B18: 2024 Q4 | C18: 0.52844615 | D18: 6.6548687 | E18: 147.15429
A19: FRN 2025 Q1 | B19: 2025 Q1 | C19: 0.66878042 | D19: 6.5747833 | E19: 147.07671
A20: FRN 2025 Q2 | B20: 2025 Q2 | C20: 1.2730461 | D20: 7.8426495 | E20: 149.75003 | H20: rec+ltv | I20: 2023 Q3 | J20: 2023 Q4 | K20: 2024 Q1 | L20: 2024 Q2 | M20: 2024 Q3 | N20: 2024 Q4 | O20: 2025 Q1 | P20: 2025 Q2 | Q20: 2025 Q3 | R20: 2025 Q4 | S20: 2026 Q1 | AA20: GL | AB20: 2023 Q3 | AC20: 2023 Q4 | AD20: 2024 Q1 | AE20: 2024 Q2 | AF20: 2024 Q3 | AG20: 2024 Q4 | AH20: 2025 Q1 | AI20: 2025 Q2 | AJ20: 2025 Q3 | AK20: 2025 Q4 | AL20: 2026 Q1 | AN20: GL | AO20: 2023 Q3 | AP20: 2023 Q4 | AQ20: 2024 Q1 | AR20: 2024 Q2 | AS20: 2024 Q3 | AT20: 2024 Q4 | AU20: 2025 Q1 | AV20: 2025 Q2 | AW20: 2025 Q3 | AX20: 2025 Q4 | AY20: 2026 Q1
A21: FRN 2025 Q3 | B21: 2025 Q3 | C21: 1.7966555 | D21: 8.4573206 | E21: 151.21786 | H21: KMX | I21: =I8*I17 -> -2.097574 | J21: =J8*J17 -> -1.7532948 | K21: =K8*K17 -> -2.3400926 | L21: =L8*L17 -> -0.52331708 | M21: =M8*M17 -> -1.2015877 | N21: =N8*N17 -> -1.1642039 | O21: =O8*O17 -> -0.95588293 | P21: =P8*P17 -> -0.42431282 | ... S21: =S8*S17 -> 0.34527948 | AA21: KMX | AB21: =AB8*AB17 -> 0.65693586 | AC21: =AC8*AC17 -> 0.60101438 | AD21: =AD8*AD17 -> 0.66612457 | AE21: =AE8*AE17 -> 0.96663166 | AF21: =AF8*AF17 -> 0.96019638 | AG21: =AG8*AG17 -> 0.40893214 | AH21: =AH8*AH17 -> -0.15422945 | AI21: =AI8*AI17 -> 0.59320628 | ... AL21: =AL8*AL17 -> 1.1228868 | AN21: KMX | AO21: =AO8*AO17 -> 61.527336 | AP21: =AP8*AP17 -> 47.967506 | AQ21: =AQ8*AQ17 -> 70.078862 | AR21: =AR8*AR17 -> 61.138246 | AS21: =AS8*AS17 -> 68.782453 | AT21: =AT8*AT17 -> 64.682736 | AU21: =AU8*AU17 -> 63.300925 | AV21: =AV8*AV17 -> 59.355517 | ... AY21: =AY8*AY17 -> 78.166967
A22: FRN 2025 Q4 | B22: 2025 Q4 | C22: 2.7856639 | D22: 9.0905852 | E22: 153.73374 | H22: AN | I22: =I3*I12 -> 0.15425009 | J22: =J3*J12 -> 0.15120078 | K22: =K3*K12 -> 0.08680514 | L22: =L3*L12 -> 0.14752056 | M22: =M3*M12 -> 0.20852254 | N22: =N3*N12 -> 0.23879959 | O22: =O3*O12 -> 0.27284125 | P22: =P3*P12 -> 0.38240389 | ... S22: =S3*S12 -> 0.33045932 | AA22: AN | AB22: =AB3*AB12 -> 0.049275244 | AC22: =AC3*AC12 -> 0.061664797 | AD22: =AD3*AD12 -> 0.038256236 | AE22: =AE3*AE12 -> 0.06891479 | AF22: =AF3*AF12 -> 0.048811468 | AG22: =AG3*AG12 -> 0.060682134 | AH22: =AH3*AH12 -> 0.083317327 | AI22: =AI3*AI12 -> 0.15752241 | ... AL22: =AL3*AL12 -> 0.10588427 | AN22: AN | AO22: =AO3*AO12 -> 9.677459 | AP22: =AP3*AP12 -> 10.179583 | AQ22: =AQ3*AQ12 -> 7.9346852 | AR22: =AR3*AR12 -> 7.9995282 | AS22: =AS3*AS12 -> 6.9329604 | AT22: =AT3*AT12 -> 7.0333904 | AU22: =AU3*AU12 -> 7.8179883 | AV22: =AV3*AV12 -> 8.7948091 | ... AY22: =AY3*AY12 -> 7.0646598
A23: FRN 2026 Q1 | B23: 2026 Q1 | C23: 2.4440368 | D23: 7.9979948 | E23: 153.3139 | H23: FRN | I23: =I4*I13 -> 0.5925454 | J23: =J4*J13 -> 1.0941859 | K23: =K4*K13 -> 0.80961243 | L23: =L4*L13 -> 1.0695669 | M23: =M4*M13 -> 1.0303998 | N23: =N4*N13 -> 1.270807 | O23: =O4*O13 -> 1.1738563 | P23: =P4*P13 -> 1.5295673 | ... S23: =S4*S13 -> 1.1884109 | AA23: FRN | AB23: =AB4*AB13 -> 0.2140079 | AC23: =AC4*AC13 -> 0.18477502 | AD23: =AD4*AD13 -> -0.032473335 | AE23: =AE4*AE13 -> 0.060470433 | AF23: =AF4*AF13 -> 0.13435153 | AG23: =AG4*AG13 -> 0.10091154 | AH23: =AH4*AH13 -> 0.1194035 | AI23: =AI4*AI13 -> 0.24828469 | ... AL23: =AL4*AL13 -> 0.36315603 | AN23: FRN | AO23: =AO4*AO13 -> 18.537258 | AP23: =AP4*AP13 -> 28.829207 | AQ23: =AQ4*AQ13 -> 23.297988 | AR23: =AR4*AR13 -> 27.476708 | AS23: =AS4*AS13 -> 25.100442 | AT23: =AT4*AT13 -> 26.728716 | AU23: =AU4*AU13 -> 24.965694 | AV23: =AV4*AV13 -> 27.42819 | ... AY23: =AY4*AY13 -> 21.229132
A24: STG 2023 Q3 | B24: 2023 Q3 | C24: 1.4591709 | D24: 5.8706334 | E24: 145.86964 | H24: STG | I24: =I5*I14 -> 0.51176818 | J24: =J5*J14 -> 0.73119863 | K24: =K5*K14 -> 0.37598831 | L24: =L5*L14 -> 0.636871 | M24: =M5*M14 -> 0.69579993 | N24: =N5*N14 -> 0.80530638 | O24: =O5*O14 -> 0.75299844 | P24: =P5*P14 -> 0.9989085 | ... S24: =S5*S14 -> 0.75117824 | AA24: STG | AB24: =AB5*AB14 -> 0.12720216 | AC24: =AC5*AC14 -> 0.15588995 | AD24: =AD5*AD14 -> 0.090094472 | AE24: =AE5*AE14 -> 0.25642037 | AF24: =AF5*AF14 -> 0.25696388 | AG24: =AG5*AG14 -> 0.23367012 | AH24: =AH5*AH14 -> 0.20623123 | AI24: =AI5*AI14 -> 0.26227159 | ... AL24: =AL5*AL14 -> 0.2262686 | AN24: STG | AO24: =AO5*AO14 -> 12.077109 | AP24: =AP5*AP14 -> 16.808413 | AQ24: =AQ5*AQ14 -> 12.04604 | AR24: =AR5*AR14 -> 17.420163 | AS24: =AS5*AS14 -> 15.673784 | AT24: =AT5*AT14 -> 15.519778 | AU24: =AU5*AU14 -> 15.320413 | AV24: =AV5*AV14 -> 17.826264 | ... AY24: =AY5*AY14 -> 13.703821
A25: STG 2023 Q4 | B25: 2023 Q4 | C25: 1.2751302 | D25: 5.9809721 | E25: 144.74358 | H25: FLD | I25: =I6*I15 -> 0.11985825 | J25: =J6*J15 -> 0.092142124 | K25: =K6*K15 -> 0.019054436 | L25: =L6*L15 -> 0.063809701 | M25: =M6*M15 -> 0.072834735 | N25: =N6*N15 -> 0.11131334 | O25: =O6*O15 -> 0.11460964 | P25: =P6*P15 -> 0.099560201 | ... S25: =S6*S15 -> 0.093140089 | AA25: FLD | AB25: =AB6*AB15 -> 0.048390588 | AC25: =AC6*AC15 -> 0.0622814 | AD25: =AD6*AD15 -> 0.054092955 | AE25: =AE6*AE15 -> 0.11622793 | AF25: =AF6*AF15 -> 0.11675322 | AG25: =AG6*AG15 -> 0.10092 | AH25: =AH6*AH15 -> 0.10732218 | AI25: =AI6*AI15 -> 0.11141705 | ... AL25: =AL6*AL15 -> 0.064219327 | AN25: FLD | AO25: =AO6*AO15 -> 6.4736796 | AP25: =AP6*AP15 -> 5.7414457 | AQ25: =AQ6*AQ15 -> 4.8305089 | AR25: =AR6*AR15 -> 6.5968485 | AS25: =AS6*AS15 -> 4.9923603 | AT25: =AT6*AT15 -> 4.7084047 | AU25: =AU6*AU15 -> 6.0938019 | AV25: =AV6*AV15 -> 6.1885914 | ... AY25: =AY6*AY15 -> 7.6587026
A26: STG 2024 Q1 | B26: 2024 Q1 | C26: 1.0228541 | D26: 4.2686434 | E26: 142.05173 | H26: ENT | I26: =I7*I16 -> 0.22424453 | J26: =J7*J16 -> 0.19130668 | K26: =K7*K16 -> 0.015771018 | L26: =L7*L16 -> 0.10836252 | M26: =M7*M16 -> 0.19915415 | N26: =N7*N16 -> 0.55977717 | O26: =O7*O16 -> 0.80243801 | P26: =P7*P16 -> 0.64109149 | ... S26: =S7*S16 -> 0.44112426 | AA26: ENT | AB26: =AB7*AB16 -> -0.16238043 | AC26: =AC7*AC16 -> 0.097320484 | AD26: =AD7*AD16 -> -0.086600805 | AE26: =AE7*AE16 -> -0.044824978 | AF26: =AF7*AF16 -> -0.06326482 | AG26: =AG7*AG16 -> -0.041775152 | AH26: =AH7*AH16 -> -0.15072853 | AI26: =AI7*AI16 -> 0.029623704 | ... AL26: =AL7*AL16 -> 0.16358592 | AN26: ENT | AO26: =AO7*AO16 -> 30.142908 | AP26: =AP7*AP16 -> 28.915333 | AQ26: =AQ7*AQ16 -> 20.165603 | AR26: =AR7*AR16 -> 18.594808 | AS26: =AS7*AS16 -> 18.052484 | AT26: =AT7*AT16 -> 19.932882 | AU26: =AU7*AU16 -> 20.799448 | AV26: =AV7*AV16 -> 19.497365 | ... AY26: =AY7*AY16 -> 13.801989
A27: STG 2024 Q2 | B27: 2024 Q2 | C27: 2.0236416 | D27: 5.0261164 | E27: 144.52778
A28: STG 2024 Q3 | B28: 2024 Q3 | C28: 2.2713522 | D28: 6.150307 | E28: 146.96519
A29: STG 2024 Q4 | B29: 2024 Q4 | C29: 2.0658579 | D29: 7.1196459 | E29: 146.39455 | H29: SUM | I29: =SUM(I21:I26) -> -0.49490755 | J29: =SUM(J21:J26) -> 0.50673926 | K29: =SUM(K21:K26) -> -1.0328613 | L29: =SUM(L21:L26) -> 1.5028136 | M29: =SUM(M21:M26) -> 1.0051235 | N29: =SUM(N21:N26) -> 1.8217996 | O29: =SUM(O21:O26) -> 2.1608607 | P29: =SUM(P21:P26) -> 3.2272186 | ... S29: =SUM(S21:S26) -> 3.1495923 | AA29: SUM | AB29: =SUM(AB21:AB26) -> 0.93343132 | AC29: =SUM(AC21:AC26) -> 1.162946 | AD29: =SUM(AD21:AD26) -> 0.7294941 | AE29: =SUM(AE21:AE26) -> 1.4238402 | AF29: =SUM(AF21:AF26) -> 1.4538116 | AG29: =SUM(AG21:AG26) -> 0.86334079 | AH29: =SUM(AH21:AH26) -> 0.21131625 | AI29: =SUM(AI21:AI26) -> 1.4023257 | ... AL29: =SUM(AL21:AL26) -> 2.0460009 | AN29: SUM | AO29: =SUM(AO21:AO26) -> 138.43575 | AP29: =SUM(AP21:AP26) -> 138.44149 | AQ29: =SUM(AQ21:AQ26) -> 138.35369 | AR29: =SUM(AR21:AR26) -> 139.2263 | AS29: =SUM(AS21:AS26) -> 139.53448 | AT29: =SUM(AT21:AT26) -> 138.60591 | AU29: =SUM(AU21:AU26) -> 138.29827 | AV29: =SUM(AV21:AV26) -> 139.09074 | ... AY29: =SUM(AY21:AY26) -> 141.62527
A30: STG 2025 Q1 | B30: 2025 Q1 | C30: 1.8397214 | D30: 6.717253 | E30: 145.22537 | I30: =SUMPRODUCT(I3:I8,I12:I17) -> -0.49490755 | J30: =SUMPRODUCT(J3:J8,J12:J17) -> 0.50673926 | K30: =SUMPRODUCT(K3:K8,K12:K17) -> -1.0328613 | L30: =SUMPRODUCT(L3:L8,L12:L17) -> 1.5028136 | M30: =SUMPRODUCT(M3:M8,M12:M17) -> 1.0051235 | N30: =SUMPRODUCT(N3:N8,N12:N17) -> 1.8217996 | O30: =SUMPRODUCT(O3:O8,O12:O17) -> 2.1608607 | P30: =SUMPRODUCT(P3:P8,P12:P17) -> 3.2272186 | ... S30: =SUMPRODUCT(S3:S8,S12:S17) -> 3.1495923
A31: STG 2025 Q2 | B31: 2025 Q2 | C31: 2.0295688 | D31: 7.7299777 | E31: 147.70674 | AN31: kmx | AO31: 140.50459 | AR31: 140.43212 | AU31: 139.70877 | AW31: 139.91791 | AY31: 141.86953
A32: STG 2025 Q3 | B32: 2025 Q3 | C32: 2.2461463 | D32: 8.1055835 | E32: 149.01228 | H32: nonkmx | I32: =SUM(I22:I26) -> 1.6026664 | J32: =SUM(J22:J26) -> 2.2600341 | K32: =SUM(K22:K26) -> 1.3072313 | L32: =SUM(L22:L26) -> 2.0261307 | M32: =SUM(M22:M26) -> 2.2067111 | N32: =SUM(N22:N26) -> 2.9860035 | O32: =SUM(O22:O26) -> 3.1167437 | P32: =SUM(P22:P26) -> 3.6515314 | ... S32: =SUM(S22:S26) -> 2.8043128 | AA32: nonkmx | AB32: =SUM(AB22:AB26) -> 0.27649545 | AC32: =SUM(AC22:AC26) -> 0.56193165 | AD32: =SUM(AD22:AD26) -> 0.063369523 | AE32: =SUM(AE22:AE26) -> 0.45720854 | AF32: =SUM(AF22:AF26) -> 0.49361527 | AG32: =SUM(AG22:AG26) -> 0.45440864 | AH32: =SUM(AH22:AH26) -> 0.3655457 | AI32: =SUM(AI22:AI26) -> 0.80911944 | ... AL32: =SUM(AL22:AL26) -> 0.92311414 | AN32: nonkmx | AO32: =(AO29-AO31*AO17)/(1-AO17) -> 136.82401 | AR32: =(AR29-AR31*AR17)/(1-AR17) -> 138.29658 | AU32: =(AU29-AU31*AU17)/(1-AU17) -> 137.12973 | AW32: =(AW29-AW31*AW17)/(1-AW17) -> 138.9713 | AY32: =(AY29-AY31*AY17)/(1-AY17) -> 141.32556
A33: STG 2025 Q4 | B33: 2025 Q4 | C33: 2.9427504 | D33: 9.0623202 | E33: 152.04259
A34: STG 2026 Q1 | B34: 2026 Q1 | C34: 2.3362459 | D34: 7.7559905 | E34: 151.58557 | AN34: kmx | AO34: 140.50459 | AP34: 140.43212 | AQ34: 139.70877 | AR34: 139.91791 | AS34: 141.86953
A35: FLD 2023 Q3 | B35: 2023 Q3 | C35: 1.0312225 | D35: 2.5542264 | E35: 141.54211 | AN35: nonkmx | AO35: 136.82401 | AP35: 138.29658 | AQ35: 137.12973 | AR35: 138.9713 | AS35: 141.32556
A36: FLD 2023 Q4 | B36: 2023 Q4 | C36: 1.5139703 | D36: 2.2398411 | E36: 143.32001
A37: FLD 2024 Q1 | B37: 2024 Q1 | C37: 1.5512225 | D37: 0.54642364 | E37: 140.62205
A38: FLD 2024 Q2 | B38: 2024 Q2 | C38: 2.4386011 | D38: 1.3388039 | E38: 142.18719
A39: FLD 2024 Q3 | B39: 2024 Q3 | C39: 3.2825892 | D39: 2.0477938 | E39: 145.69369
A40: FLD 2024 Q4 | B40: 2024 Q4 | C40: 2.9662031 | D40: 3.2716804 | E40: 144.62557
...

Sheet factory
A1: LOB | B1: =Main!B1 -> FLD
A2: Start | B2: =Main!B2 -> 2025 Q1
A3: End | B3: =Main!B3 -> 2025 Q4
C5: =B1 -> FLD | H5: =B1 -> FLD
C6: multipliers | D6: =B2 -> 2025 Q1 | E6: =B3 -> 2025 Q4 | H6: population % | I6: =B2 -> 2025 Q1 | J6: =B3 -> 2025 Q4 | L6: =B1 -> FLD | M6: =B2 -> 2025 Q1 | N6: =B3 -> 2025 Q4
C7: Previous ACA Chargeoff | D7: =INDEX(multipliers!$A3:$BD3,MATCH($B$1&" | "&D$6,Mult[#Headers], 0)) -> 1.0005481 | E7: =INDEX(multipliers!$A3:$BD3,MATCH($B$1&" | "&E$6,Mult[#Headers], 0)) -> 1.0002115 | H7: =populations!A2 -> prev_co_flag | I7: =INDEX(populations!$A2:$BD2,MATCH($B$1&" | "&I$6,flag[#Headers], 0)) -> 0.0054808171 | J7: =INDEX(populations!$A2:$BD2,MATCH($B$1&" | "&J$6,flag[#Headers], 0)) -> 0.0021152829 | L7: Good Dealer % | M7: =INDEX(dll[good_dealer],MATCH($B$1&" "&M$6,dll[lookup], 0)) -> 0.48391282 | N7: =INDEX(dll[good_dealer],MATCH($B$1&" "&N$6,dll[lookup], 0)) -> 0.5343
C8: Small Amount Financed | D8: =INDEX(multipliers!$A4:$BD4,MATCH($B$1&" | "&D$6,Mult[#Headers], 0)) -> 1.0005481 | E8: =INDEX(multipliers!$A4:$BD4,MATCH($B$1&" | "&E$6,Mult[#Headers], 0)) -> 1.0002115 | H8: =populations!A3 -> small_amt_financed_flag | I8: =INDEX(populations!$A3:$BD3,MATCH($B$1&" | "&I$6,flag[#Headers], 0)) -> 0.0004982561 | J8: =INDEX(populations!$A3:$BD3,MATCH($B$1&" | "&J$6,flag[#Headers], 0)) -> 0.00052882073 | L8: Bad Dealer % | M8: =INDEX(dll[bad_dealer],MATCH($B$1&" "&M$6,dll[lookup], 0)) -> 0.051282051 | N8: =INDEX(dll[bad_dealer],MATCH($B$1&" "&N$6,dll[lookup], 0)) -> 0.059375
C9: Zero Cash Down | D9: =INDEX(multipliers!$A5:$BD5,MATCH($B$1&" | "&D$6,Mult[#Headers], 0)) -> 1.0005481 | E9: =INDEX(multipliers!$A5:$BD5,MATCH($B$1&" | "&E$6,Mult[#Headers], 0)) -> 1.0002115 | H9: =populations!A4 -> pricing_change_flag | I9: =INDEX(populations!$A4:$BD4,MATCH($B$1&" | "&I$6,flag[#Headers], 0)) -> 1 | J9: =INDEX(populations!$A4:$BD4,MATCH($B$1&" | "&J$6,flag[#Headers], 0)) -> 1
C10: High Mileage | D10: =INDEX(multipliers!$A6:$BD6,MATCH($B$1&" | "&D$6,Mult[#Headers], 0)) -> 1.0012955 | E10: =INDEX(multipliers!$A6:$BD6,MATCH($B$1&" | "&E$6,Mult[#Headers], 0)) -> 1.0002115 | H10: =populations!A5 -> zero_cash_down_flag | I10: =INDEX(populations!$A5:$BD5,MATCH($B$1&" | "&I$6,flag[#Headers], 0)) -> 0.069755855 | J10: =INDEX(populations!$A5:$BD5,MATCH($B$1&" | "&J$6,flag[#Headers], 0)) -> 0.13326282
C11: High PTI | D11: =INDEX(multipliers!$A7:$BD7,MATCH($B$1&" | "&D$6,Mult[#Headers], 0)) -> 1.0012955 | E11: =INDEX(multipliers!$A7:$BD7,MATCH($B$1&" | "&E$6,Mult[#Headers], 0)) -> 1.0002115 | H11: =populations!A6 -> high_mileage_vehicle_flag | I11: =INDEX(populations!$A6:$BD6,MATCH($B$1&" | "&I$6,flag[#Headers], 0)) -> 0.0074738416 | J11: =INDEX(populations!$A6:$BD6,MATCH($B$1&" | "&J$6,flag[#Headers], 0)) -> 0
C12: Toyota/Honda | D12: =INDEX(multipliers!$A8:$BD8,MATCH($B$1&" | "&D$6,Mult[#Headers], 0)) -> 0.96003986 | E12: =INDEX(multipliers!$A8:$BD8,MATCH($B$1&" | "&E$6,Mult[#Headers], 0)) -> 0.94986779 | H12: =populations!A7 -> high_pti_flag | I12: =INDEX(populations!$A7:$BD7,MATCH($B$1&" | "&I$6,flag[#Headers], 0)) -> 0.0099651221 | J12: =INDEX(populations!$A7:$BD7,MATCH($B$1&" | "&J$6,flag[#Headers], 0)) -> 0.013220518 | L12: =B1 -> FLD | M12: =B2 -> 2025 Q1 | N12: =B3 -> 2025 Q4
C13: Theft Risk | D13: =INDEX(multipliers!$A9:$BD9,MATCH($B$1&" | "&D$6,Mult[#Headers], 0)) -> 0.96003986 | E13: =INDEX(multipliers!$A9:$BD9,MATCH($B$1&" | "&E$6,Mult[#Headers], 0)) -> 0.94986779 | H13: =populations!A8 -> car_make_penalty_flag | I13: =INDEX(populations!$A8:$BD8,MATCH($B$1&" | "&I$6,flag[#Headers], 0)) -> 0 | J13: =INDEX(populations!$A8:$BD8,MATCH($B$1&" | "&J$6,flag[#Headers], 0)) -> 0 | L13: Positive Fraud | M13: =INDEX(fraud[pos_fraud],MATCH($B$1&" "&M$12,fraud[lookup], 0)) -> 0.2137 | N13: =INDEX(fraud[pos_fraud],MATCH($B$1&" "&N$12,fraud[lookup], 0)) -> 0.1659
C14: 08_mcy_low_mileage | D14: =INDEX(multipliers!$A10:$BD10,MATCH($B$1&" | "&D$6,Mult[#Headers], 0)) -> 0.96003986 | E14: =INDEX(multipliers!$A10:$BD10,MATCH($B$1&" | "&E$6,Mult[#Headers], 0)) -> 0.94986779 | H14: =populations!A9 -> car_make_benefit_flag | I14: =INDEX(populations!$A9:$BD9,MATCH($B$1&" | "&I$6,flag[#Headers], 0)) -> 0.20627803 | J14: =INDEX(populations!$A9:$BD9,MATCH($B$1&" | "&J$6,flag[#Headers], 0)) -> 0.25171867 | L14: Negative Fraud | M14: =INDEX(fraud[neg_fraud],MATCH($B$1&" "&M$12,fraud[lookup], 0)) -> 0.032 | N14: =INDEX(fraud[neg_fraud],MATCH($B$1&" "&N$12,fraud[lookup], 0)) -> 0.0739
C15: Weekday/Weekend | D15: =INDEX(multipliers!$A11:$BD11,MATCH($B$1&" | "&D$6,Mult[#Headers], 0)) -> 0.95886497 | E15: =INDEX(multipliers!$A11:$BD11,MATCH($B$1&" | "&E$6,Mult[#Headers], 0)) -> 0.94915336 | H15: =populations!A10 -> theft_risk_flag | I15: =INDEX(populations!$A10:$BD10,MATCH($B$1&" | "&I$6,flag[#Headers], 0)) -> 0.064275037 | J15: =INDEX(populations!$A10:$BD10,MATCH($B$1&" | "&J$6,flag[#Headers], 0)) -> 0.03648863
C16: Student Loans | D16: =INDEX(multipliers!$A12:$BD12,MATCH($B$1&" | "&D$6,Mult[#Headers], 0)) -> 0.96787514 | E16: =INDEX(multipliers!$A12:$BD12,MATCH($B$1&" | "&E$6,Mult[#Headers], 0)) -> 0.9490828 | H16: =populations!A11 -> mcy_low_mileage_flag | I16: =INDEX(populations!$A11:$BD11,MATCH($B$1&" | "&I$6,flag[#Headers], 0)) -> 0 | J16: =INDEX(populations!$A11:$BD11,MATCH($B$1&" | "&J$6,flag[#Headers], 0)) -> 0
C17: Low PTI | D17: =INDEX(multipliers!$A13:$BD13,MATCH($B$1&" | "&D$6,Mult[#Headers], 0)) -> 0.96172353 | E17: =INDEX(multipliers!$A13:$BD13,MATCH($B$1&" | "&E$6,Mult[#Headers], 0)) -> 0.94256779 | H17: =populations!A12 -> weekend_flag | I17: =INDEX(populations!$A12:$BD12,MATCH($B$1&" | "&I$6,flag[#Headers], 0)) -> 0.30293971 | J17: =INDEX(populations!$A12:$BD12,MATCH($B$1&" | "&J$6,flag[#Headers], 0)) -> 0.29613961
C18: Chime | D18: =INDEX(multipliers!$A14:$BD14,MATCH($B$1&" | "&D$6,Mult[#Headers], 0)) -> 0.99006136 | E18: =INDEX(multipliers!$A14:$BD14,MATCH($B$1&" | "&E$6,Mult[#Headers], 0)) -> 0.95590668 | H18: =populations!A13 -> weekday_flag | I18: =INDEX(populations!$A13:$BD13,MATCH($B$1&" | "&I$6,flag[#Headers], 0)) -> 0.69706029 | J18: =INDEX(populations!$A13:$BD13,MATCH($B$1&" | "&J$6,flag[#Headers], 0)) -> 0.70386039
C19: Waiter/Seasonal | D19: =INDEX(multipliers!$A15:$BD15,MATCH($B$1&" | "&D$6,Mult[#Headers], 0)) -> 0.98939699 | E19: =INDEX(multipliers!$A15:$BD15,MATCH($B$1&" | "&E$6,Mult[#Headers], 0)) -> 0.95515159 | H19: =populations!A14 -> student_loan_flag | I19: =INDEX(populations!$A14:$BD14,MATCH($B$1&" | "&I$6,flag[#Headers], 0)) -> 0.26208271 | J19: =INDEX(populations!$A14:$BD14,MATCH($B$1&" | "&J$6,flag[#Headers], 0)) -> 0.20306716 | L19: =B1 -> FLD | M19: =B2 -> 2025 Q1 | N19: =B3 -> 2025 Q4
C20: Authorized Tradelines | D20: =INDEX(multipliers!$A16:$BD16,MATCH($B$1&" | "&D$6,Mult[#Headers], 0)) -> 0.99114741 | E20: =INDEX(multipliers!$A16:$BD16,MATCH($B$1&" | "&E$6,Mult[#Headers], 0)) -> 0.9571671 | H20: =populations!A15 -> student_loans_cutoff_date | I20: =INDEX(populations!$A15:$BD15,MATCH($B$1&" | "&I$6,flag[#Headers], 0)) -> 1 | J20: =INDEX(populations!$A15:$BD15,MATCH($B$1&" | "&J$6,flag[#Headers], 0)) -> 1 | L20: DQ MOB 3 | M20: =INDEX(dq[dq_3],MATCH($B$1&" "&M$19,dq[lookup], 0)) -> 0.186 | N20: =INDEX(dq[dq_3],MATCH($B$1&" "&N$19,dq[lookup], 0)) -> #N/A
C21: Fraud | D21: =INDEX(multipliers!$A17:$BD17,MATCH($B$1&" | "&D$6,Mult[#Headers], 0)) -> 0.98255731 | E21: =INDEX(multipliers!$A17:$BD17,MATCH($B$1&" | "&E$6,Mult[#Headers], 0)) -> 0.9499005 | H21: =populations!A16 -> low_pti_flag | I21: =INDEX(populations!$A16:$BD16,MATCH($B$1&" | "&I$6,flag[#Headers], 0)) -> 0.045341305 | J21: =INDEX(populations!$A16:$BD16,MATCH($B$1&" | "&J$6,flag[#Headers], 0)) -> 0.044949762 | L21: DQ MOB 6 | M21: =INDEX(dq[dq_6],MATCH($B$1&" "&M$19,dq[lookup], 0)) -> 0.2091 | N21: =INDEX(dq[dq_6],MATCH($B$1&" "&N$19,dq[lookup], 0)) -> #N/A
C22: Driver | D22: =INDEX(multipliers!$A18:$BD18,MATCH($B$1&" | "&D$6,Mult[#Headers], 0)) -> 0.98521821 | E22: =INDEX(multipliers!$A18:$BD18,MATCH($B$1&" | "&E$6,Mult[#Headers], 0)) -> 0.95366538 | H22: =populations!A17 -> nonkmx_chime_flag | I22: =INDEX(populations!$A17:$BD17,MATCH($B$1&" | "&I$6,flag[#Headers], 0)) -> 0.22720478 | J22: =INDEX(populations!$A17:$BD17,MATCH($B$1&" | "&J$6,flag[#Headers], 0)) -> 0.18085669 | L22: CO Rate MOB 6 | M22: =INDEX(dq[co_6],MATCH($B$1&" "&M$19,dq[lookup], 0)) -> 0.0356 | N22: =INDEX(dq[co_6],MATCH($B$1&" "&N$19,dq[lookup], 0)) -> #N/A
C23: Dealer Level Loss | D23: =INDEX(multipliers!$A19:$BD19,MATCH($B$1&" | "&D$6,Mult[#Headers], 0)) -> 0.90094692 | E23: =INDEX(multipliers!$A19:$BD19,MATCH($B$1&" | "&E$6,Mult[#Headers], 0)) -> 0.93240953 | H23: =populations!A18 -> seasonal_employment_pct | I23: =INDEX(populations!$A18:$BD18,MATCH($B$1&" | "&I$6,flag[#Headers], 0)) -> 0.0069755855 | J23: =INDEX(populations!$A18:$BD18,MATCH($B$1&" | "&J$6,flag[#Headers], 0)) -> 0.011634056 | L23: CO Rate MOB 12 | M23: =INDEX(dq[co_12],MATCH($B$1&" "&M$19,dq[lookup], 0)) -> 0.1288 | N23: =INDEX(dq[co_12],MATCH($B$1&" "&N$19,dq[lookup], 0)) -> #N/A
C24: Clip | D24: =INDEX(multipliers!$A20:$BD20,MATCH($B$1&" | "&D$6,Mult[#Headers], 0)) -> 0.90433308 | E24: =INDEX(multipliers!$A20:$BD20,MATCH($B$1&" | "&E$6,Mult[#Headers], 0)) -> 0.93068818 | H24: =populations!A19 -> waiter_employment_pct | I24: =INDEX(populations!$A19:$BD19,MATCH($B$1&" | "&I$6,flag[#Headers], 0)) -> 0.014449427 | J24: =INDEX(populations!$A19:$BD19,MATCH($B$1&" | "&J$6,flag[#Headers], 0)) -> 0.018508726
C25: Final Multplier | D25: =INDEX(multipliers!$A21:$BD21,MATCH($B$1&" | "&D$6,Mult[#Headers], 0)) -> 0.90433308 | E25: =INDEX(multipliers!$A21:$BD21,MATCH($B$1&" | "&E$6,Mult[#Headers], 0)) -> 0.93068818 | H25: =populations!A20 -> other_employment_pct | I25: =INDEX(populations!$A20:$BD20,MATCH($B$1&" | "&I$6,flag[#Headers], 0)) -> 0.97857499 | J25: =INDEX(populations!$A20:$BD20,MATCH($B$1&" | "&J$6,flag[#Headers], 0)) -> 0.96985722
C26: Weighted Multiplier | D26: =INDEX(multipliers!$A22:$BD22,MATCH($B$1&" | "&D$6,Mult[#Headers], 0)) -> 0.90369402 | E26: =INDEX(multipliers!$A22:$BD22,MATCH($B$1&" | "&E$6,Mult[#Headers], 0)) -> 0.93518247 | H26: =populations!A21 -> nonkmx_auth_tradelines_flag | I26: =INDEX(populations!$A21:$BD21,MATCH($B$1&" | "&I$6,flag[#Headers], 0)) -> 0.018933732 | J26: =INDEX(populations!$A21:$BD21,MATCH($B$1&" | "&J$6,flag[#Headers], 0)) -> 0.022210471 | L26: =B1 -> FLD | M26: =B2 -> 2025 Q1 | N26: =B3 -> 2025 Q4 | Q26: KMX | R26: =B2 -> 2025 Q1 | S26: =B3 -> 2025 Q4 | U26: POS | V26: =B2 -> 2025 Q1 | W26: =B3 -> 2025 Q4
C27: RAGU Impact | D27: =INDEX(multipliers!$A23:$BD23,MATCH($B$1&" | "&D$6,Mult[#Headers], 0)) -> 2.4076495 | E27: =INDEX(multipliers!$A23:$BD23,MATCH($B$1&" | "&E$6,Mult[#Headers], 0)) -> 1.6204382 | H27: =populations!A22 -> fraud_adjustment_mean | I27: =INDEX(populations!$A22:$BD22,MATCH($B$1&" | "&I$6,flag[#Headers], 0)) -> 0.99033881 | J27: =INDEX(populations!$A22:$BD22,MATCH($B$1&" | "&J$6,flag[#Headers], 0)) -> 0.99207827 | L27: Model Score | M27: =INDEX(ragu!$B3:$BZ3,MATCH($L$26&" "&M$26,ragu!$B$1:$BZ$1, 0)) -> 136.70743 | N27: =INDEX(ragu!$B3:$BZ3,MATCH($L$26&" "&N$26,ragu!$B$1:$BZ$1, 0)) -> 138.94555 | Q27: Model Score | R27: =INDEX(ragu!$B3:$BZ3,MATCH($Q$26&" "&R$26,ragu!$B$1:$BZ$1, 0)) -> 139.70877 | S27: =INDEX(ragu!$B3:$BZ3,MATCH($Q$26&" "&S$26,ragu!$B$1:$BZ$1, 0)) -> 140.94205 | U27: Model Score | V27: =INDEX(ragu!$B3:$BZ3,MATCH($U$26&" "&V$26,ragu!$B$1:$BZ$1, 0)) -> 138.29936 | W27: =INDEX(ragu!$B3:$BZ3,MATCH($U$26&" "&W$26,ragu!$B$1:$BZ$1, 0)) -> 140.32
H28: =populations!A23 -> driver_flag | I28: =INDEX(populations!$A23:$BD23,MATCH($B$1&" | "&I$6,flag[#Headers], 0)) -> 0.019431988 | J28: =INDEX(populations!$A23:$BD23,MATCH($B$1&" | "&J$6,flag[#Headers], 0)) -> 0.026969857 | L28: Gross Loss | M28: =INDEX(ragu!$B4:$BZ4,MATCH($L$26&" "&M$26,ragu!$B$1:$BZ$1, 0)) -> 2.4076495 | N28: =INDEX(ragu!$B4:$BZ4,MATCH($L$26&" "&N$26,ragu!$B$1:$BZ$1, 0)) -> 1.6204382 | Q28: Gross Loss | R28: =INDEX(ragu!$B4:$BZ4,MATCH($Q$26&" "&R$26,ragu!$B$1:$BZ$1, 0)) -> -0.34039323 | S28: =INDEX(ragu!$B4:$BZ4,MATCH($Q$26&" "&S$26,ragu!$B$1:$BZ$1, 0)) -> 1.489745 | U28: Gross Loss | V28: =INDEX(ragu!$B4:$BZ4,MATCH($U$26&" "&V$26,ragu!$B$1:$BZ$1, 0)) -> 0.21131625 | W28: =INDEX(ragu!$B4:$BZ4,MATCH($U$26&" "&W$26,ragu!$B$1:$BZ$1, 0)) -> 1.9565456
