Workbook

Sheet KMX
A1: KMX | B1: =tzero_results!C1 | C1: =tzero_results!D1 | D1: =tzero_results!E1 | E1: =tzero_results!F1 | F1: =tzero_results!G1 | G1: t-1 | H1: Proposed True ups
A2: Model Score (W) | B2: =tzero_results!C50 | C2: =tzero_results!D50 | D2: =tzero_results!E50 | E2: =tzero_results!F50 | F2: =tzero_results!G50 | G2: =tminusone!O6
A3: Discount (Average) | B3: =tzero_results!C51 | C3: =tzero_results!D51 | D3: =tzero_results!E51 | E3: =tzero_results!F51 | F3: =tzero_results!G51
A4: Discount % (Weighted) | B4: =tzero_results!C52 | C4: =tzero_results!D52 | D4: =tzero_results!E52 | E4: =tzero_results!F52 | F4: =tzero_results!G52 | G4: =tminusone!V6
A5: APR (Average) | B5: =tzero_results!C53 | C5: =tzero_results!D53 | D5: =tzero_results!E53 | E5: =tzero_results!F53 | F5: =tzero_results!G53
A6: APR (Weighted) | B6: =tzero_results!C54 | C6: =tzero_results!D54 | D6: =tzero_results!E54 | E6: =tzero_results!F54 | F6: =tzero_results!G54 | G6: =tminusone!T6
A7: Applications | B7: =tzero_results!C55 | C7: =tzero_results!D55 | D7: =tzero_results!E55 | E7: =tzero_results!F55 | F7: =tzero_results!G55 | J7: tier 2.5
A8: Contracts (In house, Not Funded) | B8: =tzero_results!C56 | C8: =tzero_results!D56 | D8: =tzero_results!E56 | E8: =tzero_results!F56 | F8: =tzero_results!G56 | J8: beeter apps
A9: Contracts | B9: =tzero_results!C57 | C9: =tzero_results!D57 | D9: =tzero_results!E57 | E9: =tzero_results!F57 | F9: =tzero_results!G57
A10: BlackBook Value (Average) | B10: =tzero_results!C58 | C10: =tzero_results!D58 | D10: =tzero_results!E58 | E10: =tzero_results!F58 | F10: =tzero_results!G58
A11: BlackBook LTV (Weighted) | B11: =tzero_results!C59 | C11: =tzero_results!D59 | D11: =tzero_results!E59 | E11: =tzero_results!F59 | F11: =tzero_results!G59
A12: Mileage (Average) | B12: =tzero_results!C60 | C12: =tzero_results!D60 | D12: =tzero_results!E60 | E12: =tzero_results!F60 | F12: =tzero_results!G60
A13: Vehicle Age (Average) | B13: =tzero_results!C61 | C13: =tzero_results!D61 | D13: =tzero_results!E61 | E13: =tzero_results!F61 | F13: =tzero_results!G61
A14: RAGU Score | B14: =B30 | C14: =C30 | D14: =D30 | E14: =E30 | F14: =F30 | G14: =tminusone!BD6
A15: CNL | B15: =$G$15-(B14-$G$14)*0.0065 | C15: =$G$15-(C14-$G$14)*0.0065 | D15: =$G$15-(D14-$G$14)*0.0065 | E15: =$G$15-(E14-$G$14)*0.0065 | F15: =$G$15-(F14-$G$14)*0.0065 | G15: =tminusone!Z6
A16: WAL | B16: =$G$16 | C16: =$G$16 | D16: =$G$16 | E16: =$G$16 | F16: =$G$16 | G16: =tminusone!Q6
A17: + Origination Yield | B17: =B6*tminusone!$U$6+B4/B16+tminusone!$W$6+tminusone!$X$6+tminusone!$Y$6 | C17: =C6*tminusone!$U$6+C4/C16+tminusone!$W$6+tminusone!$X$6+tminusone!$Y$6 | D17: =D6*tminusone!$U$6+D4/D16+tminusone!$W$6+tminusone!$X$6+tminusone!$Y$6 | E17: =E6*tminusone!$U$6+E4/E16+tminusone!$W$6+tminusone!$X$6+tminusone!$Y$6 | F17: =F6*tminusone!$U$6+F4/F16+tminusone!$W$6+tminusone!$X$6+tminusone!$Y$6 | G17: =G6*tminusone!$U$6+G4/G16+tminusone!$W$6+tminusone!$X$6+tminusone!$Y$6
A18: - CNL Effect | B18: =B15/B16 | C18: =C15/C16 | D18: =D15/D16 | E18: =E15/E16 | F18: =F15/F16 | G18: =G15/G16
A19: - Variable Cost | B19: =$G$19 | C19: =$G$19 | D19: =$G$19 | E19: =$G$19 | F19: =$G$19 | G19: =tminusone!L6
A20: - Cost of Debt Effect (5.5% int rate) | B20: =$G$20 | C20: =$G$20 | D20: =$G$20 | E20: =$G$20 | F20: =$G$20 | G20: =tminusone!M6
A21: = mROA | B21: =B17-B18-B19-B20 | C21: =C17-C18-C19-C20 | D21: =D17-D18-D19-D20 | E21: =E17-E18-E19-E20 | F21: =F17-F18-F19-F20 | G21: =G17-G18-G19-G20
A22: vROA | B22: =B21-0.77% | C22: =C21-0.77% | D22: =D21-0.77% | E22: =E21-0.77% | F22: =F21-0.77% | G22: =G21-0.77%
A24: =A1 | B24: =B1 | C24: =C1 | D24: =D1 | E24: =E1 | F24: =F1
A25: Model Score | B25: 142.94132 | C25: 142.73532 | D25: 142.77958 | E25: 142.87746 | F25: 142.92092
A26: Gross Loss Adjustments | B26: 1.394996 | C26: 0.83465992 | D26: 0.51478797 | E26: 0.38733179 | F26: 0.3135806
A27: Recovery Adjustments | B27: 0.82495537 | C27: 1.1118159 | D27: 1.2622803 | E27: 0.77329382 | F27: 1.1321721
A28: BBLTV Adjustments | B28: 0.19509273 | C28: 0.62804032 | D28: 0.66971847 | E28: 0.62039651 | F28: 1.0948552
A29: APR Adjustments | B29: 0.60950574 | C29: 0.60875326 | D29: 0.65221053 | E29: 0.72279997 | F29: 0.69841264
A30: RAGU Score | B30: 145.96586 | C30: 145.91859 | D30: 145.87858 | E30: 145.38128 | F30: 146.15994

Sheet FLD
A1: FLD | B1: =tzero_results!C1 | C1: =tzero_results!D1 | D1: =tzero_results!E1 | E1: =tzero_results!F1 | F1: =tzero_results!G1 | G1: t-1 | H1: Proposed True ups
A2: Model Score (W) | B2: =tzero_results!C26 | C2: =tzero_results!D26 | D2: =tzero_results!E26 | E2: =tzero_results!F26 | F2: =tzero_results!G26 | G2: =tminusone!O4
A3: Discount (Average) | B3: =tzero_results!C27 | C3: =tzero_results!D27 | D3: =tzero_results!E27 | E3: =tzero_results!F27 | F3: =tzero_results!G27
A4: Discount % (Weighted) | B4: =tzero_results!C28 | C4: =tzero_results!D28 | D4: =tzero_results!E28 | E4: =tzero_results!F28 | F4: =tzero_results!G28 | G4: =tminusone!V4
A5: APR (Average) | B5: =tzero_results!C29 | C5: =tzero_results!D29 | D5: =tzero_results!E29 | E5: =tzero_results!F29 | F5: =tzero_results!G29
A6: APR (Weighted) | B6: =tzero_results!C30 | C6: =tzero_results!D30 | D6: =tzero_results!E30 | E6: =tzero_results!F30 | F6: =tzero_results!G30 | G6: =tminusone!T4
A7: Applications | B7: =tzero_results!C31 | C7: =tzero_results!D31 | D7: =tzero_results!E31 | E7: =tzero_results!F31 | F7: =tzero_results!G31
A8: Contracts (In house, Not Funded) | B8: =tzero_results!C32 | C8: =tzero_results!D32 | D8: =tzero_results!E32 | E8: =tzero_results!F32 | F8: =tzero_results!G32
A9: Contracts | B9: =tzero_results!C33 | C9: =tzero_results!D33 | D9: =tzero_results!E33 | E9: =tzero_results!F33 | F9: =tzero_results!G33
A10: BlackBook Value (Average) | B10: =tzero_results!C34 | C10: =tzero_results!D34 | D10: =tzero_results!E34 | E10: =tzero_results!F34 | F10: =tzero_results!G34
A11: BlackBook LTV (Weighted) | B11: =tzero_results!C35 | C11: =tzero_results!D35 | D11: =tzero_results!E35 | E11: =tzero_results!F35 | F11: =tzero_results!G35
A12: Mileage (Average) | B12: =tzero_results!C36 | C12: =tzero_results!D36 | D12: =tzero_results!E36 | E12: =tzero_results!F36 | F12: =tzero_results!G36
A13: Vehicle Age (Average) | B13: =tzero_results!C37 | C13: =tzero_results!D37 | D13: =tzero_results!E37 | E13: =tzero_results!F37 | F13: =tzero_results!G37
A14: RAGU Score | B14: =B30 | C14: =C30 | D14: =D30 | E14: =E30 | F14: =F30 | G14: =tminusone!BD4
A15: CNL | B15: =$G$15-(B14-$G$14)*0.01 | C15: =$G$15-(C14-$G$14)*0.01 | D15: =$G$15-(D14-$G$14)*0.01 | E15: =$G$15-(E14-$G$14)*0.01 | F15: =$G$15-(F14-$G$14)*0.01 | G15: =tminusone!Z4
A16: WAL | B16: =$G$16 | C16: =$G$16 | D16: =$G$16 | E16: =$G$16 | F16: =$G$16 | G16: =tminusone!Q4
A17: + Origination Yield | B17: =B6*tminusone!$U$4+B4/B16+tminusone!$W$4+tminusone!$X$4+tminusone!$Y$4 | C17: =C6*tminusone!$U$4+C4/C16+tminusone!$W$4+tminusone!$X$4+tminusone!$Y$4 | D17: =D6*tminusone!$U$4+D4/D16+tminusone!$W$4+tminusone!$X$4+tminusone!$Y$4 | E17: =E6*tminusone!$U$4+E4/E16+tminusone!$W$4+tminusone!$X$4+tminusone!$Y$4 | F17: =F6*tminusone!$U$4+F4/F16+tminusone!$W$4+tminusone!$X$4+tminusone!$Y$4 | G17: =G6*tminusone!$U$4+G4/G16+tminusone!$W$4+tminusone!$X$4+tminusone!$Y$4
A18: - CNL Effect | B18: =B15/B16 | C18: =C15/C16 | D18: =D15/D16 | E18: =E15/E16 | F18: =F15/F16 | G18: =G15/G16
A19: - Variable Cost | B19: =$G$19 | C19: =$G$19 | D19: =$G$19 | E19: =$G$19 | F19: =$G$19 | G19: =tminusone!L4
A20: - Cost of Debt Effect (5.5% int rate) | B20: =$G$20 | C20: =$G$20 | D20: =$G$20 | E20: =$G$20 | F20: =$G$20 | G20: =tminusone!M4
A21: = mROA | B21: =B17-B18-B19-B20 | C21: =C17-C18-C19-C20 | D21: =D17-D18-D19-D20 | E21: =E17-E18-E19-E20 | F21: =F17-F18-F19-F20 | G21: =G17-G18-G19-G20
A22: vROA | B22: =B21-0.77% | C22: =C21-0.77% | D22: =D21-0.77% | E22: =E21-0.77% | F22: =F21-0.77% | G22: =G21-0.77%
A24: =A1 | B24: =B1 | C24: =C1 | D24: =D1 | E24: =E1 | F24: =F1
A25: Model Score | B25: 141.7987 | C25: 141.45815 | D25: 141.18827 | E25: 141.80572 | F25: 141.43597
A26: Gross Loss Adjustments | B26: 2.5062758 | C26: 2.3194437 | D26: 2.2868141 | E26: 2.6043381 | F26: 2.4715904
A27: Recovery Adjustments | B27: 0.069794818 | C27: 0.22853859 | D27: 0.56992062 | E27: 0.12689541 | F27: 0.73592002
A28: BBLTV Adjustments | B28: -0.30156829 | C28: -0.40869874 | D28: -0.63401485 | E28: -0.47245983 | F28: -0.1093357
A29: APR Adjustments | B29: -0.3932378 | C29: -0.26293836 | D29: -0.34214133 | E29: -0.34261245 | F29: -0.52195745
A30: RAGU Score | B30: 143.67997 | C30: 143.33449 | D30: 143.06885 | E30: 143.72188 | F30: 144.01219

Sheet AN
A1: AN | B1: =tzero_results!C1 | C1: =tzero_results!D1 | D1: =tzero_results!E1 | E1: =tzero_results!F1 | F1: =tzero_results!G1 | G1: t-1 | H1: Proposed True ups
A2: Model Score (W) | B2: =tzero_results!C2 | C2: =tzero_results!D2 | D2: =tzero_results!E2 | E2: =tzero_results!F2 | F2: =tzero_results!G2 | G2: =tminusone!O2
A3: Discount (Average) | B3: =tzero_results!C3 | C3: =tzero_results!D3 | D3: =tzero_results!E3 | E3: =tzero_results!F3 | F3: =tzero_results!G3
A4: Discount % (Weighted) | B4: =tzero_results!C4 | C4: =tzero_results!D4 | D4: =tzero_results!E4 | E4: =tzero_results!F4 | F4: =tzero_results!G4 | G4: =tminusone!V2
A5: APR (Average) | B5: =tzero_results!C5 | C5: =tzero_results!D5 | D5: =tzero_results!E5 | E5: =tzero_results!F5 | F5: =tzero_results!G5
A6: APR (Weighted) | B6: =tzero_results!C6 | C6: =tzero_results!D6 | D6: =tzero_results!E6 | E6: =tzero_results!F6 | F6: =tzero_results!G6 | G6: =tminusone!T2
A7: Applications | B7: =tzero_results!C7 | C7: =tzero_results!D7 | D7: =tzero_results!E7 | E7: =tzero_results!F7 | F7: =tzero_results!G7
A8: Contracts (In house, Not Funded) | B8: =tzero_results!C8 | C8: =tzero_results!D8 | D8: =tzero_results!E8 | E8: =tzero_results!F8 | F8: =tzero_results!G8
A9: Contracts | B9: =tzero_results!C9 | C9: =tzero_results!D9 | D9: =tzero_results!E9 | E9: =tzero_results!F9 | F9: =tzero_results!G9
A10: BlackBook Value (Average) | B10: =tzero_results!C10 | C10: =tzero_results!D10 | D10: =tzero_results!E10 | E10: =tzero_results!F10 | F10: =tzero_results!G10
A11: BlackBook LTV (Weighted) | B11: =tzero_results!C11 | C11: =tzero_results!D11 | D11: =tzero_results!E11 | E11: =tzero_results!F11 | F11: =tzero_results!G11
A12: Mileage (Average) | B12: =tzero_results!C12 | C12: =tzero_results!D12 | D12: =tzero_results!E12 | E12: =tzero_results!F12 | F12: =tzero_results!G12
A13: Vehicle Age (Average) | B13: =tzero_results!C13 | C13: =tzero_results!D13 | D13: =tzero_results!E13 | E13: =tzero_results!F13 | F13: =tzero_results!G13
A14: RAGU Score | B14: =B30 | C14: =C30 | D14: =D30 | E14: =E30 | F14: =F30 | G14: =tminusone!BD2
A15: CNL | B15: =$G$15-(B14-$G$14)*0.01 | C15: =$G$15-(C14-$G$14)*0.01 | D15: =$G$15-(D14-$G$14)*0.01 | E15: =$G$15-(E14-$G$14)*0.01 | F15: =$G$15-(F14-$G$14)*0.01 | G15: =tminusone!Z2
A16: WAL | B16: =$G$16 | C16: =$G$16 | D16: =$G$16 | E16: =$G$16 | F16: =$G$16 | G16: =tminusone!Q2
A17: + Origination Yield | B17: =B6*tminusone!$U$2+B4/B16+tminusone!$W$2+tminusone!$X$2+tminusone!$Y$2 | C17: =C6*tminusone!$U$2+C4/C16+tminusone!$W$2+tminusone!$X$2+tminusone!$Y$2 | D17: =D6*tminusone!$U$2+D4/D16+tminusone!$W$2+tminusone!$X$2+tminusone!$Y$2 | E17: =E6*tminusone!$U$2+E4/E16+tminusone!$W$2+tminusone!$X$2+tminusone!$Y$2 | F17: =F6*tminusone!$U$2+F4/F16+tminusone!$W$2+tminusone!$X$2+tminusone!$Y$2 | G17: =G6*tminusone!$U$2+G4/G16+tminusone!$W$2+tminusone!$X$2+tminusone!$Y$2
A18: - CNL Effect | B18: =B15/B16 | C18: =C15/C16 | D18: =D15/D16 | E18: =E15/E16 | F18: =F15/F16 | G18: =G15/G16
A19: - Variable Cost | B19: =$G$19 | C19: =$G$19 | D19: =$G$19 | E19: =$G$19 | F19: =$G$19 | G19: =tminusone!L2
A20: - Cost of Debt Effect (5.5% int rate) | B20: =$G$20 | C20: =$G$20 | D20: =$G$20 | E20: =$G$20 | F20: =$G$20 | G20: =tminusone!M2
A21: = mROA | B21: =B17-B18-B19-B20 | C21: =C17-C18-C19-C20 | D21: =D17-D18-D19-D20 | E21: =E17-E18-E19-E20 | F21: =F17-F18-F19-F20 | G21: =G17-G18-G19-G20
A22: vROA | B22: =B21-0.77% | C22: =C21-0.77% | D22: =D21-0.77% | E22: =E21-0.77% | F22: =F21-0.77% | G22: =G21-0.77%
A24: =AN!A1 | B24: =B1 | C24: =C1 | D24: =D1 | E24: =E1 | F24: =F1
A25: Model Score | B25: 139.78268 | C25: 140.67513 | D25: 140.73106 | E25: 140.82002 | F25: 140.97967
A26: Gross Loss Adjustments | B26: 3.0806129 | C26: 3.3463221 | D26: 3.6857796 | E26: 3.4159251 | F26: 3.7298543
A27: Recovery Adjustments | B27: 1.4177311 | C27: 4.3985073 | D27: 3.3650677 | E27: 3.6849201 | F27: 3.5456008
A28: BBLTV Adjustments | B28: 3.1102104 | C28: 4.7687929 | D28: 3.4852278 | E28: 4.9280744 | F28: 4.0663777
A29: APR Adjustments | B29: 0.86180155 | C29: 1.1377468 | D29: 1.0112657 | E29: 1.5287806 | F29: 1.7675801
A30: RAGU Score | B30: 148.25303 | C30: 154.3265 | D30: 152.2784 | E30: 154.37772 | F30: 154.08908

Sheet ENT
A1: ENT | B1: =tzero_results!C1 | C1: =tzero_results!D1 | D1: =tzero_results!E1 | E1: =tzero_results!F1 | F1: =tzero_results!G1 | G1: t-1 | H1: Proposed True ups
A2: Model Score (W) | B2: =tzero_results!C14 | C2: =tzero_results!D14 | D2: =tzero_results!E14 | E2: =tzero_results!F14 | F2: =tzero_results!G14 | G2: =tminusone!O3
A3: Discount (Average) | B3: =tzero_results!C15 | C3: =tzero_results!D15 | D3: =tzero_results!E15 | E3: =tzero_results!F15 | F3: =tzero_results!G15
A4: Discount % (Weighted) | B4: =tzero_results!C16 | C4: =tzero_results!D16 | D4: =tzero_results!E16 | E4: =tzero_results!F16 | F4: =tzero_results!G16 | G4: =tminusone!V3
A5: APR (Average) | B5: =tzero_results!C17 | C5: =tzero_results!D17 | D5: =tzero_results!E17 | E5: =tzero_results!F17 | F5: =tzero_results!G17
A6: APR (Weighted) | B6: =tzero_results!C18 | C6: =tzero_results!D18 | D6: =tzero_results!E18 | E6: =tzero_results!F18 | F6: =tzero_results!G18 | G6: =tminusone!T3
A7: Applications | B7: =tzero_results!C19 | C7: =tzero_results!D19 | D7: =tzero_results!E19 | E7: =tzero_results!F19 | F7: =tzero_results!G19
A8: Contracts (In house, Not Funded) | B8: =tzero_results!C20 | C8: =tzero_results!D20 | D8: =tzero_results!E20 | E8: =tzero_results!F20 | F8: =tzero_results!G20
A9: Contracts | B9: =tzero_results!C21 | C9: =tzero_results!D21 | D9: =tzero_results!E21 | E9: =tzero_results!F21 | F9: =tzero_results!G21
A10: BlackBook Value (Average) | B10: =tzero_results!C22 | C10: =tzero_results!D22 | D10: =tzero_results!E22 | E10: =tzero_results!F22 | F10: =tzero_results!G22
A11: BlackBook LTV (Weighted) | B11: =tzero_results!C23 | C11: =tzero_results!D23 | D11: =tzero_results!E23 | E11: =tzero_results!F23 | F11: =tzero_results!G23
A12: Mileage (Average) | B12: =tzero_results!C24 | C12: =tzero_results!D24 | D12: =tzero_results!E24 | E12: =tzero_results!F24 | F12: =tzero_results!G24
A13: Vehicle Age (Average) | B13: =tzero_results!C25 | C13: =tzero_results!D25 | D13: =tzero_results!E25 | E13: =tzero_results!F25 | F13: =tzero_results!G25
A14: RAGU Score | B14: =B30 | C14: =C30 | D14: =D30 | E14: =E30 | F14: =F30 | G14: =tminusone!BD3
A15: CNL | B15: =$G$15-(B14-$G$14)*0.01 | C15: =$G$15-(C14-$G$14)*0.01 | D15: =$G$15-(D14-$G$14)*0.01 | E15: =$G$15-(E14-$G$14)*0.01 | F15: =$G$15-(F14-$G$14)*0.01 | G15: =tminusone!Z3
A16: WAL | B16: =$G$16 | C16: =$G$16 | D16: =$G$16 | E16: =$G$16 | F16: =$G$16 | G16: =tminusone!Q3
A17: + Origination Yield | B17: =B6*tminusone!$U$3+B4/B16+tminusone!$W$3+tminusone!$X$3+tminusone!$Y$3 | C17: =C6*tminusone!$U$3+C4/C16+tminusone!$W$3+tminusone!$X$3+tminusone!$Y$3 | D17: =D6*tminusone!$U$3+D4/D16+tminusone!$W$3+tminusone!$X$3+tminusone!$Y$3 | E17: =E6*tminusone!$U$3+E4/E16+tminusone!$W$3+tminusone!$X$3+tminusone!$Y$3 | F17: =F6*tminusone!$U$3+F4/F16+tminusone!$W$3+tminusone!$X$3+tminusone!$Y$3 | G17: =G6*tminusone!$U$3+G4/G16+tminusone!$W$3+tminusone!$X$3+tminusone!$Y$3
A18: - CNL Effect | B18: =B15/B16 | C18: =C15/C16 | D18: =D15/D16 | E18: =E15/E16 | F18: =F15/F16 | G18: =G15/G16
A19: - Variable Cost | B19: =$G$19 | C19: =$G$19 | D19: =$G$19 | E19: =$G$19 | F19: =$G$19 | G19: =tminusone!L3
A20: - Cost of Debt Effect (5.5% int rate) | B20: =$G$20 | C20: =$G$20 | D20: =$G$20 | E20: =$G$20 | F20: =$G$20 | G20: =tminusone!M3
A21: = mROA | B21: =B17-B18-B19-B20 | C21: =C17-C18-C19-C20 | D21: =D17-D18-D19-D20 | E21: =E17-E18-E19-E20 | F21: =F17-F18-F19-F20 | G21: =G17-G18-G19-G20
A22: vROA | B22: =B21-0.77% | C22: =C21-0.77% | D22: =D21-0.77% | E22: =E21-0.77% | F22: =F21-0.77% | G22: =G21-0.77%
A24: =ENT!A1 | B24: =B1 | C24: =C1 | D24: =D1 | E24: =E1 | F24: =F1
A25: Model Score | B25: 140.63706 | C25: 140.64275 | D25: 141.23291 | E25: 140.53635 | F25: 141.32495
A26: Gross Loss Adjustments | B26: 0.71167875 | C26: 0.53820467 | D26: 0.36360109 | E26: 0.12602707 | F26: 0.24862571
A27: Recovery Adjustments | B27: 1.6781168 | C27: 1.7405541 | D27: 1.7145554 | E27: 1.5003702 | F27: 1.2214399
A28: BBLTV Adjustments | B28: 2.1614206 | C28: 2.1106277 | D28: 1.7499151 | E28: 2.4300721 | F28: 1.8798393
A29: APR Adjustments | B29: -0.05541244 | C29: -0.06189132 | D29: -0.00048140345 | E29: -0.19619969 | F29: -0.08812659
A30: RAGU Score | B30: 145.13286 | C30: 144.97025 | D30: 145.0605 | E30: 144.39662 | F30: 144.58673

Sheet FRN
A1: FRN | B1: =tzero_results!C1 | C1: =tzero_results!D1 | D1: =tzero_results!E1 | E1: =tzero_results!F1 | F1: =tzero_results!G1 | G1: t-1 | H1: Proposed True ups
A2: Model Score (W) | B2: =tzero_results!C38 | C2: =tzero_results!D38 | D2: =tzero_results!E38 | E2: =tzero_results!F38 | F2: =tzero_results!G38 | G2: =tminusone!O5
A3: Discount (Average) | B3: =tzero_results!C39 | C3: =tzero_results!D39 | D3: =tzero_results!E39 | E3: =tzero_results!F39 | F3: =tzero_results!G39
A4: Discount % (Weighted) | B4: =tzero_results!C40 | C4: =tzero_results!D40 | D4: =tzero_results!E40 | E4: =tzero_results!F40 | F4: =tzero_results!G40 | G4: =tminusone!V5
A5: APR (Average) | B5: =tzero_results!C41 | C5: =tzero_results!D41 | D5: =tzero_results!E41 | E5: =tzero_results!F41 | F5: =tzero_results!G41
A6: APR (Weighted) | B6: =tzero_results!C42 | C6: =tzero_results!D42 | D6: =tzero_results!E42 | E6: =tzero_results!F42 | F6: =tzero_results!G42 | G6: =tminusone!T5
A7: Applications | B7: =tzero_results!C43 | C7: =tzero_results!D43 | D7: =tzero_results!E43 | E7: =tzero_results!F43 | F7: =tzero_results!G43
A8: Contracts (In house, Not Funded) | B8: =tzero_results!C44 | C8: =tzero_results!D44 | D8: =tzero_results!E44 | E8: =tzero_results!F44 | F8: =tzero_results!G44
A9: Contracts | B9: =tzero_results!C45 | C9: =tzero_results!D45 | D9: =tzero_results!E45 | E9: =tzero_results!F45 | F9: =tzero_results!G45
A10: BlackBook Value (Average) | B10: =tzero_results!C46 | C10: =tzero_results!D46 | D10: =tzero_results!E46 | E10: =tzero_results!F46 | F10: =tzero_results!G46
A11: BlackBook LTV (Weighted) | B11: =tzero_results!C47 | C11: =tzero_results!D47 | D11: =tzero_results!E47 | E11: =tzero_results!F47 | F11: =tzero_results!G47
A12: Mileage (Average) | B12: =tzero_results!C48 | C12: =tzero_results!D48 | D12: =tzero_results!E48 | E12: =tzero_results!F48 | F12: =tzero_results!G48
A13: Vehicle Age (Average) | B13: =tzero_results!C49 | C13: =tzero_results!D49 | D13: =tzero_results!E49 | E13: =tzero_results!F49 | F13: =tzero_results!G49
A14: RAGU Score | B14: =B30 | C14: =C30 | D14: =D30 | E14: =E30 | F14: =F30 | G14: =tminusone!BD5
A15: CNL | B15: =$G$15-(B14-$G$14)*0.01 | C15: =$G$15-(C14-$G$14)*0.01 | D15: =$G$15-(D14-$G$14)*0.01 | E15: =$G$15-(E14-$G$14)*0.01 | F15: =$G$15-(F14-$G$14)*0.01 | G15: =tminusone!Z5
A16: WAL | B16: =$G$16 | C16: =$G$16 | D16: =$G$16 | E16: =$G$16 | F16: =$G$16 | G16: =tminusone!Q5
A17: + Origination Yield | B17: =B6*tminusone!$U$5+B4/B16+tminusone!$W$5+tminusone!$X$5+tminusone!$Y$5 | C17: =C6*tminusone!$U$5+C4/C16+tminusone!$W$5+tminusone!$X$5+tminusone!$Y$5 | D17: =D6*tminusone!$U$5+D4/D16+tminusone!$W$5+tminusone!$X$5+tminusone!$Y$5 | E17: =E6*tminusone!$U$5+E4/E16+tminusone!$W$5+tminusone!$X$5+tminusone!$Y$5 | F17: =F6*tminusone!$U$5+F4/F16+tminusone!$W$5+tminusone!$X$5+tminusone!$Y$5 | G17: =G6*tminusone!$U$5+G4/G16+tminusone!$W$5+tminusone!$X$5+tminusone!$Y$5
A18: - CNL Effect | B18: =B15/B16 | C18: =C15/C16 | D18: =D15/D16 | E18: =E15/E16 | F18: =F15/F16 | G18: =G15/G16
A19: - Variable Cost | B19: =$G$19 | C19: =$G$19 | D19: =$G$19 | E19: =$G$19 | F19: =$G$19 | G19: =tminusone!L5
A20: - Cost of Debt Effect (5.5% int rate) | B20: =$G$20 | C20: =$G$20 | D20: =$G$20 | E20: =$G$20 | F20: =$G$20 | G20: =tminusone!M5
A21: = mROA | B21: =B17-B18-B19-B20 | C21: =C17-C18-C19-C20 | D21: =D17-D18-D19-D20 | E21: =E17-E18-E19-E20 | F21: =F17-F18-F19-F20 | G21: =G17-G18-G19-G20
A22: vROA | B22: =B21-0.77% | C22: =C21-0.77% | D22: =D21-0.77% | E22: =E21-0.77% | F22: =F21-0.77% | G22: =G21-0.77%
A24: =A1 | B24: =B1 | C24: =C1 | D24: =D1 | E24: =E1 | F24: =F1
A25: Model Score | B25: 143.5155 | C25: 142.96001 | D25: 142.89759 | E25: 142.96731 | F25: 142.86901
A26: Gross Loss Adjustments | B26: 2.8152053 | C26: 3.2623954 | D26: 2.9811186 | E26: 2.9436187 | F26: 3.2592568
A27: Recovery Adjustments | B27: 2.1533345 | C27: 2.8574101 | D27: 2.5959593 | E27: 2.3639172 | F27: 3.4985025
A28: BBLTV Adjustments | B28: 5.1891524 | C28: 4.9403844 | D28: 5.1283296 | E28: 5.1145293 | F28: 4.9764799
A29: APR Adjustments | B29: -0.24539004 | C29: -0.300548 | D29: -0.35214433 | E29: -0.26697328 | F29: -0.27630191
A30: RAGU Score | B30: 153.4278 | C30: 153.71965 | D30: 153.25085 | E30: 153.1224 | F30: 154.32695

Sheet STG
A1: STG | B1: =tzero_results!C1 | C1: =tzero_results!D1 | D1: =tzero_results!E1 | E1: =tzero_results!F1 | F1: =tzero_results!G1 | G1: t-1 | H1: Proposed True ups
A2: Model Score (W) | B2: =tzero_results!C98 | C2: =tzero_results!D98 | D2: =tzero_results!E98 | E2: =tzero_results!F98 | F2: =tzero_results!G98 | G2: =tminusone!O9
A3: Discount (Average) | B3: =tzero_results!C99 | C3: =tzero_results!D99 | D3: =tzero_results!E99 | E3: =tzero_results!F99 | F3: =tzero_results!G99
A4: Discount % (Weighted) | B4: =tzero_results!C100 | C4: =tzero_results!D100 | D4: =tzero_results!E100 | E4: =tzero_results!F100 | F4: =tzero_results!G100 | G4: =tminusone!V9
A5: APR (Average) | B5: =tzero_results!C101 | C5: =tzero_results!D101 | D5: =tzero_results!E101 | E5: =tzero_results!F101 | F5: =tzero_results!G101
A6: APR (Weighted) | B6: =tzero_results!C102 | C6: =tzero_results!D102 | D6: =tzero_results!E102 | E6: =tzero_results!F102 | F6: =tzero_results!G102 | G6: =tminusone!T9
A7: Applications | B7: =tzero_results!C103 | C7: =tzero_results!D103 | D7: =tzero_results!E103 | E7: =tzero_results!F103 | F7: =tzero_results!G103
A8: Contracts (In house, Not Funded) | B8: =tzero_results!C104 | C8: =tzero_results!D104 | D8: =tzero_results!E104 | E8: =tzero_results!F104 | F8: =tzero_results!G104
A9: Contracts | B9: =tzero_results!C105 | C9: =tzero_results!D105 | D9: =tzero_results!E105 | E9: =tzero_results!F105 | F9: =tzero_results!G105
A10: BlackBook Value (Average) | B10: =tzero_results!C106 | C10: =tzero_results!D106 | D10: =tzero_results!E106 | E10: =tzero_results!F106 | F10: =tzero_results!G106
A11: BlackBook LTV (Weighted) | B11: =tzero_results!C107 | C11: =tzero_results!D107 | D11: =tzero_results!E107 | E11: =tzero_results!F107 | F11: =tzero_results!G107
A12: Mileage (Average) | B12: =tzero_results!C108 | C12: =tzero_results!D108 | D12: =tzero_results!E108 | E12: =tzero_results!F108 | F12: =tzero_results!G108
A13: Vehicle Age (Average) | B13: =tzero_results!C109 | C13: =tzero_results!D109 | D13: =tzero_results!E109 | E13: =tzero_results!F109 | F13: =tzero_results!G109
A14: RAGU Score | B14: =B30 | C14: =C30 | D14: =D30 | E14: =E30 | F14: =F30 | G14: =tminusone!BD9
A15: CNL | B15: =$G$15-(B14-$G$14)*0.01 | C15: =$G$15-(C14-$G$14)*0.01 | D15: =$G$15-(D14-$G$14)*0.01 | E15: =$G$15-(E14-$G$14)*0.01 | F15: =$G$15-(F14-$G$14)*0.01 | G15: =tminusone!Z9
A16: WAL | B16: =$G$16 | C16: =$G$16 | D16: =$G$16 | E16: =$G$16 | F16: =$G$16 | G16: =tminusone!Q9
A17: + Origination Yield | B17: =B6*tminusone!$U$9+B4/B16+tminusone!$W$9+tminusone!$X$9+tminusone!$Y$9 | C17: =C6*tminusone!$U$9+C4/C16+tminusone!$W$9+tminusone!$X$9+tminusone!$Y$9 | D17: =D6*tminusone!$U$9+D4/D16+tminusone!$W$9+tminusone!$X$9+tminusone!$Y$9 | E17: =E6*tminusone!$U$9+E4/E16+tminusone!$W$9+tminusone!$X$9+tminusone!$Y$9 | F17: =F6*tminusone!$U$9+F4/F16+tminusone!$W$9+tminusone!$X$9+tminusone!$Y$9 | G17: =G6*tminusone!$U$9+G4/G16+tminusone!$W$9+tminusone!$X$9+tminusone!$Y$9
A18: - CNL Effect | B18: =B15/B16 | C18: =C15/C16 | D18: =D15/D16 | E18: =E15/E16 | F18: =F15/F16 | G18: =G15/G16
A19: - Variable Cost | B19: =$G$19 | C19: =$G$19 | D19: =$G$19 | E19: =$G$19 | F19: =$G$19 | G19: =tminusone!L9
A20: - Cost of Debt Effect (5.5% int rate) | B20: =$G$20 | C20: =$G$20 | D20: =$G$20 | E20: =$G$20 | F20: =$G$20 | G20: =tminusone!M9
A21: = mROA | B21: =B17-B18-B19-B20 | C21: =C17-C18-C19-C20 | D21: =D17-D18-D19-D20 | E21: =E17-E18-E19-E20 | F21: =F17-F18-F19-F20 | G21: =G17-G18-G19-G20
A22: vROA | B22: =B21-0.77% | C22: =C21-0.77% | D22: =D21-0.77% | E22: =E21-0.77% | F22: =F21-0.77% | G22: =G21-0.77%
A24: =A1 | B24: =B1 | C24: =C1 | D24: =D1 | E24: =E1 | F24: =F1
A25: Model Score | B25: 140.89075 | C25: 140.99981 | D25: 141.32782 | E25: 141.66329 | F25: 141.06491
A26: Gross Loss Adjustments | B26: 3.1935336 | C26: 2.8762479 | D26: 3.3285466 | E26: 3.4714487 | F26: 3.3512782
A27: Recovery Adjustments | B27: 3.1164795 | C27: 4.6713033 | D27: 4.4156812 | E27: 4.6069677 | F27: 4.3587022
A28: BBLTV Adjustments | B28: 4.5362132 | C28: 5.4266942 | D28: 6.0266738 | E28: 5.9928804 | F28: 5.8192967
A29: APR Adjustments | B29: 0.78002932 | C29: 0.77961752 | D29: 1.2530402 | E29: 1.102533 | F29: 1.0762888
A30: RAGU Score | B30: 152.517 | C30: 154.75367 | D30: 156.35176 | E30: 156.83712 | F30: 155.67048

Sheet STE
A1: STE | B1: =tzero_results!C1 | C1: =tzero_results!D1 | D1: =tzero_results!E1 | E1: =tzero_results!F1 | F1: =tzero_results!G1 | G1: t-1 | H1: Proposed True ups
A2: Model Score (W) | B2: =tzero_results!C86 | C2: =tzero_results!D86 | D2: =tzero_results!E86 | E2: =tzero_results!F86 | F2: =tzero_results!G86 | G2: 132.9
A3: Discount (Average) | B3: =tzero_results!C87 | C3: =tzero_results!D87 | D3: =tzero_results!E87 | E3: =tzero_results!F87 | F3: =tzero_results!G87
A4: Discount % (Weighted) | B4: =tzero_results!C88 | C4: =tzero_results!D88 | D4: =tzero_results!E88 | E4: =tzero_results!F88 | F4: =tzero_results!G88 | G4: =tminusone!V8
A5: APR (Average) | B5: =tzero_results!C89 | C5: =tzero_results!D89 | D5: =tzero_results!E89 | E5: =tzero_results!F89 | F5: =tzero_results!G89
A6: APR (Weighted) | B6: =tzero_results!C90 | C6: =tzero_results!D90 | D6: =tzero_results!E90 | E6: =tzero_results!F90 | F6: =tzero_results!G90 | G6: =tminusone!T8
A7: Applications | B7: =tzero_results!C91 | C7: =tzero_results!D91 | D7: =tzero_results!E91 | E7: =tzero_results!F91 | F7: =tzero_results!G91
A8: Contracts | B8: =tzero_results!C93 | C8: =tzero_results!D93 | D8: =tzero_results!E93 | E8: =tzero_results!F93 | F8: =tzero_results!G93
A9: BlackBook Value (Average) | B9: =tzero_results!C94 | C9: =tzero_results!D94 | D9: =tzero_results!E94 | E9: =tzero_results!F94 | F9: =tzero_results!G94
A10: BlackBook LTV (Weighted) | B10: =tzero_results!C95 | C10: =tzero_results!D95 | D10: =tzero_results!E95 | E10: =tzero_results!F95 | F10: =tzero_results!G95
A11: Mileage (Average) | B11: =tzero_results!C96 | C11: =tzero_results!D96 | D11: =tzero_results!E96 | E11: =tzero_results!F96 | F11: =tzero_results!G96
A12: Vehicle Age (Average) | B12: =tzero_results!C97 | C12: =tzero_results!D97 | D12: =tzero_results!E97 | E12: =tzero_results!F97 | F12: =tzero_results!G97
A13: RAGU Score | B13: =B29 | C13: =C29 | D13: =D29 | E13: =E29 | F13: =F29 | G13: 143
A14: CNL | B14: =$G$14-(B13-$G$13)*0.01 | C14: =$G$14-(C13-$G$13)*0.01 | D14: =$G$14-(D13-$G$13)*0.01 | E14: =$G$14-(E13-$G$13)*0.01 | F14: =$G$14-(F13-$G$13)*0.01 | G14: =tminusone!Z8
A15: WAL | B15: =$G$15 | C15: =$G$15 | D15: =$G$15 | E15: =$G$15 | F15: =$G$15 | G15: =tminusone!R8
A16: + Origination Yield | B16: =B6*tminusone!$U$8+B4/B15+tminusone!$W$8+tminusone!$X$8+tminusone!$Y$8 | C16: =C6*tminusone!$U$8+C4/C15+tminusone!$W$8+tminusone!$X$8+tminusone!$Y$8 | D16: =D6*tminusone!$U$8+D4/D15+tminusone!$W$8+tminusone!$X$8+tminusone!$Y$8 | E16: =E6*tminusone!$U$8+E4/E15+tminusone!$W$8+tminusone!$X$8+tminusone!$Y$8 | F16: =F6*tminusone!$U$8+F4/F15+tminusone!$W$8+tminusone!$X$8+tminusone!$Y$8 | G16: =G6*tminusone!$U$8+G4/G15+tminusone!$W$8+tminusone!$X$8+tminusone!$Y$8
A17: - CNL Effect | B17: =B14/B15 | C17: =C14/C15 | D17: =D14/D15 | E17: =E14/E15 | F17: =F14/F15 | G17: =G14/G15
A18: - Variable Cost | B18: =$G$18 | C18: =$G$18 | D18: =$G$18 | E18: =$G$18 | F18: =$G$18 | G18: =tminusone!L8
A19: - Cost of Debt Effect (5.5% int rate) | B19: =$G$19 | C19: =$G$19 | D19: =$G$19 | E19: =$G$19 | F19: =$G$19 | G19: =tminusone!M8
A20: = mROA | B20: =B16-B17-B18-B19 | C20: =C16-C17-C18-C19 | D20: =D16-D17-D18-D19 | E20: =E16-E17-E18-E19 | F20: =F16-F17-F18-F19 | G20: =G16-G17-G18-G19
A21: vROA | B21: =B20-0.77% | C21: =C20-0.77% | D21: =D20-0.77% | E21: =E20-0.77% | F21: =F20-0.77% | G21: =G20-0.77%
A23: =A1 | B23: =B1 | C23: =C1 | D23: =D1 | E23: =E1 | F23: =F1
A24: Model Score | B24: 135.21197 | C24: 134.98826 | D24: 135.79702 | E24: 136.32888 | F24: 136.37522
A25: Gross Loss Adjustments | B25: -0.060833235 | C25: -0.25670088 | D25: -0.10629657 | E25: -0.29955926 | F25: -0.2367439
A26: Recovery Adjustments | B26: 2.2649551 | C26: 2.7187276 | D26: 2.3775973 | E26: 3.6719622 | F26: 3.6050476
A27: BBLTV Adjustments | B27: 5.6719442 | C27: 5.995603 | D27: 6.3326972 | E27: 6.3857219 | F27: 6.3243059
A28: APR Adjustments | B28: 1.6553502 | C28: 1.4383098 | D28: 1.529568 | E28: 1.6314334 | F28: 1.9839784
A29: RAGU Score | B29: 144.71944 | C29: 144.90499 | D29: 145.97732 | E29: 147.70815 | F29: 148.14972

Sheet MCY
A1: MCY | B1: =tzero_results!C1 | C1: =tzero_results!D1 | D1: =tzero_results!E1 | E1: =tzero_results!F1 | F1: =tzero_results!G1 | G1: t-1 | H1: Proposed True ups
A2: Model Score (W) | B2: =tzero_results!C62 | C2: =tzero_results!D62 | D2: =tzero_results!E62 | E2: =tzero_results!F62 | F2: =tzero_results!G62 | G2: =tminusone!O7
A3: Discount (Average) | B3: =tzero_results!C63 | C3: =tzero_results!D63 | D3: =tzero_results!E63 | E3: =tzero_results!F63 | F3: =tzero_results!G63
A4: Discount % (Weighted) | B4: =tzero_results!C64 | C4: =tzero_results!D64 | D4: =tzero_results!E64 | E4: =tzero_results!F64 | F4: =tzero_results!G64 | G4: =tminusone!V7
A5: APR (Average) | B5: =tzero_results!C65 | C5: =tzero_results!D65 | D5: =tzero_results!E65 | E5: =tzero_results!F65 | F5: =tzero_results!G65
A6: APR (Weighted) | B6: =tzero_results!C66 | C6: =tzero_results!D66 | D6: =tzero_results!E66 | E6: =tzero_results!F66 | F6: =tzero_results!G66 | G6: =tminusone!T7
A7: Applications | B7: =tzero_results!C67 | C7: =tzero_results!D67 | D7: =tzero_results!E67 | E7: =tzero_results!F67 | F7: =tzero_results!G67
A8: Contracts | B8: =tzero_results!C69 | C8: =tzero_results!D69 | D8: =tzero_results!E69 | E8: =tzero_results!F69 | F8: =tzero_results!G69
A9: Mileage (Average) | B9: =tzero_results!C72 | C9: =tzero_results!D72 | D9: =tzero_results!E72 | E9: =tzero_results!F72 | F9: =tzero_results!G72
A10: Vehicle Age (Average) | B10: =tzero_results!C73 | C10: =tzero_results!D73 | D10: =tzero_results!E73 | E10: =tzero_results!F73 | F10: =tzero_results!G73
A11: Model Score (W) | B11: =B2 | C11: =C2 | D11: =D2 | E11: =E2 | F11: =F2 | G11: =G2
A12: CNL | B12: =$G$12-(B11-$G$11)*0.01 | C12: =$G$12-(C11-$G$11)*0.01 | D12: =$G$12-(D11-$G$11)*0.01 | E12: =$G$12-(E11-$G$11)*0.01 | F12: =$G$12-(F11-$G$11)*0.01 | G12: =tminusone!Z7
A13: WAL | B13: =$G$13 | C13: =$G$13 | D13: =$G$13 | E13: =$G$13 | F13: =$G$13 | G13: =tminusone!Q7
A14: + Origination Yield | B14: =B6*tminusone!$U$7+B4/B13+tminusone!$W$8+tminusone!$X$8+tminusone!$Y$7 | C14: =C6*tminusone!$U$7+C4/C13+tminusone!$W$8+tminusone!$X$8+tminusone!$Y$7 | D14: =D6*tminusone!$U$7+D4/D13+tminusone!$W$8+tminusone!$X$8+tminusone!$Y$7 | E14: =E6*tminusone!$U$7+E4/E13+tminusone!$W$8+tminusone!$X$8+tminusone!$Y$7 | F14: =F6*tminusone!$U$7+F4/F13+tminusone!$W$8+tminusone!$X$8+tminusone!$Y$7 | G14: =G6*tminusone!$U$7+G4/G13+tminusone!$W$7+tminusone!$X$7+tminusone!$Y$7
A15: - CNL Effect | B15: =B12/B13 | C15: =C12/C13 | D15: =D12/D13 | E15: =E12/E13 | F15: =F12/F13 | G15: =G12/G13
A16: - Variable Cost | B16: =$G$16 | C16: =$G$16 | D16: =$G$16 | E16: =$G$16 | F16: =$G$16 | G16: =tminusone!L7
A17: - Cost of Debt Effect (5.5% int rate) | B17: =$G$17 | C17: =$G$17 | D17: =$G$17 | E17: =$G$17 | F17: =$G$17 | G17: =tminusone!M7
A18: = mROA | B18: =B14-B15-B16-B17 | C18: =C14-C15-C16-C17 | D18: =D14-D15-D16-D17 | E18: =E14-E15-E16-E17 | F18: =F14-F15-F16-F17 | G18: =G14-G15-G16-G17
A19: vROA | B19: =B18-0.77% | C19: =C18-0.77% | D19: =D18-0.77% | E19: =E18-0.77% | F19: =F18-0.77% | G19: =G18-0.77%

Sheet tzero_results
A1: lob | B1: measure | C1: 12-Apr-26 | D1: 19-Apr-26 | E1: 26-Apr-26 | F1: 03-May-26 | G1: 10-May-26
A2: AN | B2: model score weighted | C2: 140.74009 | D2: 140.75733 | E2: 140.93136 | F2: 140.9996 | G2: 141.45274
B3: discount avg | C3: 967.30109 | D3: 1015.2668 | E3: 982.32916 | F3: 916.05511 | G3: 914.90753
B4: discount pct | C4: 0.039355581 | D4: 0.041941232 | E4: 0.037637099 | F4: 0.036018019 | G4: 0.036165839
B5: apr avg | C5: 0.24049307 | D5: 0.24266947 | E5: 0.2353278 | F5: 0.23439731 | G5: 0.24020112
B6: apr wtd | C6: 0.23374647 | D6: 0.23540596 | E6: 0.22734285 | F6: 0.22371444 | G6: 0.23154837
B7: applications | C7: 3523 | D7: 3698 | E7: 3710 | F7: 3267 | G7: 3546
B8: booked not funded | C8: 0 | D8: 0 | E8: 1 | F8: 5 | G8: 16
B9: contracts num | C9: 202 | D9: 226 | E9: 205 | F9: 186 | G9: 179
B10: Blackbook Value avg | C10: 17603.406 | D10: 16527.987 | E10: 17979.146 | F10: 17448.054 | G10: 17683.38
B11: bbltv 2weighted | C11: 1.5150128 | D11: 1.6079456 | E11: 1.5091559 | F11: 1.5643004 | G11: 1.5344435
B12: mileage avg | C12: 69088.084 | D12: 79064.602 | E12: 71317.937 | F12: 74563.78 | G12: 65299.402
B13: vehicle age avg | C13: 6.4084158 | D13: 7.0077434 | E13: 6.1085366 | F13: 6.655914 | G13: 6.4543762
A14: ENT | B14: model score weighted | C14: 140.64275 | D14: 141.19162 | E14: 140.49567 | F14: 141.2717 | G14: 143.89063
B15: discount avg | C15: 892.35519 | D15: 879.20907 | E15: 899.04275 | F15: 900.50211 | G15: 868.91656
B16: discount pct | C16: 0.037779228 | D16: 0.037095972 | E16: 0.038590908 | F16: 0.037993798 | G16: 0.036336853
B17: apr avg | C17: 0.2355601 | D17: 0.23425181 | E17: 0.23819167 | F17: 0.23624865 | G17: 0.23543817
B18: apr wtd | C18: 0.23588416 | D18: 0.23509188 | E18: 0.2379628 | F18: 0.23614051 | G18: 0.23622941
B19: applications | C19: 8898 | D19: 8827 | E19: 8390 | F19: 7769 | G19: 7829
B20: booked not funded | C20: 0 | D20: 0 | E20: 2 | F20: 12 | G20: 13
B21: contracts num | C21: 208 | D21: 193 | E21: 204 | F21: 185 | G21: 131
B22: Blackbook Value avg | C22: 18616.346 | D22: 18497.021 | E22: 18703.431 | F22: 18603.243 | G22: 18704.389
B23: bbltv 2weighted | C23: 1.2898582 | D23: 1.3147522 | E23: 1.2677618 | F23: 1.3013518 | G23: 1.2976383
B24: mileage avg | C24: 50012.659 | D24: 51757.658 | E24: 51193.853 | F24: 53261.065 | G24: 52755.321
B25: vehicle age avg | C25: 2.9923878 | D25: 3.0051813 | E25: 3.0857843 | F25: 3.1423423 | G25: 2.9262087
A26: FLD | B26: model score weighted | C26: 141.43224 | D26: 141.18174 | E26: 141.9601 | F26: 141.43048 | G26: 141.66827
B27: discount avg | C27: 492.91326 | D27: 478.92404 | E27: 441.63902 | F27: 448.1197 | G27: 452.67285
B28: discount pct | C28: 0.023344098 | D28: 0.021934811 | E28: 0.020413291 | F28: 0.019197263 | G28: 0.020769757
B29: apr avg | C29: 0.24035078 | D29: 0.24117049 | E29: 0.24072526 | F29: 0.24281717 | G29: 0.24158692
B30: apr wtd | C30: 0.23878315 | D30: 0.24034187 | E30: 0.2399457 | F30: 0.24206952 | G30: 0.23950702
B31: applications | C31: 4092 | D31: 4160 | E31: 3992 | F31: 3945 | G31: 3704
B32: booked not funded | C32: 0 | D32: 0 | E32: 2 | F32: 6 | G32: 12
B33: contracts num | C33: 193 | D33: 183 | E33: 194 | F33: 198 | G33: 130
B34: Blackbook Value avg | C34: 15219.43 | D34: 15412.842 | E34: 15582.284 | F34: 17245.96 | G34: 15664.808
B35: bbltv 2weighted | C35: 1.4866694 | D35: 1.5033617 | E35: 1.4885855 | F35: 1.4630285 | G35: 1.4956639
B36: mileage avg | C36: 72265.585 | D36: 66255.563 | E36: 67363.088 | F36: 62986.106 | G36: 63530.808
B37: vehicle age avg | C37: 6.0474957 | D37: 5.5068306 | E37: 5.6713918 | F37: 5.4141414 | G37: 5.8897436
A38: FRN | B38: model score weighted | C38: 142.9616 | D38: 142.88539 | E38: 143.00658 | F38: 142.92793 | G38: 143.02922
B39: discount avg | C39: 1369.9669 | D39: 1360.1304 | E39: 1455.3091 | F39: 1403.7252 | G39: 1438.1079
B40: discount pct | C40: 0.057544909 | D40: 0.057899206 | E40: 0.061486586 | F40: 0.057905042 | G40: 0.060853847
...

Sheet in house not funded
F17: 20260419 | G17: KMX | H17: 6 | I17: 6
F18: 20260405 | G18: MCY | H18: 3 | I18: 3
F19: 20260412 | G19: MCY | H19: 2 | I19: 2
F20: 20260329 | G20: STG | H20: 3 | I20: 3
F21: 20260405 | G21: STG | H21: 5 | I21: 5
F22: 20260412 | G22: STG | H22: 19 | I22: 19
F23: 20260419 | G23: STG | H23: 16 | I23: 16

Sheet tminusone
B1: roa_dealer_group | C1: rowid | D1: lookup | E1: notes | F1: datetime_inserted | G1: effective_date | H1: halfbaked_date | I1: mroa | J1: orig_yield | K1: cnl_effect | L1: var_cost | M1: cost_of_debt | N1: run_rate_nb | O1: model_score | P1: model_name | Q1: wal | R1: wal_cfc | S1: wal_adj_factor | T1: apr | U1: apr_realization_factor | V1: discount | W1: fee_income | X1: pmt_proc_income | Y1: addl_income | Z1: cnl | AA1: gross_loss | AB1: recovery | AC1: cnl_adj_factor | AD1: gross_loss_cfc | AE1: gross_loss_adj_factor | AF1: recovery_cfc | AG1: recovery_adj_factor | AH1: debt_int_rate | AI1: securitization_cost | AJ1: debt_adv_rate | AK1: orig_cost | AL1: serv_cost | AM1: addl_cost | AN1: days_till_half_baked | AO1: sort | AP1: latest_row_flag | AQ1: loss_meeting_flag | AR1: pricing_change_flag | AS1: is_current_flag | AT1: elasticity | AU1: nb_ratio | AV1: version_start_datetime | AW1: version_end_datetime | AX1: ticket_no | AY1: addl_cost_of_debt | AZ1: tier | BA1: fixed_cost | BB1: subdebt_expense | BC1: vroa | BD1: ragu_score | BE1: baseline_ltv | BF1: ltv | BG1: baseline_apr | BH1: ragu_gross_loss_adjustment | BI1: ragu_recovery_adjustment | BJ1: ragu_ltv_adjustment | BK1: ragu_market_expectation_adjustment | BL1: ragu_apr_adjustment
A2: 0 | B2: AN | C2: 407 | D2: AN407 | E2: Cost of Funds Update (5.9%) | F2: 46162 | G2: 46160 | I2: 0.06876975 | J2: 0.26431292 | K2: 0.11882505 | L2: 0.026206119 | M2: 0.050512 | N2: 200 | O2: 139.6 | P2: Franchise3.0 | Q2: 2.12 | R2: 2.2171798 | S2: 0.95616961 | T2: 0.25076585 | U2: 0.9198 | V2: 0.0527 | W2: 0.003 | X2: 0.0041 | Y2: 0.0017 | Z2: 0.2519091 | AA2: 0.57819624 | AB2: 0.32628714 | AC2: 1.3195796 | AD2: 0.438167 | AE2: 1 | AF2: 0.24726597 | AG2: 1 | AH2: 0.059 | AI2: 0.0026 | AJ2: 0.82 | AK2: 0.029480973 | AL2: 0.0123 | AM2: 0 | AN2: 16 | AO2: 2 | AP2: 1 | AQ2: 0 | AR2: 0 | AS2: 1 | AT2: 0.01 | AU2: 0.9935 | AV2: 46162.705 | AW2: 2958101 | AY2: 0 | BA2: 0.005 | BB2: 0.0027 | BC2: 0.06106975 | BD2: 147.3 | BE2: 1.94 | BF2: 1.58 | BG2: 0.25 | BH2: 3.6 | BI2: 0.5 | BJ2: 3.9 | BK2: 0 | BL2: -0.3
A3: 1 | B3: ENT | C3: 294 | D3: ENT294 | E3: Cost of Funds Update (5.9%) | F3: 46162 | G3: 46160 | I3: 0.059143186 | J3: 0.24922037 | K3: 0.11335109 | L3: 0.0262141 | M3: 0.050512 | N3: 304 | O3: 139.6 | P3: Franchise3.0 | Q3: 2.39 | R3: 2.3048594 | S3: 1.0369396 | T3: 0.24028528 | U3: 0.9229 | V3: 0.0446 | W3: 0.003 | X3: 0.0041 | Y3: 0.0017 | Z3: 0.2709091 | AA3: 0.56376635 | AB3: 0.29285725 | AC3: 1.1408541 | AD3: 0.49416165 | AE3: 1 | AF3: 0.2567 | AG3: 1 | AH3: 0.059 | AI3: 0.0026 | AJ3: 0.82 | AK3: 0.033254699 | AL3: 0.0123 | AM3: 0 | AN3: 13 | AO3: 4 | AP3: 1 | AQ3: 0 | AR3: 0 | AS3: 1 | AT3: 0.01 | AU3: 0.9935 | AV3: 46162.705 | AW3: 2958101 | AY3: 0 | BA3: 0.005 | BB3: 0.0027 | BC3: 0.051443186 | BD3: 145 | BE3: 1.45 | BF3: 1.33 | BG3: 0.235 | BH3: 1.2 | BI3: 3 | BJ3: 1.5 | BK3: 0 | BL3: -0.3
A4: 2 | B4: FLD | C4: 295 | D4: FLD295 | E4: Cost of Funds Update (5.9%) | F4: 46162 | G4: 46160 | I4: 0.054680078 | J4: 0.23621655 | K4: 0.10482213 | L4: 0.026202346 | M4: 0.050512 | N4: 188.1 | O4: 139.9 | P4: Franchise3.0 | Q4: 2.3 | R4: 2.2284644 | S4: 1.0321008 | T4: 0.23670091 | U4: 0.93 | V4: 0.01675482 | W4: 0.003 | X4: 0.0041 | Y4: 0.0017 | Z4: 0.2410909 | AA4: 0.69760191 | AB4: 0.45651101 | AC4: 1.8542283 | AD4: 0.37622223 | AE4: 1 | AF4: 0.2462 | AG4: 1 | AH4: 0.059 | AI4: 0.0026 | AJ4: 0.82 | AK4: 0.031975396 | AL4: 0.0123 | AM4: 0 | AN4: 13 | AO4: 5 | AP4: 1 | AQ4: 0 | AR4: 0 | AS4: 1 | AT4: 0.01 | AU4: 0.9935 | AV4: 46162.705 | AW4: 2958101 | AY4: 0 | BA4: 0.005 | BB4: 0.0027 | BC4: 0.046980078 | BD4: 144 | BE4: 1.45 | BF4: 1.45 | BG4: 0.235 | BH4: 2.5 | BI4: 1.7 | BJ4: 0 | BK4: 0 | BL4: -0.1
A5: 3 | B5: FRN | C5: 419 | D5: FRN419 | E5: Cost of Funds Update (5.9%) | F5: 46162 | G5: 46160 | I5: 0.056040527 | J5: 0.27404749 | K5: 0.1413182 | L5: 0.026176765 | M5: 0.050512 | N5: 598.5 | O5: 142.3 | P5: Franchise3.0 | Q5: 2 | R5: 2.1786756 | S5: 0.9179889 | T5: 0.25645294 | U5: 0.9023 | V5: 0.0677 | W5: 0.003 | X5: 0.0041 | Y5: 0.0017 | Z5: 0.2826364 | AA5: 0.61251549 | AB5: 0.32987909 | AC5: 1.3176004 | AD5: 0.46487197 | AE5: 1 | AF5: 0.25036353 | AG5: 1 | AH5: 0.059 | AI5: 0.0026 | AJ5: 0.82 | AK5: 0.027753529 | AL5: 0.0123 | AM5: 0 | AN5: 19 | AO5: 6 | AP5: 1 | AQ5: 0 | AR5: 0 | AS5: 1 | AT5: 0.01 | AU5: 0.993 | AV5: 46162.705 | AW5: 2958101 | AY5: 0 | BA5: 0.005 | BB5: 0.0027 | BC5: 0.048340527 | BD5: 151 | BE5: 1.94 | BF5: 1.44 | BG5: 0.25 | BH5: 3.4 | BI5: 0 | BJ5: 5.9 | BK5: 0 | BL5: -0.6
A6: 4 | B6: KMX | C6: 436 | D6: KMX436 | E6: Cost of Funds Update (5.9%) | F6: 46162 | G6: 46160 | I6: 0.062059697 | J6: 0.2478521 | K6: 0.11940412 | L6: 0.015876287 | M6: 0.050512 | N6: 1764 | O6: 142.6 | P6: Mountain3 | Q6: 2.38 | R6: 2.4173564 | S6: 0.9845466 | T6: 0.24479264 | U6: 0.9173 | V6: 0.032377076 | W6: 0.003 | X6: 0.0041 | Y6: 0.0026 | Z6: 0.2841818 | AA6: 0.65251831 | AB6: 0.36833651 | AC6: 1.3077071 | AD6: 0.49897895 | AE6: 1 | AF6: 0.28166591 | AG6: 1 | AH6: 0.059 | AI6: 0.0026 | AJ6: 0.82 | AK6: 0.008987564 | AL6: 0.0121 | AM6: 0 | AN6: 4 | AO6: 1 | AP6: 1 | AQ6: 0 | AR6: 0 | AS6: 1 | AT6: 0.0065 | AU6: 0.94 | AV6: 46162.705 | AW6: 2958101 | AY6: 0 | BA6: 0.005 | BB6: 0.0027 | BC6: 0.054359697 | BD6: 144 | BE6: 1.59 | BF6: 1.57 | BG6: 0.25 | BH6: 0.2 | BI6: 0.47 | BJ6: 0.2 | BK6: 0 | BL6: 0.5
A7: 5 | B7: MCY | C7: 348 | D7: MCY348 | E7: Cost of Funds Update (5.9%) | F7: 46162 | G7: 46160 | I7: 0.051838186 | J7: 0.30033126 | K7: 0.17180431 | L7: 0.026176764 | M7: 0.050512 | N7: 30 | O7: 148.7 | P7: MCY2.0 | Q7: 1.97 | R7: 2.2435149 | S7: 0.87808644 | T7: 0.252 | U7: 0.88772712 | V7: 0.13361334 | W7: 0.003 | X7: 0.0041 | Y7: 0.0017 | Z7: 0.3384545 | AA7: 0.58590708 | AB7: 0.24745258 | AC7: 1.4531425 | AD7: 0.4032 | AE7: 1 | AF7: 0.17028789 | AG7: 1 | AH7: 0.059 | AI7: 0.0026 | AJ7: 0.82 | AK7: 0.027337226 | AL7: 0.0123 | AM7: 0 | AN7: 12 | AO7: 7 | AP7: 1 | AQ7: 0 | AR7: 0 | AS7: 1 | AT7: 0.0117 | AU7: 0.9915 | AV7: 46162.705 | AW7: 2958101 | AY7: 0 | BA7: 0.005 | BB7: 0.0027 | BC7: 0.044138186
A8: 6 | B8: SFS | C8: 45 | D8: SFS45 | E8: Cost of Funds Update (5.9%) | F8: 46162 | G8: 46160 | I8: 0.055775246 | J8: 0.22648952 | K8: 0.10620227 | L8: 0.014 | M8: 0.050512 | N8: 710 | O8: 0 | Q8: 2.27 | R8: 2.27 | S8: 1 | T8: 0.228 | U8: 0.92 | V8: 0.018 | W8: 0.003 | X8: 0.0041 | Y8: 0.0017 | Z8: 0.24107915 | AA8: 0.46164093 | AB8: 0.22056178 | AC8: 1.0258687 | AD8: 0.45 | AE8: 1 | AF8: 0.215 | AG8: 1 | AH8: 0.059 | AI8: 0.0026 | AJ8: 0.82 | AK8: 0.003405 | AL8: 0.0125 | AM8: 0 | AN8: 2 | AO8: 10 | AP8: 1 | AQ8: 0 | AR8: 0 | AS8: 1 | AT8: 0.01 | AU8: 1 | AV8: 46162.705 | AW8: 2958101 | AY8: 0 | BA8: 0.005 | BB8: 0.0027 | BC8: 0.048075246
A9: 7 | B9: STG | C9: 426 | D9: STG426 | E9: Cost of Funds Update (5.9%) | F9: 46162 | G9: 46160 | I9: 0.064466445 | J9: 0.25716409 | K9: 0.11600888 | L9: 0.026176764 | M9: 0.050512 | N9: 380 | O9: 138.8 | P9: Franchise3.0 | Q9: 2.05 | R9: 2.1801666 | S9: 0.9402951 | T9: 0.2456 | U9: 0.9185 | V9: 0.0467 | W9: 0.003 | X9: 0.0041 | Y9: 0.0017 | Z9: 0.2378182 | AA9: 0.50537612 | AB9: 0.26755792 | AC9: 1.0895914 | AD9: 0.46382167 | AE9: 1 | AF9: 0.24555802 | AG9: 1 | AH9: 0.059 | AI9: 0.0026 | AJ9: 0.82 | AK9: 0.028447367 | AL9: 0.0123 | AM9: 0 | AN9: 17 | AO9: 3 | AP9: 1 | AQ9: 0 | AR9: 0 | AS9: 1 | AT9: 0.01 | AU9: 0.995 | AV9: 46162.705 | AW9: 2958101 | AY9: 0 | BA9: 0.005 | BB9: 0.0027 | BC9: 0.056766445 | BD9: 151.2 | BE9: 1.94 | BF9: 1.45 | BG9: 0.25 | BH9: 3.7 | BI9: 3 | BJ9: 5.7 | BK9: 0 | BL9: 0

Sheet POS 
A1: POS | B1: =tzero_results!C1 | C1: =tzero_results!D1 | D1: =tzero_results!E1 | E1: =tzero_results!F1 | F1: =tzero_results!G1 | G1: t-1
A2: Model Score (W) | B2: =tzero_results!C66 | C2: =tzero_results!D66 | D2: =tzero_results!E66 | E2: =tzero_results!F66 | F2: =tzero_results!G66
A3: Discount (Average) | B3: =tzero_results!C67 | C3: =tzero_results!D67 | D3: =tzero_results!E67 | E3: =tzero_results!F67 | F3: =tzero_results!G67
A4: Discount % (Weighted) | B4: =tzero_results!C68 | C4: =tzero_results!D68 | D4: =tzero_results!E68 | E4: =tzero_results!F68 | F4: =tzero_results!G68
A5: APR (Average) | B5: =tzero_results!C69 | C5: =tzero_results!D69 | D5: =tzero_results!E69 | E5: =tzero_results!F69 | F5: =tzero_results!G69
A6: APR (Weighted) | B6: =tzero_results!C70 | C6: =tzero_results!D70 | D6: =tzero_results!E70 | E6: =tzero_results!F70 | F6: =tzero_results!G70
A7: Applications | B7: =tzero_results!C71 | C7: =tzero_results!D71 | D7: =tzero_results!E71 | E7: =tzero_results!F71 | F7: =tzero_results!G71
A8: Contracts (In house, Not Funded)
A9: Contracts | B9: =tzero_results!C72 | C9: =tzero_results!D72 | D9: =tzero_results!E72 | E9: =tzero_results!F72 | F9: =tzero_results!G72
A10: BlackBook Value (Average) | B10: =tzero_results!C73 | C10: =tzero_results!D73 | D10: =tzero_results!E73 | E10: =tzero_results!F73 | F10: =tzero_results!G73
A11: BlackBook LTV (Weighted) | B11: =tzero_results!C74 | C11: =tzero_results!D74 | D11: =tzero_results!E74 | E11: =tzero_results!F74 | F11: =tzero_results!G74
A12: Mileage (Average) | B12: =tzero_results!C75 | C12: =tzero_results!D75 | D12: =tzero_results!E75 | E12: =tzero_results!F75 | F12: =tzero_results!G75
A13: Vehicle Age (Average) | B13: =tzero_results!C76 | C13: =tzero_results!D76 | D13: =tzero_results!E76 | E13: =tzero_results!F76 | F13: =tzero_results!G76
A14: CNL | G14: =tminusone!AA9
A15: vROA | G15: =#REF!-0.77%
