Workbook

Sheet Main
A1: LOB | B1: STG
A2: Start | B2: 2024 Q1 | D2: =B1 | E2: =B2 | F2: =B3 | G2: Delta
A3: End | B3: 2025 Q3 | D3: Model Score | E3: =factory!M27 | F3: =factory!N27 | G3: =F3-E3
D4: Gross Loss | E4: =factory!M28 | F4: =factory!N28 | G4: =F4-E4
A5: LOB Dictionary | D5: Recovery + LTV | E5: =factory!M29 | F5: =factory!N29 | G5: =F5-E5
A6: AN | D6: RAGU Score | E6: =factory!M30 | F6: =factory!N30 | G6: =F6-E6
A7: STG
A8: ENT | D8: =B1 | E8: =B2 | F8: =B3 | G8: Delta
A9: FLD | D9: Chime | E9: =factory!H49 | F9: =factory!H74 | G9: =F9-E9
A10: FRN | D10: population % | E10: =factory!I22 | F10: =factory!J22 | G10: =F10-E10
D11: Student Loans | E11: =factory!H47 | F11: =factory!H72 | G11: =F11-E11
D12: population % | E12: =factory!I19 | F12: =factory!J19 | G12: =F12-E12
D13: Toyota/Honda | E13: =factory!H43 | F13: =factory!H68 | G13: =F13-E13
D14: population % | E14: =factory!I14 | F14: =factory!J14 | G14: =F14-E14
D15: Fraud | E15: =factory!H52 | F15: =factory!H77 | G15: =F15-E15
D16: Low Fraud % | E16: =factory!M13 | F16: =factory!N13 | G16: =F16-E16
D17: High Fraud % | E17: =factory!M14 | F17: =factory!N14 | G17: =F17-E17
D18: Dealer Level Loss | E18: =factory!H54 | F18: =factory!H79 | G18: =F18-E18
D19: Good Dealer % | E19: =factory!M7 | F19: =factory!N7 | G19: =F19-E19
D20: Bad Dealer % | E20: =factory!M8 | F20: =factory!N8 | G20: =F20-E20
D21: Other Adjustments | E21: =SUM(factory!H38:H57,-factory!H43-factory!H47-factory!H49-factory!H52-factory!H54) | F21: =SUM(factory!H63:H82,-factory!H68-factory!H72-factory!H74-factory!H77-factory!H79) | G21: =F21-E21
D22: Final Gross Loss | E22: =SUM(E9,E11,E13,E15,E18,E21) | F22: =SUM(F9,F11,F13,F15,F18,F21) | G22: =F22-E22
D26: =B1 | E26: =B2 | F26: =B3
D27: DQ @ 3 MOB | E27: =factory!M20 | F27: =factory!N20
D28: DQ @ 6 MOB | E28: =factory!M21 | F28: =factory!N21
D29: CO @ 6 MOB | E29: =factory!M22 | F29: =factory!N22
D30: CO @ 12 MOB | E30: =factory!M23 | F30: =factory!N23

Sheet factory
A1: LOB | B1: =Main!B1
A2: Start | B2: =Main!B2
A3: End | B3: =Main!B3
C6: adjustment snapshots | D6: =B2 | E6: =B3 | H6: population % | I6: =B2 | J6: =B3 | M6: =B2 | N6: =B3
C7: Previous ACA Chargeoff | D7: =INDEX(multipliers!$A3:$BD3,MATCH($B$1&" | "&D$6,Mult[#Headers], 0)) | E7: =INDEX(multipliers!$A3:$BD3,MATCH($B$1&" | "&E$6,Mult[#Headers], 0)) | H7: =populations!A2 | I7: =INDEX(populations!$A2:$BD2,MATCH($B$1&" | "&I$6,flag[#Headers], 0)) | J7: =INDEX(populations!$A2:$BD2,MATCH($B$1&" | "&J$6,flag[#Headers], 0)) | L7: Good Dealer % | M7: =INDEX(dll[good_dealer],MATCH($B$1&" "&M$6,dll[lookup], 0)) | N7: =INDEX(dll[good_dealer],MATCH($B$1&" "&N$6,dll[lookup], 0))
C8: Small Amount Financed | D8: =INDEX(multipliers!$A4:$BD4,MATCH($B$1&" | "&D$6,Mult[#Headers], 0)) | E8: =INDEX(multipliers!$A4:$BD4,MATCH($B$1&" | "&E$6,Mult[#Headers], 0)) | H8: =populations!A3 | I8: =INDEX(populations!$A3:$BD3,MATCH($B$1&" | "&I$6,flag[#Headers], 0)) | J8: =INDEX(populations!$A3:$BD3,MATCH($B$1&" | "&J$6,flag[#Headers], 0)) | L8: Bad Dealer % | M8: =INDEX(dll[bad_dealer],MATCH($B$1&" "&M$6,dll[lookup], 0)) | N8: =INDEX(dll[bad_dealer],MATCH($B$1&" "&N$6,dll[lookup], 0))
C9: Zero Cash Down | D9: =INDEX(multipliers!$A5:$BD5,MATCH($B$1&" | "&D$6,Mult[#Headers], 0)) | E9: =INDEX(multipliers!$A5:$BD5,MATCH($B$1&" | "&E$6,Mult[#Headers], 0)) | H9: =populations!A4 | I9: =INDEX(populations!$A4:$BD4,MATCH($B$1&" | "&I$6,flag[#Headers], 0)) | J9: =INDEX(populations!$A4:$BD4,MATCH($B$1&" | "&J$6,flag[#Headers], 0))
C10: High Mileage | D10: =INDEX(multipliers!$A6:$BD6,MATCH($B$1&" | "&D$6,Mult[#Headers], 0)) | E10: =INDEX(multipliers!$A6:$BD6,MATCH($B$1&" | "&E$6,Mult[#Headers], 0)) | H10: =populations!A5 | I10: =INDEX(populations!$A5:$BD5,MATCH($B$1&" | "&I$6,flag[#Headers], 0)) | J10: =INDEX(populations!$A5:$BD5,MATCH($B$1&" | "&J$6,flag[#Headers], 0))
C11: High PTI | D11: =INDEX(multipliers!$A7:$BD7,MATCH($B$1&" | "&D$6,Mult[#Headers], 0)) | E11: =INDEX(multipliers!$A7:$BD7,MATCH($B$1&" | "&E$6,Mult[#Headers], 0)) | H11: =populations!A6 | I11: =INDEX(populations!$A6:$BD6,MATCH($B$1&" | "&I$6,flag[#Headers], 0)) | J11: =INDEX(populations!$A6:$BD6,MATCH($B$1&" | "&J$6,flag[#Headers], 0))
C12: Toyota/Honda | D12: =INDEX(multipliers!$A8:$BD8,MATCH($B$1&" | "&D$6,Mult[#Headers], 0)) | E12: =INDEX(multipliers!$A8:$BD8,MATCH($B$1&" | "&E$6,Mult[#Headers], 0)) | H12: =populations!A7 | I12: =INDEX(populations!$A7:$BD7,MATCH($B$1&" | "&I$6,flag[#Headers], 0)) | J12: =INDEX(populations!$A7:$BD7,MATCH($B$1&" | "&J$6,flag[#Headers], 0)) | M12: =B2 | N12: =B3
C13: Theft Risk | D13: =INDEX(multipliers!$A9:$BD9,MATCH($B$1&" | "&D$6,Mult[#Headers], 0)) | E13: =INDEX(multipliers!$A9:$BD9,MATCH($B$1&" | "&E$6,Mult[#Headers], 0)) | H13: =populations!A8 | I13: =INDEX(populations!$A8:$BD8,MATCH($B$1&" | "&I$6,flag[#Headers], 0)) | J13: =INDEX(populations!$A8:$BD8,MATCH($B$1&" | "&J$6,flag[#Headers], 0)) | L13: Positive Fraud | M13: =INDEX(fraud[pos_fraud],MATCH($B$1&" "&M$12,fraud[lookup], 0)) | N13: =INDEX(fraud[pos_fraud],MATCH($B$1&" "&N$12,fraud[lookup], 0))
C14: 08_mcy_low_mileage | D14: =INDEX(multipliers!$A10:$BD10,MATCH($B$1&" | "&D$6,Mult[#Headers], 0)) | E14: =INDEX(multipliers!$A10:$BD10,MATCH($B$1&" | "&E$6,Mult[#Headers], 0)) | H14: =populations!A9 | I14: =INDEX(populations!$A9:$BD9,MATCH($B$1&" | "&I$6,flag[#Headers], 0)) | J14: =INDEX(populations!$A9:$BD9,MATCH($B$1&" | "&J$6,flag[#Headers], 0)) | L14: Negative Fraud | M14: =INDEX(fraud[neg_fraud],MATCH($B$1&" "&M$12,fraud[lookup], 0)) | N14: =INDEX(fraud[neg_fraud],MATCH($B$1&" "&N$12,fraud[lookup], 0))
C15: Weekday/Weekend | D15: =INDEX(multipliers!$A11:$BD11,MATCH($B$1&" | "&D$6,Mult[#Headers], 0)) | E15: =INDEX(multipliers!$A11:$BD11,MATCH($B$1&" | "&E$6,Mult[#Headers], 0)) | H15: =populations!A10 | I15: =INDEX(populations!$A10:$BD10,MATCH($B$1&" | "&I$6,flag[#Headers], 0)) | J15: =INDEX(populations!$A10:$BD10,MATCH($B$1&" | "&J$6,flag[#Headers], 0))
C16: Student Loans | D16: =INDEX(multipliers!$A12:$BD12,MATCH($B$1&" | "&D$6,Mult[#Headers], 0)) | E16: =INDEX(multipliers!$A12:$BD12,MATCH($B$1&" | "&E$6,Mult[#Headers], 0)) | H16: =populations!A11 | I16: =INDEX(populations!$A11:$BD11,MATCH($B$1&" | "&I$6,flag[#Headers], 0)) | J16: =INDEX(populations!$A11:$BD11,MATCH($B$1&" | "&J$6,flag[#Headers], 0))
C17: Low PTI | D17: =INDEX(multipliers!$A13:$BD13,MATCH($B$1&" | "&D$6,Mult[#Headers], 0)) | E17: =INDEX(multipliers!$A13:$BD13,MATCH($B$1&" | "&E$6,Mult[#Headers], 0)) | H17: =populations!A12 | I17: =INDEX(populations!$A12:$BD12,MATCH($B$1&" | "&I$6,flag[#Headers], 0)) | J17: =INDEX(populations!$A12:$BD12,MATCH($B$1&" | "&J$6,flag[#Headers], 0))
C18: Chime | D18: =INDEX(multipliers!$A14:$BD14,MATCH($B$1&" | "&D$6,Mult[#Headers], 0)) | E18: =INDEX(multipliers!$A14:$BD14,MATCH($B$1&" | "&E$6,Mult[#Headers], 0)) | H18: =populations!A13 | I18: =INDEX(populations!$A13:$BD13,MATCH($B$1&" | "&I$6,flag[#Headers], 0)) | J18: =INDEX(populations!$A13:$BD13,MATCH($B$1&" | "&J$6,flag[#Headers], 0))
C19: Waiter/Seasonal | D19: =INDEX(multipliers!$A15:$BD15,MATCH($B$1&" | "&D$6,Mult[#Headers], 0)) | E19: =INDEX(multipliers!$A15:$BD15,MATCH($B$1&" | "&E$6,Mult[#Headers], 0)) | H19: =populations!A14 | I19: =INDEX(populations!$A14:$BD14,MATCH($B$1&" | "&I$6,flag[#Headers], 0)) | J19: =INDEX(populations!$A14:$BD14,MATCH($B$1&" | "&J$6,flag[#Headers], 0)) | M19: =B2 | N19: =B3
C20: Authorized Tradelines | D20: =INDEX(multipliers!$A16:$BD16,MATCH($B$1&" | "&D$6,Mult[#Headers], 0)) | E20: =INDEX(multipliers!$A16:$BD16,MATCH($B$1&" | "&E$6,Mult[#Headers], 0)) | H20: =populations!A15 | I20: =INDEX(populations!$A15:$BD15,MATCH($B$1&" | "&I$6,flag[#Headers], 0)) | J20: =INDEX(populations!$A15:$BD15,MATCH($B$1&" | "&J$6,flag[#Headers], 0)) | L20: DQ MOB 3 | M20: =INDEX(dq[dq_3],MATCH($B$1&" "&M$19,dq[lookup], 0)) | N20: =INDEX(dq[dq_3],MATCH($B$1&" "&N$19,dq[lookup], 0))
C21: Fraud | D21: =INDEX(multipliers!$A17:$BD17,MATCH($B$1&" | "&D$6,Mult[#Headers], 0)) | E21: =INDEX(multipliers!$A17:$BD17,MATCH($B$1&" | "&E$6,Mult[#Headers], 0)) | H21: =populations!A16 | I21: =INDEX(populations!$A16:$BD16,MATCH($B$1&" | "&I$6,flag[#Headers], 0)) | J21: =INDEX(populations!$A16:$BD16,MATCH($B$1&" | "&J$6,flag[#Headers], 0)) | L21: DQ MOB 6 | M21: =INDEX(dq[dq_6],MATCH($B$1&" "&M$19,dq[lookup], 0)) | N21: =INDEX(dq[dq_6],MATCH($B$1&" "&N$19,dq[lookup], 0))
C22: Driver | D22: =INDEX(multipliers!$A18:$BD18,MATCH($B$1&" | "&D$6,Mult[#Headers], 0)) | E22: =INDEX(multipliers!$A18:$BD18,MATCH($B$1&" | "&E$6,Mult[#Headers], 0)) | H22: =populations!A17 | I22: =INDEX(populations!$A17:$BD17,MATCH($B$1&" | "&I$6,flag[#Headers], 0)) | J22: =INDEX(populations!$A17:$BD17,MATCH($B$1&" | "&J$6,flag[#Headers], 0)) | L22: CO Rate MOB 6 | M22: =INDEX(dq[co_6],MATCH($B$1&" "&M$19,dq[lookup], 0)) | N22: =INDEX(dq[co_6],MATCH($B$1&" "&N$19,dq[lookup], 0))
C23: Dealer Level Loss | D23: =INDEX(multipliers!$A19:$BD19,MATCH($B$1&" | "&D$6,Mult[#Headers], 0)) | E23: =INDEX(multipliers!$A19:$BD19,MATCH($B$1&" | "&E$6,Mult[#Headers], 0)) | H23: =populations!A18 | I23: =INDEX(populations!$A18:$BD18,MATCH($B$1&" | "&I$6,flag[#Headers], 0)) | J23: =INDEX(populations!$A18:$BD18,MATCH($B$1&" | "&J$6,flag[#Headers], 0)) | L23: CO Rate MOB 12 | M23: =INDEX(dq[co_12],MATCH($B$1&" "&M$19,dq[lookup], 0)) | N23: =INDEX(dq[co_12],MATCH($B$1&" "&N$19,dq[lookup], 0))
C24: Clip | D24: =INDEX(multipliers!$A20:$BD20,MATCH($B$1&" | "&D$6,Mult[#Headers], 0)) | E24: =INDEX(multipliers!$A20:$BD20,MATCH($B$1&" | "&E$6,Mult[#Headers], 0)) | H24: =populations!A19 | I24: =INDEX(populations!$A19:$BD19,MATCH($B$1&" | "&I$6,flag[#Headers], 0)) | J24: =INDEX(populations!$A19:$BD19,MATCH($B$1&" | "&J$6,flag[#Headers], 0))
C25: Final Multplier | D25: =INDEX(multipliers!$A21:$BD21,MATCH($B$1&" | "&D$6,Mult[#Headers], 0)) | E25: =INDEX(multipliers!$A21:$BD21,MATCH($B$1&" | "&E$6,Mult[#Headers], 0)) | H25: =populations!A20 | I25: =INDEX(populations!$A20:$BD20,MATCH($B$1&" | "&I$6,flag[#Headers], 0)) | J25: =INDEX(populations!$A20:$BD20,MATCH($B$1&" | "&J$6,flag[#Headers], 0))
C26: Weighted Multiplier | D26: =INDEX(multipliers!$A22:$BD22,MATCH($B$1&" | "&D$6,Mult[#Headers], 0)) | E26: =INDEX(multipliers!$A22:$BD22,MATCH($B$1&" | "&E$6,Mult[#Headers], 0)) | H26: =populations!A21 | I26: =INDEX(populations!$A21:$BD21,MATCH($B$1&" | "&I$6,flag[#Headers], 0)) | J26: =INDEX(populations!$A21:$BD21,MATCH($B$1&" | "&J$6,flag[#Headers], 0)) | L26: =B1 | M26: =B2 | N26: =B3
C27: RAGU Impact | D27: =INDEX(multipliers!$A23:$BD23,MATCH($B$1&" | "&D$6,Mult[#Headers], 0)) | E27: =INDEX(multipliers!$A23:$BD23,MATCH($B$1&" | "&E$6,Mult[#Headers], 0)) | H27: =populations!A22 | I27: =INDEX(populations!$A22:$BD22,MATCH($B$1&" | "&I$6,flag[#Headers], 0)) | J27: =INDEX(populations!$A22:$BD22,MATCH($B$1&" | "&J$6,flag[#Headers], 0)) | L27: Model Score | M27: =INDEX(ragu!$B3:$BD3,MATCH($B$1&" "&M$26,ragu!$B$1:$BD$1, 0)) | N27: =INDEX(ragu!$B3:$BD3,MATCH($B$1&" "&N$26,ragu!$B$1:$BD$1, 0))
H28: =populations!A23 | I28: =INDEX(populations!$A23:$BD23,MATCH($B$1&" | "&I$6,flag[#Headers], 0)) | J28: =INDEX(populations!$A23:$BD23,MATCH($B$1&" | "&J$6,flag[#Headers], 0)) | L28: Gross Loss | M28: =INDEX(ragu!$B4:$BD4,MATCH($B$1&" "&M$26,ragu!$B$1:$BD$1, 0)) | N28: =INDEX(ragu!$B4:$BD4,MATCH($B$1&" "&N$26,ragu!$B$1:$BD$1, 0))
L29: Recovery + LTV | M29: =INDEX(ragu!$B7:$BD7,MATCH($B$1&" "&M$26,ragu!$B$1:$BD$1, 0)) | N29: =INDEX(ragu!$B7:$BD7,MATCH($B$1&" "&N$26,ragu!$B$1:$BD$1, 0))
L30: RAGU Score | M30: =INDEX(ragu!$B8:$BD8,MATCH($B$1&" "&M$26,ragu!$B$1:$BD$1, 0)) | N30: =INDEX(ragu!$B8:$BD8,MATCH($B$1&" "&N$26,ragu!$B$1:$BD$1, 0))
M32: =SUM(M27:M29)
C37: =B2 | D37: mult before adjustment | E37: adjustment size | F37: ln | G37: share | H37: Ragu impact per adjustment
C38: Previous ACA Chargeoff | D38: =$D$26/D7 | E38: =D7/1 | F38: =LN(E38) | G38: =F38/SUM($F$38:$F$57) | H38: =25*G38*(1-$D$26)
C39: Small Amount Financed | D39: =$D$26/D8 | E39: =D8/D7 | F39: =LN(E39) | G39: =F39/SUM($F$38:$F$57) | H39: =25*G39*(1-$D$26)
C40: Zero Cash Down | D40: =$D$26/D9 | E40: =D9/D8 | F40: =LN(E40) | G40: =F40/SUM($F$38:$F$57) | H40: =25*G40*(1-$D$26)
C41: High Mileage | D41: =$D$26/D10 | E41: =D10/D9 | F41: =LN(E41) | G41: =F41/SUM($F$38:$F$57) | H41: =25*G41*(1-$D$26)
C42: High PTI | D42: =$D$26/D11 | E42: =D11/D10 | F42: =LN(E42) | G42: =F42/SUM($F$38:$F$57) | H42: =25*G42*(1-$D$26)
C43: Toyota/Honda | D43: =$D$26/D12 | E43: =D12/D11 | F43: =LN(E43) | G43: =F43/SUM($F$38:$F$57) | H43: =25*G43*(1-$D$26)
C44: Theft Risk | D44: =$D$26/D13 | E44: =D13/D12 | F44: =LN(E44) | G44: =F44/SUM($F$38:$F$57) | H44: =25*G44*(1-$D$26)
C45: 08_mcy_low_mileage | D45: =$D$26/D14 | E45: =D14/D13 | F45: =LN(E45) | G45: =F45/SUM($F$38:$F$57) | H45: =25*G45*(1-$D$26)
C46: Weekday/Weekend | D46: =$D$26/D15 | E46: =D15/D14 | F46: =LN(E46) | G46: =F46/SUM($F$38:$F$57) | H46: =25*G46*(1-$D$26)
C47: Student Loans | D47: =$D$26/D16 | E47: =D16/D15 | F47: =LN(E47) | G47: =F47/SUM($F$38:$F$57) | H47: =25*G47*(1-$D$26)
...

Sheet multipliers
A1: Column1 | B1: FRN | 2023 Q3 | C1: AN | 2023 Q3 | D1: STG | 2023 Q3 | E1: FLD | 2023 Q3 | F1: ENT | 2023 Q3 | G1: FRN | 2023 Q4 | H1: AN | 2023 Q4 | I1: STG | 2023 Q4 | J1: FLD | 2023 Q4 | K1: ENT | 2023 Q4 | L1: FRN | 2024 Q1 | M1: AN | 2024 Q1 | N1: STG | 2024 Q1 | O1: FLD | 2024 Q1 | P1: ENT | 2024 Q1 | Q1: FRN | 2024 Q2 | R1: AN | 2024 Q2 | S1: STG | 2024 Q2 | T1: FLD | 2024 Q2 | U1: ENT | 2024 Q2 | V1: FRN | 2024 Q3 | W1: AN | 2024 Q3 | X1: STG | 2024 Q3 | Y1: FLD | 2024 Q3 | Z1: ENT | 2024 Q3 | AA1: FRN | 2024 Q4 | AB1: AN | 2024 Q4 | AC1: STG | 2024 Q4 | AD1: FLD | 2024 Q4 | AE1: ENT | 2024 Q4 | AF1: FRN | 2025 Q1 | AG1: AN | 2025 Q1 | AH1: STG | 2025 Q1 | AI1: FLD | 2025 Q1 | AJ1: ENT | 2025 Q1 | AK1: FRN | 2025 Q2 | AL1: AN | 2025 Q2 | AM1: STG | 2025 Q2 | AN1: FLD | 2025 Q2 | AO1: ENT | 2025 Q2 | AP1: FRN | 2025 Q3 | AQ1: AN | 2025 Q3 | AR1: STG | 2025 Q3 | AS1: FLD | 2025 Q3 | AT1: ENT | 2025 Q3 | AU1: FRN | 2025 Q4 | AV1: AN | 2025 Q4 | AW1: STG | 2025 Q4 | AX1: FLD | 2025 Q4 | AY1: ENT | 2025 Q4 | AZ1: FRN | 2026 Q1 | BA1: AN | 2026 Q1 | BB1: STG | 2026 Q1 | BC1: FLD | 2026 Q1 | BD1: ENT | 2026 Q1
A2: 00_initial | B2: 1 | C2: 1 | D2: 1 | E2: 1 | F2: 1 | G2: 1 | H2: 1 | I2: 1 | J2: 1 | K2: 1 | L2: 1 | M2: 1 | N2: 1 | O2: 1 | P2: 1 | Q2: 1 | R2: 1 | S2: 1 | T2: 1 | U2: 1 | V2: 1 | W2: 1 | X2: 1 | Y2: 1 | Z2: 1 | AA2: 1 | AB2: 1 | AC2: 1 | AD2: 1 | AE2: 1 | AF2: 1 | AG2: 1 | AH2: 1 | AI2: 1 | AJ2: 1 | AK2: 1 | AL2: 1 | AM2: 1 | AN2: 1 | AO2: 1 | AP2: 1 | AQ2: 1 | AR2: 1 | AS2: 1 | AT2: 1 | AU2: 1 | AV2: 1 | AW2: 1 | AX2: 1 | AY2: 1 | AZ2: 1 | BA2: 1 | BB2: 1 | BC2: 1 | BD2: 1 | BF2: =AVERAGE(B2:BD2)
A3: 01_prev_aca_chargeoff | B3: 1.0001704 | C3: 1.0002327 | D3: 1.0001429 | E3: 1.0001517 | F3: 1.0001511 | G3: 1.0002363 | H3: 1.0001901 | I3: 1.000236 | J3: 1.0001481 | K3: 1.0000569 | L3: 1.0002033 | M3: 1.0003148 | N3: 1.0000852 | O3: 1.000224 | P3: 1.000196 | Q3: 1.0001803 | R3: 1.0003049 | S3: 1.0002341 | T3: 1.0001213 | U3: 1.0001479 | V3: 1.0002942 | W3: 1.0003679 | X3: 1.0001596 | Y3: 1.0006616 | Z3: 1.000137 | AA3: 1.0003471 | AB3: 1.0002488 | AC3: 1.0001917 | AD3: 1.0004086 | AE3: 1.0001514 | AF3: 1.0003382 | AG3: 1.0003202 | AH3: 1.0003428 | AI3: 1.0005481 | AJ3: 1.0001764 | AK3: 1.0005695 | AL3: 1.0004743 | AM3: 1.0003686 | AN3: 1.0004226 | AO3: 1.0001405 | AP3: 1.0002975 | AQ3: 1.0003932 | AR3: 1.0002407 | AS3: 1.0001596 | AT3: 1.0002214 | AU3: 1.0002706 | AV3: 1.0002867 | AW3: 1.0002782 | AX3: 1.0002115 | AY3: 1.0003447 | AZ3: 1.0005 | BA3: 1.0003367 | BB3: 1.0002935 | BC3: 1.0006504 | BD3: 1.0003298 | BF3: =AVERAGE(B3:BD3) | BG3: =BF3/BF2 | BH3: =1-BG3 | BI3: =A3
A4: 02_small_amt_financed | B4: 1.0021721 | C4: 1.0006982 | D4: 1.0007857 | E4: 1.0003035 | F4: 1.0001511 | G4: 1.0012864 | H4: 1.0003802 | I4: 1.0010382 | J4: 1.0005926 | K4: 1.0000569 | L4: 1.0010456 | M4: 1.0005903 | N4: 1.0007948 | O4: 1.0007468 | P4: 1.000196 | Q4: 1.0009985 | R4: 1.0005662 | S4: 1.0006556 | T4: 1.0004851 | U4: 1.0001479 | V4: 1.0011217 | W4: 1.0008584 | X4: 1.000894 | Y4: 1.0008507 | Z4: 1.000137 | AA4: 1.0003471 | AB4: 1.0002488 | AC4: 1.0001917 | AD4: 1.0004086 | AE4: 1.0001514 | AF4: 1.0003382 | AG4: 1.0003202 | AH4: 1.0003428 | AI4: 1.0005481 | AJ4: 1.0001764 | AK4: 1.0005695 | AL4: 1.0004743 | AM4: 1.0003686 | AN4: 1.0004226 | AO4: 1.0001405 | AP4: 1.0002975 | AQ4: 1.0003932 | AR4: 1.0002407 | AS4: 1.0001596 | AT4: 1.0002214 | AU4: 1.0002706 | AV4: 1.0002867 | AW4: 1.0002782 | AX4: 1.0002115 | AY4: 1.0003447 | AZ4: 1.0005 | BA4: 1.0003367 | BB4: 1.0002935 | BC4: 1.0006504 | BD4: 1.0003298 | BF4: =AVERAGE(B4:BD4) | BG4: =BF4/BF3 | BH4: =1-BG4 | BI4: =A4
A5: 03_zero_cash_down | B5: 1.0029472 | C5: 1.0022498 | D5: 1.00315 | E5: 1.0022762 | F5: 1.0068299 | G5: 1.0022316 | H5: 1.0035488 | I5: 1.0036904 | J5: 1.0040148 | K5: 1.007023 | L5: 1.0014261 | M5: 1.0032664 | N5: 1.0028129 | O5: 1.0028379 | P5: 1.00433 | Q5: 1.0016516 | R5: 1.0024826 | S5: 1.0029806 | T5: 1.0046089 | U5: 1.0036763 | V5: 1.001861 | W5: 1.0030043 | X5: 1.0031003 | Y5: 1.0035066 | Z5: 1.006137 | AA5: 1.0003471 | AB5: 1.0002488 | AC5: 1.0001917 | AD5: 1.0004086 | AE5: 1.0001514 | AF5: 1.0003382 | AG5: 1.0003202 | AH5: 1.0003428 | AI5: 1.0005481 | AJ5: 1.0001764 | AK5: 1.0005695 | AL5: 1.0004743 | AM5: 1.0003686 | AN5: 1.0004226 | AO5: 1.0001405 | AP5: 1.0002975 | AQ5: 1.0003932 | AR5: 1.0002407 | AS5: 1.0001596 | AT5: 1.0002214 | AU5: 1.0002706 | AV5: 1.0002867 | AW5: 1.0002782 | AX5: 1.0002115 | AY5: 1.0003447 | AZ5: 1.0005 | BA5: 1.0003367 | BB5: 1.0002935 | BC5: 1.0006504 | BD5: 1.0003298 | BF5: =AVERAGE(B5:BD5) | BG5: =BF5/BF4 | BH5: =1-BG5 | BI5: =A5
A6: 04_high_mileage | B6: 1.0047019 | C6: 1.006827 | D6: 1.0064007 | E6: 1.0027314 | F6: 1.0068299 | G6: 1.0034392 | H6: 1.0079278 | I6: 1.0066163 | J6: 1.0043259 | K6: 1.007023 | L6: 1.0030685 | M6: 1.0066627 | N6: 1.0056035 | O6: 1.0032114 | P6: 1.00433 | Q6: 1.0024574 | R6: 1.0043206 | S6: 1.0046387 | T6: 1.0049727 | U6: 1.0036763 | V6: 1.002214 | W6: 1.0046045 | X6: 1.0042944 | Y6: 1.0036957 | Z6: 1.006137 | AA6: 1.0010934 | AB6: 1.0031095 | AC6: 1.0022684 | AD6: 1.000715 | AE6: 1.0001514 | AF6: 1.0007348 | AG6: 1.0017076 | AH6: 1.001835 | AI6: 1.0012955 | AJ6: 1.0001764 | AK6: 1.0008099 | AL6: 1.0011675 | AM6: 1.0009216 | AN6: 1.0005811 | AO6: 1.0001405 | AP6: 1.0005637 | AQ6: 1.0011796 | AR6: 1.0009093 | AS6: 1.0002128 | AT6: 1.0002214 | AU6: 1.0005827 | AV6: 1.0009748 | AW6: 1.000765 | AX6: 1.0002115 | AY6: 1.0003447 | AZ6: 1.0009375 | BA6: 1.0010101 | BB6: 1.0005871 | BC6: 1.000813 | BD6: 1.0003298 | BF6: =AVERAGE(B6:BD6) | BG6: =BF6/BF5 | BH6: =1-BG6 | BI6: =A6
A7: 05_high_pti | B7: 1.005 | C7: 1.0074554 | D7: 1.0066864 | E7: 1.0047041 | F7: 1.0088909 | G7: 1.0036755 | H7: 1.0081179 | I7: 1.0067579 | J7: 1.0050667 | K7: 1.0085641 | L7: 1.0032283 | M7: 1.0070996 | N7: 1.0057454 | O7: 1.0036594 | P7: 1.0052584 | Q7: 1.0026238 | R7: 1.0045819 | S7: 1.0050602 | T7: 1.0055185 | U7: 1.004944 | V7: 1.0024531 | W7: 1.0052299 | X7: 1.0048052 | Y7: 1.0042628 | Z7: 1.0073726 | AA7: 1.0010934 | AB7: 1.0031095 | AC7: 1.0022684 | AD7: 1.000715 | AE7: 1.0001514 | AF7: 1.0007348 | AG7: 1.0017076 | AH7: 1.001835 | AI7: 1.0012955 | AJ7: 1.0001764 | AK7: 1.0008099 | AL7: 1.0011675 | AM7: 1.0009216 | AN7: 1.0005811 | AO7: 1.0001405 | AP7: 1.0005637 | AQ7: 1.0011796 | AR7: 1.0009093 | AS7: 1.0002128 | AT7: 1.0002214 | AU7: 1.0005827 | AV7: 1.0009748 | AW7: 1.000765 | AX7: 1.0002115 | AY7: 1.0003447 | AZ7: 1.0009375 | BA7: 1.0010101 | BB7: 1.0005871 | BC7: 1.000813 | BD7: 1.0003298 | BF7: =AVERAGE(B7:BD7) | BG7: =BF7/BF6 | BH7: =1-BG7 | BI7: =A7
A8: 06_car_make | B8: 0.99313842 | C8: 0.99276183 | D8: 0.99315143 | E8: 0.98889226 | F8: 1.0055817 | G8: 0.99313993 | H8: 0.99085551 | I8: 0.99152855 | J8: 0.9914963 | K8: 1.0017032 | L8: 0.99376706 | M8: 0.99028335 | N8: 0.98902756 | O8: 0.99066468 | P8: 0.99998218 | Q8: 0.99012883 | R8: 0.9848824 | S8: 0.98679747 | T8: 0.99226804 | U8: 0.99738855 | V8: 0.98722692 | W8: 0.98341447 | X8: 0.9832152 | Y8: 0.98811909 | Z8: 0.99749041 | AA8: 0.95653593 | AB8: 0.95429726 | AC8: 0.95338019 | AD8: 0.95903984 | AE8: 0.9712664 | AF8: 0.95198974 | AG8: 0.95488794 | AH8: 0.95291389 | AI8: 0.96003986 | AJ8: 0.96465814 | AK8: 0.94916983 | AL8: 0.94931047 | AM8: 0.94437846 | AN8: 0.95186476 | AO8: 0.94753206 | AP8: 0.94559349 | AQ8: 0.94131935 | AR8: 0.94292859 | AS8: 0.95110638 | AT8: 0.94359973 | AU8: 0.93593757 | AV8: 0.93788417 | AW8: 0.93069889 | AX8: 0.94986779 | AY8: 0.93300981 | AZ8: 0.9365625 | BA8: 0.93232323 | BB8: 0.92189824 | BC8: 0.95138211 | BD8: 0.93404782 | BF8: =AVERAGE(B8:BD8) | BG8: =BF8/BF7 | BH8: =1-BG8 | BI8: =A8
A9: 07_theft_risk | B9: 0.98567515 | C9: 0.98457168 | D9: 0.98585517 | E9: 0.98309736 | F9: 1.0105353 | G9: 0.98598354 | H9: 0.9830185 | I9: 0.98345553 | J9: 0.98522151 | K9: 0.99970416 | L9: 0.98820336 | M9: 0.98315253 | N9: 0.98249294 | O9: 0.98639216 | P9: 0.99572694 | Q9: 0.98351485 | R9: 0.97718416 | S9: 0.9789504 | T9: 0.98816389 | U9: 0.99142968 | V9: 0.98038067 | W9: 0.97453909 | X9: 0.97363541 | Y9: 0.98117799 | Z9: 0.98851016 | AA9: 0.95653593 | AB9: 0.95429726 | AC9: 0.95338019 | AD9: 0.95903984 | AE9: 0.9712664 | AF9: 0.95198974 | AG9: 0.95488794 | AH9: 0.95291389 | AI9: 0.96003986 | AJ9: 0.96465814 | AK9: 0.94916983 | AL9: 0.94931047 | AM9: 0.94437846 | AN9: 0.95186476 | AO9: 0.94753206 | AP9: 0.94559349 | AQ9: 0.94131935 | AR9: 0.94292859 | AS9: 0.95110638 | AT9: 0.94359973 | AU9: 0.93593757 | AV9: 0.93788417 | AW9: 0.93069889 | AX9: 0.94986779 | AY9: 0.93300981 | AZ9: 0.9365625 | BA9: 0.93232323 | BB9: 0.92189824 | BC9: 0.95138211 | BD9: 0.93404782 | BF9: =AVERAGE(B9:BD9) | BG9: =BF9/BF8 | BH9: =1-BG9 | BI9: =A9
A10: 08_mcy_low_mileage | B10: 0.98567515 | C10: 0.98457168 | D10: 0.98585517 | E10: 0.98309736 | F10: 1.0105353 | G10: 0.98598354 | H10: 0.9830185 | I10: 0.98345553 | J10: 0.98522151 | K10: 0.99970416 | L10: 0.98820336 | M10: 0.98315253 | N10: 0.98249294 | O10: 0.98639216 | P10: 0.99572694 | Q10: 0.98351485 | R10: 0.97718416 | S10: 0.9789504 | T10: 0.98816389 | U10: 0.99142968 | V10: 0.98038067 | W10: 0.97453909 | X10: 0.97363541 | Y10: 0.98117799 | Z10: 0.98851016 | AA10: 0.95653593 | AB10: 0.95429726 | AC10: 0.95338019 | AD10: 0.95903984 | AE10: 0.9712664 | AF10: 0.95198974 | AG10: 0.95488794 | AH10: 0.95291389 | AI10: 0.96003986 | AJ10: 0.96465814 | AK10: 0.94916983 | AL10: 0.94931047 | AM10: 0.94437846 | AN10: 0.95186476 | AO10: 0.94753206 | AP10: 0.94559349 | AQ10: 0.94131935 | AR10: 0.94292859 | AS10: 0.95110638 | AT10: 0.94359973 | AU10: 0.93593757 | AV10: 0.93788417 | AW10: 0.93069889 | AX10: 0.94986779 | AY10: 0.93300981 | AZ10: 0.9365625 | BA10: 0.93232323 | BB10: 0.92189824 | BC10: 0.95138211 | BD10: 0.93404782 | BF10: =AVERAGE(B10:BD10) | BG10: =BF10/BF9 | BH10: =1-BG10 | BI10: =A10
A11: 09_weekend_weekday | B11: 0.98992933 | C11: 0.98466665 | D11: 0.98884726 | E11: 0.98143538 | F11: 1.018942 | G11: 0.99078408 | H11: 0.98369107 | I11: 0.98523277 | J11: 0.98307151 | K11: 1.0046721 | L11: 0.99221672 | M11: 0.98378183 | N11: 0.98432433 | O11: 0.98769017 | P11: 1.0005353 | Q11: 0.9872308 | R11: 0.97725956 | S11: 0.98063285 | T11: 0.98930005 | U11: 0.99800377 | V11: 0.98304946 | W11: 0.97511321 | X11: 0.97529167 | Y11: 0.98519394 | Z11: 0.99366322 | AA11: 0.95864068 | AB11: 0.95385025 | AC11: 0.95451169 | AD11: 0.95922268 | AE11: 0.97616726 | AF11: 0.9521906 | AG11: 0.95201999 | AH11: 0.95247959 | AI11: 0.95886497 | AJ11: 0.9674607 | AK11: 0.95023511 | AL11: 0.9475421 | AM11: 0.94430295 | AN11: 0.95162525 | AO11: 0.95143633 | AP11: 0.94641256 | AQ11: 0.94097754 | AR11: 0.94326384 | AS11: 0.95100511 | AT11: 0.94806106 | AU11: 0.93569877 | AV11: 0.93547769 | AW11: 0.92964642 | AX11: 0.94915336 | AY11: 0.93691822 | AZ11: 0.935895 | BA11: 0.92927441 | BB11: 0.92076771 | BC11: 0.95096911 | BD11: 0.93661665 | BF11: =AVERAGE(B11:BD11) | BG11: =BF11/BF10 | BH11: =1-BG11 | BI11: =A11
A12: 10_student_loans | B12: 0.96375789 | C12: 0.96362678 | D12: 0.96564269 | E12: 0.95708832 | F12: 0.9947896 | G12: 0.97269094 | H12: 0.97726537 | I12: 0.97264452 | J12: 0.96724634 | K12: 0.9951325 | L12: 0.9890473 | M12: 0.98667275 | N12: 0.98139298 | O12: 0.98640217 | P12: 1.0056633 | Q12: 0.98006021 | R12: 0.97732748 | S12: 0.97688379 | T12: 0.98973458 | U12: 1.0021768 | V12: 0.97531673 | W12: 0.97242733 | X12: 0.97066346 | Y12: 0.986064 | Z12: 0.99887113 | AA12: 0.95480678 | AB12: 0.95528701 | AC12: 0.95610359 | AD12: 0.96356744 | AE12: 0.98602205 | AF12: 0.94890957 | AG12: 0.95482543 | AH12: 0.95448673 | AI12: 0.96747191 | AJ12: 0.97844842 | AK12: 0.94064359 | AL12: 0.9427608 | AM12: 0.93932857 | AN12: 0.95472692 | AO12: 0.9544624 | AP12: 0.93759815 | AQ12: 0.93690099 | AR12: 0.93848496 | AS12: 0.95095226 | AT12: 0.94942215 | AU12: 0.914206 | AV12: 0.91685786 | AW12: 0.91137915 | AX12: 0.93407027 | AY12: 0.92053774 | AZ12: 0.90913712 | BA12: 0.90418223 | BB12: 0.89476513 | BC12: 0.92396944 | BD12: 0.90963169 | BF12: =AVERAGE(B12:BD12) | BG12: =BF12/BF11 | BH12: =1-BG12 | BI12: =A12
A13: 11_low_pti | B13: 0.95651153 | C13: 0.95685787 | D13: 0.959924 | E13: 0.95334968 | F13: 0.9947896 | G13: 0.96639135 | H13: 0.97215948 | I13: 0.96839922 | J13: 0.96464191 | K13: 0.9951325 | L13: 0.98297831 | M13: 0.97969789 | N13: 0.97648637 | O13: 0.98033686 | P13: 1.0056633 | Q13: 0.97277836 | R13: 0.96905692 | S13: 0.9710207 | T13: 0.98170574 | U13: 1.0021768 | V13: 0.96750678 | W13: 0.96506195 | X13: 0.9646993 | Y13: 0.97818641 | Z13: 0.99887113 | AA13: 0.94745981 | AB13: 0.94749252 | AC13: 0.95045223 | AD13: 0.95645352 | AE13: 0.98602205 | AF13: 0.94106472 | AG13: 0.94732141 | AH13: 0.94816785 | AI13: 0.96131237 | AJ13: 0.97844842 | AK13: 0.93419153 | AL13: 0.93447133 | AM13: 0.93410233 | AN13: 0.9469567 | AO13: 0.9544624 | AP13: 0.93165776 | AQ13: 0.93003213 | AR13: 0.93279092 | AS13: 0.94391431 | AT13: 0.94942215 | AU13: 0.90902261 | AV13: 0.91094622 | AW13: 0.90573379 | AX13: 0.92772106 | AY13: 0.92053774 | AZ13: 0.90352855 | BA13: 0.89864238 | BB13: 0.88890782 | BC13: 0.91882025 | BD13: 0.90963169 | BF13: =AVERAGE(B13:BD13) | BG13: =BF13/BF12 | BH13: =1-BG13 | BI13: =A13
A14: 12_chime | B14: 0.94937799 | C14: 0.94154554 | D14: 0.94614666 | E14: 0.94072804 | F14: 0.9867749 | G14: 0.96394221 | H14: 0.96016135 | I14: 0.95466083 | J14: 0.94721578 | K14: 0.99054527 | L14: 0.99602842 | M14: 0.97590469 | N14: 0.97914289 | O14: 0.97727245 | P14: 1.0162376 | Q14: 0.97448819 | R14: 0.96231921 | S14: 0.96559252 | T14: 0.97385397 | U14: 1.0053773 | V14: 0.96388582 | W14: 0.95813585 | X14: 0.95842055 | Y14: 0.96968519 | Z14: 1.0017321 | AA14: 0.94856637 | AB14: 0.94993655 | AC14: 0.95036712 | AD14: 0.96159926 | AE14: 0.99900394 | AF14: 0.96409848 | AG14: 0.96038477 | AH14: 0.9640173 | AI14: 0.98965496 | AJ14: 1.0143377 | AK14: 0.93967073 | AL14: 0.93247253 | AM14: 0.93399205 | AN14: 0.95636662 | AO14: 0.97041512 | AP14: 0.94022284 | AQ14: 0.93162769 | AR14: 0.93598615 | AS14: 0.95896019 | AT14: 0.96481016 | AU14: 0.9102331 | AV14: 0.91026816 | AW14: 0.90419717 | AX14: 0.94085959 | AY14: 0.92922103 | AZ14: 0.90164902 | BA14: 0.89688635 | BB14: 0.88491549 | BC14: 0.92610494 | BD14: 0.91317506 | BF14: =AVERAGE(B14:BD14) | BG14: =BF14/BF13 | BH14: =1-BG14 | BI14: =A14
... A20: 18_final | B20: 0.95125989 | C20: 0.96625873 | D20: 0.93964922 | E20: 0.9267511 | F20: 1.0277066 | G20: 0.97809223 | H20: 0.97807379 | I20: 0.95813531 | J20: 0.92738081 | K20: 0.99719084 | L20: 1.0126311 | M20: 0.97249214 | N20: 0.96349127 | O20: 0.93314372 | P20: 1.0276785 | Q20: 0.99119965 | R20: 0.95158907 | S20: 0.92619345 | T20: 0.89624713 | U20: 1.01645 | V20: 0.97481236 | W20: 0.96310724 | X20: 0.92270771 | Y20: 0.8681367 | Z20: 1.0209875 | AA20: 0.97731937 | AB20: 0.95871445 | AC20: 0.92330815 | AD20: 0.88179161 | AE20: 1.0117047 | AF20: 0.9750672 | AG20: 0.94013461 | AH20: 0.9314045 | AI20: 0.90405562 | AJ20: 1.0417165 | AK20: 0.95114773 | AL20: 0.90088688 | AM20: 0.91907672 | AN20: 0.90020497 | AO20: 0.99276336 | AP20: 0.92777098 | AQ20: 0.88416205 | AR20: 0.9084808 | AS20: 0.88113244 | AT20: 0.9947915 | AU20: 0.88446654 | AV20: 0.86584411 | AW20: 0.88116935 | AX20: 0.92068793 | AY20: 0.93513571 | AZ20: 0.90402804 | BA20: 0.90903941 | BB20: 0.90287471 | BC20: 0.93872585 | BD20: 0.92394564 | BF20: =AVERAGE(B20:BD20) | BG20: =BF20/BF19 | BH20: =1-BG20 | BI20: =A20
A21: --- FINAL_MULT (mean) | B21: 0.95125989 | C21: 0.96625873 | D21: 0.93964922 | E21: 0.9267511 | F21: 1.0277066 | G21: 0.97809223 | H21: 0.97807379 | I21: 0.95813531 | J21: 0.92738081 | K21: 0.99719084 | L21: 1.0126311 | M21: 0.97249214 | N21: 0.96349127 | O21: 0.93314372 | P21: 1.0276785 | Q21: 0.99119965 | R21: 0.95158907 | S21: 0.92619345 | T21: 0.89624713 | U21: 1.01645 | V21: 0.97481236 | W21: 0.96310724 | X21: 0.92270771 | Y21: 0.8681367 | Z21: 1.0209875 | AA21: 0.97731937 | AB21: 0.95871445 | AC21: 0.92330815 | AD21: 0.88179161 | AE21: 1.0117047 | AF21: 0.9750672 | AG21: 0.94013461 | AH21: 0.9314045 | AI21: 0.90405562 | AJ21: 1.0417165 | AK21: 0.95114773 | AL21: 0.90088688 | AM21: 0.91907672 | AN21: 0.90020497 | AO21: 0.99276336 | AP21: 0.92777098 | AQ21: 0.88416205 | AR21: 0.9084808 | AS21: 0.88113244 | AT21: 0.9947915 | AU21: 0.88446654 | AV21: 0.86584411 | AW21: 0.88116935 | AX21: 0.92068793 | AY21: 0.93513571 | AZ21: 0.90402804 | BA21: 0.90903941 | BB21: 0.90287471 | BC21: 0.93872585 | BD21: 0.92394564
A22: --- WTD_MULT_RAGU | B22: 0.93416492 | C22: 0.97011248 | D22: 0.94043709 | E22: 0.95665522 | F22: 1.0254866 | G22: 0.96790749 | H22: 0.97740448 | I22: 0.95498596 | J22: 0.94377928 | K22: 0.99370718 | L22: 1.0050086 | M22: 0.97285906 | N22: 0.95747762 | O22: 0.93615452 | P22: 1.0235932 | Q22: 0.98722769 | R22: 0.95249233 | S22: 0.91901778 | T22: 0.90241156 | U22: 1.0130421 | V22: 0.96954732 | W22: 0.96113892 | X22: 0.90906478 | Y22: 0.86869643 | Z22: 1.0190451 | AA22: 0.97882185 | AB22: 0.95278864 | AC22: 0.91732284 | AD22: 0.88122985 | AE22: 1.0111521 | AF22: 0.97259071 | AG22: 0.94126799 | AH22: 0.92582635 | AI22: 0.90346964 | AJ22: 1.0383536 | AK22: 0.94886111 | AL22: 0.90089589 | AM22: 0.91864972 | AN22: 0.90019013 | AO22: 0.99138753 | AP22: 0.9277897 | AQ22: 0.88246942 | AR22: 0.90961689 | AS22: 0.87931433 | AT22: 0.99218523 | AU22: 0.88243911 | AV22: 0.860154 | AW22: 0.87540853 | AX22: 0.92541049 | AY22: 0.93276029 | AZ22: 0.89794119 | BA22: 0.90667181 | BB22: 0.89608183 | BC22: 0.93596495 | BD22: 0.92095416
A23: --- GROSS_LOSS_IMPACT | B23: 1.6458771 | C23: 0.7471879 | D23: 1.4890728 | E23: 1.0836194 | F23: -0.63716492 | G23: 0.80231276 | H23: 0.56488788 | I23: 1.1253509 | J23: 1.4055179 | K23: 0.15732039 | L23: -0.12521506 | M23: 0.67852359 | N23: 1.0630595 | O23: 1.596137 | P23: -0.58982951 | Q23: 0.31930787 | R23: 1.1876918 | S23: 2.0245554 | T23: 2.4397109 | U23: -0.32605264 | V23: 0.761317 | W23: 0.97152704 | X23: 2.2733806 | Y23: 3.2825892 | Z23: -0.47612709 | AA23: 0.52945382 | AB23: 1.180284 | AC23: 2.0669291 | AD23: 2.9692538 | AE23: -0.2788024 | AF23: 0.68523213 | AG23: 1.4683002 | AH23: 1.8543413 | AI23: 2.413259 | AJ23: -0.95884076 | AK23: 1.2784722 | AL23: 2.4776027 | AM23: 2.033757 | AN23: 2.4952467 | AO23: 0.21531176 | AP23: 1.8052574 | AQ23: 2.9382644 | AR23: 2.2595778 | AS23: 3.0171417 | AT23: 0.19536934 | AU23: 2.9390222 | AV23: 3.4961501 | AW23: 3.1147868 | AX23: 1.8647378 | AY23: 1.6809929 | AZ23: 2.5514703 | BA23: 2.3332048 | BB23: 2.5979543 | BC23: 1.6008762 | BD23: 1.976146
A24: --- N_RECORDS | B24: 2348 | C24: 1289 | D24: 1400 | E24: 659 | F24: 3309 | G24: 3809 | H24: 1578 | I24: 2119 | J24: 675 | K24: 3517 | L24: 6886 | M24: 2541 | N24: 3523 | O24: 1339 | P24: 5612 | Q24: 7211 | R24: 2296 | S24: 4271 | T24: 1649 | U24: 4733 | V24: 5438 | W24: 1631 | X24: 3132 | Y24: 1058 | Z24: 3650 | AA24: 5762 | AB24: 1608 | AC24: 3130 | AD24: 979 | AE24: 3964 | AF24: 8574 | AG24: 2811 | AH24: 4959 | AI24: 2007 | AJ24: 6801 | AK24: 7902 | AL24: 2741 | AM24: 4883 | AN24: 1893 | AO24: 5693 | AP24: 6386 | AQ24: 2289 | AR24: 3739 | AS24: 1880 | AT24: 4517 | AU24: 4805 | AV24: 1744 | AW24: 2876 | AX24: 1891 | AY24: 3771 | AZ24: 1600 | BA24: 594 | BB24: 1022 | BC24: 615 | BD24: 1213

Sheet populations
A1: Column1 | B1: FRN | 2023 Q3 | C1: AN | 2023 Q3 | D1: STG | 2023 Q3 | E1: FLD | 2023 Q3 | F1: ENT | 2023 Q3 | G1: FRN | 2023 Q4 | H1: AN | 2023 Q4 | I1: STG | 2023 Q4 | J1: FLD | 2023 Q4 | K1: ENT | 2023 Q4 | L1: FRN | 2024 Q1 | M1: AN | 2024 Q1 | N1: STG | 2024 Q1 | O1: FLD | 2024 Q1 | P1: ENT | 2024 Q1 | Q1: FRN | 2024 Q2 | R1: AN | 2024 Q2 | S1: STG | 2024 Q2 | T1: FLD | 2024 Q2 | U1: ENT | 2024 Q2 | V1: FRN | 2024 Q3 | W1: AN | 2024 Q3 | X1: STG | 2024 Q3 | Y1: FLD | 2024 Q3 | Z1: ENT | 2024 Q3 | AA1: FRN | 2024 Q4 | AB1: AN | 2024 Q4 | AC1: STG | 2024 Q4 | AD1: FLD | 2024 Q4 | AE1: ENT | 2024 Q4 | AF1: FRN | 2025 Q1 | AG1: AN | 2025 Q1 | AH1: STG | 2025 Q1 | AI1: FLD | 2025 Q1 | AJ1: ENT | 2025 Q1 | AK1: FRN | 2025 Q2 | AL1: AN | 2025 Q2 | AM1: STG | 2025 Q2 | AN1: FLD | 2025 Q2 | AO1: ENT | 2025 Q2 | AP1: FRN | 2025 Q3 | AQ1: AN | 2025 Q3 | AR1: STG | 2025 Q3 | AS1: FLD | 2025 Q3 | AT1: ENT | 2025 Q3 | AU1: FRN | 2025 Q4 | AV1: AN | 2025 Q4 | AW1: STG | 2025 Q4 | AX1: FLD | 2025 Q4 | AY1: ENT | 2025 Q4 | AZ1: FRN | 2026 Q1 | BA1: AN | 2026 Q1 | BB1: STG | 2026 Q1 | BC1: FLD | 2026 Q1 | BD1: ENT | 2026 Q1
A2: prev_co_flag | B2: 0.0017035775 | C2: 0.0023273856 | D2: 0.0014285714 | E2: 0.0015174507 | F2: 0.0015110305 | G2: 0.0023628249 | H2: 0.0019011407 | I2: 0.0023596036 | J2: 0.0014814815 | K2: 0.00056866648 | L2: 0.0020331107 | M2: 0.0031483668 | N2: 0.00085154698 | O2: 0.002240478 | P2: 0.0019600855 | Q2: 0.0018028013 | R2: 0.0030487805 | S2: 0.002341372 | T2: 0.0012128563 | U2: 0.0014789774 | V2: 0.0029422582 | W2: 0.0036787247 | X2: 0.001596424 | Y2: 0.0066162571 | Z2: 0.001369863 | AA2: 0.003471017 | AB2: 0.0024875622 | AC2: 0.0019169329 | AD2: 0.0040858018 | AE2: 0.0015136226 | AF2: 0.0033823186 | AG2: 0.0032017076 | AH2: 0.0034281105 | AI2: 0.0054808171 | AJ2: 0.0017644464 | AK2: 0.0056947608 | AL2: 0.0047427946 | AM2: 0.0036862584 | AN2: 0.0042260961 | AO2: 0.0014052345 | AP2: 0.0029752584 | AQ2: 0.003931848 | AR2: 0.0024070607 | AS2: 0.0015957447 | AT2: 0.0022138588 | AU2: 0.0027055151 | AV2: 0.0028669725 | AW2: 0.0027816412 | AX2: 0.0021152829 | AY2: 0.0034473614 | AZ2: 0.005 | BA2: 0.0033670034 | BB2: 0.0029354207 | BC2: 0.006504065 | BD2: 0.0032976092
A3: small_amt_financed_flag | B3: 0.020017036 | C3: 0.0046547711 | D3: 0.0064285714 | E3: 0.0015174507 | F3: 0 | G3: 0.010501444 | H3: 0.0019011407 | I3: 0.0080226522 | J3: 0.0044444444 | K3: 0 | L3: 0.008422887 | M3: 0.0027548209 | N3: 0.0070962248 | O3: 0.0052277819 | P3: 0 | Q3: 0.0081819443 | R3: 0.0026132404 | S3: 0.0042144697 | T3: 0.0036385688 | U3: 0 | V3: 0.0082751011 | W3: 0.0049049663 | X3: 0.0073435504 | Y3: 0.0018903592 | Z3: 0 | AA3: 0.011107254 | AB3: 0.0018656716 | AC3: 0.0060702875 | AD3: 0.0040858018 | AE3: 0 | AF3: 0.0080475857 | AG3: 0.0028459623 | AH3: 0.0074611817 | AI3: 0.0004982561 | AJ3: 0 | AK3: 0.0082257656 | AL3: 0.0043779642 | AM3: 0.0055293877 | AN3: 0.0015847861 | AO3: 0 | AP3: 0.0075164422 | AQ3: 0.003494976 | AR3: 0.0072211821 | AS3: 0.0021276596 | AT3: 0 | AU3: 0.0085327784 | AV3: 0.0040137615 | AW3: 0.0093880389 | AX3: 0.00052882073 | AY3: 0 | AZ3: 0.01125 | BA3: 0.0050505051 | BB3: 0.010763209 | BC3: 0.0032520325 | BD3: 0
A4: pricing_change_flag | B4: 0 | C4: 0 | D4: 0 | E4: 0 | F4: 0 | G4: 0 | H4: 0 | I4: 0 | J4: 0 | K4: 0 | L4: 0 | M4: 0 | N4: 0 | O4: 0 | P4: 0 | Q4: 0 | R4: 0 | S4: 0 | T4: 0 | U4: 0 | V4: 0 | W4: 0 | X4: 0 | Y4: 0 | Z4: 0 | AA4: 1 | AB4: 1 | AC4: 1 | AD4: 1 | AE4: 1 | AF4: 1 | AG4: 1 | AH4: 1 | AI4: 1 | AJ4: 1 | AK4: 1 | AL4: 1 | AM4: 1 | AN4: 1 | AO4: 1 | AP4: 1 | AQ4: 1 | AR4: 1 | AS4: 1 | AT4: 1 | AU4: 1 | AV4: 1 | AW4: 1 | AX4: 1 | AY4: 1 | AZ4: 1 | BA4: 1 | BB4: 1 | BC4: 1 | BD4: 1
A5: zero_cash_down_flag | B5: 0.0076660988 | C5: 0.015515904 | D5: 0.023571429 | E5: 0.019726859 | F5: 0.066787549 | G5: 0.0094512996 | H5: 0.031685678 | I5: 0.02642756 | J5: 0.034074074 | K5: 0.069661643 | L5: 0.0037757769 | M5: 0.026761118 | N5: 0.020153278 | O5: 0.020911128 | P5: 0.041339986 | Q5: 0.00651782 | R5: 0.019163763 | S5: 0.023179583 | T5: 0.041237113 | U5: 0.035284175 | V5: 0.0073556455 | W5: 0.021459227 | X5: 0.022030651 | Y5: 0.026465028 | Z5: 0.06 | AA5: 0.021173204 | AB5: 0.052238806 | AC5: 0.049201278 | AD5: 0.062308478 | AE5: 0.12512614 | AF5: 0.011663168 | AG5: 0.038776236 | AH5: 0.036902601 | AI5: 0.069755855 | AJ5: 0.10248493 | AK5: 0.013793976 | AL5: 0.045968625 | AM5: 0.04505427 | AN5: 0.0681458 | AO5: 0.1203232 | AP5: 0.024898215 | AQ5: 0.081695063 | AR5: 0.055362396 | AS5: 0.1143617 | AT5: 0.16980297 | AU5: 0.026014568 | AV5: 0.078555046 | AW5: 0.057371349 | AX5: 0.13326282 | AY5: 0.17104216 | AZ5: 0.03125 | BA5: 0.1010101 | BB5: 0.080234834 | BC5: 0.16747967 | BD5: 0.16735367
A6: high_mileage_vehicle_flag | B6: 0.01746167 | C6: 0.045771916 | D6: 0.032142857 | E6: 0.004552352 | F6: 0 | G6: 0.012076661 | H6: 0.043726236 | I6: 0.029259084 | J6: 0.002962963 | K6: 0 | L6: 0.016410107 | M6: 0.033844943 | N6: 0.027817201 | O6: 0.0037341299 | P6: 0 | Q6: 0.0080432672 | R6: 0.018292683 | S6: 0.016389604 | T6: 0.0036385688 | U6: 0 | V6: 0.0034939316 | W6: 0.01594114 | X6: 0.011813538 | Y6: 0.0018903592 | Z6: 0 | AA6: 0.0074626866 | AB6: 0.028606965 | AC6: 0.020766773 | AD6: 0.0030643514 | AE6: 0 | AF6: 0.003965477 | AG6: 0.013874066 | AH6: 0.014922363 | AI6: 0.0074738416 | AJ6: 0 | AK6: 0.0024044546 | AL6: 0.0069317767 | AM6: 0.0055293877 | AN6: 0.0015847861 | AO6: 0 | AP6: 0.0026620733 | AQ6: 0.0078636959 | AR6: 0.0066862798 | AS6: 0.00053191489 | AT6: 0 | AU6: 0.0031217482 | AV6: 0.0068807339 | AW6: 0.004867872 | AX6: 0 | AY6: 0 | AZ6: 0.004375 | BA6: 0.0067340067 | BB6: 0.0029354207 | BC6: 0.0016260163 | BD6: 0
A7: high_pti_flag | B7: 0.0029812606 | C7: 0.0062063615 | D7: 0.0028571429 | E7: 0.019726859 | F7: 0.020550015 | G7: 0.0023628249 | H7: 0.0019011407 | I7: 0.0014157622 | J7: 0.0074074074 | K7: 0.015353995 | L7: 0.0015974441 | M7: 0.0043290043 | N7: 0.001419245 | O7: 0.0044809559 | P7: 0.0092658589 | Q7: 0.0016641243 | R7: 0.0026132404 | S7: 0.0042144697 | T7: 0.0054578532 | U7: 0.012676949 | V7: 0.0023905848 | W7: 0.0061312078 | X7: 0.0051085568 | Y7: 0.0056710775 | Z7: 0.012328767 | AA7: 0.004685873 | AB7: 0.006840796 | AC7: 0.0067092652 | AD7: 0.0051072523 | AE7: 0.018668012 | AF7: 0.0044320037 | AG7: 0.0042689434 | AH7: 0.0058479532 | AI7: 0.0099651221 | AJ7: 0.015880018 | AK7: 0.0058213111 | AL7: 0.0065669464 | AM7: 0.010034815 | AN7: 0.0089804543 | AO7: 0.020551555 | AP7: 0.0079862199 | AQ7: 0.005242464 | AR7: 0.0082909869 | AS7: 0.012234043 | AT7: 0.018153642 | AU7: 0.0072840791 | AV7: 0.0051605505 | AW7: 0.0079972184 | AX7: 0.013220518 | AY7: 0.014319809 | AZ7: 0.0025 | BA7: 0.0067340067 | BB7: 0.0039138943 | BC7: 0.006504065 | BD7: 0.018136851
A8: car_make_penalty_flag | B8: 0.0025553663 | C8: 0.0069821567 | D8: 0.0014285714 | E8: 0.0015174507 | F8: 0.0060441221 | G8: 0.0023628249 | H8: 0.0057034221 | I8: 0.0056630486 | J8: 0.002962963 | K8: 0.001137333 | L8: 0.006099332 | M8: 0.0074773711 | N8: 0.0036900369 | O8: 0.002240478 | P8: 0.0017818959 | Q8: 0.0019414783 | R8: 0.00087108014 | S8: 0.0014048232 | T8: 0 | U8: 0.0014789774 | V8: 0 | W8: 0.0030656039 | X8: 0.0006385696 | Y8: 0.00094517958 | Z8: 0.0002739726 | AA8: 0.00017355085 | AB8: 0.0018656716 | AC8: 0.00063897764 | AD8: 0 | AE8: 0.0012613522 | AF8: 0.00058315839 | AG8: 0.0014229811 | AH8: 0.0016132285 | AI8: 0 | AJ8: 0.0001470372 | AK8: 0.00025310048 | AL8: 0.0018241518 | AM8: 0.0010239607 | AN8: 0 | AO8: 0.00052696294 | AP8: 0 | AQ8: 0 | AR8: 0.0010698048 | AS8: 0.00053191489 | AT8: 0.00022138588 | AU8: 0.00083246618 | AV8: 0.001146789 | AW8: 0.0010431154 | AX8: 0 | AY8: 0.00026518165 | AZ8: 0 | BA8: 0 | BB8: 0 | BC8: 0 | BD8: 0
A9: car_make_benefit_flag | B9: 0.120954 | C9: 0.15360745 | D9: 0.13642857 | E9: 0.15933232 | F9: 0.038984587 | G9: 0.1076398 | H9: 0.1774398 | I9: 0.1571496 | J9: 0.13777778 | K9: 0.068808644 | L9: 0.10049376 | M9: 0.1751279 | N9: 0.17059324 | O9: 0.13144137 | P9: 0.053991447 | Q9: 0.12661212 | R9: 0.19686411 | S9: 0.18332943 | T9: 0.13159491 | U9: 0.076484259 | V9: 0.15189408 | W9: 0.22011036 | X9: 0.21551724 | Y9: 0.16162571 | Z9: 0.098082192 | AA9: 0.22283929 | AB9: 0.24502488 | AC9: 0.24472843 | AD9: 0.20837589 | AE9: 0.1450555 | AF9: 0.24399347 | AG9: 0.23479189 | AH9: 0.24541238 | AI9: 0.20627803 | AJ9: 0.17762094 | AK9: 0.25828904 | AL9: 0.26012404 | AM9: 0.28322752 | AN9: 0.24352879 | AO9: 0.26330581 | AP9: 0.27481992 | AQ9: 0.29925732 | AR9: 0.29045199 | AS9: 0.24574468 | AT9: 0.28315253 | AU9: 0.32362123 | AV9: 0.31594037 | AW9: 0.35083449 | AX9: 0.25171867 | AY9: 0.33678069 | AZ9: 0.321875 | BA9: 0.34343434 | BB9: 0.39334638 | BC9: 0.24715447 | BD9: 0.33140973
A10: theft_risk_flag | B10: 0.054940375 | C10: 0.047323507 | D10: 0.056428571 | E10: 0.071320182 | F10: 0.18011484 | G10: 0.058020478 | H10: 0.050697085 | I10: 0.048607834 | J10: 0.066666667 | K10: 0.1103213 | L10: 0.074208539 | M10: 0.05785124 | N10: 0.063582174 | O10: 0.086631815 | P10: 0.08784747 | Q10: 0.063098045 | R10: 0.051393728 | S10: 0.050105362 | T10: 0.088538508 | U10: 0.070357067 | V10: 0.060316293 | W10: 0.03923973 | X10: 0.032247765 | Y10: 0.059546314 | Z10: 0.04 | AA10: 0.055536272 | AB10: 0.052860697 | AC10: 0.042811502 | AD10: 0.040858018 | AE10: 0.025731584 | AF10: 0.055749942 | AG10: 0.052650302 | AH10: 0.04759024 | AI10: 0.064275037 | AJ10: 0.0092633436 | AK10: 0.050366996 | AL10: 0.046333455 | AM10: 0.045668646 | AN10: 0.06550449 | AO10: 0.0075531354 | AP10: 0.038678359 | AQ10: 0.03713412 | AR10: 0.044396898 | AS10: 0.058510638 | AT10: 0.0044277175 | AU10: 0.024765869 | AV10: 0.047591743 | AW10: 0.031293463 | AX10: 0.03648863 | AY10: 0.0026518165 | AZ10: 0.028125 | BA10: 0.043771044 | BB10: 0.034246575 | BC10: 0.03902439 | BD10: 0.0032976092
A11: mcy_low_mileage_flag | B11: 0 | C11: 0 | D11: 0 | E11: 0 | F11: 0 | G11: 0 | H11: 0 | I11: 0 | J11: 0 | K11: 0 | L11: 0 | M11: 0 | N11: 0 | O11: 0 | P11: 0 | Q11: 0 | R11: 0 | S11: 0 | T11: 0 | U11: 0 | V11: 0 | W11: 0 | X11: 0 | Y11: 0 | Z11: 0 | AA11: 0 | AB11: 0 | AC11: 0 | AD11: 0 | AE11: 0 | AF11: 0 | AG11: 0 | AH11: 0 | AI11: 0 | AJ11: 0 | AK11: 0 | AL11: 0 | AM11: 0 | AN11: 0 | AO11: 0 | AP11: 0 | AQ11: 0 | AR11: 0 | AS11: 0 | AT11: 0 | AU11: 0 | AV11: 0 | AW11: 0 | AX11: 0 | AY11: 0 | AZ11: 0 | BA11: 0 | BB11: 0 | BC11: 0 | BD11: 0
A12: weekend_flag | B12: 0.22359455 | C12: 0.28394104 | D12: 0.24214286 | E12: 0.30955994 | F12: 0.16651556 | G12: 0.21606721 | H12: 0.27629911 | I12: 0.25908447 | J12: 0.31555556 | K12: 0.21438726 | L12: 0.22741795 | M12: 0.27587564 | N12: 0.25915413 | O12: 0.26661688 | P12: 0.21650036 | Q12: 0.23186798 | R12: 0.28397213 | S12: 0.26106298 | T12: 0.26986052 | U12: 0.19099937 | V12: 0.2469658 | W12: 0.27835684 | X12: 0.26149425 | Y12: 0.2268431 | Z12: 0.2109589 | AA12: 0.2552933 | AB12: 0.29166667 | AC12: 0.26805112 | AD12: 0.28396323 | AE12: 0.21316852 | AF12: 0.28283182 | AG12: 0.32692992 | AH12: 0.29118774 | AI12: 0.30293971 | AJ12: 0.24275842 | AK12: 0.26955201 | AL12: 0.31229478 | AM12: 0.28507065 | AN12: 0.28843106 | AO12: 0.22554014 | AP12: 0.2730974 | AQ12: 0.29008301 | AR12: 0.27895159 | AS12: 0.28510638 | AT12: 0.21651539 | AU12: 0.28969823 | AV12: 0.32224771 | AW12: 0.30180807 | AX12: 0.29613961 | AY12: 0.22460886 | AZ12: 0.294375 | BA12: 0.33333333 | BB12: 0.30332681 | BC12: 0.29105691 | BD12: 0.24484749
A13: weekday_flag | B13: 0.77640545 | C13: 0.71605896 | D13: 0.75785714 | E13: 0.69044006 | F13: 0.83348444 | G13: 0.78393279 | H13: 0.72370089 | I13: 0.74091553 | J13: 0.68444444 | K13: 0.78561274 | L13: 0.77258205 | M13: 0.72412436 | N13: 0.74084587 | O13: 0.73338312 | P13: 0.78349964 | Q13: 0.76813202 | R13: 0.71602787 | S13: 0.73893702 | T13: 0.73013948 | U13: 0.80900063 | V13: 0.7530342 | W13: 0.72164316 | X13: 0.73850575 | Y13: 0.7731569 | Z13: 0.7890411 | AA13: 0.7447067 | AB13: 0.70833333 | AC13: 0.73194888 | AD13: 0.71603677 | AE13: 0.78683148 | AF13: 0.71716818 | AG13: 0.67307008 | AH13: 0.70881226 | AI13: 0.69706029 | AJ13: 0.75724158 | AK13: 0.73044799 | AL13: 0.68770522 | AM13: 0.71492935 | AN13: 0.71156894 | AO13: 0.77445986 | AP13: 0.7269026 | AQ13: 0.70991699 | AR13: 0.72104841 | AS13: 0.71489362 | AT13: 0.78348461 | AU13: 0.71030177 | AV13: 0.67775229 | AW13: 0.69819193 | AX13: 0.70386039 | AY13: 0.77539114 | AZ13: 0.705625 | BA13: 0.66666667 | BB13: 0.69667319 | BC13: 0.70894309 | BD13: 0.75515251
... A25: --- N_RECORDS | B25: 2348 | C25: 1289 | D25: 1400 | E25: 659 | F25: 3309 | G25: 3809 | H25: 1578 | I25: 2119 | J25: 675 | K25: 3517 | L25: 6886 | M25: 2541 | N25: 3523 | O25: 1339 | P25: 5612 | Q25: 7211 | R25: 2296 | S25: 4271 | T25: 1649 | U25: 4733 | V25: 5438 | W25: 1631 | X25: 3132 | Y25: 1058 | Z25: 3650 | AA25: 5762 | AB25: 1608 | AC25: 3130 | AD25: 979 | AE25: 3964 | AF25: 8574 | AG25: 2811 | AH25: 4959 | AI25: 2007 | AJ25: 6801 | AK25: 7902 | AL25: 2741 | AM25: 4883 | AN25: 1893 | AO25: 5693 | AP25: 6386 | AQ25: 2289 | AR25: 3739 | AS25: 1880 | AT25: 4517 | AU25: 4805 | AV25: 1744 | AW25: 2876 | AX25: 1891 | AY25: 3771 | AZ25: 1600 | BA25: 594 | BB25: 1022 | BC25: 615 | BD25: 1213

Sheet ragu
B1: =_xlfn.CONCAT($A$2," ",B2) | C1: =_xlfn.CONCAT($A$2," ",C2) | D1: =_xlfn.CONCAT($A$2," ",D2) | E1: =_xlfn.CONCAT($A$2," ",E2) | F1: =_xlfn.CONCAT($A$2," ",F2) | G1: =_xlfn.CONCAT($A$2," ",G2) | H1: =_xlfn.CONCAT($A$2," ",H2) | I1: =_xlfn.CONCAT($A$2," ",I2) | ... L1: =_xlfn.CONCAT($A$2," ",L2) | M1: =_xlfn.CONCAT($A$11," ",M2) | N1: =_xlfn.CONCAT($A$11," ",N2) | O1: =_xlfn.CONCAT($A$11," ",O2) | P1: =_xlfn.CONCAT($A$11," ",P2) | Q1: =_xlfn.CONCAT($A$11," ",Q2) | R1: =_xlfn.CONCAT($A$11," ",R2) | S1: =_xlfn.CONCAT($A$11," ",S2) | T1: =_xlfn.CONCAT($A$11," ",T2) | ... W1: =_xlfn.CONCAT($A$11," ",W2) | X1: =_xlfn.CONCAT($A$21," ",X2) | Y1: =_xlfn.CONCAT($A$21," ",Y2) | Z1: =_xlfn.CONCAT($A$21," ",Z2) | AA1: =_xlfn.CONCAT($A$21," ",AA2) | AB1: =_xlfn.CONCAT($A$21," ",AB2) | AC1: =_xlfn.CONCAT($A$21," ",AC2) | AD1: =_xlfn.CONCAT($A$21," ",AD2) | AE1: =_xlfn.CONCAT($A$21," ",AE2) | ... AH1: =_xlfn.CONCAT($A$21," ",AH2) | AI1: =_xlfn.CONCAT($A$30," ",AI2) | AJ1: =_xlfn.CONCAT($A$30," ",AJ2) | AK1: =_xlfn.CONCAT($A$30," ",AK2) | AL1: =_xlfn.CONCAT($A$30," ",AL2) | AM1: =_xlfn.CONCAT($A$30," ",AM2) | AN1: =_xlfn.CONCAT($A$30," ",AN2) | AO1: =_xlfn.CONCAT($A$30," ",AO2) | AP1: =_xlfn.CONCAT($A$30," ",AP2) | ... AS1: =_xlfn.CONCAT($A$30," ",AS2) | AT1: =_xlfn.CONCAT($A$41," ",AT2) | AU1: =_xlfn.CONCAT($A$41," ",AU2) | AV1: =_xlfn.CONCAT($A$41," ",AV2) | AW1: =_xlfn.CONCAT($A$41," ",AW2) | AX1: =_xlfn.CONCAT($A$41," ",AX2) | AY1: =_xlfn.CONCAT($A$41," ",AY2) | AZ1: =_xlfn.CONCAT($A$41," ",AZ2) | BA1: =_xlfn.CONCAT($A$41," ",BA2) | ... BD1: =_xlfn.CONCAT($A$41," ",BD2)
A2: AN | B2: 2023 Q3 | C2: 2023 Q4 | D2: 2024 Q1 | E2: 2024 Q2 | F2: 2024 Q3 | G2: 2024 Q4 | H2: 2025 Q1 | I2: 2025 Q2 | J2: 2025 Q3 | K2: 2025 Q4 | L2: 2026 Q1 | M2: 2023 Q3 | N2: 2023 Q4 | O2: 2024 Q1 | P2: 2024 Q2 | Q2: 2024 Q3 | R2: 2024 Q4 | S2: 2025 Q1 | T2: 2025 Q2 | U2: 2025 Q3 | V2: 2025 Q4 | W2: 2026 Q1 | X2: 2023 Q3 | Y2: 2023 Q4 | Z2: 2024 Q1 | AA2: 2024 Q2 | AB2: 2024 Q3 | AC2: 2024 Q4 | AD2: 2025 Q1 | AE2: 2025 Q2 | AF2: 2025 Q3 | AG2: 2025 Q4 | AH2: 2026 Q1 | AI2: 2023 Q3 | AJ2: 2023 Q4 | AK2: 2024 Q1 | AL2: 2024 Q2 | AM2: 2024 Q3 | AN2: 2024 Q4 | AO2: 2025 Q1 | AP2: 2025 Q2 | AQ2: 2025 Q3 | AR2: 2025 Q4 | AS2: 2026 Q1 | AT2: 2023 Q3 | AU2: 2023 Q4 | AV2: 2024 Q1 | AW2: 2024 Q2 | AX2: 2024 Q3 | AY2: 2024 Q4 | AZ2: 2025 Q1 | BA2: 2025 Q2 | BB2: 2025 Q3 | BC2: 2025 Q4 | BD2: 2026 Q1
A3: ms | B3: 136.43849 | C3: 137.02135 | D3: 136.37212 | E3: 137.12198 | F3: 138.09052 | G3: 136.80136 | H3: 136.83702 | I3: 138.03382 | J3: 138.55808 | K3: 139.3761 | L3: 140.44073 | M3: 140.72103 | N3: 139.02514 | O3: 138.13163 | P3: 140.17356 | Q3: 141.55375 | R3: 139.97097 | S3: 139.83315 | T3: 140.63434 | U3: 140.96388 | V3: 141.85749 | W3: 142.91144 | X3: 138.53984 | Y3: 137.48747 | Z3: 136.76023 | AA3: 137.47802 | AB3: 138.54354 | AC3: 137.20905 | AD3: 136.6684 | AE3: 137.94719 | AF3: 138.66055 | AG3: 140.03752 | AH3: 141.56614 | AI3: 137.95666 | AJ3: 139.5662 | AK3: 138.5244 | AL3: 138.40978 | AM3: 140.36331 | AN3: 138.38769 | AO3: 136.70743 | AP3: 138.3478 | AQ3: 138.1021 | AR3: 138.94555 | AS3: 141.1332 | AT3: 133.76755 | AU3: 135.31367 | AV3: 136.17456 | AW3: 136.8171 | AX3: 136.69241 | AY3: 134.94875 | AZ3: 134.57148 | BA3: 136.41792 | BB3: 137.0063 | BC3: 137.20721 | BD3: 139.55151
A4: gl | B4: 0.7471879 | C4: 0.56488788 | D4: 0.67852359 | E4: 1.1876918 | F4: 0.97152704 | G4: 1.180284 | H4: 1.4683002 | I4: 2.4776027 | J4: 2.9382644 | K4: 3.4961501 | L4: 2.3332048 | M4: 1.6458771 | N4: 0.80231276 | O4: -0.12521506 | P4: 0.31930787 | Q4: 0.761317 | R4: 0.52945382 | S4: 0.68523213 | T4: 1.2784722 | U4: 1.8052574 | V4: 2.9390222 | W4: 2.5514703 | X4: 1.4890728 | Y4: 1.1253509 | Z4: 1.0630595 | AA4: 2.0245554 | AB4: 2.2733806 | AC4: 2.0669291 | AD4: 1.8543413 | AE4: 2.033757 | AF4: 2.2595778 | AG4: 3.1147868 | AH4: 2.5979543 | AI4: 1.0836194 | AJ4: 1.4055179 | AK4: 1.596137 | AL4: 2.4397109 | AM4: 3.2825892 | AN4: 2.9692538 | AO4: 2.413259 | AP4: 2.4952467 | AQ4: 3.0171417 | AR4: 1.8647378 | AS4: 1.6008762 | AT4: -0.63716492 | AU4: 0.15732039 | AV4: -0.58982951 | AW4: -0.32605264 | AX4: -0.47612709 | AY4: -0.2788024 | AZ4: -0.95884076 | BA4: 0.21531176 | BB4: 0.19536934 | BC4: 1.6809929 | BD4: 1.976146
A5: rec | B5: -1.4136354 | C5: -1.5472765 | D5: -1.7109542 | E5: -0.9372902 | F5: -0.87902048 | G5: 0.28454546 | H5: 0.19540391 | I5: 0.76701266 | J5: 0.75510153 | K5: 1.4463265 | L5: 0.88900847 | M5: -1.4993741 | N5: -1.1772882 | O5: -1.6266921 | P5: -1.1902044 | Q5: -0.52517726 | R5: 0.13442814 | S5: 0.25848634 | T5: 0.37109516 | U5: 1.0144541 | V5: 1.6876202 | W5: 1.5074339 | X5: -1.6020033 | Y5: -1.3403709 | Z5: -1.3938753 | AA5: -1.0263043 | AB5: -0.61440042 | AC5: 0.523839 | AD5: 0.2378778 | AE5: 0.49356392 | AF5: 0.99568501 | AG5: 1.4667777 | AH5: 1.3030209 | AI5: -1.5153392 | AJ5: -1.4320807 | AK5: -1.5909144 | AL5: -0.76823536 | AM5: -0.58192997 | AN5: 0.44232336 | AO5: 0.15029169 | AP5: 0.2472084 | AQ5: 0.50401656 | AR5: 1.6058713 | AS5: 1.3832904 | AT5: -3.5287145 | AU5: -2.9984759 | AV5: -3.5895939 | AW5: -3.204689 | AX5: -2.4202094 | AY5: 0.13834392 | AZ5: 1.1069598 | BA5: 0.099570657 | BB5: 0.32921504 | BC5: 1.2115262 | BD5: 0.62228186
A6: ltv | B6: 2.7072148 | C6: 2.2880395 | D6: 2.0027207 | E6: 2.5931537 | F6: 3.7446502 | G6: 3.3881857 | H6: 3.5073793 | I6: 4.0402816 | J6: 3.9702313 | K6: 4.2537913 | L6: 4.0861473 | M6: 5.0332926 | N6: 5.5678321 | O6: 5.235131 | P6: 5.3286289 | Q6: 5.1245756 | R6: 5.2098344 | S6: 5.1666469 | T6: 6.0848516 | U6: 6.1510731 | V6: 6.2080978 | W6: 5.6750128 | X6: 6.1354791 | Y6: 6.0717535 | Z6: 4.5804624 | AA6: 5.1378366 | AB6: 5.7066459 | AC6: 5.5483695 | AD6: 5.2166813 | AE6: 6.1403637 | AF6: 6.0382608 | AG6: 6.2534723 | AH6: 5.2901018 | AI6: 2.4767312 | AJ6: 2.1566317 | AK6: 0.82751227 | AL6: 1.0685351 | AM6: 1.32396 | AN6: 1.3976667 | AO6: 0.86631646 | AP6: 0.47398655 | AQ6: 0.45527757 | AR6: 0.48685779 | AS6: -0.27871139 | AT6: 2.6273819 | AU6: 1.8482391 | AV6: 1.7170448 | AW6: 1.9627113 | AX6: 1.7519385 | AY6: 1.3235352 | AZ6: 1.517698 | BA6: 1.9215073 | BB6: 1.8477536 | BC6: 1.6963273 | BD6: 1.2163821
A7: recltv | B7: =B5+B6 | C7: =C5+C6 | D7: =D5+D6 | E7: =E5+E6 | F7: =F5+F6 | G7: =G5+G6 | H7: =H5+H6 | I7: =I5+I6 | ... BD7: =BD5+BD6
A8: RAGU Score | B8: 138.47926 | C8: 138.327 | D8: 137.34241 | E8: 139.96554 | F8: 141.92768 | G8: 141.65437 | H8: 142.00811 | I8: 145.31872 | J8: 146.22168 | K8: 148.57237 | L8: 147.74909 | M8: 145.90082 | N8: 144.218 | O8: 141.61486 | P8: 144.63129 | Q8: 146.91447 | R8: 145.84469 | S8: 145.94352 | T8: 148.36875 | U8: 149.93467 | V8: 152.69223 | W8: 152.64535 | X8: 144.56238 | Y8: 143.34421 | Z8: 141.00988 | AA8: 143.61411 | AB8: 145.90916 | AC8: 145.34819 | AD8: 143.9773 | AE8: 146.61488 | AF8: 147.95407 | AG8: 150.87255 | AH8: 150.75722 | AI8: 140.00167 | AJ8: 141.69627 | AK8: 139.35713 | AL8: 141.14979 | AM8: 144.38793 | AN8: 143.19693 | AO8: 140.1373 | AP8: 141.56424 | AQ8: 142.07853 | AR8: 142.90302 | AS8: 143.83865 | AT8: 132.22906 | AU8: 134.32075 | AV8: 133.71219 | AW8: 135.24907 | AX8: 135.54801 | AY8: 136.13183 | AZ8: 136.2373 | BA8: 138.65431 | BB8: 139.37863 | BC8: 141.79606 | BD8: 143.36632
A11: FRN
A12: Contract Model Score¹
A13: Shift to FRN 3.1 Score²
A14: Gross Loss Adjustments (Dealer Level, vehicle age, etc.)²
A15: Recovery Adjustments excluding LTV (Mileage, LOB, etc.)³
A16: BBLTV Adjustments⁴
A17: RAGU Score
A21: STG
A22: Contract Model Score¹
A23: Shift to FRN 3.1 Score²
A24: Gross Loss Adjustments (Dealer Level, vehicle age, etc.)²
A25: Recovery Adjustments excluding LTV (Mileage, LOB, etc.)³
... A47: RAGU Score

Sheet fraud
A1: time | B1: lob | C1: neg_fraud | D1: pos_fraud | E1: other_fraud | F1: lookup
A2: 2023 Q3 | B2: FRN | C2: 0.0891 | D2: 0.2678 | E2: 0.643 | F2: =_xlfn.CONCAT(fraud[[#This Row],[lob]], " ",fraud[[#This Row],[time]])
A3: 2023 Q3 | B3: FLD | C3: 0.0634 | D3: 0.2698 | E3: 0.6666 | F3: =_xlfn.CONCAT(fraud[[#This Row],[lob]], " ",fraud[[#This Row],[time]])
A4: 2023 Q3 | B4: KMX | C4: 0.084 | D4: 0.26 | E4: 0.6558 | F4: =_xlfn.CONCAT(fraud[[#This Row],[lob]], " ",fraud[[#This Row],[time]])
A5: 2023 Q3 | B5: ENT | C5: 0.0585 | D5: 0.1723 | E5: 0.769 | F5: =_xlfn.CONCAT(fraud[[#This Row],[lob]], " ",fraud[[#This Row],[time]])
A6: 2023 Q3 | B6: AN | C6: 0.0798 | D6: 0.1857 | E6: 0.7343 | F6: =_xlfn.CONCAT(fraud[[#This Row],[lob]], " ",fraud[[#This Row],[time]])
A7: 2023 Q3 | B7: STG | C7: 0.0881 | D7: 0.22 | E7: 0.6917 | F7: =_xlfn.CONCAT(fraud[[#This Row],[lob]], " ",fraud[[#This Row],[time]])
A8: 2023 Q4 | B8: AN | C8: 0.0905 | D8: 0.1865 | E8: 0.7229 | F8: =_xlfn.CONCAT(fraud[[#This Row],[lob]], " ",fraud[[#This Row],[time]])
A9: 2023 Q4 | B9: FRN | C9: 0.0794 | D9: 0.2455 | E9: 0.675 | F9: =_xlfn.CONCAT(fraud[[#This Row],[lob]], " ",fraud[[#This Row],[time]])
A10: 2023 Q4 | B10: FLD | C10: 0.0937 | D10: 0.2755 | E10: 0.6306 | F10: =_xlfn.CONCAT(fraud[[#This Row],[lob]], " ",fraud[[#This Row],[time]])
A11: 2023 Q4 | B11: KMX | C11: 0.0856 | D11: 0.2775 | E11: 0.6368 | F11: =_xlfn.CONCAT(fraud[[#This Row],[lob]], " ",fraud[[#This Row],[time]])
A12: 2023 Q4 | B12: ENT | C12: 0.0503 | D12: 0.2688 | E12: 0.6807 | F12: =_xlfn.CONCAT(fraud[[#This Row],[lob]], " ",fraud[[#This Row],[time]])
A13: 2023 Q4 | B13: STG | C13: 0.0936 | D13: 0.1773 | E13: 0.7289 | F13: =_xlfn.CONCAT(fraud[[#This Row],[lob]], " ",fraud[[#This Row],[time]])
... A68: 2026 Q1 | B68: ORL | C68: 0 | D68: 0 | E68: 1 | F68: =_xlfn.CONCAT(fraud[[#This Row],[lob]], " ",fraud[[#This Row],[time]])

Sheet dealer
A1: valid_vintage | B1: lob | C1: a_dealers | D1: b_dealers | E1: c_dealers | F1: d_dealers | G1: e_dealers | H1: f_dealers | I1: good_dealer | J1: bad_dealer | K1: lookup
A2: 2026 Q1 | B2: ENT | C2: 0.017 | D2: 0.17613636 | E2: 0.68181818 | F2: 0.125 | G2: 0 | H2: 0 | I2: 0.19313636 | K2: =_xlfn.CONCAT(dll[[#This Row],[lob]], " ", dll[[#This Row],[valid_vintage]])
A3: 2026 Q1 | B3: STG | C3: 0.0264 | D3: 0.23589436 | E3: 0.59903962 | F3: 0.085234094 | G3: 0.044417767 | H3: 0.0090036014 | I3: 0.26229436 | J3: 0.13865546 | K3: =_xlfn.CONCAT(dll[[#This Row],[lob]], " ", dll[[#This Row],[valid_vintage]])
A4: 2026 Q1 | B4: FRN | C4: 0.012 | D4: 0.16746511 | E4: 0.75275984 | F4: 0.040824828 | G4: 0.026036242 | H4: 0.00083315976 | I4: 0.17946511 | J4: 0.06769423 | K4: =_xlfn.CONCAT(dll[[#This Row],[lob]], " ", dll[[#This Row],[valid_vintage]])
A5: 2026 Q1 | B5: AN | C5: 0.0643 | D5: 0.25146199 | E5: 0.56725146 | F5: 0.081871345 | G5: 0.035087719 | H5: 0 | I5: 0.31576199 | J5: 0.11695906 | K5: =_xlfn.CONCAT(dll[[#This Row],[lob]], " ", dll[[#This Row],[valid_vintage]])
A6: 2026 Q1 | B6: FLD | C6: 0.1156 | D6: 0.346875 | E6: 0.475 | F6: 0.0375 | G6: 0.025 | H6: 0 | I6: 0.462475 | J6: 0.0625 | K6: =_xlfn.CONCAT(dll[[#This Row],[lob]], " ", dll[[#This Row],[valid_vintage]])
A7: 2025 Q4 | B7: STG | C7: 0.0264 | D7: 0.21248499 | E7: 0.62605042 | F7: 0.083433373 | G7: 0.042617047 | H7: 0.0090036014 | I7: 0.23888499 | J7: 0.13505402 | K7: =_xlfn.CONCAT(dll[[#This Row],[lob]], " ", dll[[#This Row],[valid_vintage]])
A8: 2025 Q4 | B8: FRN | C8: 0.0093 | D8: 0.17142262 | E8: 0.75796709 | F8: 0.03478442 | G8: 0.026036242 | H8: 0.00041657988 | I8: 0.18072262 | J8: 0.061237242 | K8: =_xlfn.CONCAT(dll[[#This Row],[lob]], " ", dll[[#This Row],[valid_vintage]])
A9: 2025 Q4 | B9: AN | C9: 0.0672 | D9: 0.25146199 | E9: 0.54678363 | F9: 0.099415205 | G9: 0.035087719 | H9: 0 | I9: 0.31866199 | J9: 0.13450292 | K9: =_xlfn.CONCAT(dll[[#This Row],[lob]], " ", dll[[#This Row],[valid_vintage]])
A10: 2025 Q4 | B10: FLD | C10: 0.1093 | D10: 0.425 | E10: 0.40625 | F10: 0.0375 | G10: 0.01875 | H10: 0.003125 | I10: 0.5343 | J10: 0.059375 | K10: =_xlfn.CONCAT(dll[[#This Row],[lob]], " ", dll[[#This Row],[valid_vintage]])
A11: 2025 Q4 | B11: ENT | C11: 0 | D11: 0.17613636 | E11: 0.69318182 | F11: 0.13068182 | G11: 0 | H11: 0 | I11: 0.17613636 | J11: 0.13068182 | K11: =_xlfn.CONCAT(dll[[#This Row],[lob]], " ", dll[[#This Row],[valid_vintage]])
A12: 2025 Q3 | B12: AN | C12: 0.0351 | D12: 0.28445748 | E12: 0.56304985 | F12: 0.090909091 | G12: 0.026392962 | H12: 0 | I12: 0.31955748 | J12: 0.11730205 | K12: =_xlfn.CONCAT(dll[[#This Row],[lob]], " ", dll[[#This Row],[valid_vintage]])
A13: 2025 Q3 | B13: FRN | C13: 0.0099 | D13: 0.16060093 | E13: 0.75243335 | F13: 0.052475667 | G13: 0.024121879 | H13: 0.00042319086 | I13: 0.17050093 | J13: 0.077020736 | K13: =_xlfn.CONCAT(dll[[#This Row],[lob]], " ", dll[[#This Row],[valid_vintage]])
A14: 2025 Q3 | B14: ENT | C14: 0 | D14: 0.21590909 | E14: 0.51136364 | F14: 0.24431818 | G14: 0.028409091 | H14: 0 | I14: 0.21590909 | J14: 0.27272727 | K14: =_xlfn.CONCAT(dll[[#This Row],[lob]], " ", dll[[#This Row],[valid_vintage]])
... A188: 2016 Q1 | B188: STG | C188: 0.0283 | D188: 0.35460993 | E188: 0.54609929 | F188: 0.063829787 | G188: 0.0070921986 | H188: 0 | I188: 0.38290993 | J188: 0.070921986 | K188: =_xlfn.CONCAT(dll[[#This Row],[lob]], " ", dll[[#This Row],[valid_vintage]])

Sheet tc
A1: vintage | B1: lob | C1: dq_3 | D1: dq_6 | E1: co_6 | F1: co_12 | G1: lookup
A2: 2023 Q3 | B2: AN | C2: 0.1846 | D2: 0.1658 | E2: 0.0528 | F2: 0.1322 | G2: =_xlfn.CONCAT(dq[[#This Row],[lob]]," ", dq[[#This Row],[vintage]])
A3: 2023 Q4 | B3: AN | C3: 0.1478 | D3: 0.138 | E3: 0.038 | F3: 0.1305 | G3: =_xlfn.CONCAT(dq[[#This Row],[lob]]," ", dq[[#This Row],[vintage]])
A4: 2024 Q1 | B4: AN | C4: 0.1518 | D4: 0.1625 | E4: 0.0364 | F4: 0.1368 | G4: =_xlfn.CONCAT(dq[[#This Row],[lob]]," ", dq[[#This Row],[vintage]])
A5: 2024 Q2 | B5: AN | C5: 0.1709 | D5: 0.1747 | E5: 0.0446 | F5: 0.1401 | G5: =_xlfn.CONCAT(dq[[#This Row],[lob]]," ", dq[[#This Row],[vintage]])
A6: 2024 Q3 | B6: AN | C6: 0.1679 | D6: 0.1688 | E6: 0.0449 | F6: 0.142 | G6: =_xlfn.CONCAT(dq[[#This Row],[lob]]," ", dq[[#This Row],[vintage]])
A7: 2024 Q4 | B7: AN | C7: 0.1683 | D7: 0.1494 | E7: 0.0358 | F7: 0.1521 | G7: =_xlfn.CONCAT(dq[[#This Row],[lob]]," ", dq[[#This Row],[vintage]])
A8: 2025 Q1 | B8: AN | C8: 0.1923 | D8: 0.1858 | E8: 0.0484 | F8: 0.1579 | G8: =_xlfn.CONCAT(dq[[#This Row],[lob]]," ", dq[[#This Row],[vintage]])
A9: 2025 Q2 | B9: AN | C9: 0.1683 | D9: 0.1775 | E9: 0.0382 | G9: =_xlfn.CONCAT(dq[[#This Row],[lob]]," ", dq[[#This Row],[vintage]])
A10: 2025 Q3 | B10: AN | C10: 0.1724 | D10: 0.1693 | E10: 0.0265 | G10: =_xlfn.CONCAT(dq[[#This Row],[lob]]," ", dq[[#This Row],[vintage]])
A11: 2023 Q3 | B11: ENT | C11: 0.1628 | D11: 0.1814 | E11: 0.0348 | F11: 0.1416 | G11: =_xlfn.CONCAT(dq[[#This Row],[lob]]," ", dq[[#This Row],[vintage]])
A12: 2023 Q4 | B12: ENT | C12: 0.1561 | D12: 0.1573 | E12: 0.0307 | F12: 0.1298 | G12: =_xlfn.CONCAT(dq[[#This Row],[lob]]," ", dq[[#This Row],[vintage]])
A13: 2024 Q1 | B13: ENT | C13: 0.1618 | D13: 0.181 | E13: 0.0322 | F13: 0.1311 | G13: =_xlfn.CONCAT(dq[[#This Row],[lob]]," ", dq[[#This Row],[vintage]])
